Workbook

Sheet 預測IC
A1: Predict
B2: Time | C2: 2013/12 | D2: 2014/01 | E2: 2014/02 | F2: 2014/03 | G2: 2014/04 | H2: 2014/05 | I2: 2014/06 | J2: 2014/07 | K2: 2014/08 | L2: 2014/09 | M2: 2014/10 | N2: 2014/11 | O2: 2014/12 | P2: 2015/01 | Q2: 2015/02 | R2: 2015/03 | S2: 2015/04 | T2: 2015/05 | U2: 2015/06 | V2: 2015/07 | W2: 2015/08 | X2: 2015/09 | Y2: 2015/10 | Z2: 2015/11 | AA2: 2015/12 | AB2: 2016/01 | AC2: 2016/02 | AD2: 2016/03 | AE2: 2016/04 | AF2: 2016/05 | AG2: 2016/06 | AH2: 2016/07 | AI2: 2016/08 | AJ2: 2016/09 | AK2: 2016/10 | AL2: 2016/11 | AM2: 2016/12 | AN2: 2017/01 | AO2: 2017/02 | AP2: 2017/03 | AQ2: 2017/04 | AR2: 2017/05 | AS2: 2017/06 | AT2: 2017/07 | AU2: 2017/08 | AV2: 2017/09 | AW2: 2017/10 | AX2: 2017/11 | AY2: 2017/12 | AZ2: 2018/01 | BA2: 2018/02 | BB2: 2018/03 | BC2: 2018/04 | BD2: 2018/05 | BE2: 2018/06 | BF2: 2018/07 | BG2: 2018/08 | BH2: 2018/09 | BI2: 2018/10 | BJ2: 2018/11 | BK2: 2018/12 | BL2: 2019/01 | BM2: 2019/02 | BN2: 2019/03 | BO2: 2019/04 | BP2: 2019/05 | BQ2: 2019/06 | BR2: 2019/07 | BS2: 2019/08 | BT2: 2019/09 | BU2: 2019/10 | BV2: 2019/11 | BW2: 2019/12 | BX2: 2020/01 | BY2: 2020/02 | BZ2: 2020/03 | CA2: 2020/04 | CB2: 2020/05 | CC2: 2020/06 | CD2: 2020/07 | CE2: 2020/08 | CF2: 2020/09 | CG2: 2020/10 | CH2: 2020/11 | CI2: 2020/12 | CJ2: 2021/01 | CK2: 2021/02 | CL2: 2021/03 | CM2: 2021/04 | CN2: 2021/05 | CO2: 2021/06 | CP2: 2021/07 | CQ2: 2021/08 | CR2: 2021/09 | CS2: 2021/10 | CT2: 2021/11 | CU2: 2021/12 | CV2: 2022/01 | CW2: 2022/02 | CX2: 2022/03 | CY2: 2022/04 | CZ2: 2022/05 | DA2: 2022/06 | DB2: 2022/07 | DC2: 2022/08 | DD2: 2022/09 | DE2: 2022/10 | DF2: 2022/11 | DG2: 2022/12 | DH2: 2023/01 | DI2: 2023/02 | DJ2: 2023/03 | DK2: 2023/04 | DL2: 2023/05 | DM2: 2023/06 | DN2: 2023/07 | DO2: 2023/08 | DP2: 2023/09 | DQ2: 2023/10 | DR2: 2023/11 | DS2: 2023/12 | DT2: 2024/01 | DU2: 2024/02 | DV2: 2024/03 | DW2: 2024/04 | DX2: 2024/05 | DY2: 2024/06 | DZ2: 2024/07 | EA2: 2024/08 | EB2: 2024/09 | EC2: 2024/10 | ED2: 2024/11 | EE2: 2024/12 | EF2: 2025/01
B3: mom1 | C3: 0.1206107 | D3: 0.045588622 | E3: 0.16704505 | F3: -0.073748988 | G3: -0.032506587 | H3: -0.032847119 | I3: -0.12110158 | J3: 0.0025822337 | K3: 0.071968625 | L3: 0.034342712 | M3: 0.040084603 | N3: 0.041563467 | O3: -0.0069002801 | P3: 0.035779379 | Q3: 0.068350636 | R3: -0.045413081 | S3: 0.01967398 | T3: -0.10645092 | U3: -0.032053189 | V3: -0.014865616 | W3: -0.093405071 | X3: -0.037053876 | Y3: -0.047379645 | Z3: -0.035732976 | AA3: 0.074709415 | AB3: -0.10149167 | AC3: -0.00029589017 | AD3: -0.068848797 | AE3: -0.022266032 | AF3: 0.041625472 | AG3: -0.0080508267 | AH3: -0.038264652 | AI3: 0.045184246 | AJ3: 0.034215625 | AK3: 0.044138223 | AL3: -0.035587567 | AM3: -0.013077529 | AN3: 0.004148564 | AO3: -0.07768507 | AP3: -0.0069983939 | AQ3: 0.13094784 | AR3: -0.086792709 | AS3: -0.052702983 | AT3: 0.065228471 | AU3: -0.065193823 | AV3: 0.0085695092 | AW3: -0.040024303 | AX3: -0.031442522 | AY3: -0.0040051979 | AZ3: -0.007879886 | BA3: -0.0060724257 | BB3: -0.011000775 | BC3: -0.026379572 | BD3: 0.039479545 | BE3: 0.031278312 | BF3: -0.0060707145 | BG3: -0.060537315 | BH3: -0.085381434 | BI3: 0.064493155 | BJ3: -0.0062276101 | BK3: 0.046391114 | BL3: -0.011560822 | BM3: -0.044558442 | BN3: 0.0027621487 | BO3: 0.0083121426 | BP3: -0.055860349 | BQ3: 0.03570663 | BR3: -0.022012849 | BS3: 0.039643525 | BT3: -0.0035802524 | BU3: 0.0089809504 | BV3: -0.0089428833 | BW3: -0.076064018 | BX3: -0.040663011 | BY3: -0.059083336 | BZ3: -0.026982576 | CA3: -0.12652495 | CB3: 0.012022261 | CC3: -0.050881431 | CD3: 0.025276041 | CE3: 0.087027484 | CF3: -0.024625967 | CG3: 0.018747262 | CH3: 0.04151248 | CI3: -0.029820276 | CJ3: -0.012665491 | CK3: 0.047987524 | CL3: -0.0066815212 | CM3: 0.023373144 | CN3: 0.010890171 | CO3: 0.14646344 | CP3: 0.019768545 | CQ3: 0.017749236 | CR3: -0.028991521 | CS3: -0.0092105434 | CT3: 0.036848143 | CU3: 0.030504116 | CV3: 0.040383351 | CW3: -0.0093859596 | CX3: -0.077248887 | CY3: 0.0025482207 | CZ3: -0.023356789 | DA3: -0.035608657 | DB3: 0.0044999953 | DC3: -0.043417921 | DD3: 0.077585487 | DE3: 0.045548818 | DF3: -0.073761037 | DG3: -0.013836029 | DH3: -0.013146588 | DI3: -0.11844415 | DJ3: 0.04971576 | DK3: 0.028876918 | DL3: -0.013181525 | DM3: 0.043520521 | DN3: -0.060662479 | DO3: 0.08256415 | DP3: -0.096015988 | DQ3: -0.019845472 | DR3: -0.018579634 | DS3: -0.025784659 | DT3: -0.037591586 | DU3: -0.045291919 | DV3: -0.022458423 | DW3: 0.00027164709 | DX3: -0.064503989 | DY3: 0.06012526 | DZ3: 0.0058245219 | EA3: 0.015503895 | EB3: 0.030904913 | EC3: 0.039813075 | ED3: 0.006018647 | EE3: -0.039888767 | EF3: -0.096081351
B4: mom12 | C4: -0.20935792 | D4: -0.24145621 | E4: 0.26636596 | F4: 0.33022979 | G4: 0.20358638 | H4: 0.55373417 | I4: 0.66979451 | J4: 0.61032591 | K4: 0.86207446 | L4: 0.37355796 | M4: 0.62222012 | N4: 0.29351052 | O4: 0.3562869 | P4: 0.17806893 | Q4: 0.15635752 | R4: 0.2248304 | S4: 0.18264462 | T4: 0.15307368 | U4: 0.22557714 | V4: -0.09158029 | W4: -0.049495832 | X4: -0.26789506 | Y4: -0.36478829 | Z4: -0.37790601 | AA4: -0.43955485 | AB4: -0.41859417 | AC4: -0.31816515 | AD4: -0.20856537 | AE4: -0.10236498 | AF4: -0.14886861 | AG4: -0.18669023 | AH4: -0.25393275 | AI4: -0.14773923 | AJ4: 0.044513506 | AK4: -0.058155621 | AL4: -0.091865238 | AM4: -0.1682627 | AN4: -0.33743701 | AO4: -0.36868153 | AP4: -0.28691959 | AQ4: -0.30523873 | AR4: -0.2933138 | AS4: -0.3026703 | AT4: -0.28045675 | AU4: -0.18262992 | AV4: -0.12130979 | AW4: -0.15372123 | AX4: -0.02163156 | AY4: 0.10122186 | AZ4: 0.18954151 | BA4: 0.095279708 | BB4: 0.011130473 | BC4: 0.19620313 | BD4: 0.15224713 | BE4: 0.209344 | BF4: 0.16752253 | BG4: 0.16855713 | BH4: 0.23475758 | BI4: 0.27598377 | BJ4: 0.26154896 | BK4: 0.1930056 | BL4: 0.032255305 | BM4: 0.084649699 | BN4: -0.015702242 | BO4: 0.029608765 | BP4: -0.082625544 | BQ4: -0.079330451 | BR4: -0.11353413 | BS4: -0.16045061 | BT4: -0.028989653 | BU4: -0.0038417136 | BV4: -0.17414888 | BW4: -0.050655463 | BX4: -0.0097462302 | BY4: 0.043118718 | BZ4: 0.08359471 | CA4: 0.059758542 | CB4: 0.22654685 | CC4: 0.16059562 | CD4: 0.12478222 | CE4: 0.070316847 | CF4: 0.037786686 | CG4: 0.14783135 | CH4: 0.16146329 | CI4: 0.19050379 | CJ4: 0.057810008 | CK4: 0.18159576 | CL4: 0.15995891 | CM4: -0.19344889 | CN4: 0.09266165 | CO4: 0.18420346 | CP4: 0.21509938 | CQ4: 0.07822216 | CR4: 0.23262305 | CS4: 0.12461762 | CT4: 0.2146341 | CU4: 0.29380323 | CV4: 0.16458639 | CW4: 0.22758953 | CX4: 0.30967914 | CY4: 0.10082695 | CZ4: 0.2739919 | DA4: 0.29613632 | DB4: 0.44409378 | DC4: 0.2773995 | DD4: 0.20846194 | DE4: 0.050065625 | DF4: 0.079342541 | DG4: 0.041263423 | DH4: -0.0074014042 | DI4: 0.091903679 | DJ4: 0.18881041 | DK4: 0.0050346205 | DL4: -0.065302736 | DM4: -0.16991943 | DN4: -0.048355536 | DO4: 0.30239134 | DP4: 0.40249618 | DQ4: 0.42337951 | DR4: 0.31958732 | DS4: 0.27007262 | DT4: 0.24555915 | DU4: 0.18374522 | DV4: 0.16882438 | DW4: 0.21735693 | DX4: 0.18716202 | DY4: 0.12863278 | DZ4: 0.11389562 | EA4: 0.069887094 | EB4: 0.12681711 | EC4: 0.15628153 | ED4: 0.36668827 | EE4: 0.4725008 | EF4: 0.72972326
B5: chmom | C5: 0.14158921 | D5: 0.092586945 | E5: 0.11349879 | F5: -0.0073769777 | G5: -0.31863967 | H5: -0.42059899 | I5: -0.61741575 | J5: -0.43362009 | K5: -0.25626772 | L5: -0.2113105 | M5: -0.20647602 | N5: -0.32791237 | O5: 0.015729811 | P5: 0.068442695 | Q5: 0.052648856 | R5: -0.020694613 | S5: 0.02495929 | T5: -0.086843647 | U5: -0.52458473 | V5: -0.47921434 | W5: -0.36348833 | X5: -0.39764648 | Y5: -0.4756211 | Z5: -0.29400139 | AA5: -0.21990455 | AB5: 0.018176812 | AC5: -0.079990064 | AD5: -0.10289298 | AE5: 0.14449675 | AF5: 0.094619546 | AG5: 0.15888809 | AH5: 0.11961817 | AI5: 0.26749724 | AJ5: 0.28042018 | AK5: -0.030700048 | AL5: 0.045908625 | AM5: 0.1749829 | AN5: 0.12715124 | AO5: 0.18467502 | AP5: 0.084214377 | AQ5: 0.19594427 | AR5: 0.13323353 | AS5: 0.16593562 | AT5: 0.020797245 | AU5: 0.012255111 | AV5: -0.013354263 | AW5: -0.16291629 | AX5: 0.021398073 | AY5: -0.31841892 | AZ5: -0.23894029 | BA5: -0.22999541 | BB5: -0.071523536 | BC5: 0.19523407 | BD5: 0.1343817 | BE5: 0.36448653 | BF5: 0.44848254 | BG5: 0.43221301 | BH5: 0.27475197 | BI5: 0.27625006 | BJ5: 0.015584695 | BK5: 0.10580514 | BL5: 0.126551 | BM5: 0.2284809 | BN5: 0.28499472 | BO5: 0.10343621 | BP5: 0.37735476 | BQ5: 0.20037256 | BR5: 0.22737663 | BS5: 0.2800057 | BT5: 0.25048842 | BU5: 0.40950604 | BV5: 0.2791434 | BW5: 0.42338682 | BX5: 0.20681397 | BY5: 0.16995656 | BZ5: 0.25229151 | CA5: 0.32026293 | CB5: 0.51463583 | CC5: 0.18153007 | CD5: 0.1200337 | CE5: -0.025943293 | CF5: 0.045043616 | CG5: -0.35445425 | CH5: -0.25260244 | CI5: 0.14395187 | CJ5: 0.27306771 | CK5: 0.017040846 | CL5: -0.24283421 | CM5: -0.0062585842 | CN5: -0.31007511 | CO5: -0.48661942 | CP5: -0.58562675 | CQ5: -0.21352734 | CR5: -0.16518612 | CS5: -0.15856953 | CT5: -0.2953033 | CU5: -0.12548188 | CV5: -0.047694294 | CW5: -0.069955239 | CX5: -0.0092457956 | CY5: -0.022135305 | CZ5: 0.055799951 | DA5: 0.0046904915 | DB5: -0.19841703 | DC5: -0.14815778 | DD5: -0.078448866 | DE5: -0.034735831 | DF5: 0.23309856 | DG5: 0.10547592 | DH5: 0.2602456 | DI5: 0.24342212 | DJ5: 0.061619871 | DK5: 0.089139844 | DL5: 0.029253194 | DM5: 0.14236144 | DN5: 0.14615257 | DO5: 0.049079226 | DP5: 0.4032296 | DQ5: 0.46524422 | DR5: 0.25491522 | DS5: 0.14490164 | DT5: 0.10964787 | DU5: 0.14664794 | DV5: -0.3751533 | DW5: -0.29741986 | DX5: -0.19544278 | DY5: -0.082428266 | DZ5: 0.058661833 | EA5: -0.046779078 | EB5: 0.16414324 | EC5: -0.038064247 | ED5: 0.055317447 | EE5: 0.045666052 | EF5: -0.015130552
B6: retvol | C6: -0.055287602 | D6: -0.14445299 | E6: -0.091431301 | F6: 0.3549518 | G6: 0.21923638 | H6: 0.2831342 | I6: 0.37143267 | J6: 0.41062409 | K6: 0.40769934 | L6: -0.0071596741 | M6: -0.0073648091 | N6: -0.05151582 | O6: 0.2542621 | P6: 0.25179108 | Q6: 0.22183502 | R6: 0.24564423 | S6: 0.21802587 | T6: 0.22885928 | U6: -0.038365896 | V6: -0.00024933566 | W6: -0.069911431 | X6: -0.064564491 | Y6: 0.041605297 | Z6: -0.019800016 | AA6: -0.072143291 | AB6: -0.068452121 | AC6: 0.032607263 | AD6: 0.017594646 | AE6: -0.0029019286 | AF6: -0.0022483566 | AG6: -0.0055811273 | AH6: -0.0066841359 | AI6: -0.0013854994 | AJ6: -0.00086481173 | AK6: 0.056462115 | AL6: 0.07849301 | AM6: -0.11226929 | AN6: -0.22946842 | AO6: -0.13981329 | AP6: -0.11030393 | AQ6: -0.16861414 | AR6: -0.13718304 | AS6: 0.05211904 | AT6: 0.14234805 | AU6: 0.15576266 | AV6: 0.14491664 | AW6: 0.18538209 | AX6: 0.13665235 | AY6: 0.14596251 | AZ6: 0.2650378 | BA6: 0.14676562 | BB6: 0.0033428218 | BC6: -0.070510317 | BD6: -0.035291447 | BE6: 0.035257595 | BF6: 0.038800415 | BG6: 0.053526723 | BH6: 0.17967628 | BI6: 0.15487119 | BJ6: 0.11905581 | BK6: 0.13032726 | BL6: 0.093330538 | BM6: 0.080284022 | BN6: 0.20761045 | BO6: 0.18768666 | BP6: 0.12992121 | BQ6: 0.098717055 | BR6: 0.045233847 | BS6: 0.13778382 | BT6: 0.046964995 | BU6: 0.078535809 | BV6: 0.12030054 | BW6: 0.059755525 | BX6: 0.063549055 | BY6: -0.0065045111 | BZ6: -0.051668342 | CA6: -0.079185434 | CB6: -0.11278108 | CC6: -0.067050409 | CD6: -0.066787378 | CE6: -0.046564912 | CF6: -0.11929573 | CG6: -0.05315298 | CH6: -0.092611608 | CI6: -0.10903127 | CJ6: -0.065592489 | CK6: -0.088696833 | CL6: 0.089572677 | CM6: 0.065466675 | CN6: 0.02977826 | CO6: 0.0725081 | CP6: -0.013033581 | CQ6: 0.0095695222 | CR6: 0.024795353 | CS6: 0.048612117 | CT6: 0.060893022 | CU6: 0.034381618 | CV6: 0.1698004 | CW6: 0.20445758 | CX6: 0.11667932 | CY6: 0.020058144 | CZ6: -0.0014802745 | DA6: -0.023150115 | DB6: -0.19162966 | DC6: -0.27185177 | DD6: -0.21309613 | DE6: -0.16221912 | DF6: -0.20201256 | DG6: -0.17344116 | DH6: 0.0010129746 | DI6: 0.076205463 | DJ6: 0.068038264 | DK6: 0.058032612 | DL6: 0.0096719985 | DM6: -0.13040706 | DN6: -0.29058271 | DO6: -0.37804696 | DP6: -0.38659982 | DQ6: -0.38856602 | DR6: -0.22251358 | DS6: -0.17879173 | DT6: -0.15458476 | DU6: -0.061360687 | DV6: 0.02797793 | DW6: -0.031911652 | DX6: -0.099874593 | DY6: 0.0034834303 | DZ6: 0.028079827 | EA6: -0.0017876847 | EB6: -0.090286462 | EC6: -0.053357026 | ED6: -0.06524063 | EE6: -0.041521107 | EF6: -0.03506792
B7: maxret | C7: 0.031791852 | D7: -0.12411353 | E7: -0.1855275 | F7: -0.51750513 | G7: -0.47668017 | H7: -0.45722757 | I7: -0.5284488 | J7: -0.42896716 | K7: -0.41261834 | L7: -0.0041638076 | M7: -0.026791836 | N7: -0.1044833 | O7: 0.044211548 | P7: 0.058306596 | Q7: -0.068633319 | R7: 0.039118301 | S7: 0.014309176 | T7: 0.047434316 | U7: -0.0058521477 | V7: -0.084536823 | W7: -0.21030819 | X7: -0.29890893 | Y7: -0.28699682 | Z7: -0.24392936 | AA7: -0.26669381 | AB7: -0.2664948 | AC7: -0.092233352 | AD7: -0.11479514 | AE7: -0.1224079 | AF7: -0.095242339 | AG7: -0.078768449 | AH7: -0.10231022 | AI7: -0.057262344 | AJ7: 0.013756306 | AK7: 0.074954773 | AL7: 0.058691382 | AM7: 0.0053574223 | AN7: 0.011511209 | AO7: 0.043992852 | AP7: 0.013865785 | AQ7: -0.037826594 | AR7: 0.0020397996 | AS7: 0.1357503 | AT7: 0.096260025 | AU7: 0.10985243 | AV7: 0.054049592 | AW7: 0.091063556 | AX7: -0.0033959985 | AY7: -0.071198973 | AZ7: -0.074040979 | BA7: -0.13474835 | BB7: -0.18483968 | BC7: -0.17191627 | BD7: -0.19026125 | BE7: -0.18314879 | BF7: -0.11690615 | BG7: 0.1233003 | BH7: 0.15359622 | BI7: 0.14035134 | BJ7: 0.2346569 | BK7: 0.27295375 | BL7: 0.28953705 | BM7: 0.059430813 | BN7: 0.12537867 | BO7: 0.094402298 | BP7: 0.022123087 | BQ7: 0.038988348 | BR7: 0.039930685 | BS7: 0.042655091 | BT7: 0.036797177 | BU7: 0.076853981 | BV7: 0.086874653 | BW7: 0.045363248 | BX7: 0.033590598 | BY7: 0.050840618 | BZ7: 0.090275438 | CA7: 0.095704211 | CB7: 0.10042372 | CC7: 0.13416849 | CD7: 0.069815282 | CE7: 0.053519808 | CF7: -0.1378676 | CG7: -0.19353121 | CH7: -0.26226848 | CI7: -0.36215999 | CJ7: -0.17238617 | CK7: -0.24049517 | CL7: -0.029835663 | CM7: 0.048473892 | CN7: 0.039346739 | CO7: 0.11640796 | CP7: 0.027954672 | CQ7: 0.11747759 | CR7: 0.029545899 | CS7: 0.010751644 | CT7: 0.051099373 | CU7: 0.10823418 | CV7: 0.10010509 | CW7: 0.082435859 | CX7: 0.14446651 | CY7: 0.015434973 | CZ7: -0.068435942 | DA7: -0.040885148 | DB7: -0.090240153 | DC7: -0.072910137 | DD7: -0.074101524 | DE7: -0.038176172 | DF7: -0.080366391 | DG7: -0.084762822 | DH7: 0.045561826 | DI7: 0.015283929 | DJ7: -0.086368002 | DK7: -0.083284993 | DL7: -0.3107079 | DM7: -0.48915583 | DN7: -0.61713752 | DO7: -0.64241869 | DP7: -0.51612725 | DQ7: -0.53531008 | DR7: -0.20641258 | DS7: -0.036765638 | DT7: -0.02117636 | DU7: -0.10998909 | DV7: -0.083866243 | DW7: -0.17622427 | DX7: -0.25043733 | DY7: -0.15139281 | DZ7: -0.1158378 | EA7: -0.056648241 | EB7: 0.034255182 | EC7: -0.017395651 | ED7: 0.040598599 | EE7: 0.049896274 | EF7: 0.041656706
A8: 選絕對值最大 | C8: {=MATCH(MAX(ABS(C3:C7)), ABS(C3:C7), 0)} -> 2 | D8: {=MATCH(MAX(ABS(D3:D7)), ABS(D3:D7), 0)} -> 2 | E8: {=MATCH(MAX(ABS(E3:E7)), ABS(E3:E7), 0)} -> 2 | F8: {=MATCH(MAX(ABS(F3:F7)), ABS(F3:F7), 0)} -> 5 | G8: {=MATCH(MAX(ABS(G3:G7)), ABS(G3:G7), 0)} -> 5 | H8: {=MATCH(MAX(ABS(H3:H7)), ABS(H3:H7), 0)} -> 2 | I8: {=MATCH(MAX(ABS(I3:I7)), ABS(I3:I7), 0)} -> 2 | J8: {=MATCH(MAX(ABS(J3:J7)), ABS(J3:J7), 0)} -> 2 | ... EE8: {=MATCH(MAX(ABS(EE3:EE7)), ABS(EE3:EE7), 0)} -> 2 | EF8: 2
C9: =IF(C8=1,"mom1", IF(C8=2,"mom12", IF(C8=3,"chmom", IF(C8=4,"retvol", IF(C8=5,"maxret",""))))) -> mom12 | D9: =IF(D8=1,"mom1", IF(D8=2,"mom12", IF(D8=3,"chmom", IF(D8=4,"retvol", IF(D8=5,"maxret",""))))) -> mom12 | E9: =IF(E8=1,"mom1", IF(E8=2,"mom12", IF(E8=3,"chmom", IF(E8=4,"retvol", IF(E8=5,"maxret",""))))) -> mom12 | F9: =IF(F8=1,"mom1", IF(F8=2,"mom12", IF(F8=3,"chmom", IF(F8=4,"retvol", IF(F8=5,"maxret",""))))) -> maxret | G9: =IF(G8=1,"mom1", IF(G8=2,"mom12", IF(G8=3,"chmom", IF(G8=4,"retvol", IF(G8=5,"maxret",""))))) -> maxret | H9: =IF(H8=1,"mom1", IF(H8=2,"mom12", IF(H8=3,"chmom", IF(H8=4,"retvol", IF(H8=5,"maxret",""))))) -> mom12 | I9: =IF(I8=1,"mom1", IF(I8=2,"mom12", IF(I8=3,"chmom", IF(I8=4,"retvol", IF(I8=5,"maxret",""))))) -> mom12 | J9: =IF(J8=1,"mom1", IF(J8=2,"mom12", IF(J8=3,"chmom", IF(J8=4,"retvol", IF(J8=5,"maxret",""))))) -> mom12 | ... EF9: =IF(EF8=1,"mom1", IF(EF8=2,"mom12", IF(EF8=3,"chmom", IF(EF8=4,"retvol", IF(EF8=5,"maxret",""))))) -> mom12
C10: =IF(C8=1,C3,IF(C8=2,C4,IF(C8=3,C5,IF(C8=4,C6,IF(C8=5,C7))))) -> -0.20935792 | D10: =IF(D8=1,D3,IF(D8=2,D4,IF(D8=3,D5,IF(D8=4,D6,IF(D8=5,D7))))) -> -0.24145621 | E10: =IF(E8=1,E3,IF(E8=2,E4,IF(E8=3,E5,IF(E8=4,E6,IF(E8=5,E7))))) -> 0.26636596 | F10: =IF(F8=1,F3,IF(F8=2,F4,IF(F8=3,F5,IF(F8=4,F6,IF(F8=5,F7))))) -> -0.51750513 | G10: =IF(G8=1,G3,IF(G8=2,G4,IF(G8=3,G5,IF(G8=4,G6,IF(G8=5,G7))))) -> -0.47668017 | H10: =IF(H8=1,H3,IF(H8=2,H4,IF(H8=3,H5,IF(H8=4,H6,IF(H8=5,H7))))) -> 0.55373417 | I10: =IF(I8=1,I3,IF(I8=2,I4,IF(I8=3,I5,IF(I8=4,I6,IF(I8=5,I7))))) -> 0.66979451 | J10: =IF(J8=1,J3,IF(J8=2,J4,IF(J8=3,J5,IF(J8=4,J6,IF(J8=5,J7))))) -> 0.61032591 | ... EF10: =IF(EF8=1,EF3,IF(EF8=2,EF4,IF(EF8=3,EF5,IF(EF8=4,EF6,IF(EF8=5,EF7))))) -> 0.72972326
A12: 投資組合 | C12: 公司數 | D12: 964
A13: 等分 | B13: 家數 | C13: 2014/01 | D13: 2014/02 | E13: 2014/03 | F13: 2014/04 | G13: 2014/05 | H13: 2014/06 | I13: 2014/07 | J13: 2014/08 | K13: 2014/09 | L13: 2014/10 | M13: 2014/11 | N13: 2014/12 | O13: 2015/01 | P13: 2015/02 | Q13: 2015/03 | R13: 2015/04 | S13: 2015/05 | T13: 2015/06 | U13: 2015/07 | V13: 2015/08 | W13: 2015/09 | X13: 2015/10 | Y13: 2015/11 | Z13: 2015/12 | AA13: 2016/01 | AB13: 2016/02 | AC13: 2016/03 | AD13: 2016/04 | AE13: 2016/05 | AF13: 2016/06 | AG13: 2016/07 | AH13: 2016/08 | AI13: 2016/09 | AJ13: 2016/10 | AK13: 2016/11 | AL13: 2016/12 | AM13: 2017/01 | AN13: 2017/02 | AO13: 2017/03 | AP13: 2017/04 | AQ13: 2017/05 | AR13: 2017/06 | AS13: 2017/07 | AT13: 2017/08 | AU13: 2017/09 | AV13: 2017/10 | AW13: 2017/11 | AX13: 2017/12 | AY13: 2018/01 | AZ13: 2018/02 | BA13: 2018/03 | BB13: 2018/04 | BC13: 2018/05 | BD13: 2018/06 | BE13: 2018/07 | BF13: 2018/08 | BG13: 2018/09 | BH13: 2018/10 | BI13: 2018/11 | BJ13: 2018/12 | BK13: 2019/01 | BL13: 2019/02 | BM13: 2019/03 | BN13: 2019/04 | BO13: 2019/05 | BP13: 2019/06 | BQ13: 2019/07 | BR13: 2019/08 | BS13: 2019/09 | BT13: 2019/10 | BU13: 2019/11 | BV13: 2019/12 | BW13: 2020/01 | BX13: 2020/02 | BY13: 2020/03 | BZ13: 2020/04 | CA13: 2020/05 | CB13: 2020/06 | CC13: 2020/07 | CD13: 2020/08 | CE13: 2020/09 | CF13: 2020/10 | CG13: 2020/11 | CH13: 2020/12 | CI13: 2021/01 | CJ13: 2021/02 | CK13: 2021/03 | CL13: 2021/04 | CM13: 2021/05 | CN13: 2021/06 | CO13: 2021/07 | CP13: 2021/08 | CQ13: 2021/09 | CR13: 2021/10 | CS13: 2021/11 | CT13: 2021/12 | CU13: 2022/01 | CV13: 2022/02 | CW13: 2022/03 | CX13: 2022/04 | CY13: 2022/05 | CZ13: 2022/06 | DA13: 2022/07 | DB13: 2022/08 | DC13: 2022/09 | DD13: 2022/10 | DE13: 2022/11 | DF13: 2022/12 | DG13: 2023/01 | DH13: 2023/02 | DI13: 2023/03 | DJ13: 2023/04 | DK13: 2023/05 | DL13: 2023/06 | DM13: 2023/07 | DN13: 2023/08 | DO13: 2023/09 | DP13: 2023/10 | DQ13: 2023/11 | DR13: 2023/12 | DS13: 2024/01 | DT13: 2024/02 | DU13: 2024/03 | DV13: 2024/04 | DW13: 2024/05 | DX13: 2024/06 | DY13: 2024/07 | DZ13: 2024/08 | EA13: 2024/09 | EB13: 2024/10 | EC13: 2024/11 | ED13: 2024/12 | EE13: 2025/01 | EF13: 2025/02
A14: 10 | B14: 96 | C14: 0.014499247 | D14: -0.014678551 | E14: -0.0013937245 | F14: -0.0076284164 | G14: -0.0055955579 | H14: 0.0095992584 | I14: -0.0086581523 | J14: 0.0073897937 | K14: 0.029187998 | L14: 0.008758556 | M14: 0.026889174 | N14: -0.064808654 | O14: 0.027914759 | P14: 0.0016005017 | Q14: 0.021755609 | R14: -0.034229864 | S14: 0.0116392 | T14: -0.022313576 | U14: -0.016909795 | V14: 0.0071207345 | W14: -0.022328288 | X14: -0.10636944 | Y14: 0.03641629 | Z14: 0.053152087 | AA14: -0.026918479 | AB14: -0.01073333 | AC14: 0.046772946 | AD14: 0.0025304298 | AE14: -0.037855001 | AF14: 0.052012103 | AG14: 0.0038149304 | AH14: 0.015713034 | AI14: 0.0075237895 | AJ14: -0.0091496766 | AK14: -0.022643045 | AL14: 0.04780049 | AM14: -0.028540928 | AN14: -0.026645629 | AO14: -0.014995471 | AP14: -0.0063803695 | AQ14: 0.0016969306 | AR14: -0.022223026 | AS14: -0.019976273 | AT14: -0.072195382 | AU14: -0.0037135364 | AV14: 0.0022971223 | AW14: -0.013637776 | AX14: -0.0058446617 | AY14: 0.048156517 | AZ14: -0.02649542 | BA14: 0.0055924597 | BB14: 0.012143481 | BC14: 0.026690966 | BD14: -0.020333813 | BE14: 0.029972826 | BF14: 0.070904934 | BG14: 0.028739962 | BH14: -0.0032311813 | BI14: 0.048193838 | BJ14: -0.024663126 | BK14: 0.0082059499 | BL14: -0.020533626 | BM14: -0.020634019 | BN14: -0.014908357 | BO14: -0.061541279 | BP14: -0.032994976 | BQ14: -0.010117718 | BR14: -0.056986675 | BS14: 0.001593666 | BT14: -0.0046247973 | BU14: -0.023168961 | BV14: 0.037969142 | BW14: 0.043745729 | BX14: -0.0090180569 | BY14: -0.017771556 | BZ14: -0.011652747 | CA14: -0.018496156 | CB14: 0.019510209 | CC14: -0.043661783 | CD14: -0.044355263 | CE14: 0.0093696372 | CF14: 0.011658065 | CG14: -0.004643455 | CH14: 0.011804876 | CI14: 0.0015237996 | CJ14: -0.064059392 | CK14: 0.014501197 | CL14: 0.076121024 | CM14: 0.026353951 | CN14: 0.1397279 | CO14: -0.056181822 | CP14: 0.004251866 | CQ14: -0.067376584 | CR14: -0.057159987 | CS14: -0.024098817 | CT14: -0.065684092 | CU14: -0.074779529 | CV14: 0.035483195 | CW14: 0.013036669 | CX14: -0.030752638 | CY14: 0.016420596 | CZ14: -0.012324262 | DA14: 0.016824333 | DB14: 0.035585283 | DC14: -0.0045013638 | DD14: 0.0051114671 | DE14: -0.0087968309 | DF14: 0.019394736 | DG14: -0.014314268 | DH14: 0.0014287617 | DI14: -0.039089939 | DJ14: 0.041378043 | DK14: -0.02621306 | DL14: -0.015979407 | DM14: -0.027941837 | DN14: 0.012574616 | DO14: 0.0095209619 | DP14: 0.011064374 | DQ14: 0.011403957 | DR14: -0.010852046 | DS14: 0.046024279 | DT14: 0.024813842 | DU14: 0.045787142 | DV14: -0.0097841607 | DW14: 0.0044421707 | DX14: -0.008528382 | DY14: 0.01535213 | DZ14: 0.0070565352 | EA14: -0.11312704 | EB14: 0.031887415 | EC14: 0.014883918 | ED14: 0.023444575 | EE14: -0.02821628 | EF14: -0.031810858
A15: 20 | B15: 48 | C15: -0.0074773642 | D15: 0.00545686 | E15: -0.0055236267 | F15: -0.010393344 | G15: 0.01899402 | H15: 0.017388387 | I15: 0.032285992 | J15: 0.023000409 | K15: 0.060326139 | L15: 0.02198047 | M15: 0.0032797582 | N15: -0.075519168 | O15: 0.017422699 | P15: -0.0059731167 | Q15: 0.024058965 | R15: -0.04724251 | S15: 0.026179032 | T15: -0.026298133 | U15: -0.002277829 | V15: -0.01108566 | W15: -0.034590636 | X15: -0.15038578 | Y15: 0.021623165 | Z15: 0.081251402 | AA15: -0.047712648 | AB15: -0.015001573 | AC15: 0.0667717 | AD15: 0.020440228 | AE15: -0.040845747 | AF15: 0.073281161 | AG15: -0.0099052077 | AH15: 0.024955207 | AI15: -0.0030352421 | AJ15: -0.001069904 | AK15: -0.0236187 | AL15: 0.049258885 | AM15: -0.041837428 | AN15: -0.029977661 | AO15: 0.0017088467 | AP15: 0.0021107071 | AQ15: 0.0023400742 | AR15: -0.020848044 | AS15: -0.023404964 | AT15: -0.086422915 | AU15: 0.015695418 | AV15: -0.0049079394 | AW15: -0.011292436 | AX15: 0.00020015025 | AY15: 0.068287143 | AZ15: -0.016857007 | BA15: 0.01770477 | BB15: 0.0021019545 | BC15: 0.019110867 | BD15: 0.015529874 | BE15: 0.048963911 | BF15: 0.071981555 | BG15: 0.057825844 | BH15: 0.0010630737 | BI15: 0.037499401 | BJ15: -0.024266088 | BK15: -0.0015834533 | BL15: -0.016413796 | BM15: -0.024812054 | BN15: -0.021773575 | BO15: -0.082577836 | BP15: -0.057598025 | BQ15: -0.016153312 | BR15: -0.081428202 | BS15: 0.0027340927 | BT15: 0.022651181 | BU15: -0.025178691 | BV15: 0.069814479 | BW15: 0.08027142 | BX15: -0.01523951 | BY15: 0.0078465601 | BZ15: -0.062915716 | CA15: -0.042622978 | CB15: 0.02274976 | CC15: -0.0025665769 | CD15: -0.021204144 | CE15: 0.022670431 | CF15: 0.010965174 | CG15: -0.022196704 | CH15: 0.029497085 | CI15: 0.0066072391 | CJ15: -0.08096216 | CK15: 0.010734913 | CL15: 0.070690453 | CM15: 0.014010735 | CN15: 0.14134677 | CO15: -0.060648236 | CP15: 0.027089074 | CQ15: -0.073319276 | CR15: -0.11164489 | CS15: -0.018419378 | CT15: -0.094868405 | CU15: -0.10709096 | CV15: 0.05457689 | CW15: 0.03630912 | CX15: -0.030582841 | CY15: 0.041201752 | CZ15: -0.0048982162 | DA15: 0.016936626 | DB15: 0.061356185 | DC15: -0.014149867 | DD15: -0.00059036845 | DE15: -0.012176081 | DF15: 0.01989365 | DG15: -0.011696069 | DH15: -0.034498129 | DI15: -0.044175588 | DJ15: 0.0070211236 | DK15: -0.0039577188 | DL15: -0.023641364 | DM15: -0.034463083 | DN15: 0.010715067 | DO15: 0.012299319 | DP15: 0.013144614 | DQ15: 0.013553481 | DR15: -0.014466961 | DS15: 0.029915194 | DT15: 0.029845809 | DU15: 0.023698854 | DV15: -0.030687472 | DW15: 0.017478143 | DX15: 0.015732765 | DY15: 0.0097591276 | DZ15: -0.0069097961 | EA15: -0.12446896 | EB15: 0.058059596 | EC15: 0.021984853 | ED15: 0.05397802 | EE15: -0.03586748 | EF15: -0.047879265
A16: 50 | B16: 19 | C16: -0.033228978 | D16: 0.14164365 | E16: -0.047920746 | F16: 0.017957807 | G16: 0.018155703 | H16: -0.011508261 | I16: 0.030100135 | J16: 0.045231574 | K16: 0.050827466 | L16: 0.056271085 | M16: -0.019021714 | N16: -0.12405157 | O16: 0.0014944079 | P16: 0.01196952 | Q16: 0.049500992 | R16: 0.011453173 | S16: 0.041715658 | T16: 0.0022210255 | U16: -0.014789417 | V16: -0.01344097 | W16: -0.021702239 | X16: -0.21811054 | Y16: -0.031992262 | Z16: 0.11670403 | AA16: -0.099905879 | AB16: -0.027335979 | AC16: -0.0030865623 | AD16: 0.069874592 | AE16: -0.0056825031 | AF16: 0.096080095 | AG16: -0.025329295 | AH16: 0.080952184 | AI16: 0.063253266 | AJ16: -0.016189757 | AK16: -0.0086778642 | AL16: 0.051230183 | AM16: -0.028014229 | AN16: -0.019132523 | AO16: 0.038044353 | AP16: -0.0083517816 | AQ16: -0.02973338 | AR16: -0.0075826917 | AS16: 0.0066693384 | AT16: -0.07940348 | AU16: 0.057421613 | AV16: -0.01231335 | AW16: 0.0038276407 | AX16: -0.010615142 | AY16: 0.14324851 | AZ16: -0.031301973 | BA16: 0.064770818 | BB16: 0.032127794 | BC16: -0.028505683 | BD16: 0.052229072 | BE16: 0.076027043 | BF16: 0.11017253 | BG16: 0.10047478 | BH16: 0.091153634 | BI16: 0.070811286 | BJ16: -0.068604196 | BK16: -0.0059792702 | BL16: -0.011627052 | BM16: -0.01713028 | BN16: -0.0047838156 | BO16: -0.020140931 | BP16: -0.070319344 | BQ16: 0.017671783 | BR16: -0.086828185 | BS16: 0.005066305 | BT16: 0.026437795 | BU16: -0.076735091 | BV16: 0.10176926 | BW16: 0.015980248 | BX16: -0.092177725 | BY16: 0.042570992 | BZ16: -0.16812656 | CA16: -0.051170227 | CB16: 0.11636706 | CC16: -0.035993753 | CD16: 0.032926387 | CE16: 0.043060426 | CF16: 0.020735298 | CG16: -0.040400431 | CH16: 0.0021026353 | CI16: -0.047976499 | CJ16: -0.1253171 | CK16: 0.074599979 | CL16: 0.091851719 | CM16: -0.0050971069 | CN16: 0.20849654 | CO16: -0.11865999 | CP16: 0.025792775 | CQ16: -0.092452779 | CR16: -0.20771971 | CS16: 0.010443103 | CT16: -0.099677084 | CU16: -0.101545 | CV16: 0.058675077 | CW16: 0.044763884 | CX16: -0.090639227 | CY16: 0.09636113 | CZ16: -0.0103014 | DA16: -0.056351881 | DB16: 0.090239014 | DC16: -0.042998542 | DD16: -0.0056504594 | DE16: 0.014117833 | DF16: 0.022607974 | DG16: -0.026961754 | DH16: 0.0012662364 | DI16: -0.12514038 | DJ16: 0.0087940294 | DK16: 0.068591516 | DL16: -0.063558098 | DM16: -0.020843043 | DN16: 0.001668604 | DO16: 0.0012384092 | DP16: -0.017980561 | DQ16: 0.032384745 | DR16: -0.0054840962 | DS16: 0.089437754 | DT16: 0.0077542903 | DU16: 0.11891759 | DV16: -0.049656627 | DW16: 0.054188708 | DX16: 0.032842422 | DY16: 0.036869823 | DZ16: -0.022551538 | EA16: -0.062912685 | EB16: 0.088158782 | EC16: 0.043260018 | ED16: 0.078399264 | EE16: -0.042505739 | EF16: -0.084951384
A17: 100 | B17: 10 | C17: -0.036350225 | D17: 0.27303487 | E17: -0.095344605 | F17: 0.013344162 | G17: -5.0918187e-05 | H17: -0.0012437261 | I17: 0.079293091 | J17: 0.06212121 | K17: 0.094514798 | L17: 0.081171061 | M17: -0.0021330164 | N17: -0.13481826 | O17: -0.012270796 | P17: 0.0045502269 | Q17: 0.052757304 | R17: -0.033711168 | S17: 0.088560885 | T17: -0.0065780207 | U17: 0.0080881446 | V17: -0.00055125571 | W17: -0.0060794047 | X17: -0.25186325 | Y17: -0.046039335 | Z17: 0.062704119 | AA17: -0.16085038 | AB17: -0.022166401 | AC17: 0.0043176688 | AD17: 0.081713375 | AE17: 0.01572749 | AF17: 0.13772629 | AG17: -0.044324544 | AH17: 0.13296737 | AI17: 0.078876382 | AJ17: 0.022201118 | AK17: 0.060211989 | AL17: 0.032360174 | AM17: 0.021048665 | AN17: -0.03550046 | AO17: 0.05138452 | AP17: -0.090555375 | AQ17: -0.036453319 | AR17: -0.017733826 | AS17: 0.048733221 | AT17: -0.070989813 | AU17: 0.077174077 | AV17: -0.094716061 | AW17: -0.022828047 | AX17: -0.054416045 | AY17: 0.20000627 | AZ17: -0.0056675795 | BA17: 0.14335282 | BB17: 0.030366028 | BC17: -0.030936692 | BD17: 0.059932733 | BE17: 0.074808226 | BF17: 0.12725231 | BG17: 0.12916989 | BH17: 0.051044265 | BI17: 0.10593719 | BJ17: -0.13011026 | BK17: 0.037923726 | BL17: -0.0047008904 | BM17: -0.011126533 | BN17: -0.059531748 | BO17: -0.028938091 | BP17: -0.13827563 | BQ17: 0.028214169 | BR17: -0.13180033 | BS17: 0.00055831707 | BT17: 0.095399787 | BU17: -0.040466167 | BV17: 0.16459385 | BW17: -0.014167149 | BX17: -0.0056261887 | BY17: 0.0024922433 | BZ17: -0.14914636 | CA17: -0.12993344 | CB17: 0.16188291 | CC17: -0.061217177 | CD17: -0.047114468 | CE17: 0.10253544 | CF17: 0.045210671 | CG17: -0.12524703 | CH17: 0.011834855 | CI17: -0.031100781 | CJ17: -0.056967559 | CK17: 0.085724331 | CL17: 0.13737052 | CM17: -0.046626536 | CN17: 0.2769722 | CO17: -0.19945622 | CP17: 0.092551972 | CQ17: -0.067089016 | CR17: -0.18148893 | CS17: 0.065435917 | CT17: -0.16873607 | CU17: -0.12404993 | CV17: 0.084641843 | CW17: 0.026072091 | CX17: -0.15238778 | CY17: 0.092947904 | CZ17: -0.023763335 | DA17: 0.057882147 | DB17: 0.2096634 | DC17: -0.067692432 | DD17: -0.013691371 | DE17: -0.00016019757 | DF17: 0.044700313 | DG17: -0.03745733 | DH17: -0.032902476 | DI17: -0.11060974 | DJ17: 0.060023777 | DK17: 0.15651374 | DL17: -0.062537168 | DM17: 0.0044523917 | DN17: 0.017128288 | DO17: -0.014779004 | DP17: -0.045072435 | DQ17: 0.043002665 | DR17: 0.03047264 | DS17: 0.0095715425 | DT17: 0.05271879 | DU17: 0.18864064 | DV17: -0.096902151 | DW17: 0.0096290501 | DX17: 0.050285288 | DY17: 0.010392759 | DZ17: -0.027874507 | EA17: -0.04345122 | EB17: 0.07529439 | EC17: 0.076157077 | ED17: 0.11066003 | EE17: -0.04934418 | EF17: -0.15968344
A18: 107 | B18: 9 | C18: -0.03943539 | D18: 0.23433798 | E18: -0.086704171 | F18: 0.024642133 | G18: -0.0018178771 | H18: -0.00064934946 | I18: 0.10921796 | J18: 0.073104639 | K18: 0.086420892 | L18: 0.085161604 | M18: -0.013987436 | N18: -0.16464784 | O18: -0.028587077 | P18: 0.0022388474 | Q18: 0.052802704 | R18: -0.034488337 | S18: 0.096643246 | T18: -0.030934916 | U18: 0.052915685 | V18: -0.036407149 | W18: 0.02678889 | X18: -0.27113096 | Y18: -0.047902109 | Z18: 0.043010058 | AA18: -0.16615889 | AB18: -0.032295414 | AC18: -0.012765448 | AD18: 0.053136056 | AE18: 0.048227124 | AF18: 0.14791561 | AG18: -0.04377616 | AH18: 0.14840163 | AI18: 0.10020271 | AJ18: 0.035776244 | AK18: 0.053699967 | AL18: 0.0054397026 | AM18: 0.028978861 | AN18: -0.022032518 | AO18: 0.041090153 | AP18: -0.094724683 | AQ18: -0.054497753 | AR18: -0.034371979 | AS18: 0.052642718 | AT18: -0.12256404 | AU18: 0.082090272 | AV18: -0.095921542 | AW18: -0.013947617 | AX18: -0.050559496 | AY18: 0.22593249 | AZ18: -0.003982412 | BA18: 0.15260112 | BB18: 0.073011429 | BC18: -0.038999392 | BD18: 0.035639774 | BE18: 0.075589961 | BF18: 0.15869235 | BG18: 0.12077889 | BH18: 0.043805074 | BI18: 0.13815009 | BJ18: -0.096566804 | BK18: 0.020691262 | BL18: -0.00073027177 | BM18: 0.0014382607 | BN18: -0.057828559 | BO18: -0.029487267 | BP18: -0.12596295 | BQ18: 0.02854154 | BR18: -0.14752203 | BS18: 0.0014379327 | BT18: 0.1024804 | BU18: -0.042432187 | BV18: 0.17428476 | BW18: -0.035276084 | BX18: -0.016073282 | BY18: 0.019693375 | BZ18: -0.14002572 | CA18: -0.13814774 | CB18: 0.16089687 | CC18: -0.055432229 | CD18: -0.060988526 | CE18: 0.12192791 | CF18: -0.01199364 | CG18: -0.091116257 | CH18: 0.016724789 | CI18: -0.037593168 | CJ18: -0.054788462 | CK18: 0.11174511 | CL18: 0.089066417 | CM18: -0.0069997267 | CN18: 0.32067948 | CO18: -0.20410183 | CP18: 0.082195843 | CQ18: -0.09163939 | CR18: -0.18928653 | CS18: 0.075198615 | CT18: -0.156979 | CU18: -0.1354717 | CV18: 0.090097055 | CW18: 0.047341659 | CX18: -0.16226598 | CY18: 0.081280638 | CZ18: -0.032724822 | DA18: 0.078106298 | DB18: 0.23166535 | DC18: -0.083264052 | DD18: 0.0077053805 | DE18: 0.00094053142 | DF18: 0.046156787 | DG18: -0.036227532 | DH18: -0.035919639 | DI18: -0.12794229 | DJ18: 0.070955052 | DK18: 0.15889822 | DL18: -0.076014086 | DM18: -0.0018719094 | DN18: 0.01150354 | DO18: -0.0062760956 | DP18: -0.047675807 | DQ18: 0.044220142 | DR18: 0.068305382 | DS18: -0.010423024 | DT18: 0.059112975 | DU18: 0.19010824 | DV18: -0.058480746 | DW18: 0.04052346 | DX18: 0.051507217 | DY18: 0.011151605 | DZ18: -0.049161819 | EA18: -0.00042051524 | EB18: 0.088908954 | EC18: 0.068501481 | ED18: 0.11469923 | EE18: -0.059240997 | EF18: -0.15799175
A19: 120 | B19: 8 | C19: -0.038913469 | D19: 0.16854736 | E19: -0.096671109 | F19: 0.027531384 | G19: -0.023814422 | H19: 0.0079428568 | I19: 0.11307752 | J19: 0.048286948 | K19: 0.10156008 | L19: 0.042234791 | M19: 0.014659142 | N19: -0.22574704 | O19: -0.011306676 | P19: 0.00069459976 | Q19: 0.058333135 | R19: -0.030203789 | S19: 0.12484658 | T19: -0.03752488 | U19: 0.031355564 | V19: -0.11295912 | W19: 0.058245239 | X19: -0.27133595 | Y19: -0.095475865 | Z19: 0.048325674 | AA19: -0.19128344 | AB19: -0.044538303 | AC19: -0.020086255 | AD19: 0.049777375 | AE19: 0.07787902 | AF19: 0.12028632 | AG19: -0.062640142 | AH19: 0.14702489 | AI19: 0.091956591 | AJ19: 0.023536896 | AK19: 0.03866433 | AL19: 0.027018182 | AM19: 0.029521143 | AN19: 0.0064561354 | AO19: 0.076694528 | AP19: -0.09341758 | AQ19: -0.061277252 | AR19: -0.045802626 | AS19: 0.058802957 | AT19: -0.12707179 | AU19: 0.11569961 | AV19: -0.10115858 | AW19: -0.0087282505 | AX19: -0.034695778 | AY19: 0.23807944 | AZ19: -0.0072219644 | BA19: 0.1515431 | BB19: 0.085202879 | BC19: -0.027292824 | BD19: 0.040997019 | BE19: 0.068529222 | BF19: 0.055060757 | BG19: 0.11262105 | BH19: 0.029758528 | BI19: 0.13096213 | BJ19: -0.097868244 | BK19: 0.016537443 | BL19: -0.012917736 | BM19: 0.0085086093 | BN19: -0.033552831 | BO19: -0.032197286 | BP19: -0.14972725 | BQ19: 0.053490466 | BR19: -0.1782881 | BS19: 0.033757817 | BT19: 0.093199875 | BU19: -0.067306502 | BV19: 0.18846884 | BW19: -0.068357545 | BX19: -0.0018025829 | BY19: -0.030092828 | BZ19: -0.13820224 | CA19: -0.12225927 | CB19: 0.1830453 | CC19: -0.037574482 | CD19: -0.076385115 | CE19: 0.16590361 | CF19: 0.00055948197 | CG19: -0.089267428 | CH19: 0.020669136 | CI19: -0.05509642 | CJ19: -0.081164387 | CK19: 0.116866 | CL19: 0.093869894 | CM19: 0.0016699729 | CN19: 0.3264374 | CO19: -0.18269785 | CP19: 0.085732279 | CQ19: -0.091887762 | CR19: -0.19640263 | CS19: 0.054006151 | CT19: -0.11450657 | CU19: -0.15535189 | CV19: 0.066457648 | CW19: 0.063393219 | CX19: -0.12500986 | CY19: 0.075608913 | CZ19: -0.031592684 | DA19: 0.048109805 | DB19: 0.22431697 | DC19: -0.098849393 | DD19: -0.0069842221 | DE19: 0.00077277579 | DF19: 0.040777929 | DG19: -0.038939056 | DH19: -0.028745682 | DI19: -0.14979688 | DJ19: 0.12892506 | DK19: 0.17164705 | DL19: -0.087764625 | DM19: -0.0025817581 | DN19: 0.010858502 | DO19: -0.0018782094 | DP19: -0.056639794 | DQ19: 0.036728692 | DR19: 0.045431264 | DS19: -0.0065055362 | DT19: 0.059811935 | DU19: 0.1595551 | DV19: -0.055500328 | DW19: 0.045629335 | DX19: 0.036950346 | DY19: -0.02002421 | DZ19: -0.047637765 | EA19: 0.0046325242 | EB19: 0.086858714 | EC19: 0.12151202 | ED19: 0.10329067 | EE19: -0.0642787 | EF19: -0.13981485
A20: 137 | B20: 7 | C20: -0.059146798 | D20: 0.18401889 | E20: -0.10047562 | F20: 0.021575273 | G20: -0.0090534051 | H20: 0.0086222278 | I20: 0.12862656 | J20: 0.091173232 | K20: 0.13564789 | L20: 0.050758207 | M20: 0.029051464 | N20: -0.23903745 | O20: 0.031737941 | P20: -0.0015852985 | Q20: 0.059093355 | R20: -0.035055205 | S20: 0.12739823 | T20: -0.047527599 | U20: 0.031634303 | V20: -0.13883427 | W20: 0.06596244 | X20: -0.28203659 | Y20: -0.11656972 | Z20: 0.051469726 | AA20: -0.17257066 | AB20: -0.062644805 | AC20: 0.0013654205 | AD20: 0.072443789 | AE20: 0.084086671 | AF20: 0.15054364 | AG20: -0.08171998 | AH20: 0.1630685 | AI20: 0.052553497 | AJ20: 0.046670517 | AK20: 0.014380613 | AL20: 0.032812812 | AM20: 0.039803316 | AN20: -0.0027944178 | AO20: -0.02458428 | AP20: -0.095545793 | AQ20: -0.064154974 | AR20: -0.039002474 | AS20: 0.083253128 | AT20: -0.16638581 | AU20: 0.13889821 | AV20: -0.11622238 | AW20: -0.020326564 | AX20: -0.03377089 | AY20: 0.25333878 | AZ20: -0.026067638 | BA20: 0.12875947 | BB20: 0.098925815 | BC20: 0.027942051 | BD20: 0.011404978 | BE20: 0.067547173 | BF20: 0.039489138 | BG20: 0.039685382 | BH20: 0.077457082 | BI20: 0.12468721 | BJ20: -0.098533857 | BK20: 0.019536271 | BL20: -0.019474133 | BM20: 0.015736216 | BN20: -0.048298491 | BO20: -0.029971588 | BP20: -0.16487337 | BQ20: 0.088664658 | BR20: -0.17418737 | BS20: 0.032879368 | BT20: 0.11280721 | BU20: -0.081337969 | BV20: 0.18988257 | BW20: -0.068489667 | BX20: -0.0077412973 | BY20: -0.028376458 | BZ20: -0.027370167 | CA20: -0.14000845 | CB20: 0.14365511 | CC20: -0.036515326 | CD20: -0.12159522 | CE20: 0.18645852 | CF20: 0.012563582 | CG20: -0.070437854 | CH20: 0.011128647 | CI20: -0.042128275 | CJ20: -0.074164048 | CK20: 0.050004768 | CL20: 0.12756845 | CM20: 0.01554875 | CN20: 0.29455502 | CO20: -0.2167774 | CP20: 0.10138046 | CQ20: -0.091780217 | CR20: -0.19372241 | CS20: 0.023923939 | CT20: -0.10089785 | CU20: -0.14456482 | CV20: 0.049648574 | CW20: 0.066558574 | CX20: -0.15307569 | CY20: 0.093178384 | CZ20: -0.091459213 | DA20: 0.076890546 | DB20: 0.22238211 | DC20: -0.082819707 | DD20: -0.012694658 | DE20: -0.0059605139 | DF20: 0.032824494 | DG20: -0.033314284 | DH20: -0.045324297 | DI20: -0.11909332 | DJ20: 0.14619608 | DK20: 0.1745113 | DL20: -0.091548177 | DM20: -0.0040596524 | DN20: 0.018961985 | DO20: 9.3113999e-05 | DP20: -0.040347675 | DQ20: 0.046889265 | DR20: 0.052461064 | DS20: -0.025385651 | DT20: 0.022601035 | DU20: 0.16258878 | DV20: -0.052647244 | DW20: 0.033724892 | DX20: 0.047265611 | DY20: -0.042035875 | DZ20: -0.070710335 | EA20: 0.0047382972 | EB20: 0.10197848 | EC20: 0.14304023 | ED20: 0.082759101 | EE20: -0.05301504 | EF20: -0.1549361
A21: 160 | B21: 6 | C21: -0.07386193 | D21: 0.21954287 | E21: -0.14058368 | F21: 0.027253382 | G21: -0.013871626 | H21: -0.012068788 | I21: 0.13411218 | J21: 0.11143724 | K21: 0.23878941 | L21: 0.02032665 | M21: -0.043690236 | N21: -0.31670199 | O21: 0.031561874 | P21: 0.0043138923 | Q21: 0.068942247 | R21: -0.05154014 | S21: 0.1365758 | T21: -0.043836093 | U21: 0.10479422 | V21: -0.16816101 | W21: 0.031863713 | X21: -0.27968945 | Y21: -0.091155341 | Z21: 0.057888725 | AA21: -0.1318329 | AB21: -0.051718753 | AC21: 0.014141543 | AD21: 0.023997457 | AE21: 0.097714156 | AF21: 0.16883058 | AG21: -0.041487103 | AH21: 0.20415629 | AI21: 0.075071918 | AJ21: 0.027981425 | AK21: 0.017600246 | AL21: 0.014914608 | AM21: 0.044370985 | AN21: 0.010239548 | AO21: -0.055890126 | AP21: -0.12482825 | AQ21: -0.042375665 | AR21: 0.041144515 | AS21: 0.10919888 | AT21: -0.18459366 | AU21: 0.15301463 | AV21: -0.15016236 | AW21: -0.065603456 | AX21: -0.043882228 | AY21: 0.28470839 | AZ21: -0.023985446 | BA21: 0.057635882 | BB21: 0.10665587 | BC21: 0.18457179 | BD21: 0.016662972 | BE21: 0.023058343 | BF21: 0.047638579 | BG21: 0.069151689 | BH21: 0.087994482 | BI21: 0.049004762 | BJ21: -0.058912217 | BK21: 0.018708692 | BL21: -0.029096141 | BM21: 0.0028667915 | BN21: -0.083155327 | BO21: -0.038154863 | BP21: -0.15328773 | BQ21: 0.1034959 | BR21: -0.19272349 | BS21: 0.025184534 | BT21: 0.14734952 | BU21: -0.050510197 | BV21: 0.17061194 | BW21: -0.057164411 | BX21: -0.015318949 | BY21: -0.028339166 | BZ21: 0.042433815 | CA21: -0.11835435 | CB21: 0.18311774 | CC21: -0.056829694 | CD21: -0.14873191 | CE21: 0.25475115 | CF21: 0.011263406 | CG21: -0.1135231 | CH21: -0.016324923 | CI21: -0.054197537 | CJ21: -0.12177619 | CK21: 0.069580909 | CL21: 0.13637708 | CM21: 0.075581871 | CN21: 0.22784777 | CO21: -0.2337067 | CP21: 0.11300079 | CQ21: -0.085571877 | CR21: -0.17630672 | CS21: 0.021899638 | CT21: -0.13687457 | CU21: -0.14660754 | CV21: 0.01631017 | CW21: 0.060515879 | CX21: -0.14815029 | CY21: 0.10789212 | CZ21: -0.057499263 | DA21: 0.1196964 | DB21: 0.28613845 | DC21: -0.065587585 | DD21: -0.022199214 | DE21: -0.028601638 | DF21: 0.027823184 | DG21: -0.040671953 | DH21: -0.059463187 | DI21: -0.1356139 | DJ21: 0.16525047 | DK21: 0.17247327 | DL21: -0.054935239 | DM21: -0.011867092 | DN21: 0.02730408 | DO21: -0.0016379752 | DP21: -0.017369959 | DQ21: 0.073200505 | DR21: 0.033181055 | DS21: -0.044918963 | DT21: 0.0050332465 | DU21: 0.19451944 | DV21: -0.067700156 | DW21: 0.068228373 | DX21: 0.062255644 | DY21: -0.037938573 | DZ21: -0.067585946 | EA21: -0.032919727 | EB21: 0.125676 | EC21: 0.1437742 | ED21: 0.080285258 | EE21: -0.022815886 | EF21: -0.16823694
A22: 192 | B22: 5 | C22: 0.011241332 | D22: 0.22258639 | E22: -0.14612491 | F22: 0.023820703 | G22: -0.020083254 | H22: 0.011583026 | I22: 0.18586318 | J22: 0.14728813 | K22: 0.2147245 | L22: 0.0089997713 | M22: -0.077718228 | N22: -0.35652158 | O22: 0.049864886 | P22: -0.0023378558 | Q22: 0.088288774 | R22: -0.068588879 | S22: 0.16333492 | T22: -0.059783537 | U22: 0.16139447 | V22: -0.15781631 | W22: 0.037687448 | X22: -0.22338311 | Y22: -0.085531421 | Z22: 0.074027168 | AA22: -0.13048337 | AB22: -0.032898545 | AC22: 0.047248263 | AD22: 0.026987304 | AE22: 0.18759777 | AF22: 0.22349782 | AG22: -0.032163249 | AH22: 0.21664245 | AI22: 0.11037372 | AJ22: 0.041672455 | AK22: 0.025137514 | AL22: 0.020780265 | AM22: -0.043441575 | AN22: -0.034444519 | AO22: -0.049108295 | AP22: -0.13972026 | AQ22: -0.033308231 | AR22: 0.029739 | AS22: 0.042291716 | AT22: -0.23912375 | AU22: 0.14307264 | AV22: -0.23551037 | AW22: -0.023968299 | AX22: -0.027057055 | AY22: 0.35493548 | AZ22: -0.028192862 | BA22: 0.010123627 | BB22: 0.062082765 | BC22: 0.24014067 | BD22: 0.029538661 | BE22: -0.020269759 | BF22: 0.059849354 | BG22: 0.056039329 | BH22: 0.037117062 | BI22: 0.081599623 | BJ22: -0.049139784 | BK22: 0.017963616 | BL22: 0.00084992523 | BM22: -0.0094222031 | BN22: -0.058380234 | BO22: -0.065655954 | BP22: -0.19922882 | BQ22: 0.045535404 | BR22: -0.21419006 | BS22: -0.0031186946 | BT22: 0.049007782 | BU22: -0.071351408 | BV22: 0.12943768 | BW22: -0.069784214 | BX22: 0.011684771 | BY22: -0.08425685 | BZ22: 0.037624224 | CA22: -0.127773 | CB22: 0.17266284 | CC22: -0.039277116 | CD22: -0.18885951 | CE22: 0.30509173 | CF22: 0.014094959 | CG22: -0.08418532 | CH22: -0.00022578669 | CI22: -0.091926463 | CJ22: -0.15596956 | CK22: 0.071530757 | CL22: 0.18841701 | CM22: 0.079454727 | CN22: 0.12992727 | CO22: -0.21426905 | CP22: 0.13145166 | CQ22: -0.07430263 | CR22: -0.19548611 | CS22: 0.023038502 | CT22: -0.11054396 | CU22: -0.14672801 | CV22: 0.027137039 | CW22: 0.067903708 | CX22: -0.14515419 | CY22: 0.10096666 | CZ22: -0.013062634 | DA22: 0.22461946 | DB22: 0.38248992 | DC22: -0.037332311 | DD22: -0.0026928905 | DE22: -0.037422803 | DF22: 0.092325886 | DG22: -0.046312237 | DH22: -0.034819127 | DI22: -0.12984972 | DJ22: 0.13655809 | DK22: 0.11290373 | DL22: -0.064166849 | DM22: -0.0053147808 | DN22: 0.053230522 | DO22: -0.0048887633 | DP22: -0.029220507 | DQ22: 0.069989438 | DR22: 0.088208884 | DS22: 0.069792758 | DT22: -0.029685339 | DU22: 0.27264433 | DV22: -0.14143996 | DW22: 0.063299144 | DX22: 0.042217605 | DY22: 0.0085083891 | DZ22: -0.061285559 | EA22: 0.0059255993 | EB22: 0.21024949 | EC22: 0.13100615 | ED22: 0.057827564 | EE22: -0.020017587 | EF22: -0.20954174
A23: 241 | B23: 4 | C23: 0.010384834 | D23: 0.32500828 | E23: -0.043717555 | F23: -0.0027590447 | G23: -0.025104067 | H23: -0.037844077 | I23: 0.23932306 | J23: 0.090566639 | K23: 0.20688003 | L23: 0.057226167 | M23: -0.099684593 | N23: -0.25375271 | O23: 0.034351989 | P23: -0.0022004018 | Q23: 0.10429481 | R23: -0.11112096 | S23: 0.21207201 | T23: -0.051427686 | U23: 0.17196778 | V23: -0.18314234 | W23: -0.11046338 | X23: -0.2689283 | Y23: -0.1092693 | Z23: 0.1093802 | AA23: -0.11063591 | AB23: -0.021955944 | AC23: 0.018827737 | AD23: -0.025933276 | AE23: 0.123702 | AF23: 0.29514426 | AG23: -0.011046572 | AH23: 0.24035126 | AI23: 0.14069942 | AJ23: 0.028564743 | AK23: 0.038160669 | AL23: 0.037391486 | AM23: -0.09159817 | AN23: -0.02178903 | AO23: -0.085567775 | AP23: -0.18810121 | AQ23: -0.037036188 | AR23: 0.034197901 | AS23: 0.045406682 | AT23: -0.26483826 | AU23: 0.06345533 | AV23: -0.27117384 | AW23: -0.0068901309 | AX23: -0.025460074 | AY23: 0.31298446 | AZ23: -0.020838982 | BA23: 0.042907777 | BB23: 0.068628374 | BC23: 0.16446053 | BD23: 0.054069378 | BE23: -0.01244989 | BF23: -0.0014405499 | BG23: 0.0088386262 | BH23: 0.043132469 | BI23: 0.056209635 | BJ23: -0.031982514 | BK23: 0.022605763 | BL23: -0.014781229 | BM23: -0.0028428272 | BN23: -0.013929185 | BO23: -0.074350174 | BP23: -0.20473422 | BQ23: 0.04876556 | BR23: -0.28727554 | BS23: -0.023146914 | BT23: 0.0078416551 | BU23: -0.087704926 | BV23: 0.18815701 | BW23: -0.011068494 | BX23: -0.03210607 | BY23: -0.039989541 | BZ23: 0.082791085 | CA23: 0.031340141 | CB23: 0.092096681 | CC23: -0.098470654 | CD23: -0.15078839 | CE23: 0.36420754 | CF23: 0.017618699 | CG23: -0.086945778 | CH23: -0.0073515592 | CI23: -0.11491526 | CJ23: -0.075528009 | CK23: 0.069914657 | CL23: 0.25947077 | CM23: 0.062994333 | CN23: 0.12031662 | CO23: -0.22242559 | CP23: 0.15989089 | CQ23: -0.12107338 | CR23: -0.23905997 | CS23: -0.012422126 | CT23: -0.067240263 | CU23: -0.15891662 | CV23: 0.056706712 | CW23: 0.038345517 | CX23: -0.15696885 | CY23: 0.15245231 | CZ23: -0.013847206 | DA23: 0.27617087 | DB23: 0.47235074 | DC23: -0.1539048 | DD23: 0.0040045209 | DE23: -0.037537974 | DF23: 0.056743675 | DG23: -0.040285673 | DH23: -0.031634902 | DI23: -0.11687556 | DJ23: 0.15660572 | DK23: 0.024780782 | DL23: -0.082190176 | DM23: 0.02386982 | DN23: 0.072086999 | DO23: -0.011234841 | DP23: -0.022876694 | DQ23: 0.01904972 | DR23: 0.11639751 | DS23: 0.084605434 | DT23: -0.0052151903 | DU23: 0.33980664 | DV23: -0.16008075 | DW23: 0.082401531 | DX23: 0.034708549 | DY23: -0.0049335772 | DZ23: -0.060338949 | EA23: 0.035066457 | EB23: 0.23519828 | EC23: 0.14009402 | ED23: -0.1291552 | EE23: 0.010955945 | EF23: -0.17865428
A24: 321 | B24: 3 | C24: 0.025922327 | D24: 0.41742192 | E24: -0.022230412 | F24: -4.2698865e-05 | G24: -0.024265746 | H24: -0.22980554 | I24: 0.2544329 | J24: 0.11837828 | K24: 0.24536591 | L24: 0.10748717 | M24: -0.074100059 | N24: -0.26414339 | O24: -0.0067158783 | P24: -0.010249158 | Q24: 0.12465636 | R24: -0.15188793 | S24: 0.11046183 | T24: -0.048773718 | U24: 0.17404563 | V24: -0.18487564 | W24: -0.084051092 | X24: -0.37472542 | Y24: -0.13590679 | Z24: 0.15015011 | AA24: -0.082524426 | AB24: 0.0038652301 | AC24: 0.085776461 | AD24: -0.018593749 | AE24: 0.1637474 | AF24: 0.42991677 | AG24: -0.010812101 | AH24: 0.24762225 | AI24: 0.19681697 | AJ24: 0.01067462 | AK24: 0.045065255 | AL24: 0.0011447262 | AM24: -0.1129979 | AN24: -0.027860567 | AO24: -0.15815288 | AP24: -0.25139506 | AQ24: 0.055126721 | AR24: 0.1081837 | AS24: -0.073843703 | AT24: -0.017728371 | AU24: 0.1099146 | AV24: -0.32909465 | AW24: -0.0045525394 | AX24: -0.0116517 | AY24: 0.30688012 | AZ24: -0.063401942 | BA24: 0.095016086 | BB24: 0.076073857 | BC24: 0.19562604 | BD24: -0.0047258791 | BE24: -0.01500766 | BF24: -0.10506563 | BG24: 0.068467458 | BH24: 0.078524243 | BI24: 0.11621667 | BJ24: 0.010233975 | BK24: 0.045489373 | BL24: -0.034329494 | BM24: 0.055446908 | BN24: -0.085932691 | BO24: -0.096567135 | BP24: -0.2391521 | BQ24: 0.032072135 | BR24: -0.37344457 | BS24: -0.08034693 | BT24: -0.039909924 | BU24: -0.14432676 | BV24: 0.21912061 | BW24: -0.029096932 | BX24: -0.014375782 | BY24: -0.037237852 | BZ24: 0.20053848 | CA24: -0.0026375687 | CB24: 0.15401169 | CC24: -0.26285714 | CD24: -0.31577166 | CE24: 0.344438 | CF24: 0.011724243 | CG24: -0.20956592 | CH24: 0.045441139 | CI24: -0.040508171 | CJ24: -0.056504408 | CK24: 0.12259805 | CL24: 0.14235436 | CM24: 0.046441279 | CN24: 0.12155884 | CO24: -0.2497464 | CP24: 0.081770051 | CQ24: -0.16015079 | CR24: -0.24677277 | CS24: -0.015126839 | CT24: -0.11773152 | CU24: -0.16735391 | CV24: 0.046660081 | CW24: 0.022884042 | CX24: -0.054293295 | CY24: 0.16243987 | CZ24: -0.0075872464 | DA24: 0.30545166 | DB24: 0.59337517 | DC24: -0.14116724 | DD24: 0.0004387308 | DE24: -0.046276179 | DF24: 0.07573946 | DG24: -0.054384439 | DH24: -0.035224492 | DI24: -0.18424672 | DJ24: 0.15369976 | DK24: 0.041065356 | DL24: -0.10181692 | DM24: 0.044016622 | DN24: 0.078357182 | DO24: -0.011605117 | DP24: 0.0087286277 | DQ24: -0.021456635 | DR24: 0.12963071 | DS24: 0.12952384 | DT24: 0.027128754 | DU24: 0.37526887 | DV24: -0.24032453 | DW24: -0.14291358 | DX24: 0.029115498 | DY24: -0.0092631562 | DZ24: -0.051518808 | EA24: 0.034191242 | EB24: 0.21821707 | EC24: -0.028428812 | ED24: -0.18368199 | EE24: 0.035899357 | EF24: -0.1611462
A25: 482 | B25: 2 | C25: 0.031325685 | D25: -0.088966623 | E25: -0.015061588 | F25: -0.044985282 | G25: -0.045824355 | H25: -0.26281024 | I25: 0.25570287 | J25: 0.15529382 | K25: 0.14260758 | L25: 0.23244436 | M25: -0.25844992 | N25: -0.16380597 | O25: -0.019407711 | P25: -0.058479235 | Q25: 0.1372071 | R25: -0.083127639 | S25: 0.1253013 | T25: -0.0150697 | U25: 0.15399525 | V25: -0.055931004 | W25: -0.21896378 | X25: -0.258703 | Y25: -0.079065036 | Z25: 0.14764041 | AA25: 0.056748446 | AB25: 0.030991385 | AC25: 0.1687548 | AD25: -0.0029952916 | AE25: 0.28317169 | AF25: 0.32465933 | AG25: 0.14589389 | AH25: -0.13564892 | AI25: 0.23406806 | AJ25: 0.047410734 | AK25: 0.093103067 | AL25: 0.051310311 | AM25: 0.032985765 | AN25: -0.16052014 | AO25: -0.09078248 | AP25: 0.010447821 | AQ25: -0.17571221 | AR25: 0.2534608 | AS25: -0.081663621 | AT25: -0.1095059 | AU25: 0.20359589 | AV25: -0.49926904 | AW25: 0.031913994 | AX25: -0.0091618244 | AY25: 0.42235449 | AZ25: -0.065450517 | BA25: 0.20896699 | BB25: 0.076715561 | BC25: 0.25286918 | BD25: -0.0088533634 | BE25: 0.043416826 | BF25: -0.040543091 | BG25: 0.060876158 | BH25: -0.021231065 | BI25: -0.013081385 | BJ25: -0.058020214 | BK25: 0.096518567 | BL25: -0.054331555 | BM25: 0.0011227371 | BN25: -0.22146322 | BO25: 0.021041233 | BP25: -0.24739863 | BQ25: 0.0060880572 | BR25: -0.36684673 | BS25: -0.12846429 | BT25: 0.027321575 | BU25: -0.17488044 | BV25: 0.31036374 | BW25: -0.050701833 | BX25: -0.12417427 | BY25: 0.020834549 | BZ25: 0.33659833 | CA25: -0.03428362 | CB25: 0.15352444 | CC25: -0.14108249 | CD25: -0.64074658 | CE25: 0.20376719 | CF25: 0.043442465 | CG25: -0.07510947 | CH25: 0.053255922 | CI25: -0.017992039 | CJ25: 0.035304074 | CK25: 0.093711931 | CL25: 0.12377064 | CM25: 0.006975009 | CN25: 0.30821328 | CO25: -0.21630903 | CP25: 0.075994055 | CQ25: -0.11922818 | CR25: -0.15099817 | CS25: -0.018055426 | CT25: -0.099939179 | CU25: -0.20210388 | CV25: 0.079103173 | CW25: -0.024186288 | CX25: -0.061859993 | CY25: 0.28171083 | CZ25: 0.061281101 | DA25: 0.51777096 | DB25: 0.86457557 | DC25: -0.1579489 | DD25: 0.035921303 | DE25: -0.045120356 | DF25: 0.10739389 | DG25: -0.084700305 | DH25: -0.055816077 | DI25: -0.21772999 | DJ25: 0.12003258 | DK25: 0.05737779 | DL25: -0.065805388 | DM25: 0.024810734 | DN25: 0.067384283 | DO25: 0.046262407 | DP25: 0.020394015 | DQ25: 0.048382875 | DR25: 0.12391735 | DS25: 0.24719455 | DT25: -0.022296457 | DU25: 0.52524171 | DV25: -0.30144336 | DW25: -0.22828224 | DX25: 0.017152664 | DY25: -0.00019524715 | DZ25: -0.075564413 | EA25: 0.093362079 | EB25: 0.31038588 | EC25: -0.12320494 | ED25: -0.19432328 | EE25: 0.069545558 | EF25: -0.083271777
A26: 964 | B26: 1 | C26: 0.027766967 | D26: -0.081988379 | E26: 0.081880335 | F26: -0.21039774 | G26: -0.056221512 | H26: -0.35082219 | I26: 0.24038624 | J26: 0.0040357249 | K26: 0.050444336 | L26: 0.33375944 | M26: -0.14681934 | N26: -0.045513037 | O26: 0.036648791 | P26: 0.023793042 | Q26: -0.058526355 | R26: -0.2057195 | S26: 0.16214817 | T26: 0.0086879701 | U26: 0.31319605 | V26: 0.11987087 | W26: -0.35846339 | X26: -0.39438028 | Y26: 0.014221313 | Z26: 0.15040993 | AA26: -0.21854458 | AB26: 0.30039379 | AC26: 0.40174733 | AD26: -0.059922147 | AE26: -0.0076910296 | AF26: 0.49538941 | AG26: 0.38005539 | AH26: -0.30212276 | AI26: 0.22020304 | AJ26: -0.043060157 | AK26: 0.074462095 | AL26: 0.10745443 | AM26: 0.0087353687 | AN26: -0.11066077 | AO26: -0.1029057 | AP26: 0.41640853 | AQ26: -0.35649193 | AR26: 0.020350844 | AS26: -0.0032867737 | AT26: -0.15076898 | AU26: 0.22984102 | AV26: -0.027012954 | AW26: 0.11069274 | AX26: -0.087562372 | AY26: -0.15123353 | AZ26: -0.13517478 | BA26: 0.17216878 | BB26: 0.097411652 | BC26: -0.0043668696 | BD26: -0.0084626104 | BE26: -0.22532542 | BF26: 0.005307218 | BG26: 0.23814201 | BH26: 0.38455842 | BI26: 0.012888999 | BJ26: 0.060567254 | BK26: 0.1360958 | BL26: -0.18502182 | BM26: -0.08478294 | BN26: -0.019890158 | BO26: 0.059152693 | BP26: -0.56718861 | BQ26: -0.030219752 | BR26: -0.46561903 | BS26: -0.29899424 | BT26: 0.013565278 | BU26: -0.42401331 | BV26: 0.57736679 | BW26: -0.12626742 | BX26: -0.11547585 | BY26: -0.062216433 | BZ26: 0.17452437 | CA26: -0.085352139 | CB26: 0.064127083 | CC26: -0.21339418 | CD26: -0.69133197 | CE26: -0.011613905 | CF26: -0.22059977 | CG26: -0.26059873 | CH26: 0.18315276 | CI26: -0.1449395 | CJ26: 0.2858032 | CK26: 0.07040769 | CL26: 0.085620879 | CM26: 0.044688538 | CN26: 0.5691225 | CO26: -0.47231299 | CP26: -0.039424886 | CQ26: 0.051440028 | CR26: -0.13778746 | CS26: 0.25680382 | CT26: -0.1020926 | CU26: -0.052729045 | CV26: 0.089725835 | CW26: -0.23499322 | CX26: -0.14669463 | CY26: 0.36022805 | CZ26: 0.16210691 | DA26: 0.8130224 | DB26: 0.94810959 | DC26: -0.28272978 | DD26: 0.029493018 | DE26: -0.11126516 | DF26: 0.10068726 | DG26: -0.21872041 | DH26: -0.082747512 | DI26: -0.37614904 | DJ26: 0.22936987 | DK26: 0.22005458 | DL26: -0.1532614 | DM26: -0.13104387 | DN26: 0.075677388 | DO26: 0.052337525 | DP26: 0.011914248 | DQ26: 0.048815483 | DR26: 0.34727417 | DS26: 0.14400697 | DT26: -0.029435726 | DU26: 0.77054331 | DV26: -0.32149889 | DW26: -0.22665737 | DX26: 0.028142323 | DY26: 0.16578721 | DZ26: 0.058303293 | EA26: 0.023171502 | EB26: 0.66580759 | EC26: -0.25665138 | ED26: -0.084540093 | EE26: -0.035663983 | EF26: -0.12895777
A27: 大盤 | B27: TWⅡ | C27: -0.017446771 | D27: 0.020701061 | E27: 0.023982129 | F27: -0.006557579 | G27: 0.03184513 | H27: 0.034348533 | I27: -0.0082549328 | J27: 0.012843524 | K27: -0.051018525 | L27: 0.00087394274 | M27: 0.023389576 | N27: 0.012988972 | O27: 0.0058545887 | P27: 0.027413207 | Q27: -0.0037129361 | R27: 0.024076614 | S27: -0.012190025 | T27: -0.039749578 | U27: -0.07315545 | V27: -0.05826023 | W27: 0.00077279757 | X27: 0.044591521 | Y27: -0.02769968 | Z27: 0.0020950059 | AA27: -0.023400551 | AB27: 0.032129371 | AC27: 0.038903273 | AD27: -0.042865382 | AE27: 0.018647195 | AF27: 0.015229768 | AG27: 0.036016604 | AH27: 0.0093546114 | AI27: 0.010748251 | AJ27: 0.013357754 | AK27: -0.0053327473 | AL27: 0.0013831358 | AM27: 0.020795928 | AN27: 0.031517702 | AO27: 0.0062417165 | AP27: 0.0061452617 | AQ27: 0.016946358 | AR27: 0.03468283 | AS27: 0.0030985886 | AT27: 0.015081347 | AU27: -0.019251209 | AV27: 0.038711513 | AW27: -0.021856951 | AX27: 0.0077743007 | AY27: 0.042397247 | AZ27: -0.026308975 | BA27: 0.0095717493 | BB27: -0.024249741 | BC27: 0.020163374 | BD27: -0.0035049988 | BE27: 0.020151935 | BF27: 0.00058133623 | BG27: -0.005219701 | BH27: -0.11587176 | BI27: 0.0087252257 | BJ27: -0.016377261 | BK27: 0.020840372 | BL27: 0.044975872 | BM27: 0.023954306 | BN27: 0.030239101 | BO27: -0.043725888 | BP27: 0.02188947 | BQ27: 0.0086274303 | BR27: -0.019192954 | BS27: 0.01973513 | BT27: 0.047694337 | BU27: 0.011454817 | BV27: 0.043228621 | BW27: -0.04274743 | BX27: -0.017811292 | BY27: -0.1511531 | BZ27: 0.124224 | CA27: -0.0045572538 | CB27: 0.06021124 | CC27: 0.085992033 | CD27: -0.0058084796 | CE27: -0.006041347 | CF27: 0.0024523244 | CG27: 0.089636252 | CH27: 0.070992733 | CI27: 0.027170643 | CJ27: 0.052468428 | CK27: 0.029480661 | CL27: 0.066825081 | CM27: -0.028772229 | CN27: 0.039462516 | CO27: -0.029031087 | CP27: 0.013983883 | CQ27: -0.032276965 | CR27: 0.0031035766 | CS27: 0.025591856 | CT27: 0.044391886 | CU27: -0.030338959 | CV27: -0.0012579765 | CW27: 0.0023363565 | CX27: -0.064264145 | CY27: 0.012909779 | CZ27: -0.12547709 | DA27: 0.011690683 | DB27: 0.0063378437 | DC27: -0.11730536 | DD27: -0.036010872 | DE27: 0.1389113 | DF27: -0.051143506 | DG27: 0.076731447 | DH27: 0.015508782 | DI27: 0.023223774 | DJ27: -0.018372876 | DK27: 0.062199014 | DL27: 0.020098304 | DM27: 0.01349894 | DN27: -0.030252213 | DO27: -0.017022836 | DP27: -0.021788523 | DQ27: 0.085745625 | DR27: 0.028106744 | DS27: -0.0023031598 | DT27: 0.058471198 | DU27: 0.067658949 | DV27: 0.0050207706 | DW27: 0.037416184 | DX27: 0.084111004 | DY27: -0.036832399 | DZ27: 0.0030917028 | EA27: -0.0019576282 | EB27: 0.026459104 | EC27: -0.024752539 | ED27: 0.034115491 | EE27: 0.021061974 | EF27: -0.020277393
C29: 1101 | D29: 2484 | E29: 1233 | F29: 2524 | G29: 2611 | H29: 1233 | I29: 2379 | J29: 2379 | K29: 2524 | L29: 1233 | M29: 2524 | N29: 1805 | O29: 2538 | P29: 3033 | Q29: 2385 | R29: 3024 | S29: 3024 | T29: 1314 | U29: 3024 | V29: 3024 | W29: 5521 | X29: 2535 | Y29: 3033 | Z29: 5201 | AA29: 2535 | AB29: 5201 | AC29: 5471 | AD29: 5521 | AE29: 2023 | AF29: 2023 | AG29: 3017 | AH29: 3033 | AI29: 1464 | AJ29: 2451 | AK29: 2451 | AL29: 4413 | AM29: 2451 | AN29: 2451 | AO29: 6121 | AP29: 2451 | AQ29: 1805 | AR29: 4416 | AS29: 5523 | AT29: 2524 | AU29: 1436 | AV29: 2338 | AW29: 5212 | AX29: 2338 | AY29: 6186 | AZ29: 5523 | BA29: 5523 | BB29: 5443 | BC29: 3051 | BD29: 5523 | BE29: 3051 | BF29: 3051 | BG29: 3051 | BH29: 6186 | BI29: 6186 | BJ29: 2537 | BK29: 2537 | BL29: 2488 | BM29: 6192 | BN29: 8927 | BO29: 2537 | BP29: 4416 | BQ29: 2537 | BR29: 6128 | BS29: 3002 | BT29: 5007 | BU29: 4109 | BV29: 6128 | BW29: 8085 | BX29: 8927 | BY29: 1737 | BZ29: 6242 | CA29: 6242 | CB29: 8927 | CC29: 8927 | CD29: 6242 | CE29: 8927 | CF29: 6242 | CG29: 8050 | CH29: 6242 | CI29: 6242 | CJ29: 8050 | CK29: 8050 | CL29: 6242 | CM29: 4402 | CN29: 3016 | CO29: 1436 | CP29: 6242 | CQ29: 3016 | CR29: 6242 | CS29: 3005 | CT29: 2493 | CU29: 2423 | CV29: 1734 | CW29: 5306 | CX29: 4402 | CY29: 9904 | CZ29: 8072 | DA29: 5007 | DB29: 9904 | DC29: 8072 | DD29: 6021 | DE29: 3232 | DF29: 2538 | DG29: 2538 | DH29: 5306 | DI29: 2538 | DJ29: 2434 | DK29: 2538 | DL29: 6020 | DM29: 2538 | DN29: 4402 | DO29: 2538 | DP29: 5425 | DQ29: 5425 | DR29: 4402 | DS29: 6291 | DT29: 2031 | DU29: 6291 | DV29: 3232 | DW29: 2538 | DX29: 6291 | DY29: 2538 | DZ29: 2538 | EA29: 8074 | EB29: 8074 | EC29: 3232 | ED29: 4402 | EE29: 2538 | EF29: 2538
