Workbook

Sheet 預測IC
A1: Predict
B2: Time | C2: 2013/12 | D2: 2014/01 | E2: 2014/02 | F2: 2014/03 | G2: 2014/04 | H2: 2014/05 | I2: 2014/06 | J2: 2014/07 | K2: 2014/08 | L2: 2014/09 | M2: 2014/10 | N2: 2014/11 | O2: 2014/12 | P2: 2015/01 | Q2: 2015/02 | R2: 2015/03 | S2: 2015/04 | T2: 2015/05 | U2: 2015/06 | V2: 2015/07 | W2: 2015/08 | X2: 2015/09 | Y2: 2015/10 | Z2: 2015/11 | AA2: 2015/12 | AB2: 2016/01 | AC2: 2016/02 | AD2: 2016/03 | AE2: 2016/04 | AF2: 2016/05 | AG2: 2016/06 | AH2: 2016/07 | AI2: 2016/08 | AJ2: 2016/09 | AK2: 2016/10 | AL2: 2016/11 | AM2: 2016/12 | AN2: 2017/01 | AO2: 2017/02 | AP2: 2017/03 | AQ2: 2017/04 | AR2: 2017/05 | AS2: 2017/06 | AT2: 2017/07 | AU2: 2017/08 | AV2: 2017/09 | AW2: 2017/10 | AX2: 2017/11 | AY2: 2017/12 | AZ2: 2018/01 | BA2: 2018/02 | BB2: 2018/03 | BC2: 2018/04 | BD2: 2018/05 | BE2: 2018/06 | BF2: 2018/07 | BG2: 2018/08 | BH2: 2018/09 | BI2: 2018/10 | BJ2: 2018/11 | BK2: 2018/12 | BL2: 2019/01 | BM2: 2019/02 | BN2: 2019/03 | BO2: 2019/04 | BP2: 2019/05 | BQ2: 2019/06 | BR2: 2019/07 | BS2: 2019/08 | BT2: 2019/09 | BU2: 2019/10 | BV2: 2019/11 | BW2: 2019/12 | BX2: 2020/01 | BY2: 2020/02 | BZ2: 2020/03 | CA2: 2020/04 | CB2: 2020/05 | CC2: 2020/06 | CD2: 2020/07 | CE2: 2020/08 | CF2: 2020/09 | CG2: 2020/10 | CH2: 2020/11 | CI2: 2020/12 | CJ2: 2021/01 | CK2: 2021/02 | CL2: 2021/03 | CM2: 2021/04 | CN2: 2021/05 | CO2: 2021/06 | CP2: 2021/07 | CQ2: 2021/08 | CR2: 2021/09 | CS2: 2021/10 | CT2: 2021/11 | CU2: 2021/12 | CV2: 2022/01 | CW2: 2022/02 | CX2: 2022/03 | CY2: 2022/04 | CZ2: 2022/05 | DA2: 2022/06 | DB2: 2022/07 | DC2: 2022/08 | DD2: 2022/09 | DE2: 2022/10 | DF2: 2022/11 | DG2: 2022/12 | DH2: 2023/01 | DI2: 2023/02 | DJ2: 2023/03 | DK2: 2023/04 | DL2: 2023/05 | DM2: 2023/06 | DN2: 2023/07 | DO2: 2023/08 | DP2: 2023/09 | DQ2: 2023/10 | DR2: 2023/11 | DS2: 2023/12 | DT2: 2024/01 | DU2: 2024/02 | DV2: 2024/03 | DW2: 2024/04 | DX2: 2024/05 | DY2: 2024/06 | DZ2: 2024/07 | EA2: 2024/08 | EB2: 2024/09 | EC2: 2024/10 | ED2: 2024/11 | EE2: 2024/12 | EF2: 2025/01
B3: mom1 | C3: -0.084296037 | D3: -0.028453094 | E3: -0.021896736 | F3: 0.0049927875 | G3: -0.12759725 | H3: 0.012816976 | I3: -0.048252078 | J3: -0.03769571 | K3: -0.094919957 | L3: -0.05809928 | M3: -0.03382241 | N3: 0.0089612257 | O3: -0.03212113 | P3: -0.032817403 | Q3: -0.046633806 | R3: -0.018320594 | S3: 0.0069135447 | T3: 0.0061760095 | U3: -0.031689833 | V3: -0.030298885 | W3: -0.0021307535 | X3: -0.086751883 | Y3: -0.037445057 | Z3: -0.046435733 | AA3: -0.046019081 | AB3: 0.015009172 | AC3: -0.0082020305 | AD3: 0.0080247193 | AE3: -0.014694865 | AF3: -0.025363234 | AG3: -0.0062780939 | AH3: -0.016290747 | AI3: -0.023747914 | AJ3: -0.0042027211 | AK3: -0.034839297 | AL3: -0.08603256 | AM3: -0.010445528 | AN3: -0.038234996 | AO3: -0.053682827 | AP3: -0.051607565 | AQ3: -0.10576687 | AR3: -0.016083889 | AS3: -0.070025962 | AT3: -0.025652004 | AU3: -0.032847243 | AV3: -0.021292943 | AW3: -0.013342953 | AX3: -0.0031210136 | AY3: -0.02905573 | AZ3: -0.0046051808 | BA3: -0.019629734 | BB3: -0.052320474 | BC3: 0.050930865 | BD3: -0.019246249 | BE3: 0.0093228681 | BF3: 0.068709222 | BG3: -0.050917387 | BH3: -0.0067289767 | BI3: 0.10163034 | BJ3: 0.067263981 | BK3: 0.050972985 | BL3: -0.04618489 | BM3: 0.025892876 | BN3: -0.026710333 | BO3: -0.049927813 | BP3: -0.0071747729 | BQ3: 0.0049605234 | BR3: 0.021221624 | BS3: -0.020949281 | BT3: -0.019188709 | BU3: -0.008492241 | BV3: 0.00094929292 | BW3: 0.0076663619 | BX3: -0.017806185 | BY3: -0.043971775 | BZ3: 0.030984032 | CA3: -0.0004806922 | CB3: 0.024421774 | CC3: -0.03139256 | CD3: 0.011642674 | CE3: -0.020740706 | CF3: -0.051309418 | CG3: -0.050579963 | CH3: -0.045668993 | CI3: -0.041886812 | CJ3: -0.013254799 | CK3: -0.056820905 | CL3: 0.011741601 | CM3: -0.009358498 | CN3: -0.047772208 | CO3: -0.015664503 | CP3: -0.030212116 | CQ3: -0.020150091 | CR3: -0.02206235 | CS3: 0.046777664 | CT3: -0.070356072 | CU3: -0.052592098 | CV3: -0.022595184 | CW3: -0.028634971 | CX3: -0.020095476 | CY3: -0.0068682508 | CZ3: -0.0083664722 | DA3: -0.012527147 | DB3: -0.034742487 | DC3: -0.035287016 | DD3: -0.040320739 | DE3: -0.018885248 | DF3: -0.0057070855 | DG3: 0.021545946 | DH3: -0.020355161 | DI3: 0.012775707 | DJ3: -0.028843413 | DK3: -0.013952374 | DL3: -0.020192651 | DM3: -0.038524102 | DN3: -0.036688151 | DO3: -0.04833259 | DP3: -0.028173829 | DQ3: -0.040410748 | DR3: -0.022062607 | DS3: 0.012081524 | DT3: -0.031258488 | DU3: -0.038229013 | DV3: -0.030951333 | DW3: -0.028482854 | DX3: -0.018710657 | DY3: -0.007841557 | DZ3: -0.052340509 | EA3: -0.00077639696 | EB3: -0.080836125 | EC3: -0.028180415 | ED3: -0.019637574 | EE3: -0.027325425 | EF3: -0.0069995168
B4: mom12 | C4: 0.031086562 | D4: 0.047767866 | E4: 0.029442859 | F4: 0.034256261 | G4: 0.036325841 | H4: 0.006332599 | I4: 0.069692227 | J4: 0.024401361 | K4: 0.045767937 | L4: 0.0314772 | M4: 0.042317701 | N4: -0.0018905536 | O4: -0.010245775 | P4: -0.0019796769 | Q4: 0.017536847 | R4: 0.0017624406 | S4: 0.021768037 | T4: 0.0059442181 | U4: 0.039464302 | V4: 0.06876214 | W4: 0.076546931 | X4: 0.031420375 | Y4: 0.07966016 | Z4: 0.085053838 | AA4: 0.091527942 | AB4: 0.049242917 | AC4: 0.085711746 | AD4: 0.071048822 | AE4: 0.10226172 | AF4: 0.069767586 | AG4: 0.0438662 | AH4: 0.021430809 | AI4: 0.079171444 | AJ4: 0.014593232 | AK4: 0.015906456 | AL4: 0.012273356 | AM4: 0.016922997 | AN4: 0.011423359 | AO4: 0.026535957 | AP4: 0.0011743756 | AQ4: 0.012771089 | AR4: 0.010317775 | AS4: 0.01697541 | AT4: 0.014166618 | AU4: 0.0082552446 | AV4: 0.023066346 | AW4: 0.023147919 | AX4: 0.023799649 | AY4: 0.014460876 | AZ4: 0.034728633 | BA4: 0.032672294 | BB4: 0.033982517 | BC4: 0.029035951 | BD4: 0.020288006 | BE4: -0.00028476376 | BF4: 0.0062749563 | BG4: 0.017906543 | BH4: 0.0063413702 | BI4: 0.0068454634 | BJ4: -0.060452063 | BK4: -0.013397291 | BL4: -0.034864653 | BM4: -0.021633195 | BN4: -0.016377984 | BO4: -0.0061762359 | BP4: -0.011117686 | BQ4: -0.0003618203 | BR4: -0.011873785 | BS4: -0.0034710975 | BT4: -0.025477536 | BU4: 0.0069430725 | BV4: -0.023398357 | BW4: -0.018522725 | BX4: 0.00059401307 | BY4: -0.014444654 | BZ4: 0.028941468 | CA4: 0.010229575 | CB4: 0.041552027 | CC4: 0.0057523362 | CD4: 0.0033523121 | CE4: 0.014197075 | CF4: -0.004569375 | CG4: -0.019029597 | CH4: -0.010788284 | CI4: 0.00063783894 | CJ4: -0.014108614 | CK4: 0.0086953487 | CL4: 0.0017359775 | CM4: 0.0040652307 | CN4: 0.0015994583 | CO4: -0.0043710701 | CP4: 0.0069698803 | CQ4: 0.010808053 | CR4: 0.0067308185 | CS4: 0.0039378843 | CT4: 0.0023343906 | CU4: 0.014161852 | CV4: 0.016578617 | CW4: -5.3767109e-05 | CX4: 0.0059573099 | CY4: -0.0031593002 | CZ4: 0.045647167 | DA4: -0.0086543633 | DB4: 0.004292258 | DC4: 0.023703575 | DD4: -0.016213709 | DE4: -0.0076176694 | DF4: -0.012475125 | DG4: 0.0092687208 | DH4: 0.022705826 | DI4: 0.023233119 | DJ4: 0.02163116 | DK4: 0.014060585 | DL4: 0.013527414 | DM4: 0.016738818 | DN4: -0.0037982045 | DO4: -0.014217691 | DP4: -0.011308714 | DQ4: -0.0079768897 | DR4: -0.021246794 | DS4: -0.0034573385 | DT4: -0.0031901923 | DU4: -0.0055752805 | DV4: 0.0012936465 | DW4: 0.0099671657 | DX4: 0.023796675 | DY4: 0.017423391 | DZ4: 0.024955597 | EA4: 0.01592509 | EB4: 0.020969357 | EC4: 0.035010762 | ED4: 0.024269625 | EE4: 0.027041592 | EF4: 0.033338079
B5: chmom | C5: -0.012769034 | D5: -0.080379557 | E5: -0.077795222 | F5: 0.0032339975 | G5: -0.049376852 | H5: -0.00047750875 | I5: -0.006410866 | J5: 0.0035346434 | K5: 0.03762383 | L5: 0.0098663401 | M5: 0.049079599 | N5: -0.052030404 | O5: -0.044621881 | P5: -0.0441503 | Q5: -0.041312605 | R5: -0.060858785 | S5: -0.0072576562 | T5: -0.0043309017 | U5: 0.002972276 | V5: -0.033837327 | W5: -0.065398147 | X5: 0.042224769 | Y5: 0.031967889 | Z5: 0.031174127 | AA5: 0.01903959 | AB5: -0.055678241 | AC5: 0.050430968 | AD5: 0.044867778 | AE5: -0.010455356 | AF5: -0.012711314 | AG5: -0.055209956 | AH5: -0.034749333 | AI5: -0.048839311 | AJ5: -0.047042933 | AK5: -0.031198327 | AL5: -0.04554627 | AM5: -0.034191704 | AN5: -0.030586555 | AO5: -0.028680839 | AP5: -0.031230965 | AQ5: -0.030843959 | AR5: -0.015263559 | AS5: -0.0073979911 | AT5: -0.0023343631 | AU5: -0.015139698 | AV5: -0.0025649844 | AW5: -0.0016685692 | AX5: -0.0077675325 | AY5: -0.0039317776 | AZ5: -0.017814331 | BA5: -0.010207532 | BB5: -0.0022441413 | BC5: -0.026053514 | BD5: -0.021648415 | BE5: -0.020364468 | BF5: -0.00279204 | BG5: -0.016380118 | BH5: -0.0170688 | BI5: 0.013178145 | BJ5: -0.005369774 | BK5: -0.03232371 | BL5: -0.04651313 | BM5: -0.065427689 | BN5: -0.028340079 | BO5: -0.068067015 | BP5: -0.057393521 | BQ5: -0.036663021 | BR5: -0.031607124 | BS5: 0.011799891 | BT5: -0.013009514 | BU5: -0.014311287 | BV5: 0.0018115701 | BW5: -0.030749639 | BX5: -0.018084769 | BY5: 0.00098999111 | BZ5: -0.013055744 | CA5: -0.0253284 | CB5: 0.038353479 | CC5: -0.016522259 | CD5: -0.00053755456 | CE5: -0.011252224 | CF5: -0.015260309 | CG5: -0.015347673 | CH5: -0.025082186 | CI5: -0.023339198 | CJ5: -0.01682036 | CK5: -0.0097529039 | CL5: -0.034307649 | CM5: -0.016145441 | CN5: -0.052400768 | CO5: -0.042581802 | CP5: -0.046556868 | CQ5: -0.020272322 | CR5: -0.0031058179 | CS5: -0.00087262058 | CT5: -0.039574466 | CU5: -0.029502153 | CV5: -0.022976063 | CW5: -0.0083811044 | CX5: -0.011353243 | CY5: -0.020845782 | CZ5: -0.027662335 | DA5: -0.029502399 | DB5: -0.022160845 | DC5: -0.074919917 | DD5: -0.058916671 | DE5: -0.057093108 | DF5: -0.053718019 | DG5: -0.058042034 | DH5: -0.045676489 | DI5: -0.015917013 | DJ5: -0.033235287 | DK5: -0.018187099 | DL5: -0.015445846 | DM5: -0.022497262 | DN5: -0.016052082 | DO5: -0.01592865 | DP5: -0.020912629 | DQ5: -0.022164842 | DR5: -0.0089371676 | DS5: -0.010982404 | DT5: -0.010795643 | DU5: -0.011575455 | DV5: -0.03691777 | DW5: -0.031998141 | DX5: -0.026040725 | DY5: -0.016413638 | DZ5: -0.022523036 | EA5: -0.030593762 | EB5: -0.023293475 | EC5: -0.027976747 | ED5: -0.017834178 | EE5: -0.099851966 | EF5: -0.011236467
B6: retvol | C6: 0.024781267 | D6: -0.0013055566 | E6: 0.016088752 | F6: 0.024671316 | G6: -0.0031626399 | H6: 0.017431697 | I6: 0.034224801 | J6: 0.021370584 | K6: 0.040150458 | L6: 0.033348308 | M6: 0.034388557 | N6: 0.035428174 | O6: 0.026141638 | P6: 0.018742898 | Q6: -0.00093773209 | R6: 0.010792956 | S6: 0.031520276 | T6: 0.010780637 | U6: 0.012518142 | V6: 0.01477949 | W6: -0.0010149845 | X6: -0.0015559868 | Y6: -0.0039166886 | Z6: 0.0039797344 | AA6: -0.012931896 | AB6: -0.0036109545 | AC6: -0.0015901802 | AD6: 0.0065947133 | AE6: 0.0090079003 | AF6: 0.005167996 | AG6: 0.011664802 | AH6: 0.075437548 | AI6: 0.017333287 | AJ6: 0.013547005 | AK6: 0.0056964666 | AL6: 0.019356861 | AM6: 0.020237432 | AN6: 0.013241048 | AO6: 0.0071526961 | AP6: 0.015454284 | AQ6: 0.033343226 | AR6: 0.021523284 | AS6: 0.025957378 | AT6: 0.013557033 | AU6: 0.016235781 | AV6: 0.023924466 | AW6: 0.012314908 | AX6: 0.027608811 | AY6: 0.019968728 | AZ6: 0.018852319 | BA6: 0.014060394 | BB6: 0.032051331 | BC6: 0.029666564 | BD6: 0.02897614 | BE6: 0.016734098 | BF6: 0.033082162 | BG6: 0.015582072 | BH6: 0.0093848799 | BI6: 0.022418834 | BJ6: 0.015080653 | BK6: 0.014967289 | BL6: 0.0027962623 | BM6: 0.0064001785 | BN6: 0.0059565527 | BO6: 0.010496731 | BP6: 0.0041071899 | BQ6: 0.0072204176 | BR6: 0.012253608 | BS6: 0.009688116 | BT6: 0.027689998 | BU6: 0.037176813 | BV6: 0.022503001 | BW6: 0.023397136 | BX6: 0.024806566 | BY6: 0.032843935 | BZ6: 0.033974649 | CA6: 0.03950916 | CB6: 0.08390838 | CC6: 0.025834606 | CD6: 0.024055735 | CE6: 0.023266115 | CF6: 0.01373645 | CG6: 0.0079774934 | CH6: 0.033776237 | CI6: 0.039098583 | CJ6: 0.094079957 | CK6: 0.024276765 | CL6: 0.022128573 | CM6: 0.035010445 | CN6: 0.020401066 | CO6: 0.027974486 | CP6: 0.027230711 | CQ6: 0.023250527 | CR6: 0.0059947723 | CS6: 0.0046918987 | CT6: 0.014269957 | CU6: 0.0066048063 | CV6: -0.0028537012 | CW6: 0.011713582 | CX6: 0.014280895 | CY6: 0.014092544 | CZ6: 0.01430786 | DA6: 0.016388941 | DB6: 0.018640834 | DC6: 0.017264688 | DD6: 0.013670796 | DE6: 0.015980331 | DF6: 0.010148804 | DG6: 0.009217544 | DH6: 0.0086918177 | DI6: 0.0083922694 | DJ6: 0.012134253 | DK6: 0.0078949549 | DL6: 0.0086436134 | DM6: 0.007171855 | DN6: 0.011896805 | DO6: 0.086997096 | DP6: 0.092320822 | DQ6: 0.091081724 | DR6: 0.086032132 | DS6: 0.085301284 | DT6: 0.1041565 | DU6: 0.11147645 | DV6: 0.11222523 | DW6: 0.11382743 | DX6: 0.11960259 | DY6: 0.12528885 | DZ6: 0.12639663 | EA6: 0.12674933 | EB6: 0.13046922 | EC6: 0.13362178 | ED6: 0.0019701395 | EE6: 0.0028774188 | EF6: 0.0013222361
B7: maxret | C7: 0.028323116 | D7: 0.012206451 | E7: 0.0037689315 | F7: -0.0089288017 | G7: -0.029484002 | H7: -0.034708549 | I7: -0.051269569 | J7: -0.031660115 | K7: -0.020045522 | L7: -0.019466422 | M7: -0.021515619 | N7: -0.010837063 | O7: 0.0052283702 | P7: 0.01022319 | Q7: 0.017629328 | R7: 0.024250753 | S7: 0.031586313 | T7: 0.046423107 | U7: 0.04512689 | V7: -0.0059353127 | W7: 0.0062574475 | X7: 0.021909646 | Y7: -0.01907875 | Z7: 0.0051659428 | AA7: -0.01227952 | AB7: -0.0017069929 | AC7: -0.00075664344 | AD7: -0.0030775684 | AE7: -0.010483986 | AF7: -0.0026502199 | AG7: 8.079779e-05 | AH7: -0.0048559479 | AI7: -0.0046092936 | AJ7: -0.014472156 | AK7: -0.012909039 | AL7: -0.015644126 | AM7: -0.0065867115 | AN7: -0.016828039 | AO7: -0.014476777 | AP7: -0.021091682 | AQ7: -0.028551068 | AR7: -0.0078151466 | AS7: -0.010129083 | AT7: -0.0078955662 | AU7: -0.0090748824 | AV7: 0.021755522 | AW7: 0.025959518 | AX7: 0.010969239 | AY7: 0.0195285 | AZ7: 0.03910909 | BA7: 0.050277286 | BB7: -0.0041446395 | BC7: 0.015062358 | BD7: 0.00082699574 | BE7: 0.0034352436 | BF7: 0.0011414189 | BG7: -0.002914366 | BH7: 0.0099346356 | BI7: 0.0059251983 | BJ7: -0.0056623803 | BK7: -0.0020464909 | BL7: -0.0038359612 | BM7: -0.0087151659 | BN7: -0.0018325715 | BO7: -0.0044087482 | BP7: -0.0028912579 | BQ7: -0.0061427376 | BR7: -0.00099651227 | BS7: 0.0064362376 | BT7: 0.0046488175 | BU7: -0.0012628116 | BV7: 0.0086401319 | BW7: 0.016261705 | BX7: 0.027921779 | BY7: 0.020634725 | BZ7: 0.022316884 | CA7: 0.0034580544 | CB7: -0.0003578152 | CC7: -0.0018413325 | CD7: 0.0016207623 | CE7: 0.0049775067 | CF7: -0.012314832 | CG7: -0.015143892 | CH7: -0.012504156 | CI7: -0.0084800575 | CJ7: -0.00082879515 | CK7: 0.0054167268 | CL7: 0.008275818 | CM7: 0.0087966919 | CN7: 0.014065471 | CO7: 0.0046390609 | CP7: 0.017356226 | CQ7: 0.012931298 | CR7: 0.014260785 | CS7: 0.0100124 | CT7: 0.014104361 | CU7: 0.0074970201 | CV7: 0.0014517656 | CW7: 0.00041397841 | CX7: -0.004716975 | CY7: -0.0036579019 | CZ7: -0.003174917 | DA7: -0.00419089 | DB7: -0.0050241844 | DC7: -0.0020616992 | DD7: 0.003859574 | DE7: 9.496941e-05 | DF7: -0.00017685341 | DG7: 0.0016713109 | DH7: 0.00058193289 | DI7: 0.00038134949 | DJ7: -0.0070806786 | DK7: -0.0037518035 | DL7: -0.00050886448 | DM7: -0.0026977714 | DN7: 0.00045161168 | DO7: -0.012603039 | DP7: -0.0092454617 | DQ7: -0.0042401797 | DR7: 0.0031142192 | DS7: -0.0020752695 | DT7: 0.0069542704 | DU7: 0.00088154032 | DV7: -0.00077751543 | DW7: -0.0028298685 | DX7: -0.00050638239 | DY7: 0.0058338743 | DZ7: 0.0006071589 | EA7: -0.003785089 | EB7: 0.002689984 | EC7: 0.002180623 | ED7: 0.0063146461 | EE7: 0.0064540842 | EF7: 0.0062494523
A8: 選絕對值最大 | C8: {=MATCH(MAX(ABS(C3:C7)), ABS(C3:C7), 0)} -> 1 | D8: {=MATCH(MAX(ABS(D3:D7)), ABS(D3:D7), 0)} -> 3 | E8: {=MATCH(MAX(ABS(E3:E7)), ABS(E3:E7), 0)} -> 3 | F8: {=MATCH(MAX(ABS(F3:F7)), ABS(F3:F7), 0)} -> 2 | G8: {=MATCH(MAX(ABS(G3:G7)), ABS(G3:G7), 0)} -> 1 | H8: {=MATCH(MAX(ABS(H3:H7)), ABS(H3:H7), 0)} -> 5 | I8: {=MATCH(MAX(ABS(I3:I7)), ABS(I3:I7), 0)} -> 2 | J8: {=MATCH(MAX(ABS(J3:J7)), ABS(J3:J7), 0)} -> 1 | ... EE8: {=MATCH(MAX(ABS(EE3:EE7)), ABS(EE3:EE7), 0)} -> 3 | EF8: 2
C9: =IF(C8=1,"mom1", IF(C8=2,"mom12", IF(C8=3,"chmom", IF(C8=4,"retvol", IF(C8=5,"maxret",""))))) -> mom1 | D9: =IF(D8=1,"mom1", IF(D8=2,"mom12", IF(D8=3,"chmom", IF(D8=4,"retvol", IF(D8=5,"maxret",""))))) -> chmom | E9: =IF(E8=1,"mom1", IF(E8=2,"mom12", IF(E8=3,"chmom", IF(E8=4,"retvol", IF(E8=5,"maxret",""))))) -> chmom | F9: =IF(F8=1,"mom1", IF(F8=2,"mom12", IF(F8=3,"chmom", IF(F8=4,"retvol", IF(F8=5,"maxret",""))))) -> mom12 | G9: =IF(G8=1,"mom1", IF(G8=2,"mom12", IF(G8=3,"chmom", IF(G8=4,"retvol", IF(G8=5,"maxret",""))))) -> mom1 | H9: =IF(H8=1,"mom1", IF(H8=2,"mom12", IF(H8=3,"chmom", IF(H8=4,"retvol", IF(H8=5,"maxret",""))))) -> maxret | I9: =IF(I8=1,"mom1", IF(I8=2,"mom12", IF(I8=3,"chmom", IF(I8=4,"retvol", IF(I8=5,"maxret",""))))) -> mom12 | J9: =IF(J8=1,"mom1", IF(J8=2,"mom12", IF(J8=3,"chmom", IF(J8=4,"retvol", IF(J8=5,"maxret",""))))) -> mom1 | ... EF9: =IF(EF8=1,"mom1", IF(EF8=2,"mom12", IF(EF8=3,"chmom", IF(EF8=4,"retvol", IF(EF8=5,"maxret",""))))) -> mom12
C10: =IF(C8=1,C3,IF(C8=2,C4,IF(C8=3,C5,IF(C8=4,C6,IF(C8=5,C7))))) -> -0.084296037 | D10: =IF(D8=1,D3,IF(D8=2,D4,IF(D8=3,D5,IF(D8=4,D6,IF(D8=5,D7))))) -> -0.080379557 | E10: =IF(E8=1,E3,IF(E8=2,E4,IF(E8=3,E5,IF(E8=4,E6,IF(E8=5,E7))))) -> -0.077795222 | F10: =IF(F8=1,F3,IF(F8=2,F4,IF(F8=3,F5,IF(F8=4,F6,IF(F8=5,F7))))) -> 0.034256261 | G10: =IF(G8=1,G3,IF(G8=2,G4,IF(G8=3,G5,IF(G8=4,G6,IF(G8=5,G7))))) -> -0.12759725 | H10: =IF(H8=1,H3,IF(H8=2,H4,IF(H8=3,H5,IF(H8=4,H6,IF(H8=5,H7))))) -> -0.034708549 | I10: =IF(I8=1,I3,IF(I8=2,I4,IF(I8=3,I5,IF(I8=4,I6,IF(I8=5,I7))))) -> 0.069692227 | J10: =IF(J8=1,J3,IF(J8=2,J4,IF(J8=3,J5,IF(J8=4,J6,IF(J8=5,J7))))) -> -0.03769571 | ... EF10: =IF(EF8=1,EF3,IF(EF8=2,EF4,IF(EF8=3,EF5,IF(EF8=4,EF6,IF(EF8=5,EF7))))) -> 0.033338079
A12: 投資組合 | C12: 公司數 | D12: 964
A13: 等分 | B13: 家數 | C13: 2014/01 | D13: 2014/02 | E13: 2014/03 | F13: 2014/04 | G13: 2014/05 | H13: 2014/06 | I13: 2014/07 | J13: 2014/08 | K13: 2014/09 | L13: 2014/10 | M13: 2014/11 | N13: 2014/12 | O13: 2015/01 | P13: 2015/02 | Q13: 2015/03 | R13: 2015/04 | S13: 2015/05 | T13: 2015/06 | U13: 2015/07 | V13: 2015/08 | W13: 2015/09 | X13: 2015/10 | Y13: 2015/11 | Z13: 2015/12 | AA13: 2016/01 | AB13: 2016/02 | AC13: 2016/03 | AD13: 2016/04 | AE13: 2016/05 | AF13: 2016/06 | AG13: 2016/07 | AH13: 2016/08 | AI13: 2016/09 | AJ13: 2016/10 | AK13: 2016/11 | AL13: 2016/12 | AM13: 2017/01 | AN13: 2017/02 | AO13: 2017/03 | AP13: 2017/04 | AQ13: 2017/05 | AR13: 2017/06 | AS13: 2017/07 | AT13: 2017/08 | AU13: 2017/09 | AV13: 2017/10 | AW13: 2017/11 | AX13: 2017/12 | AY13: 2018/01 | AZ13: 2018/02 | BA13: 2018/03 | BB13: 2018/04 | BC13: 2018/05 | BD13: 2018/06 | BE13: 2018/07 | BF13: 2018/08 | BG13: 2018/09 | BH13: 2018/10 | BI13: 2018/11 | BJ13: 2018/12 | BK13: 2019/01 | BL13: 2019/02 | BM13: 2019/03 | BN13: 2019/04 | BO13: 2019/05 | BP13: 2019/06 | BQ13: 2019/07 | BR13: 2019/08 | BS13: 2019/09 | BT13: 2019/10 | BU13: 2019/11 | BV13: 2019/12 | BW13: 2020/01 | BX13: 2020/02 | BY13: 2020/03 | BZ13: 2020/04 | CA13: 2020/05 | CB13: 2020/06 | CC13: 2020/07 | CD13: 2020/08 | CE13: 2020/09 | CF13: 2020/10 | CG13: 2020/11 | CH13: 2020/12 | CI13: 2021/01 | CJ13: 2021/02 | CK13: 2021/03 | CL13: 2021/04 | CM13: 2021/05 | CN13: 2021/06 | CO13: 2021/07 | CP13: 2021/08 | CQ13: 2021/09 | CR13: 2021/10 | CS13: 2021/11 | CT13: 2021/12 | CU13: 2022/01 | CV13: 2022/02 | CW13: 2022/03 | CX13: 2022/04 | CY13: 2022/05 | CZ13: 2022/06 | DA13: 2022/07 | DB13: 2022/08 | DC13: 2022/09 | DD13: 2022/10 | DE13: 2022/11 | DF13: 2022/12 | DG13: 2023/01 | DH13: 2023/02 | DI13: 2023/03 | DJ13: 2023/04 | DK13: 2023/05 | DL13: 2023/06 | DM13: 2023/07 | DN13: 2023/08 | DO13: 2023/09 | DP13: 2023/10 | DQ13: 2023/11 | DR13: 2023/12 | DS13: 2024/01 | DT13: 2024/02 | DU13: 2024/03 | DV13: 2024/04 | DW13: 2024/05 | DX13: 2024/06 | DY13: 2024/07 | DZ13: 2024/08 | EA13: 2024/09 | EB13: 2024/10 | EC13: 2024/11 | ED13: 2024/12 | EE13: 2025/01 | EF13: 2025/02
A14: 10 | B14: 96 | C14: -0.017914422 | D14: 0.01474379 | E14: -0.012204229 | F14: -0.053147374 | G14: 0.040128401 | H14: -0.029291093 | I14: 0.008989969 | J14: 0.023382661 | K14: 0.021930043 | L14: -0.0269641 | M14: 0.042054112 | N14: -0.062779238 | O14: 0.016232899 | P14: 0.012193469 | Q14: 0.0076230885 | R14: 0.018116053 | S14: 0.0077262328 | T14: 0.016864847 | U14: 0.023544394 | V14: 0.0071100019 | W14: 0.0034325513 | X14: -0.014388568 | Y14: -0.017673309 | Z14: 0.015356015 | AA14: -0.02023878 | AB14: -0.015252853 | AC14: 0.052316224 | AD14: 0.013841406 | AE14: -0.043800236 | AF14: 0.034362667 | AG14: -0.0011394646 | AH14: -0.011343814 | AI14: -0.027578078 | AJ14: 0.0084470293 | AK14: 0.012210252 | AL14: 0.00078536443 | AM14: -0.015189797 | AN14: -0.0031120303 | AO14: -0.012258227 | AP14: 0.011149207 | AQ14: -0.001786015 | AR14: -0.0058911143 | AS14: -0.0041443954 | AT14: 0.026630815 | AU14: 0.026437148 | AV14: 0.0020173675 | AW14: -0.0091094251 | AX14: -0.0031902494 | AY14: 0.017877521 | AZ14: -0.0024840243 | BA14: -0.032672666 | BB14: -0.028447327 | BC14: 0.0056434854 | BD14: 0.001452469 | BE14: -0.010464923 | BF14: 0.0053348007 | BG14: -0.028091151 | BH14: -0.10111457 | BI14: -0.079817936 | BJ14: -0.018070249 | BK14: 0.0011683874 | BL14: 0.0027396236 | BM14: 0.012795198 | BN14: 0.011799903 | BO14: -0.00094684798 | BP14: 0.030534431 | BQ14: 0.0037879717 | BR14: 0.044921121 | BS14: -0.0029157219 | BT14: 0.018350074 | BU14: 0.015541905 | BV14: -0.027131051 | BW14: 0.00037233386 | BX14: 0.025321738 | BY14: -0.036592154 | BZ14: -0.00080121838 | CA14: -0.001983026 | CB14: 0.021274721 | CC14: -0.019468785 | CD14: -0.014153332 | CE14: 0.046425814 | CF14: -0.035742396 | CG14: 0.021749295 | CH14: -0.019303362 | CI14: 0.0018884799 | CJ14: 0.033818884 | CK14: 1.7029972e-06 | CL14: -0.091623579 | CM14: -0.0046818755 | CN14: 0.055908726 | CO14: 0.03344169 | CP14: -0.016988097 | CQ14: -0.013259306 | CR14: -0.017079858 | CS14: -0.0026031772 | CT14: 0.03618057 | CU14: 0.025473001 | CV14: -0.027420184 | CW14: -0.017227962 | CX14: -0.0010624493 | CY14: 0.0060544407 | CZ14: 0.034360349 | DA14: 0.015074514 | DB14: 0.0031380159 | DC14: 0.037955986 | DD14: -0.032348512 | DE14: -0.02082289 | DF14: -0.0008042479 | DG14: -0.029950973 | DH14: -0.02279128 | DI14: -0.016653315 | DJ14: 0.035436352 | DK14: 0.0031399639 | DL14: -0.010422765 | DM14: -0.0029136022 | DN14: 0.035085275 | DO14: -0.016824926 | DP14: 0.0089140411 | DQ14: -0.00094653305 | DR14: 0.0012631379 | DS14: 0.021131864 | DT14: 0.010060553 | DU14: -0.018461382 | DV14: 0.0078079076 | DW14: 0.01606348 | DX14: -0.0076204184 | DY14: -0.0046646487 | DZ14: -0.019807221 | EA14: 0.013475792 | EB14: 0.013961429 | EC14: 0.0026554381 | ED14: 0.015404233 | EE14: -0.01604335 | EF14: 0.0036622338
A15: 20 | B15: 48 | C15: -0.003950283 | D15: -0.0025084934 | E15: -0.0060947418 | F15: -0.055185485 | G15: 0.048132934 | H15: -0.041932639 | I15: 0.031606175 | J15: 0.021767521 | K15: 0.042399896 | L15: -0.035107971 | M15: 0.066044614 | N15: -0.072815628 | O15: 0.030584033 | P15: 0.0055538611 | Q15: 0.024820848 | R15: 0.019114633 | S15: 0.010434531 | T15: 0.019459161 | U15: 0.031820208 | V15: -0.010824561 | W15: 0.00069474788 | X15: -0.033582969 | Y15: -0.037065107 | Z15: 0.019560793 | AA15: -0.042959051 | AB15: -0.018608172 | AC15: 0.049468075 | AD15: 0.016287212 | AE15: -0.056550969 | AF15: 0.058299593 | AG15: 0.0046532493 | AH15: -0.0029585738 | AI15: 0.0029685835 | AJ15: 0.01934611 | AK15: 0.0041515791 | AL15: -0.019143576 | AM15: 0.0007308227 | AN15: -0.013633471 | AO15: -0.008097408 | AP15: 0.012356176 | AQ15: 0.0084706181 | AR15: 0.015414591 | AS15: 0.017405365 | AT15: -0.0087288884 | AU15: 0.045568821 | AV15: 0.0021763861 | AW15: 0.0099436208 | AX15: 0.0021568869 | AY15: 0.024207464 | AZ15: 0.0076985173 | BA15: -0.028348353 | BB15: -0.035372516 | BC15: -0.011692869 | BD15: 0.021076727 | BE15: 0.0041405111 | BF15: -0.023107576 | BG15: -0.011187911 | BH15: -0.11728993 | BI15: -0.085489923 | BJ15: -0.0028021215 | BK15: 0.015026012 | BL15: 0.010811863 | BM15: -0.0010779226 | BN15: 0.0027556243 | BO15: 0.0049250299 | BP15: 0.054043902 | BQ15: 0.011818776 | BR15: 0.069886902 | BS15: 0.0013337684 | BT15: 0.010025935 | BU15: 0.03569211 | BV15: -0.042122787 | BW15: 0.0068643352 | BX15: 0.045067547 | BY15: -0.039873584 | BZ15: 0.0020573892 | CA15: 0.0068027679 | CB15: 0.059118242 | CC15: 0.0039295206 | CD15: -0.024752282 | CE15: 0.050895924 | CF15: -0.016859165 | CG15: 0.028115601 | CH15: -0.056158763 | CI15: -0.010421872 | CJ15: 0.017601347 | CK15: 0.0050814086 | CL15: -0.08865897 | CM15: -0.025314001 | CN15: 0.065478157 | CO15: 0.047109008 | CP15: -0.0017926871 | CQ15: -0.016009899 | CR15: -0.010522434 | CS15: 0.014141764 | CT15: 0.015788784 | CU15: 0.037858174 | CV15: -0.02093146 | CW15: -0.031107906 | CX15: -0.014504454 | CY15: 0.022843924 | CZ15: 0.022392373 | DA15: 0.038088297 | DB15: -0.04449956 | DC15: 0.001163238 | DD15: -0.025719971 | DE15: 0.0090249524 | DF15: -0.0037510555 | DG15: -0.04597892 | DH15: -0.011428908 | DI15: -0.022486578 | DJ15: 0.025070374 | DK15: 0.025608914 | DL15: -0.032432535 | DM15: 0.0009546467 | DN15: 0.043622927 | DO15: -0.031128307 | DP15: -0.0084223615 | DQ15: 0.010897443 | DR15: 0.0067693859 | DS15: 0.0081973445 | DT15: -0.0067101916 | DU15: 0.010343277 | DV15: 0.029949356 | DW15: 0.03862699 | DX15: -0.034424866 | DY15: 0.021058177 | DZ15: -0.028400033 | EA15: 0.012309624 | EB15: 0.036744407 | EC15: -0.0028880779 | ED15: -0.011140574 | EE15: 0.0037713156 | EF15: 0.022015488
A16: 50 | B16: 19 | C16: -0.0033019748 | D16: -0.064571216 | E16: -0.004835497 | F16: 0.032352589 | G16: 0.086666883 | H16: -0.0059818487 | I16: 0.086349551 | J16: 0.0016257159 | K16: 0.030400411 | L16: -0.071342897 | M16: 0.0070043857 | N16: -0.13761006 | O16: 0.036485842 | P16: -0.00016283972 | Q16: -0.010307655 | R16: 0.035589056 | S16: 0.013911385 | T16: -0.010024759 | U16: 0.048520728 | V16: 0.021086276 | W16: 0.053159186 | X16: -0.011985196 | Y16: 0.0083469226 | Z16: 0.10277159 | AA16: -0.034522748 | AB16: -0.014607627 | AC16: 0.074341695 | AD16: 0.034693644 | AE16: -0.061821971 | AF16: 0.13590869 | AG16: -0.0079502293 | AH16: -0.010930175 | AI16: 0.016370663 | AJ16: 0.046961948 | AK16: -0.032260639 | AL16: -0.029968038 | AM16: -0.050937933 | AN16: 0.035739294 | AO16: -0.025596766 | AP16: 0.0012189463 | AQ16: -0.041504465 | AR16: 0.025335573 | AS16: 0.010097589 | AT16: -0.010811071 | AU16: 0.043261429 | AV16: -0.010847928 | AW16: 0.0041307411 | AX16: -0.0053084129 | AY16: 0.028490601 | AZ16: 0.012086329 | BA16: -0.028568877 | BB16: -0.047089722 | BC16: 0.030207846 | BD16: 0.078092959 | BE16: -0.024172808 | BF16: -0.024511704 | BG16: -0.0058406285 | BH16: -0.13175057 | BI16: -0.072657391 | BJ16: -0.022907705 | BK16: -0.05279362 | BL16: 0.032758447 | BM16: -0.013292609 | BN16: -0.025230124 | BO16: -0.052015306 | BP16: 0.080501309 | BQ16: 0.0034503221 | BR16: 0.058227598 | BS16: -0.010442267 | BT16: -0.0090245966 | BU16: 0.035357455 | BV16: -0.11695795 | BW16: 0.07023393 | BX16: 0.069320211 | BY16: 0.012578967 | BZ16: 0.0076876374 | CA16: -0.0083220959 | CB16: 0.057043682 | CC16: -0.017633978 | CD16: -0.053812125 | CE16: 0.079259114 | CF16: 0.022318752 | CG16: -0.020837135 | CH16: -0.055070142 | CI16: 0.047076614 | CJ16: 0.021583767 | CK16: 0.0065144967 | CL16: -0.1264709 | CM16: -0.034181104 | CN16: 0.086151891 | CO16: 0.064133156 | CP16: -0.0019513094 | CQ16: -0.04011381 | CR16: -0.073959473 | CS16: 0.029653831 | CT16: 0.0320802 | CU16: 0.09479207 | CV16: 0.027207998 | CW16: -0.030757688 | CX16: -0.0053997377 | CY16: 0.053652027 | CZ16: 0.052085286 | DA16: 0.070693033 | DB16: -0.027102044 | DC16: 0.0032284748 | DD16: -0.038924516 | DE16: 0.060802243 | DF16: -0.073598301 | DG16: -0.051763352 | DH16: -0.023530661 | DI16: -0.060491998 | DJ16: 0.066055157 | DK16: -0.0071598137 | DL16: -0.070838604 | DM16: -0.019804717 | DN16: 0.039163982 | DO16: -0.052839322 | DP16: -0.0057975536 | DQ16: 0.030566702 | DR16: 0.0019011258 | DS16: 0.021013096 | DT16: -0.014455569 | DU16: 0.040471275 | DV16: 0.082461398 | DW16: 0.043423894 | DX16: -0.042781676 | DY16: 0.0071405324 | DZ16: -0.080220212 | EA16: -0.031474482 | EB16: 0.011213675 | EC16: -0.010576377 | ED16: 0.013813554 | EE16: -0.013121095 | EF16: 0.054841656
A17: 100 | B17: 10 | C17: 0.065024995 | D17: -0.077036997 | E17: -0.0030786204 | F17: 0.038184382 | G17: 0.093175457 | H17: 0.0072814308 | I17: 0.089156758 | J17: 0.01657412 | K17: 0.047793938 | L17: 0.012082397 | M17: -0.032627993 | N17: -0.14606349 | O17: 0.042228512 | P17: 3.4199147e-05 | Q17: 0.040930211 | R17: 0.078809605 | S17: 0.038629632 | T17: -0.00086051017 | U17: 0.11326912 | V17: 0.045889133 | W17: 0.078215746 | X17: 0.00602284 | Y17: -0.039359625 | Z17: 0.048588148 | AA17: -0.041170903 | AB17: 0.0024020314 | AC17: 0.066863788 | AD17: 0.034624052 | AE17: -0.083110883 | AF17: 0.11896227 | AG17: -0.022942839 | AH17: -0.044426446 | AI17: 0.068890799 | AJ17: 0.051665749 | AK17: -0.088493733 | AL17: -0.012042585 | AM17: -0.023712275 | AN17: 0.078691126 | AO17: -0.038788003 | AP17: -0.02282635 | AQ17: -0.069999892 | AR17: 0.034428829 | AS17: 0.0053876963 | AT17: -0.049657417 | AU17: 0.033348055 | AV17: 0.012826748 | AW17: -0.0093101334 | AX17: -0.038227576 | AY17: 0.056601081 | AZ17: 0.0048493021 | BA17: 0.0045373531 | BB17: -0.047840444 | BC17: -0.00050583706 | BD17: 0.052737819 | BE17: -0.019801787 | BF17: -0.050648466 | BG17: 0.047524063 | BH17: -0.097079008 | BI17: -0.077627796 | BJ17: -0.035742294 | BK17: -0.022313901 | BL17: 0.023924665 | BM17: 0.0074932598 | BN17: -0.070567261 | BO17: -0.07382028 | BP17: 0.10514705 | BQ17: 0.041747416 | BR17: 0.1604377 | BS17: -0.023733971 | BT17: 0.032657328 | BU17: 0.054206579 | BV17: -0.079065836 | BW17: 0.068269622 | BX17: 0.064696938 | BY17: 0.073249581 | BZ17: 0.0068673055 | CA17: -0.0093570307 | CB17: 0.032233264 | CC17: -0.00068775568 | CD17: -0.041271664 | CE17: 0.04504219 | CF17: -0.067171529 | CG17: -0.027427639 | CH17: -0.080336017 | CI17: 0.19284501 | CJ17: -0.0079055462 | CK17: 0.089784596 | CL17: -0.16580277 | CM17: -0.055442971 | CN17: 0.10225893 | CO17: 0.031612142 | CP17: 0.038180732 | CQ17: -0.0026617495 | CR17: -0.066644806 | CS17: 0.050923182 | CT17: 0.020256879 | CU17: 0.081219749 | CV17: 0.085248868 | CW17: -0.03572489 | CX17: -0.047706025 | CY17: -0.011989745 | CZ17: 0.11056068 | DA17: 0.049430427 | DB17: -0.070449386 | DC17: -0.0091739531 | DD17: -0.028451422 | DE17: 0.078905619 | DF17: -0.0632664 | DG17: -0.073699837 | DH17: -0.079285533 | DI17: -0.081947619 | DJ17: 0.13617866 | DK17: -0.1203309 | DL17: -0.050233041 | DM17: -0.029395195 | DN17: 0.053013488 | DO17: -0.12972371 | DP17: -0.0098689454 | DQ17: 0.047617062 | DR17: 0.024212093 | DS17: 0.0082711256 | DT17: -0.02484681 | DU17: -0.0008397302 | DV17: 0.12796254 | DW17: -0.015405392 | DX17: -0.041381168 | DY17: 0.0314516 | DZ17: -0.078069211 | EA17: -0.06603903 | EB17: -0.029080517 | EC17: -0.026393045 | ED17: -0.044477235 | EE17: 0.017437442 | EF17: 0.053625958
A18: 107 | B18: 9 | C18: 0.012727346 | D18: -0.081178361 | E18: 0.023442656 | F18: 0.031865826 | G18: 0.13694829 | H18: -0.0054385144 | I18: 0.07789373 | J18: 0.025943398 | K18: 0.05962968 | L18: -0.01482675 | M18: -0.13201409 | N18: -0.14366253 | O18: 0.042807527 | P18: 0.0024603784 | Q18: 0.037730238 | R18: 0.083950398 | S18: 0.031243215 | T18: 0.00013066301 | U18: 0.11889346 | V18: 0.045323599 | W18: 0.076963671 | X18: 0.014484535 | Y18: -0.034463446 | Z18: 0.050091717 | AA18: -0.04306462 | AB18: -0.0049527631 | AC18: 0.080335563 | AD18: 0.049880522 | AE18: -0.074208739 | AF18: 0.12119384 | AG18: 0.0082207018 | AH18: -0.056626905 | AI18: 0.090039638 | AJ18: 0.054373028 | AK18: -0.10006973 | AL18: -0.050455211 | AM18: -0.00048290398 | AN18: 0.092246966 | AO18: -0.077982407 | AP18: -0.034824531 | AQ18: -0.081982254 | AR18: 0.053434668 | AS18: -0.023885241 | AT18: 0.010714472 | AU18: 0.037533086 | AV18: 0.019593645 | AW18: -0.020035219 | AX18: -0.042937574 | AY18: 0.075887327 | AZ18: 0.0041182584 | BA18: 0.021082282 | BB18: -0.052214923 | BC18: -0.0019536551 | BD18: 0.068012372 | BE18: 0.017384475 | BF18: -0.052819587 | BG18: 0.056580512 | BH18: -0.081853736 | BI18: -0.079212078 | BJ18: -0.063145987 | BK18: -0.016675768 | BL18: 0.036493375 | BM18: -0.00047397805 | BN18: -0.10429412 | BO18: -0.069432375 | BP18: 0.11563158 | BQ18: 0.043169933 | BR18: 0.16185376 | BS18: -0.039722352 | BT18: 0.043696697 | BU18: 0.055504623 | BV18: -0.10039697 | BW18: 0.068018452 | BX18: 0.072551485 | BY18: 0.071764632 | BZ18: 0.020985904 | CA18: -0.010393545 | CB18: 0.047089122 | CC18: 0.019810439 | CD18: -0.037983875 | CE18: 0.055828567 | CF18: -0.080704041 | CG18: -0.029303665 | CH18: -0.098431929 | CI18: 0.18956145 | CJ18: -0.022028241 | CK18: 0.13691154 | CL18: -0.1674491 | CM18: -0.045612277 | CN18: 0.093722239 | CO18: 0.037338085 | CP18: 0.0052863946 | CQ18: 0.018454844 | CR18: -0.041941293 | CS18: 0.058571332 | CT18: 0.02474117 | CU18: 0.084904466 | CV18: 0.075509124 | CW18: -0.046448025 | CX18: -0.0447956 | CY18: 0.0076395826 | CZ18: 0.080269509 | DA18: 0.060609863 | DB18: -0.064855599 | DC18: -0.045653849 | DD18: -0.019305859 | DE18: 0.068800741 | DF18: -0.043022386 | DG18: -0.076482322 | DH18: -0.086660966 | DI18: -0.077294867 | DJ18: 0.15583692 | DK18: -0.11555867 | DL18: -0.073965349 | DM18: -0.035445016 | DN18: 0.054443676 | DO18: -0.051423223 | DP18: -0.01082569 | DQ18: 0.047499555 | DR18: 0.03122626 | DS18: 0.011323288 | DT18: -0.02623772 | DU18: 0.011803257 | DV18: 0.14184336 | DW18: -0.058804942 | DX18: -0.043366826 | DY18: 0.065202633 | DZ18: -0.057107413 | EA18: -0.075313262 | EB18: -0.029394572 | EC18: -0.0044447661 | ED18: -0.051872164 | EE18: 0.011620678 | EF18: 0.065544713
A19: 120 | B19: 8 | C19: 0.0034430522 | D19: -0.034114759 | E19: 0.02122993 | F19: 0.080752164 | G19: 0.14170195 | H19: -0.025334487 | I19: 0.13403569 | J19: 0.033237528 | K19: 0.080449042 | L19: 0.001286852 | M19: -0.085573118 | N19: -0.20770834 | O19: 0.060431164 | P19: -0.0039117032 | Q19: 0.03935145 | R19: 0.016659025 | S19: 0.03094762 | T19: 0.017684873 | U19: 0.12956222 | V19: 0.027569841 | W19: 0.10725357 | X19: 0.0026242628 | Y19: -0.0099203729 | Z19: 0.060105554 | AA19: -0.031296669 | AB19: -0.032246493 | AC19: 0.067722256 | AD19: 0.040802297 | AE19: -0.079743368 | AF19: 0.13710219 | AG19: -0.0045273804 | AH19: -0.053106564 | AI19: 0.10936191 | AJ19: 0.067225917 | AK19: -0.1064953 | AL19: -0.027200691 | AM19: 0.00011779734 | AN19: 0.11960126 | AO19: -0.12118239 | AP19: -0.02678496 | AQ19: -0.12413666 | AR19: 0.037953857 | AS19: -0.0076907375 | AT19: 0.021772349 | AU19: 0.041176679 | AV19: 0.01393323 | AW19: -0.045093543 | AX19: -0.027095513 | AY19: 0.0347182 | AZ19: 0.020305984 | BA19: 0.0078602069 | BB19: -0.080636654 | BC19: -0.035577806 | BD19: 0.050031578 | BE19: 0.011238807 | BF19: -0.075746703 | BG19: 0.10277794 | BH19: -0.1060004 | BI19: -0.088462215 | BJ19: -0.074190565 | BK19: -0.0074480785 | BL19: 0.051117339 | BM19: -0.014252083 | BN19: -0.10552436 | BO19: 0.0048926897 | BP19: 0.11081983 | BQ19: 0.054395197 | BR19: 0.18345257 | BS19: -0.03290331 | BT19: 0.045901123 | BU19: 0.050221349 | BV19: -0.096397571 | BW19: 0.063098423 | BX19: 0.078919709 | BY19: 0.087446929 | BZ19: 0.021993623 | CA19: -0.016113078 | CB19: 0.058471606 | CC19: 0.0044744318 | CD19: -0.06137669 | CE19: 0.079841683 | CF19: -0.086335718 | CG19: -0.095754133 | CH19: -0.13870247 | CI19: 0.21388535 | CJ19: -0.003262524 | CK19: 0.14369067 | CL19: -0.24847889 | CM19: -0.043715367 | CN19: 0.13476321 | CO19: 0.021559553 | CP19: -0.0064980884 | CQ19: 0.011135082 | CR19: -0.033683179 | CS19: 0.063773273 | CT19: 0.020322815 | CU19: 0.094327425 | CV19: 0.079651412 | CW19: -0.026165506 | CX19: -0.029866928 | CY19: 0.010867278 | CZ19: 0.090082651 | DA19: 0.067902276 | DB19: -0.0598173 | DC19: -0.044965287 | DD19: -0.017051638 | DE19: 0.0097045238 | DF19: -0.046826105 | DG19: -0.10240228 | DH19: -0.092184712 | DI19: -0.071179831 | DJ19: 0.16726498 | DK19: -0.1015602 | DL19: -0.074861808 | DM19: -0.02483125 | DN19: 0.04360622 | DO19: -0.059281068 | DP19: -0.014179585 | DQ19: 0.035883977 | DR19: 0.036688961 | DS19: 0.019903238 | DT19: -0.0075344898 | DU19: 0.015997556 | DV19: 0.14434055 | DW19: -0.038731474 | DX19: -0.042663211 | DY19: 0.078164815 | DZ19: -0.0018355678 | EA19: -0.056364519 | EB19: -0.032955059 | EC19: 0.0042087431 | ED19: -0.019877495 | EE19: 0.01792451 | EF19: 0.069255381
A20: 137 | B20: 7 | C20: 0.020288327 | D20: -0.013818096 | E20: 0.026501157 | F20: 0.11938296 | G20: 0.15796014 | H20: -0.043135563 | I20: 0.15623012 | J20: 0.05428223 | K20: 0.11505417 | L20: 0.0022842862 | M20: -0.08812279 | N20: -0.29940109 | O20: 0.06938619 | P20: 0.0094140372 | Q20: -0.035206997 | R20: 0.029378335 | S20: 0.034228436 | T20: 0.01561176 | U20: 0.13272605 | V20: 0.024136735 | W20: 0.1011943 | X20: 0.0066850737 | Y20: -0.020388839 | Z20: 0.080471111 | AA20: -0.019210041 | AB20: -0.0332956 | AC20: 0.082927243 | AD20: 0.029847713 | AE20: -0.084368787 | AF20: 0.13145645 | AG20: -0.033355881 | AH20: -0.052692405 | AI20: 0.14920003 | AJ20: 0.066902633 | AK20: -0.075500612 | AL20: -0.023756311 | AM20: -0.083278953 | AN20: 0.10794647 | AO20: -0.11794451 | AP20: -0.03598591 | AQ20: -0.14940017 | AR20: 0.053599691 | AS20: 0.011682128 | AT20: 0.014017357 | AU20: 0.031818795 | AV20: -0.0061904768 | AW20: -0.027428949 | AX20: -0.027068059 | AY20: -0.012442999 | AZ20: 0.023144842 | BA20: 0.011533372 | BB20: -0.094841437 | BC20: -0.044226477 | BD20: 0.064860699 | BE20: 0.010273402 | BF20: -0.10105953 | BG20: 0.13354478 | BH20: -0.084087318 | BI20: -0.11918947 | BJ20: -0.060352261 | BK20: -0.0042345116 | BL20: 0.034624584 | BM20: -0.021863485 | BN20: -0.094393284 | BO20: 0.008269135 | BP20: 0.039488147 | BQ20: 0.037730244 | BR20: 0.16909219 | BS20: -0.019097795 | BT20: 0.035004756 | BU20: 0.053120185 | BV20: -0.10071876 | BW20: 0.032666591 | BX20: 0.093900046 | BY20: 0.095998433 | BZ20: -0.067785243 | CA20: -0.012267473 | CB20: 0.072911257 | CC20: 0.0062139535 | CD20: -0.048949304 | CE20: 0.090608748 | CF20: -0.076914614 | CG20: -0.09826549 | CH20: -0.19591305 | CI20: 0.21915736 | CJ20: -0.0069570763 | CK20: 0.10336266 | CL20: -0.28637745 | CM20: -0.067531469 | CN20: 0.14096813 | CO20: 0.077970069 | CP20: -0.017809151 | CQ20: -0.0019469469 | CR20: -0.056637101 | CS20: 0.093034541 | CT20: 0.0034971913 | CU20: 0.09962308 | CV20: 0.088968179 | CW20: -0.055074298 | CX20: -0.042436429 | CY20: 0.00487224 | CZ20: 0.068762931 | DA20: 0.072417075 | DB20: -0.086460604 | DC20: -0.060083204 | DD20: -0.048806128 | DE20: 0.024628315 | DF20: -0.048374215 | DG20: -0.12557107 | DH20: -0.10243058 | DI20: -0.081066382 | DJ20: 0.18304163 | DK20: -0.099041062 | DL20: -0.04643854 | DM20: -0.052897131 | DN20: 0.0088925924 | DO20: -0.067259395 | DP20: -0.014209129 | DQ20: 0.034218916 | DR20: 0.051452052 | DS20: 0.0139538 | DT20: -0.005211723 | DU20: 0.00056573756 | DV20: 0.059036259 | DW20: -0.053528115 | DX20: -0.053717702 | DY20: 0.053488379 | DZ20: -0.012405472 | EA20: -0.060673147 | EB20: -0.033054231 | EC20: 0.014852473 | ED20: -0.026315806 | EE20: 0.025600683 | EF20: 0.079182484
A21: 160 | B21: 6 | C21: 0.014170614 | D21: 0.0037389426 | E21: 0.029561052 | F21: 0.17768866 | G21: 0.12538656 | H21: 0.0052119611 | I21: 0.18530146 | J21: 0.084289728 | K21: 0.13535886 | L21: 0.016273318 | M21: -0.066788099 | N21: -0.29842616 | O21: 0.082510446 | P21: 0.028471158 | Q21: -0.066220951 | R21: 0.011653818 | S21: 0.039573074 | T21: 0.03249889 | U21: 0.095375372 | V21: -0.0042103526 | W21: 0.09390667 | X21: 0.031896124 | Y21: -0.043088843 | Z21: 0.10499849 | AA21: -0.011972373 | AB21: -0.028261487 | AC21: 0.082957631 | AD21: 0.075010147 | AE21: -0.058804324 | AF21: 0.073773497 | AG21: 0.0045374132 | AH21: -0.064313304 | AI21: 0.17788052 | AJ21: 0.043796788 | AK21: -0.095792501 | AL21: -0.061708846 | AM21: -0.090506591 | AN21: 0.11555954 | AO21: -0.078897677 | AP21: -0.10438705 | AQ21: -0.13674694 | AR21: 0.060928759 | AS21: 0.048554026 | AT21: 0.0064221134 | AU21: 0.045615301 | AV21: -0.017717025 | AW21: -0.028836933 | AX21: -0.0054653746 | AY21: 0.029063425 | AZ21: 0.0058566476 | BA21: 0.01800384 | BB21: -0.11465032 | BC21: -0.065597552 | BD21: 0.083771202 | BE21: -0.0006579429 | BF21: -0.1234698 | BG21: 0.15400693 | BH21: -0.10801032 | BI21: -0.12757213 | BJ21: -0.060711578 | BK21: -0.019327912 | BL21: 0.042692696 | BM21: -0.012294533 | BN21: -0.083750817 | BO21: -0.012680736 | BP21: 0.056761407 | BQ21: 0.030274652 | BR21: 0.10212666 | BS21: 0.0095808992 | BT21: 0.041864957 | BU21: 0.069234332 | BV21: -0.12913698 | BW21: 0.046771461 | BX21: 0.11756963 | BY21: 0.11230636 | BZ21: -0.032374295 | CA21: 0.005817894 | CB21: 0.090264913 | CC21: -0.02471104 | CD21: -0.026261221 | CE21: 0.08885025 | CF21: -0.075521709 | CG21: -0.087640012 | CH21: -0.19610873 | CI21: 0.29376096 | CJ21: -0.0049615594 | CK21: 0.10481518 | CL21: -0.31598367 | CM21: -0.048507977 | CN21: 0.16662779 | CO21: 0.046133096 | CP21: -0.021714649 | CQ21: -0.003561534 | CR21: -0.00081896281 | CS21: 0.13590345 | CT21: 0.0042926339 | CU21: 0.095412972 | CV21: 0.080332617 | CW21: -0.0522044 | CX21: 0.02172448 | CY21: 0.014154188 | CZ21: 0.083234747 | DA21: 0.056810669 | DB21: -0.094786783 | DC21: -0.081591936 | DD21: -0.0015168703 | DE21: 0.060590486 | DF21: -0.05806 | DG21: -0.09792572 | DH21: -0.097100983 | DI21: -0.077990751 | DJ21: 0.17965 | DK21: -0.13347011 | DL21: -0.041539196 | DM21: -0.052482978 | DN21: 0.025084353 | DO21: -0.065203128 | DP21: -0.02579966 | DQ21: 0.0075013928 | DR21: 0.06657291 | DS21: -0.0022891794 | DT21: 0.055367513 | DU21: -0.025836396 | DV21: 0.021412871 | DW21: -0.052603058 | DX21: 0.00033962205 | DY21: 0.0770691 | DZ21: 0.029567305 | EA21: -0.093776578 | EB21: -0.016968324 | EC21: 0.017932049 | ED21: 0.017901103 | EE21: 0.042735043 | EF21: 0.10292891
A22: 192 | B22: 5 | C22: 0.012696408 | D22: 0.0057359618 | E22: 0.045567491 | F22: 0.15058182 | G22: 0.14069841 | H22: 0.025308548 | I22: 0.2404458 | J22: 0.012473748 | K22: 0.13236028 | L22: 0.0066462663 | M22: -0.069602728 | N22: -0.32558226 | O22: 0.10208977 | P22: 0.045990059 | Q22: -0.066329425 | R22: -0.01447158 | S22: 0.10575847 | T22: -0.001213181 | U22: 0.093152444 | V22: -0.022429716 | W22: 0.10823291 | X22: 0.037686844 | Y22: -0.062420342 | Z22: 0.044118993 | AA22: -0.0010042568 | AB22: -0.025291441 | AC22: 0.10044624 | AD22: 0.11238291 | AE22: -0.0099604831 | AF22: 0.12392923 | AG22: -0.0053414693 | AH22: -0.0083068788 | AI22: 0.11069 | AJ22: 0.03057109 | AK22: -0.014601134 | AL22: -0.04132625 | AM22: -0.08673153 | AN22: 0.068920855 | AO22: -0.036974261 | AP22: -0.13315504 | AQ22: -0.18588106 | AR22: 0.050828797 | AS22: -0.0078027456 | AT22: 0.003817659 | AU22: 0.060437711 | AV22: 0.011480871 | AW22: -0.063432406 | AX22: -3.4367649e-05 | AY22: 0.027198162 | AZ22: 0.0028768739 | BA22: 0.016297836 | BB22: -0.1034907 | BC22: -0.13043549 | BD22: 0.1091901 | BE22: 0.0047507091 | BF22: -0.12060345 | BG22: 0.18801366 | BH22: -0.081000614 | BI22: -0.14975677 | BJ22: -0.061310162 | BK22: -0.043094689 | BL22: 0.031001588 | BM22: -0.0073533752 | BN22: -0.16284259 | BO22: 0.008734179 | BP22: 0.038429687 | BQ22: 0.03913173 | BR22: 0.12650302 | BS22: 0.014086394 | BT22: -0.010972234 | BU22: 0.067903221 | BV22: -0.12492476 | BW22: 0.014968495 | BX22: 0.1399272 | BY22: 0.17776288 | BZ22: -0.058495426 | CA22: 0.019973455 | CB22: 0.10582941 | CC22: -0.028887093 | CD22: -0.074761637 | CE22: 0.11312962 | CF22: -0.051603358 | CG22: -0.11287215 | CH22: -0.14207979 | CI22: 0.36047329 | CJ22: 0.0022798547 | CK22: 0.14437849 | CL22: -0.42611894 | CM22: -0.039561565 | CN22: 0.20150551 | CO22: 0.07856594 | CP22: -0.016808346 | CQ22: -0.0262881 | CR22: 0.021865264 | CS22: 0.19521081 | CT22: -0.058479647 | CU22: 0.14876302 | CV22: 0.12410061 | CW22: -0.03725059 | CX22: -0.014766062 | CY22: 0.029813079 | CZ22: 0.05882934 | DA22: 0.05447617 | DB22: -0.069940938 | DC22: -0.075149732 | DD22: -0.067729867 | DE22: 0.053891433 | DF22: -0.07874799 | DG22: -0.16125763 | DH22: -0.10736633 | DI22: -0.10727767 | DJ22: 0.1341292 | DK22: -0.096606814 | DL22: -0.00013837066 | DM22: -0.018109702 | DN22: 0.034113445 | DO22: -0.056789559 | DP22: -0.025117061 | DQ22: -0.013742983 | DR22: 0.054787554 | DS22: -0.00074842879 | DT22: 0.051025246 | DU22: -0.044304975 | DV22: 0.01699776 | DW22: -0.042731049 | DX22: 0.0071212896 | DY22: 0.090467789 | DZ22: 0.033861853 | EA22: -0.094898745 | EB22: 0.055127371 | EC22: -0.017822573 | ED22: -0.010980551 | EE22: 0.041577905 | EF22: 0.080705724
A23: 241 | B23: 4 | C23: 0.017768558 | D23: 0.0036293738 | E23: 0.033365454 | F23: 0.18403858 | G23: 0.13182637 | H23: -0.033901708 | I23: 0.21972382 | J23: 0.023901226 | K23: 0.081136137 | L23: 0.057345987 | M23: -0.017826517 | N23: -0.35858597 | O23: 0.11877782 | P23: 0.051670152 | Q23: -0.054608636 | R23: -0.021618604 | S23: 0.10616276 | T23: 0.015105484 | U23: 0.085449085 | V23: 0.025839713 | W23: 0.044941372 | X23: 0.050875929 | Y23: -0.060508537 | Z23: 0.034319391 | AA23: -0.064744737 | AB23: 0.017717561 | AC23: 0.13907031 | AD23: 0.096590875 | AE23: -0.048736242 | AF23: 0.12865817 | AG23: -0.033132071 | AH23: -0.023778885 | AI23: 0.093260164 | AJ23: 0.016259809 | AK23: -0.050449209 | AL23: -0.029040961 | AM23: -0.10952467 | AN23: 0.1147438 | AO23: 0.031320906 | AP23: -0.18769588 | AQ23: -0.1424325 | AR23: 0.029043929 | AS23: -0.016452133 | AT23: 0.016240972 | AU23: 0.036693167 | AV23: 0.0064710435 | AW23: -0.078632267 | AX23: -0.003620255 | AY23: -0.0066584052 | AZ23: 0.043636806 | BA23: 0.015310521 | BB23: -0.12056482 | BC23: -0.090689496 | BD23: 0.074106514 | BE23: 0.061631803 | BF23: -0.14126018 | BG23: 0.25976446 | BH23: -0.087023735 | BI23: -0.16329975 | BJ23: -0.0046496825 | BK23: -0.032709401 | BL23: 0.021576635 | BM23: -0.056008616 | BN23: -0.047873293 | BO23: -0.019005871 | BP23: 0.06518089 | BQ23: 0.064890394 | BR23: 0.080472381 | BS23: 0.029805534 | BT23: 0.038373337 | BU23: 0.035994218 | BV23: -0.0025965389 | BW23: -0.014293919 | BX23: 0.06602193 | BY23: 0.18970454 | BZ23: -0.10725506 | CA23: 0.057609563 | CB23: 0.12801693 | CC23: -0.024582376 | CD23: -0.10063302 | CE23: 0.11849776 | CF23: -0.068491263 | CG23: -0.080124954 | CH23: -0.14246342 | CI23: 0.42336065 | CJ23: -0.0072806889 | CK23: 0.15986768 | CL23: -0.35889914 | CM23: -0.020742141 | CN23: 0.27224845 | CO23: 0.091276525 | CP23: -0.069024375 | CQ23: -0.021689423 | CR23: 0.033343086 | CS23: 0.19386831 | CT23: -0.034785012 | CU23: 0.10438155 | CV23: 0.10053199 | CW23: -0.028884808 | CX23: -0.088659967 | CY23: 0.079509195 | CZ23: 0.02797658 | DA23: 0.030745403 | DB23: -0.061865798 | DC23: -0.10851453 | DD23: -0.080548522 | DE23: 0.086208574 | DF23: -0.092197034 | DG23: -0.12503268 | DH23: -0.10136651 | DI23: -0.11530334 | DJ23: 0.13260215 | DK23: -0.080880373 | DL23: 0.015517063 | DM23: 0.010108939 | DN23: 0.076587817 | DO23: -0.036377545 | DP23: -0.020275294 | DQ23: -0.0011067564 | DR23: 0.051945146 | DS23: 0.0037581957 | DT23: 0.060108355 | DU23: -0.068452402 | DV23: 0.027650714 | DW23: -0.052355674 | DX23: -0.010180787 | DY23: 0.15835805 | DZ23: 0.051267416 | EA23: -0.075067437 | EB23: 0.049217697 | EC23: -0.023638998 | ED23: 0.0024791378 | EE23: 0.081987457 | EF23: 0.098831202
A24: 321 | B24: 3 | C24: -0.0063062694 | D24: -0.004869163 | E24: -0.019723682 | F24: 0.067831061 | G24: 0.18159615 | H24: 0.040275061 | I24: 0.24653947 | J24: -0.022304675 | K24: 0.17301942 | L24: 0.11131511 | M24: -0.029017011 | N24: -0.22759173 | O24: 0.12528368 | P24: 0.020624945 | Q24: 0.035129306 | R24: -0.043626576 | S24: 0.1002771 | T24: 0.038207711 | U24: 0.10881975 | V24: 0.039304239 | W24: 0.075881254 | X24: -0.0047154922 | Y24: -0.066619025 | Z24: 0.029560575 | AA24: -0.019168415 | AB24: 0.020918383 | AC24: 0.021426172 | AD24: 0.10524304 | AE24: -0.010814056 | AF24: 0.085420812 | AG24: -0.096262504 | AH24: -0.029239322 | AI24: 0.096775907 | AJ24: 0.019238961 | AK24: -0.072907422 | AL24: -0.00041616186 | AM24: -0.09648146 | AN24: 0.10876785 | AO24: 0.020795468 | AP24: -0.23470322 | AQ24: -0.18056535 | AR24: 0.009320952 | AS24: -0.056958809 | AT24: 0.020018044 | AU24: 0.099998295 | AV24: 0.061910958 | AW24: -0.069264748 | AX24: -0.0069511224 | AY24: 0.01163289 | AZ24: 0.10846798 | BA24: -0.0090978695 | BB24: -0.2322564 | BC24: -0.086937838 | BD24: 0.083377875 | BE24: 0.039816066 | BF24: -0.19663622 | BG24: 0.29932013 | BH24: 0.019983486 | BI24: -0.19862429 | BJ24: 0.11125405 | BK24: -0.051393366 | BL24: 0.049826377 | BM24: -0.10431373 | BN24: -0.061547943 | BO24: -0.0083627883 | BP24: 0.062981806 | BQ24: 0.074121564 | BR24: 0.097648744 | BS24: -0.026147767 | BT24: 0.046516775 | BU24: 0.053464221 | BV24: 0.10912356 | BW24: -0.041536124 | BX24: 0.10968823 | BY24: 0.25496003 | BZ24: -0.14784459 | CA24: 0.061790226 | CB24: 0.08668285 | CC24: -0.0032948818 | CD24: -0.069298645 | CE24: 0.14968584 | CF24: -0.17263227 | CG24: -0.027718504 | CH24: -0.13880496 | CI24: 0.4988715 | CJ24: -0.038237947 | CK24: 0.19282319 | CL24: -0.23559133 | CM24: 0.0029003906 | CN24: 0.35538733 | CO24: 0.10580519 | CP24: -0.067433001 | CQ24: -0.022709821 | CR24: 0.0085028481 | CS24: 0.27548718 | CT24: -0.047539112 | CU24: 0.11288422 | CV24: 0.078399902 | CW24: -0.024774013 | CX24: -0.18173616 | CY24: 0.11810958 | CZ24: 0.089602014 | DA24: 0.13290261 | DB24: -0.14650552 | DC24: -0.16784517 | DD24: -0.067394627 | DE24: 0.086433858 | DF24: -0.12235118 | DG24: -0.082917717 | DH24: -0.0063375236 | DI24: -0.15864167 | DJ24: 0.19682175 | DK24: -0.13509892 | DL24: 0.005673634 | DM24: 0.0080068754 | DN24: 0.058503042 | DO24: -0.029333554 | DP24: -0.034563659 | DQ24: 0.0050752037 | DR24: -0.028489142 | DS24: 0.027487496 | DT24: 0.059239907 | DU24: -0.059237545 | DV24: 0.047527442 | DW24: -0.10587876 | DX24: 0.039786367 | DY24: 0.29163649 | DZ24: 0.069418288 | EA24: -0.040301101 | EB24: 0.076117642 | EC24: -0.08670786 | ED24: 0.019995782 | EE24: 0.061664883 | EF24: 0.10834501
A25: 482 | B25: 2 | C25: -0.011176635 | D25: 0.10170585 | E25: 0.0017298065 | F25: 0.18239608 | G25: 0.13597331 | H25: 0.1174826 | I25: 0.27196118 | J25: 0.038118738 | K25: 0.20235701 | L25: 0.20599386 | M25: -0.056184856 | N25: -0.10897849 | O25: 0.10707325 | P25: 0.02440991 | Q25: 0.13040003 | R25: -0.11145569 | S25: 0.1587588 | T25: -0.15453823 | U25: 0.060416741 | V25: 0.012586624 | W25: 0.082796037 | X25: 0.025317077 | Y25: -0.081813474 | Z25: 0.1385019 | AA25: -0.074478126 | AB25: 0.067539196 | AC25: -0.039342473 | AD25: 0.14000637 | AE25: -0.016441839 | AF25: -0.046565531 | AG25: -0.090288917 | AH25: -0.014882818 | AI25: 0.05450632 | AJ25: -0.067327504 | AK25: -0.053778447 | AL25: 0.03535979 | AM25: -0.13989796 | AN25: 0.018071933 | AO25: 0.01728582 | AP25: -0.26878315 | AQ25: -0.17786576 | AR25: -0.0060289305 | AS25: -0.0017369853 | AT25: -0.021738457 | AU25: 0.089617389 | AV25: 0.066312772 | AW25: -0.1463286 | AX25: -0.03661045 | AY25: 0.039620455 | AZ25: 0.21271992 | BA25: 0.010230411 | BB25: -0.40590382 | BC25: -0.25872778 | BD25: 0.068750755 | BE25: 0.0048838024 | BF25: -0.078079993 | BG25: 0.28204447 | BH25: 0.078692413 | BI25: -0.20510939 | BJ25: 0.1208634 | BK25: 0.065382535 | BL25: -0.026370013 | BM25: -0.085424442 | BN25: -0.28180432 | BO25: 0.010006677 | BP25: 0.074523472 | BQ25: 0.028943449 | BR25: 0.10373006 | BS25: -0.017801572 | BT25: 0.0029470257 | BU25: 0.05351514 | BV25: 0.061355668 | BW25: 0.076821222 | BX25: 0.11648559 | BY25: 0.25922077 | BZ25: -0.054013621 | CA25: -0.063292142 | CB25: 0.050376511 | CC25: -0.054953002 | CD25: -0.04740112 | CE25: -0.026251391 | CF25: -0.097597849 | CG25: -0.12614548 | CH25: -0.19654867 | CI25: 0.24210089 | CJ25: -0.030218477 | CK25: 0.19491862 | CL25: -0.26704515 | CM25: 0.070337668 | CN25: 0.38307225 | CO25: 0.24323253 | CP25: -0.084267173 | CQ25: -0.011965492 | CR25: 0.062754605 | CS25: 0.30874974 | CT25: -0.062386893 | CU25: -0.063346804 | CV25: 0.081010744 | CW25: -0.050220956 | CX25: -0.0963714 | CY25: 0.17675246 | CZ25: 0.069488823 | DA25: 0.25064705 | DB25: -0.21468139 | DC25: -0.20796471 | DD25: -0.12145728 | DE25: 0.17933135 | DF25: -0.14752329 | DG25: -0.083393467 | DH25: 0.078069362 | DI25: -0.12881936 | DJ25: 0.12231863 | DK25: -0.021390825 | DL25: -0.002915211 | DM25: 0.054019009 | DN25: 0.010762117 | DO25: -0.036036683 | DP25: -0.022379992 | DQ25: -0.02487699 | DR25: 0.0024518062 | DS25: 0.057046335 | DT25: 0.054242171 | DU25: 0.040785589 | DV25: 0.007510108 | DW25: -0.11684588 | DX25: 0.040656365 | DY25: 0.30069223 | DZ25: 0.058520648 | EA25: -0.042626528 | EB25: 0.098940549 | EC25: 0.05681408 | ED25: -0.022318442 | EE25: 0.10807169 | EF25: 0.15302671
A26: 964 | B26: 1 | C26: -0.023978273 | D26: 0.10746684 | E26: 0.081880335 | F26: 0.20154572 | G26: -0.030122759 | H26: 0.4601534 | I26: 0.13279746 | J26: -0.13980471 | K26: 0.066573718 | L26: 0.07822828 | M26: -0.10199866 | N26: -0.045513037 | O26: 0.059180834 | P26: -0.0097279322 | Q26: -0.021923763 | R26: -0.17737141 | S26: 0.35409217 | T26: -0.32186608 | U26: 0.12158004 | V26: 0.018085838 | W26: -0.083245267 | X26: -0.011084832 | Y26: -0.1343496 | Z26: 0.30298222 | AA26: -0.064650776 | AB26: 0.29886183 | AC26: -0.11998972 | AD26: 0.0026312997 | AE26: 0.27206647 | AF26: 0.056712085 | AG26: -0.16788087 | AH26: 0.0011082145 | AI26: 0.093749654 | AJ26: 0.0099353041 | AK26: -0.20923945 | AL26: 0.051245019 | AM26: 0.041787712 | AN26: 0.022585701 | AO26: 0.25746018 | AP26: -0.12520374 | AQ26: -0.064725673 | AR26: 0.017315274 | AS26: 0.1536609 | AT26: -0.073778944 | AU26: 0.078874832 | AV26: 0.07612155 | AW26: -0.22850363 | AX26: -0.054109392 | AY26: -0.33258448 | AZ26: 0.44422924 | BA26: -0.081321871 | BB26: -0.57777575 | BC26: -0.36462735 | BD26: -0.029082265 | BE26: -0.15545516 | BF26: 0.22423064 | BG26: 0.072909504 | BH26: -0.12727242 | BI26: -0.088317144 | BJ26: -0.058521572 | BK26: -0.0010005003 | BL26: -0.0091837889 | BM26: -0.18523762 | BN26: -0.23863078 | BO26: -0.044829258 | BP26: 0.069861208 | BQ26: 0.11785998 | BR26: 0.25295734 | BS26: 0.075707377 | BT26: 0.0081280216 | BU26: 0.10139314 | BV26: 0.15057537 | BW26: 0.013813921 | BX26: 0.44324424 | BY26: 0.20360345 | BZ26: -0.10483761 | CA26: -0.025118082 | CB26: 0.010315553 | CC26: 0.12736008 | CD26: -0.16539219 | CE26: -0.027341346 | CF26: -0.20924058 | CG26: 2.2968881e-05 | CH26: -0.0542757 | CI26: -0.035124205 | CJ26: -0.02949215 | CK26: -0.024112796 | CL26: -0.31770506 | CM26: 0.15087951 | CN26: 0.61572721 | CO26: 0.33089493 | CP26: -0.13311928 | CQ26: -0.043926428 | CR26: -0.018817213 | CS26: 0.11603612 | CT26: 0.10590234 | CU26: -0.049885679 | CV26: 0.18097124 | CW26: -0.055481234 | CX26: 0.00028276545 | CY26: 0.40222269 | CZ26: 0.14897143 | DA26: 0.046293284 | DB26: -0.29234257 | DC26: -0.34795665 | DD26: 0.21542713 | DE26: 0.19912843 | DF26: -0.090697091 | DG26: -0.13032743 | DH26: 0.10631883 | DI26: 0.092112155 | DJ26: 0.28429457 | DK26: 0.18393473 | DL26: 0.090323206 | DM26: 0.45836075 | DN26: 0.13803355 | DO26: -0.058539411 | DP26: 0.066723921 | DQ26: -0.099914946 | DR26: -0.025269917 | DS26: 0.12412695 | DT26: 0.062242989 | DU26: -0.052845281 | DV26: -0.01850118 | DW26: 0.030684046 | DX26: 0.0063391654 | DY26: 0.14062865 | DZ26: 0.054973545 | EA26: -0.073102723 | EB26: 0.040453049 | EC26: 0.12090273 | ED26: 0.0036871482 | EE26: 0.041388278 | EF26: 0.088642827
A27: 大盤 | B27: TWⅡ | C27: -0.017446771 | D27: 0.020701061 | E27: 0.023982129 | F27: -0.006557579 | G27: 0.03184513 | H27: 0.034348533 | I27: -0.0082549328 | J27: 0.012843524 | K27: -0.051018525 | L27: 0.00087394274 | M27: 0.023389576 | N27: 0.012988972 | O27: 0.0058545887 | P27: 0.027413207 | Q27: -0.0037129361 | R27: 0.024076614 | S27: -0.012190025 | T27: -0.039749578 | U27: -0.07315545 | V27: -0.05826023 | W27: 0.00077279757 | X27: 0.044591521 | Y27: -0.02769968 | Z27: 0.0020950059 | AA27: -0.023400551 | AB27: 0.032129371 | AC27: 0.038903273 | AD27: -0.042865382 | AE27: 0.018647195 | AF27: 0.015229768 | AG27: 0.036016604 | AH27: 0.0093546114 | AI27: 0.010748251 | AJ27: 0.013357754 | AK27: -0.0053327473 | AL27: 0.0013831358 | AM27: 0.020795928 | AN27: 0.031517702 | AO27: 0.0062417165 | AP27: 0.0061452617 | AQ27: 0.016946358 | AR27: 0.03468283 | AS27: 0.0030985886 | AT27: 0.015081347 | AU27: -0.019251209 | AV27: 0.038711513 | AW27: -0.021856951 | AX27: 0.0077743007 | AY27: 0.042397247 | AZ27: -0.026308975 | BA27: 0.0095717493 | BB27: -0.024249741 | BC27: 0.020163374 | BD27: -0.0035049988 | BE27: 0.020151935 | BF27: 0.00058133623 | BG27: -0.005219701 | BH27: -0.11587176 | BI27: 0.0087252257 | BJ27: -0.016377261 | BK27: 0.020840372 | BL27: 0.044975872 | BM27: 0.023954306 | BN27: 0.030239101 | BO27: -0.043725888 | BP27: 0.02188947 | BQ27: 0.0086274303 | BR27: -0.019192954 | BS27: 0.01973513 | BT27: 0.047694337 | BU27: 0.011454817 | BV27: 0.043228621 | BW27: -0.04274743 | BX27: -0.017811292 | BY27: -0.1511531 | BZ27: 0.124224 | CA27: -0.0045572538 | CB27: 0.06021124 | CC27: 0.085992033 | CD27: -0.0058084796 | CE27: -0.006041347 | CF27: 0.0024523244 | CG27: 0.089636252 | CH27: 0.070992733 | CI27: 0.027170643 | CJ27: 0.052468428 | CK27: 0.029480661 | CL27: 0.066825081 | CM27: -0.028772229 | CN27: 0.039462516 | CO27: -0.029031087 | CP27: 0.013983883 | CQ27: -0.032276965 | CR27: 0.0031035766 | CS27: 0.025591856 | CT27: 0.044391886 | CU27: -0.030338959 | CV27: -0.0012579765 | CW27: 0.0023363565 | CX27: -0.064264145 | CY27: 0.012909779 | CZ27: -0.12547709 | DA27: 0.011690683 | DB27: 0.0063378437 | DC27: -0.11730536 | DD27: -0.036010872 | DE27: 0.1389113 | DF27: -0.051143506 | DG27: 0.076731447 | DH27: 0.015508782 | DI27: 0.023223774 | DJ27: -0.018372876 | DK27: 0.062199014 | DL27: 0.020098304 | DM27: 0.01349894 | DN27: -0.030252213 | DO27: -0.017022836 | DP27: -0.021788523 | DQ27: 0.085745625 | DR27: 0.028106744 | DS27: -0.0023031598 | DT27: 0.058471198 | DU27: 0.067658949 | DV27: 0.0050207706 | DW27: 0.037416184 | DX27: 0.084111004 | DY27: -0.036832399 | DZ27: 0.0030917028 | EA27: -0.0019576282 | EB27: 0.026459104 | EC27: -0.024752539 | ED27: 0.034115491 | EE27: 0.021061974 | EF27: -0.020277393
C29: 1101 | D29: 2484 | E29: 1233 | F29: 2524 | G29: 2611 | H29: 1233 | I29: 2379 | J29: 2379 | K29: 2524 | L29: 1233 | M29: 2524 | N29: 1805 | O29: 2538 | P29: 3033 | Q29: 2385 | R29: 3024 | S29: 3024 | T29: 1314 | U29: 3024 | V29: 3024 | W29: 5521 | X29: 2535 | Y29: 3033 | Z29: 5201 | AA29: 2535 | AB29: 5201 | AC29: 5471 | AD29: 5521 | AE29: 2023 | AF29: 2023 | AG29: 3017 | AH29: 3033 | AI29: 1464 | AJ29: 2451 | AK29: 2451 | AL29: 4413 | AM29: 2451 | AN29: 2451 | AO29: 6121 | AP29: 2451 | AQ29: 1805 | AR29: 4416 | AS29: 5523 | AT29: 2524 | AU29: 1436 | AV29: 2338 | AW29: 5212 | AX29: 2338 | AY29: 6186 | AZ29: 5523 | BA29: 5523 | BB29: 5443 | BC29: 3051 | BD29: 5523 | BE29: 3051 | BF29: 3051 | BG29: 3051 | BH29: 6186 | BI29: 6186 | BJ29: 2537 | BK29: 2537 | BL29: 2488 | BM29: 6192 | BN29: 8927 | BO29: 2537 | BP29: 4416 | BQ29: 2537 | BR29: 6128 | BS29: 3002 | BT29: 5007 | BU29: 4109 | BV29: 6128 | BW29: 8085 | BX29: 8927 | BY29: 1737 | BZ29: 6242 | CA29: 6242 | CB29: 8927 | CC29: 8927 | CD29: 6242 | CE29: 8927 | CF29: 6242 | CG29: 8050 | CH29: 6242 | CI29: 6242 | CJ29: 8050 | CK29: 8050 | CL29: 6242 | CM29: 4402 | CN29: 3016 | CO29: 1436 | CP29: 6242 | CQ29: 3016 | CR29: 6242 | CS29: 3005 | CT29: 2493 | CU29: 2423 | CV29: 1734 | CW29: 5306 | CX29: 4402 | CY29: 9904 | CZ29: 8072 | DA29: 5007 | DB29: 9904 | DC29: 8072 | DD29: 6021 | DE29: 3232 | DF29: 2538 | DG29: 2538 | DH29: 5306 | DI29: 2538 | DJ29: 2434 | DK29: 2538 | DL29: 6020 | DM29: 2538 | DN29: 4402 | DO29: 2538 | DP29: 5425 | DQ29: 5425 | DR29: 4402 | DS29: 6291 | DT29: 2031 | DU29: 6291 | DV29: 3232 | DW29: 2538 | DX29: 6291 | DY29: 2538 | DZ29: 2538 | EA29: 8074 | EB29: 8074 | EC29: 3232 | ED29: 4402 | EE29: 2538 | EF29: 2538
