Workbook

Sheet 預測IC
A1: Predict
B2: Time | C2: 2013/12 | D2: 2014/01 | E2: 2014/02 | F2: 2014/03 | G2: 2014/04 | H2: 2014/05 | I2: 2014/06 | J2: 2014/07 | K2: 2014/08 | L2: 2014/09 | M2: 2014/10 | N2: 2014/11 | O2: 2014/12 | P2: 2015/01 | Q2: 2015/02 | R2: 2015/03 | S2: 2015/04 | T2: 2015/05 | U2: 2015/06 | V2: 2015/07 | W2: 2015/08 | X2: 2015/09 | Y2: 2015/10 | Z2: 2015/11 | AA2: 2015/12 | AB2: 2016/01 | AC2: 2016/02 | AD2: 2016/03 | AE2: 2016/04 | AF2: 2016/05 | AG2: 2016/06 | AH2: 2016/07 | AI2: 2016/08 | AJ2: 2016/09 | AK2: 2016/10 | AL2: 2016/11 | AM2: 2016/12 | AN2: 2017/01 | AO2: 2017/02 | AP2: 2017/03 | AQ2: 2017/04 | AR2: 2017/05 | AS2: 2017/06 | AT2: 2017/07 | AU2: 2017/08 | AV2: 2017/09 | AW2: 2017/10 | AX2: 2017/11 | AY2: 2017/12 | AZ2: 2018/01 | BA2: 2018/02 | BB2: 2018/03 | BC2: 2018/04 | BD2: 2018/05 | BE2: 2018/06 | BF2: 2018/07 | BG2: 2018/08 | BH2: 2018/09 | BI2: 2018/10 | BJ2: 2018/11 | BK2: 2018/12 | BL2: 2019/01 | BM2: 2019/02 | BN2: 2019/03 | BO2: 2019/04 | BP2: 2019/05 | BQ2: 2019/06 | BR2: 2019/07 | BS2: 2019/08 | BT2: 2019/09 | BU2: 2019/10 | BV2: 2019/11 | BW2: 2019/12 | BX2: 2020/01 | BY2: 2020/02 | BZ2: 2020/03 | CA2: 2020/04 | CB2: 2020/05 | CC2: 2020/06 | CD2: 2020/07 | CE2: 2020/08 | CF2: 2020/09 | CG2: 2020/10 | CH2: 2020/11 | CI2: 2020/12 | CJ2: 2021/01 | CK2: 2021/02 | CL2: 2021/03 | CM2: 2021/04 | CN2: 2021/05 | CO2: 2021/06 | CP2: 2021/07 | CQ2: 2021/08 | CR2: 2021/09 | CS2: 2021/10 | CT2: 2021/11 | CU2: 2021/12 | CV2: 2022/01 | CW2: 2022/02 | CX2: 2022/03 | CY2: 2022/04 | CZ2: 2022/05 | DA2: 2022/06 | DB2: 2022/07 | DC2: 2022/08 | DD2: 2022/09 | DE2: 2022/10 | DF2: 2022/11 | DG2: 2022/12 | DH2: 2023/01 | DI2: 2023/02 | DJ2: 2023/03 | DK2: 2023/04 | DL2: 2023/05 | DM2: 2023/06 | DN2: 2023/07 | DO2: 2023/08 | DP2: 2023/09 | DQ2: 2023/10 | DR2: 2023/11 | DS2: 2023/12 | DT2: 2024/01 | DU2: 2024/02 | DV2: 2024/03 | DW2: 2024/04 | DX2: 2024/05 | DY2: 2024/06 | DZ2: 2024/07 | EA2: 2024/08 | EB2: 2024/09 | EC2: 2024/10 | ED2: 2024/11 | EE2: 2024/12 | EF2: 2025/01
B3: mom1 | C3: -0.028421105 | D3: -0.0032086853 | E3: -0.045759689 | F3: -0.062181713 | G3: -0.059567678 | H3: -0.010649055 | I3: -0.01276009 | J3: -0.047600297 | K3: -0.031071015 | L3: -0.028040119 | M3: -0.0090825358 | N3: -0.045141758 | O3: -0.044270346 | P3: -0.031684381 | Q3: -0.055433013 | R3: -0.02710995 | S3: -0.016227496 | T3: -0.0027466888 | U3: -0.020370614 | V3: 0.0037661807 | W3: -0.014262473 | X3: -0.0917358 | Y3: -0.031277665 | Z3: 0.013116938 | AA3: -0.0095636868 | AB3: -0.0063454766 | AC3: 0.00090571962 | AD3: -0.025965432 | AE3: -0.0096560945 | AF3: 0.0030675596 | AG3: -0.032383394 | AH3: -0.0074773786 | AI3: -0.0019157841 | AJ3: -0.009586853 | AK3: -0.012509584 | AL3: -0.032067835 | AM3: -0.023857075 | AN3: -0.055529021 | AO3: -0.054187593 | AP3: -0.020805826 | AQ3: -0.054464581 | AR3: -0.0079251422 | AS3: -0.080704946 | AT3: -0.0033286588 | AU3: -0.016730373 | AV3: -0.040662307 | AW3: -0.01334959 | AX3: 0.00041132675 | AY3: -0.015450973 | AZ3: -0.03434674 | BA3: -0.011721947 | BB3: -0.008645138 | BC3: 0.093133169 | BD3: 0.021270749 | BE3: 0.0041896161 | BF3: 0.087493563 | BG3: -0.008610178 | BH3: -0.021536217 | BI3: 0.076523317 | BJ3: 0.11053144 | BK3: 0.043903812 | BL3: -0.0057341144 | BM3: 0.085239266 | BN3: -0.027413591 | BO3: -0.026194249 | BP3: -0.0050536532 | BQ3: -0.015635984 | BR3: -0.0028605951 | BS3: -0.022503841 | BT3: -0.028888226 | BU3: 0.00046852267 | BV3: -0.014343012 | BW3: -0.0024765406 | BX3: -0.0033669345 | BY3: 0.0098781533 | BZ3: 0.059334883 | CA3: -0.016962409 | CB3: 0.015768733 | CC3: -0.04579691 | CD3: -0.016834237 | CE3: -0.028685122 | CF3: -0.061571375 | CG3: -0.0093795888 | CH3: -0.027363971 | CI3: -0.0056179209 | CJ3: -0.01841073 | CK3: -0.060048442 | CL3: 0.051031674 | CM3: -0.031853467 | CN3: -0.0034014778 | CO3: -0.0059588483 | CP3: -0.052511428 | CQ3: -0.018192283 | CR3: -0.013835788 | CS3: 0.066811104 | CT3: -0.043738323 | CU3: -0.027281598 | CV3: -0.014720715 | CW3: -0.0096698957 | CX3: -0.056823076 | CY3: -0.0077143265 | CZ3: -0.013600859 | DA3: -0.019832006 | DB3: -0.028697643 | DC3: -0.042602949 | DD3: -0.037717335 | DE3: -0.018655423 | DF3: 0.04404442 | DG3: 0.024808364 | DH3: -0.0090166159 | DI3: 0.0041737322 | DJ3: -0.021302417 | DK3: -0.035212078 | DL3: -0.025285552 | DM3: -0.018070447 | DN3: -0.024459591 | DO3: -0.022975006 | DP3: -0.022725345 | DQ3: -0.034792528 | DR3: -0.014517743 | DS3: 0.039697577 | DT3: -0.025528605 | DU3: -0.013965522 | DV3: -0.011635769 | DW3: -0.019578167 | DX3: -0.016729233 | DY3: -0.013926629 | DZ3: -0.064078277 | EA3: -0.011174082 | EB3: -0.032139421 | EC3: -0.0065260959 | ED3: -0.033025345 | EE3: -0.042642098 | EF3: 0.046335984
B4: mom12 | C4: 0.032149527 | D4: 0.031058233 | E4: 0.021920012 | F4: 0.026919816 | G4: 0.035273392 | H4: 0.072960053 | I4: 0.083700431 | J4: 0.054952607 | K4: 0.06581917 | L4: 0.04129115 | M4: 0.031112425 | N4: 0.015944504 | O4: 0.0028902999 | P4: -0.020143455 | Q4: 0.0044313998 | R4: -0.032241819 | S4: -0.014602157 | T4: 0.004411944 | U4: -0.012920894 | V4: -0.0058865342 | W4: 0.025473671 | X4: -0.0052639646 | Y4: -0.016245667 | Z4: -0.00391226 | AA4: 0.010350439 | AB4: 0.04327586 | AC4: 0.028867701 | AD4: 0.041043585 | AE4: 0.023302439 | AF4: 0.029358021 | AG4: 0.016663025 | AH4: 0.015268574 | AI4: 0.014681378 | AJ4: 0.0033443266 | AK4: 0.018997018 | AL4: 0.024881633 | AM4: 0.013787652 | AN4: 0.004016441 | AO4: 0.011853012 | AP4: -0.024002529 | AQ4: -0.0086616032 | AR4: -0.049291308 | AS4: -0.046612021 | AT4: -0.013669303 | AU4: -0.0071382332 | AV4: -0.012807856 | AW4: 0.010745089 | AX4: -0.0011321089 | AY4: 0.016647319 | AZ4: 0.018617873 | BA4: 0.023323985 | BB4: 0.0082449342 | BC4: 0.0088282726 | BD4: 0.018147156 | BE4: 0.0061555981 | BF4: -0.012290645 | BG4: -0.0059310581 | BH4: -0.004272728 | BI4: 0.014160548 | BJ4: 0.0083678246 | BK4: -0.018798857 | BL4: -0.0058491424 | BM4: -0.013166786 | BN4: 0.013885551 | BO4: 0.016162147 | BP4: 0.039650518 | BQ4: 0.031389726 | BR4: 0.040897547 | BS4: 0.013676354 | BT4: 0.016915817 | BU4: 0.017996776 | BV4: 0.016913625 | BW4: 0.0054921253 | BX4: 0.011708781 | BY4: 0.012493509 | BZ4: 0.017018809 | CA4: 0.014260342 | CB4: 0.0050213231 | CC4: -0.0018682696 | CD4: 0.020458412 | CE4: 0.020683321 | CF4: -0.0095815189 | CG4: -0.028466593 | CH4: -0.0032564911 | CI4: 0.0019169051 | CJ4: 0.011528987 | CK4: 0.010068286 | CL4: 0.012952232 | CM4: 0.0043310724 | CN4: -0.0029342907 | CO4: -0.0074118526 | CP4: -0.0084165338 | CQ4: 0.00026063257 | CR4: -0.0045614668 | CS4: -0.015033045 | CT4: -0.0064041876 | CU4: -0.0052180228 | CV4: 0.014766811 | CW4: 0.0079096072 | CX4: 0.0091865945 | CY4: 0.0079215283 | CZ4: 0.025911448 | DA4: -0.033181029 | DB4: 0.010437976 | DC4: 0.036289702 | DD4: -0.027333662 | DE4: 5.3204379e-05 | DF4: 0.011934289 | DG4: -0.0068727258 | DH4: 0.0038813537 | DI4: 0.0089454078 | DJ4: 0.014739476 | DK4: -0.0095534373 | DL4: 0.045369163 | DM4: 0.052420328 | DN4: 0.046322268 | DO4: 0.03879346 | DP4: 0.031593984 | DQ4: 0.02797446 | DR4: 0.041670046 | DS4: 0.039311671 | DT4: 0.04175682 | DU4: 0.040857076 | DV4: 0.029541589 | DW4: 0.048580647 | DX4: 0.021294874 | DY4: 0.022110302 | DZ4: 0.018187961 | EA4: 0.018972922 | EB4: 0.012440642 | EC4: 0.019440548 | ED4: 0.017895222 | EE4: 0.019741135 | EF4: 0.016674022
B5: chmom | C5: 0.032149527 | D5: 0.031058233 | E5: 0.021920012 | F5: 0.026919816 | G5: 0.035273392 | H5: 0.072960053 | I5: 0.083700431 | J5: 0.054952607 | K5: 0.06581917 | L5: 0.04129115 | M5: 0.031112425 | N5: 0.015944504 | O5: 0.0028902999 | P5: -0.020143455 | Q5: 0.0044313998 | R5: -0.032241819 | S5: -0.014602157 | T5: 0.004411944 | U5: -0.012920894 | V5: -0.0058865342 | W5: 0.025473671 | X5: -0.0052639646 | Y5: -0.016245667 | Z5: -0.00391226 | AA5: 0.010350439 | AB5: 0.04327586 | AC5: 0.028867701 | AD5: 0.041043585 | AE5: 0.023302439 | AF5: 0.029358021 | AG5: 0.016663025 | AH5: 0.015268574 | AI5: 0.014681378 | AJ5: 0.0033443266 | AK5: 0.018997018 | AL5: 0.024881633 | AM5: 0.013787652 | AN5: 0.004016441 | AO5: 0.011853012 | AP5: -0.024002529 | AQ5: -0.0086616032 | AR5: -0.049291308 | AS5: -0.046612021 | AT5: -0.013669303 | AU5: -0.0071382332 | AV5: -0.012807856 | AW5: 0.010745089 | AX5: -0.0011321089 | AY5: 0.016647319 | AZ5: 0.018617873 | BA5: 0.023323985 | BB5: 0.0082449342 | BC5: 0.0088282726 | BD5: 0.018147156 | BE5: 0.0061555981 | BF5: -0.012290645 | BG5: -0.0059310581 | BH5: -0.004272728 | BI5: 0.014160548 | BJ5: 0.0083678246 | BK5: -0.018798857 | BL5: -0.0058491424 | BM5: -0.013166786 | BN5: 0.013885551 | BO5: 0.016162147 | BP5: 0.039650518 | BQ5: 0.031389726 | BR5: 0.040897547 | BS5: 0.013676354 | BT5: 0.016915817 | BU5: 0.017996776 | BV5: 0.016913625 | BW5: 0.0054921253 | BX5: 0.011708781 | BY5: 0.012493509 | BZ5: 0.017018809 | CA5: 0.014260342 | CB5: 0.0050213231 | CC5: -0.0018682696 | CD5: 0.020458412 | CE5: 0.020683321 | CF5: -0.0095815189 | CG5: -0.028466593 | CH5: -0.0032564911 | CI5: 0.0019169051 | CJ5: 0.011528987 | CK5: 0.010068286 | CL5: 0.012952232 | CM5: 0.0043310724 | CN5: -0.0029342907 | CO5: -0.0074118526 | CP5: -0.0084165338 | CQ5: 0.00026063257 | CR5: -0.0045614668 | CS5: -0.015033045 | CT5: -0.0064041876 | CU5: -0.0052180228 | CV5: 0.014766811 | CW5: 0.0079096072 | CX5: 0.0091865945 | CY5: 0.0079215283 | CZ5: 0.025911448 | DA5: -0.033181029 | DB5: 0.010437976 | DC5: 0.036289702 | DD5: -0.027333662 | DE5: 5.3204379e-05 | DF5: 0.011934289 | DG5: -0.0068727258 | DH5: 0.0038813537 | DI5: 0.0089454078 | DJ5: 0.014739476 | DK5: -0.0095534373 | DL5: 0.045369163 | DM5: 0.052420328 | DN5: 0.046322268 | DO5: 0.03879346 | DP5: 0.031593984 | DQ5: 0.02797446 | DR5: 0.041670046 | DS5: 0.039311671 | DT5: 0.04175682 | DU5: 0.040857076 | DV5: 0.029541589 | DW5: 0.048580647 | DX5: 0.021294874 | DY5: 0.022110302 | DZ5: 0.018187961 | EA5: 0.018972922 | EB5: 0.012440642 | EC5: 0.019440548 | ED5: 0.017895222 | EE5: 0.019741135 | EF5: 0.016674022
B6: retvol | C6: 0.028280704 | D6: 0.045024379 | E6: 0.022805462 | F6: 0.030473305 | G6: 0.025801966 | H6: 0.026407937 | I6: 0.038669716 | J6: 0.036013741 | K6: 0.039669624 | L6: 0.023215574 | M6: 0.014439881 | N6: 0.020245466 | O6: 0.016677705 | P6: 0.015979594 | Q6: 0.017689819 | R6: 0.0089443822 | S6: 0.027929232 | T6: 0.012097868 | U6: 0.016471196 | V6: 0.014996151 | W6: 0.013040458 | X6: 0.018810074 | Y6: 0.0011582881 | Z6: 0.0080285515 | AA6: 0.005533116 | AB6: 0.00557342 | AC6: 0.015292133 | AD6: 0.013483451 | AE6: 0.01510215 | AF6: 0.0083251924 | AG6: 0.020406205 | AH6: 0.042947613 | AI6: 0.013234101 | AJ6: 0.010758771 | AK6: 0.0071831979 | AL6: 0.014507613 | AM6: 0.017219896 | AN6: 0.016130185 | AO6: 0.0027328542 | AP6: 0.010811339 | AQ6: 0.014269002 | AR6: 0.016671974 | AS6: 0.010903894 | AT6: 0.019352604 | AU6: 0.03336906 | AV6: 0.033609502 | AW6: 0.036213352 | AX6: 0.010755409 | AY6: 0.022281626 | AZ6: 0.029838241 | BA6: 0.0092262385 | BB6: 0.020435759 | BC6: 0.020621794 | BD6: 0.024205264 | BE6: 0.015778299 | BF6: 0.014587344 | BG6: 0.0205234 | BH6: 0.022897761 | BI6: 0.024587363 | BJ6: 0.018443815 | BK6: 0.019702031 | BL6: 0.0045770526 | BM6: 0.00072036967 | BN6: 0.0068383366 | BO6: 0.008495603 | BP6: 0.0068676055 | BQ6: 0.01214829 | BR6: 0.012729966 | BS6: 0.015897604 | BT6: 0.015357171 | BU6: 0.016534797 | BV6: 0.017159038 | BW6: 0.013147733 | BX6: 0.029391096 | BY6: 0.029697604 | BZ6: 0.023169419 | CA6: 0.021585326 | CB6: 0.036279979 | CC6: 0.0022471414 | CD6: 0.011431405 | CE6: 0.0097325278 | CF6: 0.012918743 | CG6: 0.016791522 | CH6: 0.026978402 | CI6: 0.01974305 | CJ6: 0.036282559 | CK6: 0.037565589 | CL6: 0.02740698 | CM6: 0.023252333 | CN6: 0.0072236255 | CO6: 0.0086283922 | CP6: 0.0082387791 | CQ6: 0.0090960544 | CR6: -0.019608093 | CS6: 0.0080383364 | CT6: 0.0031404346 | CU6: -0.0073210796 | CV6: -0.0023633033 | CW6: 0.0102343 | CX6: 0.028585785 | CY6: 0.031094172 | CZ6: 0.031553415 | DA6: 0.042270887 | DB6: 0.039805308 | DC6: 0.015575602 | DD6: 0.034946221 | DE6: 0.083616853 | DF6: 0.072050126 | DG6: 0.040272677 | DH6: 0.020352821 | DI6: 0.012289753 | DJ6: 0.033017884 | DK6: 0.0041169359 | DL6: 0.0032895249 | DM6: 0.016270141 | DN6: 0.019067257 | DO6: 0.043813888 | DP6: 0.042895957 | DQ6: 0.039102398 | DR6: 0.035268577 | DS6: 0.041220381 | DT6: 0.044856575 | DU6: 0.038425398 | DV6: 0.042252549 | DW6: 0.043956925 | DX6: 0.051589606 | DY6: 0.052634911 | DZ6: 0.052838321 | EA6: 0.046836473 | EB6: 0.046645625 | EC6: 0.053388727 | ED6: 0.015378748 | EE6: 0.020959301 | EF6: 0.023158289
B7: maxret | C7: 0.0074353345 | D7: -0.028755301 | E7: 2.6254979e-05 | F7: 0.0081230333 | G7: 0.001921454 | H7: 0.016301272 | I7: -0.014801552 | J7: 0.0050232193 | K7: -0.020936215 | L7: 0.012283281 | M7: -0.042762316 | N7: -0.025475367 | O7: -0.025329166 | P7: -0.0092756308 | Q7: 0.029479018 | R7: -0.012899916 | S7: 0.005530283 | T7: -0.049720071 | U7: 0.041650928 | V7: -0.024060895 | W7: -0.019445981 | X7: 0.0041013327 | Y7: 0.031114671 | Z7: -0.041235056 | AA7: 0.027015096 | AB7: 0.0052994812 | AC7: 0.030553441 | AD7: -0.0086666011 | AE7: 0.0049092226 | AF7: -0.017946305 | AG7: 0.033899838 | AH7: -0.0061240908 | AI7: 0.018774453 | AJ7: 0.029382758 | AK7: -0.033686569 | AL7: -0.032280317 | AM7: 0.0032138735 | AN7: 0.11408471 | AO7: 0.02799418 | AP7: 0.029917062 | AQ7: -0.041139472 | AR7: -0.00087443992 | AS7: 0.015026083 | AT7: -0.015190475 | AU7: -0.038575341 | AV7: 0.015312413 | AW7: 0.035025744 | AX7: 0.0035901734 | AY7: -0.030656313 | AZ7: -0.0029025725 | BA7: 0.0056352578 | BB7: -0.03405329 | BC7: -0.013759948 | BD7: -0.02257377 | BE7: 0.0055568103 | BF7: 0.0093798251 | BG7: -0.016046693 | BH7: 0.058929576 | BI7: -0.028235978 | BJ7: -0.0037545426 | BK7: 0.011294718 | BL7: -0.046188342 | BM7: -0.020443148 | BN7: -0.017926467 | BO7: 0.011582539 | BP7: -0.0028645742 | BQ7: -0.092485502 | BR7: -0.0080970018 | BS7: -0.01130158 | BT7: 0.014912762 | BU7: 0.016618493 | BV7: 0.016276276 | BW7: -0.044854207 | BX7: 0.01913616 | BY7: -0.021076646 | BZ7: -0.023497155 | CA7: -0.041401721 | CB7: -0.0042780939 | CC7: 0.022498146 | CD7: -0.011710733 | CE7: 0.058979173 | CF7: -0.019429797 | CG7: 0.018692101 | CH7: -0.0058114523 | CI7: -0.041834284 | CJ7: -0.012841469 | CK7: 0.013618815 | CL7: -0.0035360869 | CM7: -0.042807172 | CN7: 0.02064293 | CO7: -0.041396506 | CP7: 0.043251404 | CQ7: -0.025468576 | CR7: -0.0097805463 | CS7: -0.036398625 | CT7: -0.047913537 | CU7: -0.018724998 | CV7: 0.013671881 | CW7: -0.058236049 | CX7: 0.059009893 | CY7: 0.031124682 | CZ7: -0.036962005 | DA7: 0.026875191 | DB7: 0.0049460523 | DC7: 0.013273219 | DD7: 0.018110792 | DE7: -0.0050468456 | DF7: 0.0051712812 | DG7: -0.0085517408 | DH7: -0.0039740829 | DI7: 0.035094374 | DJ7: 0.042093321 | DK7: 0.041605226 | DL7: 0.03742447 | DM7: 0.0064227276 | DN7: 0.050342979 | DO7: 0.034076577 | DP7: -0.018457857 | DQ7: -0.0320199 | DR7: -0.014214254 | DS7: -0.018841137 | DT7: 0.052764154 | DU7: 0.037587698 | DV7: 0.055246083 | DW7: 0.010541023 | DX7: -0.021472144 | DY7: -0.02340917 | DZ7: -0.037468141 | EA7: 0.015257175 | EB7: 0.0017324241 | EC7: 0.0018771108 | ED7: -0.010360487 | EE7: -0.0020699837 | EF7: -0.0010624359
A8: 選絕對值最大 | C8: {=MATCH(MAX(ABS(C3:C7)), ABS(C3:C7), 0)} -> 2 | D8: {=MATCH(MAX(ABS(D3:D7)), ABS(D3:D7), 0)} -> 4 | E8: {=MATCH(MAX(ABS(E3:E7)), ABS(E3:E7), 0)} -> 1 | F8: {=MATCH(MAX(ABS(F3:F7)), ABS(F3:F7), 0)} -> 1 | G8: {=MATCH(MAX(ABS(G3:G7)), ABS(G3:G7), 0)} -> 1 | H8: {=MATCH(MAX(ABS(H3:H7)), ABS(H3:H7), 0)} -> 2 | I8: {=MATCH(MAX(ABS(I3:I7)), ABS(I3:I7), 0)} -> 2 | J8: {=MATCH(MAX(ABS(J3:J7)), ABS(J3:J7), 0)} -> 2 | ... EF8: {=MATCH(MAX(ABS(EF3:EF7)), ABS(EF3:EF7), 0)} -> 1
C9: =IF(C8=1,"mom1", IF(C8=2,"mom12", IF(C8=3,"chmom", IF(C8=4,"retvol", IF(C8=5,"maxret",""))))) -> mom12 | D9: =IF(D8=1,"mom1", IF(D8=2,"mom12", IF(D8=3,"chmom", IF(D8=4,"retvol", IF(D8=5,"maxret",""))))) -> retvol | E9: =IF(E8=1,"mom1", IF(E8=2,"mom12", IF(E8=3,"chmom", IF(E8=4,"retvol", IF(E8=5,"maxret",""))))) -> mom1 | F9: =IF(F8=1,"mom1", IF(F8=2,"mom12", IF(F8=3,"chmom", IF(F8=4,"retvol", IF(F8=5,"maxret",""))))) -> mom1 | G9: =IF(G8=1,"mom1", IF(G8=2,"mom12", IF(G8=3,"chmom", IF(G8=4,"retvol", IF(G8=5,"maxret",""))))) -> mom1 | H9: =IF(H8=1,"mom1", IF(H8=2,"mom12", IF(H8=3,"chmom", IF(H8=4,"retvol", IF(H8=5,"maxret",""))))) -> mom12 | I9: =IF(I8=1,"mom1", IF(I8=2,"mom12", IF(I8=3,"chmom", IF(I8=4,"retvol", IF(I8=5,"maxret",""))))) -> mom12 | J9: =IF(J8=1,"mom1", IF(J8=2,"mom12", IF(J8=3,"chmom", IF(J8=4,"retvol", IF(J8=5,"maxret",""))))) -> mom12 | ... EF9: =IF(EF8=1,"mom1", IF(EF8=2,"mom12", IF(EF8=3,"chmom", IF(EF8=4,"retvol", IF(EF8=5,"maxret",""))))) -> mom1
C10: =IF(C8=1,C3,IF(C8=2,C4,IF(C8=3,C5,IF(C8=4,C6,IF(C8=5,C7))))) -> 0.032149527 | D10: =IF(D8=1,D3,IF(D8=2,D4,IF(D8=3,D5,IF(D8=4,D6,IF(D8=5,D7))))) -> 0.045024379 | E10: =IF(E8=1,E3,IF(E8=2,E4,IF(E8=3,E5,IF(E8=4,E6,IF(E8=5,E7))))) -> -0.045759689 | F10: =IF(F8=1,F3,IF(F8=2,F4,IF(F8=3,F5,IF(F8=4,F6,IF(F8=5,F7))))) -> -0.062181713 | G10: =IF(G8=1,G3,IF(G8=2,G4,IF(G8=3,G5,IF(G8=4,G6,IF(G8=5,G7))))) -> -0.059567678 | H10: =IF(H8=1,H3,IF(H8=2,H4,IF(H8=3,H5,IF(H8=4,H6,IF(H8=5,H7))))) -> 0.072960053 | I10: =IF(I8=1,I3,IF(I8=2,I4,IF(I8=3,I5,IF(I8=4,I6,IF(I8=5,I7))))) -> 0.083700431 | J10: =IF(J8=1,J3,IF(J8=2,J4,IF(J8=3,J5,IF(J8=4,J6,IF(J8=5,J7))))) -> 0.054952607 | ... EF10: =IF(EF8=1,EF3,IF(EF8=2,EF4,IF(EF8=3,EF5,IF(EF8=4,EF6,IF(EF8=5,EF7))))) -> 0.046335984
A12: 投資組合 | C12: 公司數 | D12: 964
A13: 等分 | B13: 家數 | C13: 2014/01 | D13: 2014/02 | E13: 2014/03 | F13: 2014/04 | G13: 2014/05 | H13: 2014/06 | I13: 2014/07 | J13: 2014/08 | K13: 2014/09 | L13: 2014/10 | M13: 2014/11 | N13: 2014/12 | O13: 2015/01 | P13: 2015/02 | Q13: 2015/03 | R13: 2015/04 | S13: 2015/05 | T13: 2015/06 | U13: 2015/07 | V13: 2015/08 | W13: 2015/09 | X13: 2015/10 | Y13: 2015/11 | Z13: 2015/12 | AA13: 2016/01 | AB13: 2016/02 | AC13: 2016/03 | AD13: 2016/04 | AE13: 2016/05 | AF13: 2016/06 | AG13: 2016/07 | AH13: 2016/08 | AI13: 2016/09 | AJ13: 2016/10 | AK13: 2016/11 | AL13: 2016/12 | AM13: 2017/01 | AN13: 2017/02 | AO13: 2017/03 | AP13: 2017/04 | AQ13: 2017/05 | AR13: 2017/06 | AS13: 2017/07 | AT13: 2017/08 | AU13: 2017/09 | AV13: 2017/10 | AW13: 2017/11 | AX13: 2017/12 | AY13: 2018/01 | AZ13: 2018/02 | BA13: 2018/03 | BB13: 2018/04 | BC13: 2018/05 | BD13: 2018/06 | BE13: 2018/07 | BF13: 2018/08 | BG13: 2018/09 | BH13: 2018/10 | BI13: 2018/11 | BJ13: 2018/12 | BK13: 2019/01 | BL13: 2019/02 | BM13: 2019/03 | BN13: 2019/04 | BO13: 2019/05 | BP13: 2019/06 | BQ13: 2019/07 | BR13: 2019/08 | BS13: 2019/09 | BT13: 2019/10 | BU13: 2019/11 | BV13: 2019/12 | BW13: 2020/01 | BX13: 2020/02 | BY13: 2020/03 | BZ13: 2020/04 | CA13: 2020/05 | CB13: 2020/06 | CC13: 2020/07 | CD13: 2020/08 | CE13: 2020/09 | CF13: 2020/10 | CG13: 2020/11 | CH13: 2020/12 | CI13: 2021/01 | CJ13: 2021/02 | CK13: 2021/03 | CL13: 2021/04 | CM13: 2021/05 | CN13: 2021/06 | CO13: 2021/07 | CP13: 2021/08 | CQ13: 2021/09 | CR13: 2021/10 | CS13: 2021/11 | CT13: 2021/12 | CU13: 2022/01 | CV13: 2022/02 | CW13: 2022/03 | CX13: 2022/04 | CY13: 2022/05 | CZ13: 2022/06 | DA13: 2022/07 | DB13: 2022/08 | DC13: 2022/09 | DD13: 2022/10 | DE13: 2022/11 | DF13: 2022/12 | DG13: 2023/01 | DH13: 2023/02 | DI13: 2023/03 | DJ13: 2023/04 | DK13: 2023/05 | DL13: 2023/06 | DM13: 2023/07 | DN13: 2023/08 | DO13: 2023/09 | DP13: 2023/10 | DQ13: 2023/11 | DR13: 2023/12 | DS13: 2024/01 | DT13: 2024/02 | DU13: 2024/03 | DV13: 2024/04 | DW13: 2024/05 | DX13: 2024/06 | DY13: 2024/07 | DZ13: 2024/08 | EA13: 2024/09 | EB13: 2024/10 | EC13: 2024/11 | ED13: 2024/12 | EE13: 2025/01 | EF13: 2025/02
A14: 10 | B14: 96 | C14: 0.019976135 | D14: -0.012414446 | E14: -0.012674425 | F14: 0.0086411838 | G14: -0.0087066431 | H14: 0.011594983 | I14: -0.006940679 | J14: 0.0083166755 | K14: 0.0020137515 | L14: -0.025370282 | M14: -0.0062014112 | N14: 0.019976135 | O14: 0.020145241 | P14: 0.0008253807 | Q14: -0.016241729 | R14: 0.020017741 | S14: 0.034852657 | T14: -0.0025118914 | U14: -0.0056784412 | V14: 0.013373919 | W14: -0.00062233287 | X14: 0.073985909 | Y14: -0.021808715 | Z14: 0.016694136 | AA14: -0.015145026 | AB14: 0.018947661 | AC14: 0.003448596 | AD14: -0.0058971959 | AE14: 0.011278102 | AF14: -0.0068373085 | AG14: -0.012697441 | AH14: 0.01415244 | AI14: 0.0012445161 | AJ14: -0.0079266116 | AK14: -0.022365576 | AL14: -0.0053951526 | AM14: 0.026090654 | AN14: -0.022197838 | AO14: 0.011649826 | AP14: -0.015149931 | AQ14: 0.00038138395 | AR14: 0.0054141448 | AS14: 0.0056424991 | AT14: -0.0057230721 | AU14: 0.0029950721 | AV14: -0.0061160462 | AW14: -0.01035348 | AX14: -0.031641595 | AY14: 0.016739359 | AZ14: -0.00075502252 | BA14: -0.02252858 | BB14: -0.007333608 | BC14: 0.0055205804 | BD14: -0.014892474 | BE14: -0.007223487 | BF14: 0.020331569 | BG14: 0.024860565 | BH14: 0.043570809 | BI14: -0.035486503 | BJ14: -0.03396913 | BK14: 0.0098762365 | BL14: -0.016159935 | BM14: 0.0021054352 | BN14: -0.0019381649 | BO14: -0.027521252 | BP14: 0.011052976 | BQ14: -0.0087344207 | BR14: -0.019992442 | BS14: -0.016744171 | BT14: -0.036242421 | BU14: -0.012762166 | BV14: 0.033798594 | BW14: 0.01434725 | BX14: 0.0012412669 | BY14: -0.020681525 | BZ14: -0.034702631 | CA14: -0.0014042361 | CB14: 0.00037098284 | CC14: 0.017407472 | CD14: -0.023644332 | CE14: 0.033476752 | CF14: -0.013255991 | CG14: -0.005323621 | CH14: 0.018739664 | CI14: -0.0054205337 | CJ14: 0.004388599 | CK14: 0.01134328 | CL14: -0.044513226 | CM14: -0.026454786 | CN14: -0.021863562 | CO14: 0.037082214 | CP14: -0.022373345 | CQ14: 0.013297365 | CR14: -0.028294594 | CS14: -0.021508495 | CT14: -0.007671344 | CU14: 0.017738503 | CV14: -0.027089773 | CW14: -0.0069554993 | CX14: -0.0033101942 | CY14: 0.0032902421 | CZ14: -0.0011148339 | DA14: -0.0029357749 | DB14: -0.006037428 | DC14: 0.057180441 | DD14: -0.028979196 | DE14: -0.016218256 | DF14: 0.0052564625 | DG14: -0.0072644719 | DH14: -0.0054769258 | DI14: -0.017446498 | DJ14: 0.024417494 | DK14: -0.0040675028 | DL14: -0.0058466782 | DM14: -0.038207555 | DN14: 0.01006813 | DO14: -0.013548571 | DP14: 0.023899224 | DQ14: 0.011965151 | DR14: -0.0062789819 | DS14: -0.0011785772 | DT14: 0.050030753 | DU14: 0.031813717 | DV14: -0.0067854009 | DW14: 0.014411829 | DX14: -0.021905944 | DY14: -0.011608185 | DZ14: 0.0094590731 | EA14: -0.010758255 | EB14: 0.00059846779 | EC14: -0.010619071 | ED14: -0.014134192 | EE14: 0.010210984 | EF14: 0.01886514
A15: 20 | B15: 48 | C15: 0.05909992 | D15: 0.013382864 | E15: 1.9241929e-05 | F15: -0.035371097 | G15: -0.025850467 | H15: 0.0061024546 | I15: -0.0030503553 | J15: 0.030716548 | K15: -0.0094412648 | L15: -0.074417784 | M15: 0.0092012443 | N15: 0.05909992 | O15: 0.037450114 | P15: 0.0054349389 | Q15: -0.0031962278 | R15: 0.057206098 | S15: 0.062122405 | T15: 0.0035007098 | U15: -0.029784483 | V15: 0.029643698 | W15: -0.0015053504 | X15: 0.078153378 | Y15: -0.010273485 | Z15: 0.030009435 | AA15: -0.020587033 | AB15: 0.0044869316 | AC15: 0.013546781 | AD15: -0.034034187 | AE15: 0.035860456 | AF15: 0.0014442323 | AG15: -0.012320864 | AH15: 0.014015337 | AI15: 0.015905682 | AJ15: -0.0023751696 | AK15: -0.0043414316 | AL15: 0.011535027 | AM15: 0.041727786 | AN15: -0.018263735 | AO15: 0.0011763199 | AP15: -0.014526287 | AQ15: 0.029084725 | AR15: -0.0012303733 | AS15: 0.018946462 | AT15: -0.022160497 | AU15: 0.029290779 | AV15: -0.0040858745 | AW15: -0.00090899555 | AX15: -0.0029924602 | AY15: 0.061848849 | AZ15: -0.012258941 | BA15: -0.017775796 | BB15: 0.0036342754 | BC15: 0.025761857 | BD15: 0.0025204041 | BE15: 0.0115803 | BF15: 0.031248585 | BG15: 0.035089478 | BH15: 0.045523208 | BI15: -0.043094963 | BJ15: -0.022608189 | BK15: 0.019800309 | BL15: -0.012587413 | BM15: 0.012032652 | BN15: -0.032217818 | BO15: -0.029407477 | BP15: 0.027534416 | BQ15: -0.004144349 | BR15: -0.03200872 | BS15: -0.025021968 | BT15: -0.034204445 | BU15: -0.012443845 | BV15: 0.022255293 | BW15: 0.0062024165 | BX15: -0.001705413 | BY15: -0.038582502 | BZ15: -0.040214336 | CA15: -0.0092842783 | CB15: 0.039132963 | CC15: 0.020017074 | CD15: -0.054657886 | CE15: 0.0026895403 | CF15: -0.015474613 | CG15: 0.026553408 | CH15: 0.0076331163 | CI15: 0.019169952 | CJ15: 0.013611853 | CK15: 0.025877926 | CL15: -0.057172133 | CM15: -0.027221631 | CN15: -0.056515944 | CO15: 0.054212245 | CP15: -0.04179699 | CQ15: -0.005217263 | CR15: -0.059162746 | CS15: -0.031928399 | CT15: -0.029459592 | CU15: 0.02354378 | CV15: -0.04769635 | CW15: -0.025787078 | CX15: -0.0161814 | CY15: 0.010233521 | CZ15: -0.0015581484 | DA15: 0.0098965641 | DB15: -0.023807415 | DC15: 0.050592104 | DD15: -0.036860636 | DE15: -0.029290652 | DF15: -0.015226212 | DG15: -0.0088978791 | DH15: 0.016895502 | DI15: -0.015345157 | DJ15: 0.034852366 | DK15: 0.014280954 | DL15: -0.012833224 | DM15: -0.043761134 | DN15: -0.0038099185 | DO15: -0.022166032 | DP15: 0.049344205 | DQ15: 0.031418495 | DR15: -0.0023856081 | DS15: -0.0038315992 | DT15: 0.048540378 | DU15: 0.036060525 | DV15: 0.014395607 | DW15: 0.045440648 | DX15: -0.032841231 | DY15: -0.011752931 | DZ15: -0.0062856382 | EA15: -0.011225192 | EB15: -0.01597343 | EC15: -0.012826698 | ED15: 0.0030781052 | EE15: 0.010495033 | EF15: 0.0018546647
A16: 50 | B16: 19 | C16: 0.055126982 | D16: 0.018633367 | E16: 0.031515381 | F16: 0.0030562856 | G16: 0.028210865 | H16: -0.019804589 | I16: 0.0027593339 | J16: 0.034453585 | K16: 0.013668987 | L16: 0.020853654 | M16: 0.028127919 | N16: 0.055126982 | O16: 0.0031101542 | P16: -0.011155391 | Q16: -0.0083134465 | R16: 0.060946751 | S16: 0.084489708 | T16: -0.0061800602 | U16: -0.048001156 | V16: 0.032938039 | W16: -0.031415243 | X16: 0.10778384 | Y16: -0.012503897 | Z16: 0.046802633 | AA16: -0.039087384 | AB16: -0.014336959 | AC16: 0.040075665 | AD16: -0.028684992 | AE16: 0.087693914 | AF16: 0.022645649 | AG16: 0.012120892 | AH16: 0.028183451 | AI16: -0.031885714 | AJ16: 0.026796729 | AK16: 0.0047311984 | AL16: -0.01506734 | AM16: 0.078117848 | AN16: 0.0061724334 | AO16: 0.043394984 | AP16: -0.095609378 | AQ16: 0.042696521 | AR16: -0.010677678 | AS16: 0.039654554 | AT16: -0.092711585 | AU16: 0.017838715 | AV16: -0.033013089 | AW16: 0.0239841 | AX16: -0.021447353 | AY16: 0.063084296 | AZ16: -0.039911234 | BA16: 0.026862057 | BB16: -0.031399149 | BC16: -0.034242093 | BD16: 0.024820635 | BE16: 0.060726054 | BF16: 0.058640357 | BG16: -0.0015799091 | BH16: 0.058518418 | BI16: -0.056034073 | BJ16: 0.019262796 | BK16: 0.035954231 | BL16: -0.0051124163 | BM16: 0.036885081 | BN16: -0.052546239 | BO16: -0.090554105 | BP16: 0.032633648 | BQ16: -0.016095778 | BR16: -0.073605548 | BS16: -0.03836872 | BT16: -0.082648065 | BU16: -0.00031727549 | BV16: 0.0051160489 | BW16: 0.0010354539 | BX16: -0.010339986 | BY16: -0.091942672 | BZ16: 0.0075039343 | CA16: -0.10454809 | CB16: 0.02297154 | CC16: 0.019230831 | CD16: -0.1216439 | CE16: -0.058177267 | CF16: 0.0089580281 | CG16: 0.048274847 | CH16: 0.022033273 | CI16: 0.033501405 | CJ16: 0.035407106 | CK16: -0.049619091 | CL16: -0.0072691469 | CM16: -0.04446227 | CN16: -0.054047079 | CO16: 0.069704537 | CP16: -0.036459946 | CQ16: 0.017178218 | CR16: -0.11224089 | CS16: -0.023562643 | CT16: -0.037454059 | CU16: -0.0035416582 | CV16: -0.029183436 | CW16: -0.019703641 | CX16: -0.047814047 | CY16: 0.015913387 | CZ16: -0.021553043 | DA16: 0.075425594 | DB16: -0.025242264 | DC16: 0.049060793 | DD16: -0.089405338 | DE16: -0.00053224526 | DF16: -0.034649649 | DG16: -0.026511745 | DH16: 0.012049786 | DI16: 0.10558764 | DJ16: 0.097112789 | DK16: -0.0030025696 | DL16: -0.052897355 | DM16: -0.074777101 | DN16: 0.027163573 | DO16: -0.0036295418 | DP16: 0.11040694 | DQ16: 0.033367172 | DR16: -0.0087058901 | DS16: 0.0077876307 | DT16: 0.034060791 | DU16: 0.025961831 | DV16: 0.038295453 | DW16: 0.051946894 | DX16: -0.061365474 | DY16: -0.00064227789 | DZ16: 0.025457325 | EA16: -0.0064767383 | EB16: -0.013896027 | EC16: 0.010738644 | ED16: 0.037032878 | EE16: 0.024106957 | EF16: 0.0091367922
A17: 100 | B17: 10 | C17: 0.06684249 | D17: 0.069547578 | E17: 0.012203547 | F17: 0.039505104 | G17: 0.078202469 | H17: -0.064958271 | I17: -0.0055750922 | J17: -0.0025583949 | K17: -0.026456607 | L17: -0.0010510142 | M17: 0.042331428 | N17: 0.06684249 | O17: 0.041113025 | P17: 0.032730816 | Q17: 0.015563333 | R17: 0.085990084 | S17: -0.056554642 | T17: 0.025660546 | U17: -0.070512934 | V17: 0.029430752 | W17: -0.0069780295 | X17: 0.13590122 | Y17: -0.022364678 | Z17: 0.066866903 | AA17: -0.025641305 | AB17: 0.026738191 | AC17: 0.015392014 | AD17: -0.056060882 | AE17: 0.15141304 | AF17: 0.01739984 | AG17: -0.014332576 | AH17: 0.032545119 | AI17: -0.065679508 | AJ17: 0.028758521 | AK17: 0.042620203 | AL17: -0.082518198 | AM17: 0.086567395 | AN17: 0.060271273 | AO17: -0.012736346 | AP17: -0.1427344 | AQ17: 0.086789024 | AR17: -0.073032357 | AS17: 0.0067011854 | AT17: -0.066712979 | AU17: -0.05134464 | AV17: -0.052635579 | AW17: -0.06279317 | AX17: 0.071322612 | AY17: 0.13554522 | AZ17: -0.12565918 | BA17: 0.071559952 | BB17: -0.13479138 | BC17: -0.066583748 | BD17: -0.012824438 | BE17: 0.038163321 | BF17: 0.064107022 | BG17: 0.071449291 | BH17: 0.088398365 | BI17: -0.068619857 | BJ17: 0.017250548 | BK17: 0.033721258 | BL17: -0.0018105182 | BM17: 0.050925053 | BN17: -0.013595794 | BO17: -0.094559363 | BP17: 0.047356248 | BQ17: -0.0091085952 | BR17: -0.084588948 | BS17: -0.060303925 | BT17: -0.027611526 | BU17: -0.036377632 | BV17: -0.062665208 | BW17: 0.084065423 | BX17: 0.0097156208 | BY17: -0.099304509 | BZ17: 0.034028495 | CA17: -0.1445902 | CB17: 0.002536807 | CC17: -0.023553183 | CD17: -0.018719999 | CE17: -0.11919023 | CF17: -0.012060318 | CG17: 0.096763269 | CH17: -0.041751715 | CI17: -0.068627972 | CJ17: 0.019852062 | CK17: -0.056000634 | CL17: 0.11843769 | CM17: -0.050400545 | CN17: -0.17797861 | CO17: 0.081898037 | CP17: -0.068234295 | CQ17: -0.0087039362 | CR17: -0.079315609 | CS17: -0.011856101 | CT17: -0.027883119 | CU17: 0.062625404 | CV17: -0.04161766 | CW17: -0.010470073 | CX17: -0.019386726 | CY17: 0.021525587 | CZ17: 0.0023293605 | DA17: 0.14027939 | DB17: -0.055916148 | DC17: 0.064413551 | DD17: -0.099453967 | DE17: -0.023729078 | DF17: -0.03765835 | DG17: -0.05686148 | DH17: 0.045429358 | DI17: 0.033526802 | DJ17: 0.045698605 | DK17: -0.037465732 | DL17: -0.018809239 | DM17: -0.099177262 | DN17: 0.034656477 | DO17: -0.0377924 | DP17: 0.081642421 | DQ17: 0.0033337523 | DR17: 0.0066105753 | DS17: 0.017544096 | DT17: -0.0039950927 | DU17: 0.045069118 | DV17: 0.0262167 | DW17: 0.058936557 | DX17: -0.088730683 | DY17: 0.054215834 | DZ17: 0.060895872 | EA17: -0.0034276198 | EB17: 0.046209002 | EC17: 0.017104141 | ED17: 0.083327649 | EE17: 0.033415699 | EF17: 0.0073892059
A18: 107 | B18: 9 | C18: 0.044674633 | D18: 0.073315453 | E18: 0.0043253309 | F18: -0.022317515 | G18: 0.081990194 | H18: -0.054254626 | I18: -0.026819032 | J18: 0.0050890819 | K18: -0.062993878 | L18: 0.019907212 | M18: 0.063290495 | N18: 0.044674633 | O18: 0.026084284 | P18: 0.024365435 | Q18: 0.0062416258 | R18: 0.095767071 | S18: -0.051186661 | T18: 0.010747846 | U18: -0.09026661 | V18: 0.038201393 | W18: -0.002977584 | X18: 0.11953448 | Y18: -0.032688242 | Z18: 0.079580175 | AA18: 0.020507786 | AB18: 0.026207737 | AC18: 0.036258624 | AD18: -0.052483987 | AE18: 0.16628724 | AF18: 0.0076785158 | AG18: -0.0015639465 | AH18: 0.031473363 | AI18: -0.068286729 | AJ18: 0.021788025 | AK18: 0.042068969 | AL18: -0.08718798 | AM18: 0.054769116 | AN18: 0.068247365 | AO18: 0.0028057557 | AP18: -0.15621968 | AQ18: 0.075475062 | AR18: -0.073247653 | AS18: 0.010790861 | AT18: -0.082690447 | AU18: -0.052132891 | AV18: -0.04573225 | AW18: -0.043690574 | AX18: 0.098853618 | AY18: 0.13491975 | AZ18: -0.13135691 | BA18: 0.069193825 | BB18: -0.12841718 | BC18: -0.076482773 | BD18: 0.011984162 | BE18: 0.03448301 | BF18: 0.075691455 | BG18: 0.10802797 | BH18: 0.07440365 | BI18: -0.04987681 | BJ18: 0.01877953 | BK18: 0.042252615 | BL18: 0.0051769012 | BM18: 0.04769434 | BN18: -0.012196303 | BO18: -0.082426801 | BP18: 0.059012504 | BQ18: -0.0019630753 | BR18: -0.10058815 | BS18: -0.048679246 | BT18: -0.033970012 | BU18: -0.038645433 | BV18: -0.079965905 | BW18: 0.095122554 | BX18: 0.018802412 | BY18: -0.10267561 | BZ18: -0.0059631271 | CA18: -0.16649651 | CB18: 0.014547687 | CC18: -0.029211584 | CD18: -0.022761201 | CE18: -0.094507522 | CF18: -0.018594557 | CG18: 0.10647802 | CH18: -0.076175821 | CI18: -0.060170161 | CJ18: 0.054434 | CK18: -0.07173798 | CL18: 0.066336934 | CM18: -0.072844734 | CN18: -0.19363648 | CO18: 0.075142553 | CP18: -0.039243235 | CQ18: -0.021604837 | CR18: -0.07591677 | CS18: -0.0021640924 | CT18: -0.054524351 | CU18: 0.081316229 | CV18: -0.051712325 | CW18: -0.0078340178 | CX18: -0.017781465 | CY18: 0.023312294 | CZ18: 0.0027316242 | DA18: 0.16577661 | DB18: -0.055565329 | DC18: 0.03937568 | DD18: -0.084115771 | DE18: -0.020444984 | DF18: -0.038097392 | DG18: -0.021342234 | DH18: 0.041916553 | DI18: 0.055323005 | DJ18: 0.043364011 | DK18: -0.031680503 | DL18: -0.026834821 | DM18: -0.11345087 | DN18: 0.050072672 | DO18: -0.045762874 | DP18: 0.080502539 | DQ18: 0.011793937 | DR18: 0.0060234646 | DS18: 0.027002609 | DT18: -0.018188698 | DU18: 0.095864937 | DV18: 0.015717757 | DW18: 0.071406329 | DX18: -0.09676242 | DY18: 0.066842447 | DZ18: 0.058797072 | EA18: -0.0055139526 | EB18: 0.06456828 | EC18: 0.03642518 | ED18: 0.085230074 | EE18: 0.040747984 | EF18: -0.0010628316
A19: 120 | B19: 8 | C19: 0.03774037 | D19: 0.074693454 | E19: 0.060723423 | F19: -0.0055420907 | G19: 0.080637962 | H19: -0.03923466 | I19: -0.023814069 | J19: 0.010424139 | K19: -0.058138252 | L19: 0.01478219 | M19: 0.10390055 | N19: 0.03774037 | O19: 0.025638581 | P19: 0.027495798 | Q19: 0.019708409 | R19: 0.10469519 | S19: -0.034051137 | T19: 0.014179389 | U19: -0.084805632 | V19: 0.052543463 | W19: -0.002246783 | X19: 0.14805422 | Y19: -0.0422273 | Z19: 0.089852871 | AA19: 0.016625748 | AB19: 0.039195286 | AC19: 0.049506804 | AD19: -0.038625336 | AE19: 0.17978708 | AF19: 0.019566566 | AG19: -0.0077101904 | AH19: 0.038207036 | AI19: -0.077210793 | AJ19: 0.026545333 | AK19: 0.052639812 | AL19: -0.084598058 | AM19: 0.056614097 | AN19: 0.041899122 | AO19: 0.0060241213 | AP19: -0.17980301 | AQ19: 0.074530494 | AR19: -0.07668332 | AS19: 0.00011166308 | AT19: -0.11160474 | AU19: -0.076604409 | AV19: -0.066300671 | AW19: -0.052468826 | AX19: 0.10909536 | AY19: 0.12941912 | AZ19: -0.14754995 | BA19: 0.065495608 | BB19: -0.14012958 | BC19: -0.10748302 | BD19: 0.019470988 | BE19: 0.031784658 | BF19: 0.088660549 | BG19: 0.11883037 | BH19: 0.068718733 | BI19: -0.040502134 | BJ19: 0.0093489581 | BK19: 0.056589448 | BL19: 0.014533373 | BM19: 0.034392164 | BN19: 0.0029230981 | BO19: -0.089541873 | BP19: 0.0709374 | BQ19: 0.0059569331 | BR19: -0.07952646 | BS19: -0.091357777 | BT19: -0.040199781 | BU19: -0.010525501 | BV19: -0.087372069 | BW19: 0.12133671 | BX19: 0.014156235 | BY19: -0.0786271 | BZ19: -0.02924178 | CA19: -0.16574531 | CB19: 0.013032617 | CC19: -0.015383835 | CD19: -0.033773541 | CE19: -0.045480323 | CF19: -0.025121575 | CG19: 0.083766494 | CH19: -0.14331833 | CI19: -0.057620662 | CJ19: 0.047954663 | CK19: -0.090650455 | CL19: 0.10660353 | CM19: -0.11005191 | CN19: -0.12474259 | CO19: 0.10690014 | CP19: -0.041582978 | CQ19: -0.015378497 | CR19: -0.095669371 | CS19: -0.0069241996 | CT19: -0.046598247 | CU19: 0.096722204 | CV19: -0.0095877325 | CW19: -0.0032305608 | CX19: -0.029767538 | CY19: 0.031429781 | CZ19: 0.013702182 | DA19: 0.12036997 | DB19: -0.034817211 | DC19: 0.057824967 | DD19: -0.12486184 | DE19: -0.014203307 | DF19: -0.074282503 | DG19: -0.00061893419 | DH19: 0.019492308 | DI19: 0.052422018 | DJ19: 0.046146097 | DK19: -0.032261039 | DL19: -0.023197465 | DM19: -0.16085835 | DN19: 0.050042611 | DO19: -0.049517432 | DP19: 0.11901468 | DQ19: 0.00020316096 | DR19: 0.0052606806 | DS19: 0.024462506 | DT19: -0.01817895 | DU19: 0.081956764 | DV19: 0.016918927 | DW19: 0.0050306432 | DX19: -0.11794736 | DY19: 0.13584938 | DZ19: 0.022482261 | EA19: 0.021537868 | EB19: 0.076981164 | EC19: 0.036200676 | ED19: 0.092224172 | EE19: 0.054244016 | EF19: -0.0088157197
A20: 137 | B20: 7 | C20: 0.023960674 | D20: 0.061287233 | E20: 0.055594147 | F20: -0.011499924 | G20: 0.048971529 | H20: -0.04007545 | I20: -0.027390523 | J20: 0.024389223 | K20: -0.046151862 | L20: 0.015067331 | M20: 0.12839063 | N20: 0.023960674 | O20: 0.034758583 | P20: 0.031700692 | Q20: 0.019791605 | R20: 0.12896539 | S20: -0.02459534 | T20: 0.040120104 | U20: -0.10060738 | V20: 0.0414122 | W20: -0.0081212312 | X20: 0.18072645 | Y20: -0.044362895 | Z20: 0.082807328 | AA20: 0.033828014 | AB20: 0.053881385 | AC20: 0.021962224 | AD20: -0.030580864 | AE20: 0.22143325 | AF20: 0.036399608 | AG20: -0.024902554 | AH20: 0.052607918 | AI20: -0.095983927 | AJ20: 0.014247365 | AK20: 0.056876456 | AL20: -0.079623297 | AM20: 0.038443072 | AN20: 0.03928749 | AO20: -0.013294927 | AP20: -0.20436725 | AQ20: 0.099442797 | AR20: -0.090023914 | AS20: -0.04114909 | AT20: -0.13695074 | AU20: -0.091024948 | AV20: -0.072189443 | AW20: -0.0077722218 | AX20: 0.14207852 | AY20: 0.15774765 | AZ20: -0.15578392 | BA20: 0.05060146 | BB20: -0.16638053 | BC20: -0.11268293 | BD20: 0.040525693 | BE20: 0.038400126 | BF20: 0.10877919 | BG20: 0.14084341 | BH20: 0.065799635 | BI20: -0.012794986 | BJ20: -0.0017692878 | BK20: 0.037871017 | BL20: 0.023656608 | BM20: 0.056691915 | BN20: 0.035955859 | BO20: -0.11974034 | BP20: 0.081283018 | BQ20: 0.020792497 | BR20: -0.085531123 | BS20: -0.1101922 | BT20: 0.021062157 | BU20: 0.021235991 | BV20: -0.09557985 | BW20: 0.11044165 | BX20: 0.0073082335 | BY20: -0.12604645 | BZ20: -0.027112527 | CA20: -0.17016029 | CB20: 0.035496195 | CC20: -0.024938055 | CD20: -0.085963881 | CE20: -0.046587905 | CF20: -0.06720586 | CG20: 0.095321622 | CH20: -0.1861896 | CI20: -0.060535737 | CJ20: 0.062092343 | CK20: -0.11067153 | CL20: 0.053403037 | CM20: -0.13655379 | CN20: -0.14580952 | CO20: 0.12032401 | CP20: -0.031798704 | CQ20: -0.055724052 | CR20: -0.12074417 | CS20: -0.040845715 | CT20: -0.060288135 | CU20: 0.09613858 | CV20: -0.0056808048 | CW20: 0.013739428 | CX20: -0.0096883101 | CY20: 0.0051904249 | CZ20: -0.025900999 | DA20: 0.120622 | DB20: -0.046942584 | DC20: 0.064491756 | DD20: -0.1259934 | DE20: -0.02353859 | DF20: -0.086359852 | DG20: -0.0039412419 | DH20: 0.0051818377 | DI20: 0.058885758 | DJ20: 0.057994612 | DK20: -0.073067392 | DL20: 0.00049961149 | DM20: -0.18644367 | DN20: 0.09694754 | DO20: -0.056900852 | DP20: 0.15282102 | DQ20: 0.0058171498 | DR20: 0.067562772 | DS20: 0.053815681 | DT20: 0.0058385284 | DU20: 0.15703438 | DV20: -0.018496873 | DW20: -0.033493026 | DX20: -0.11616711 | DY20: 0.13321647 | DZ20: 0.065625422 | EA20: 0.020377141 | EB20: 0.074414153 | EC20: 0.0549349 | ED20: 0.094619797 | EE20: 0.074482351 | EF20: -0.040050568
A21: 160 | B21: 6 | C21: 0.017692425 | D21: 0.071963453 | E21: -0.010531128 | F21: 0.020877774 | G21: 0.047300629 | H21: -0.0038041754 | I21: -0.04475683 | J21: 0.037236508 | K21: -0.057542163 | L21: 0.011611325 | M21: 0.1452648 | N21: 0.017692425 | O21: 0.0030936635 | P21: 0.03907969 | Q21: -0.0166054 | R21: 0.10413609 | S21: -0.10461289 | T21: 0.051582066 | U21: -0.085624574 | V21: 0.050393951 | W21: -0.020429765 | X21: 0.160473 | Y21: -0.067513736 | Z21: 0.03241936 | AA21: 0.047221446 | AB21: -0.0056882655 | AC21: 0.026132759 | AD21: -0.028325064 | AE21: 0.20667272 | AF21: 0.055669543 | AG21: -0.029821574 | AH21: 0.076897628 | AI21: -0.099579092 | AJ21: 0.031027666 | AK21: 0.040834448 | AL21: -0.09382186 | AM21: 0.037895655 | AN21: 0.086147091 | AO21: -0.046038748 | AP21: -0.22949204 | AQ21: 0.11245439 | AR21: -0.11849912 | AS21: 0.018089021 | AT21: -0.13263501 | AU21: -0.11179086 | AV21: -0.071165225 | AW21: -0.012025722 | AX21: 0.15097481 | AY21: 0.19332599 | AZ21: -0.1702005 | BA21: 0.079203865 | BB21: -0.21769555 | BC21: -0.081294512 | BD21: 0.028471778 | BE21: 0.021445923 | BF21: 0.15024443 | BG21: 0.15020699 | BH21: 0.040201179 | BI21: 0.04144332 | BJ21: 0.063383655 | BK21: 0.029523395 | BL21: 0.019341645 | BM21: 0.04165935 | BN21: 0.021328504 | BO21: -0.080890091 | BP21: 0.083758521 | BQ21: -0.0083269359 | BR21: -0.097667401 | BS21: -0.15524023 | BT21: 0.03076518 | BU21: 0.023431084 | BV21: -0.056091717 | BW21: 0.099546382 | BX21: 0.044549507 | BY21: -0.11632847 | BZ21: -0.023104831 | CA21: -0.17878929 | CB21: -0.024349599 | CC21: -0.056222321 | CD21: 0.019163568 | CE21: 0.03056742 | CF21: -0.067547603 | CG21: 0.17412269 | CH21: -0.18815443 | CI21: 0.05376432 | CJ21: 0.081877313 | CK21: -0.090001731 | CL21: 0.0052893302 | CM21: -0.14531234 | CN21: -0.15110162 | CO21: 0.11688926 | CP21: -0.033103623 | CQ21: -0.074217049 | CR21: -0.17989271 | CS21: -0.074243582 | CT21: -0.05998158 | CU21: 0.10571859 | CV21: -0.060442327 | CW21: 0.0075724346 | CX21: 0.014551639 | CY21: -0.0044257755 | CZ21: -0.05171482 | DA21: 0.13546732 | DB21: 0.026428067 | DC21: 0.046063234 | DD21: -0.15390271 | DE21: -0.041764282 | DF21: -0.070504363 | DG21: -0.02601273 | DH21: 0.016074085 | DI21: 0.032965495 | DJ21: 0.051348967 | DK21: -0.14064182 | DL21: 0.0073561907 | DM21: -0.11417601 | DN21: 0.13812909 | DO21: -0.074567654 | DP21: 0.099523794 | DQ21: -0.0030147451 | DR21: 0.070782978 | DS21: 0.029355735 | DT21: -0.019228776 | DU21: 0.13894736 | DV21: 0.039614333 | DW21: -0.034028169 | DX21: -0.12593365 | DY21: 0.16925849 | DZ21: 0.07425615 | EA21: 0.025503691 | EB21: 0.038239871 | EC21: 0.08067204 | ED21: 0.11817251 | EE21: 0.045303163 | EF21: -0.039264104
A22: 192 | B22: 5 | C22: 0.036241182 | D22: 0.065137114 | E22: -0.0096236883 | F22: 0.04935145 | G22: 0.061676797 | H22: 0.0086017333 | I22: -0.0013358198 | J22: 0.016984544 | K22: -0.050564507 | L22: 0.06342992 | M22: 0.1273301 | N22: 0.036241182 | O22: -0.0032640661 | P22: 0.040080666 | Q22: -0.049896762 | R22: 0.13098712 | S22: -0.16704018 | T22: 0.10283023 | U22: -0.062373707 | V22: 0.047704615 | W22: -0.018644474 | X22: 0.18551782 | Y22: -0.084834679 | Z22: 0.052446574 | AA22: 0.090367058 | AB22: -0.01940338 | AC22: 0.019486928 | AD22: 0.0035373591 | AE22: 0.22955768 | AF22: 0.06405967 | AG22: -0.013293524 | AH22: 0.058348439 | AI22: -0.14862549 | AJ22: 0.042812543 | AK22: 0.0034571966 | AL22: -0.11125141 | AM22: 0.046411546 | AN22: 0.074185727 | AO22: -0.051335513 | AP22: -0.23349639 | AQ22: 0.1132235 | AR22: -0.12971091 | AS22: 0.033458168 | AT22: -0.12657409 | AU22: -0.12534745 | AV22: -0.070287215 | AW22: 0.0041239123 | AX22: 0.31378779 | AY22: 0.25521646 | AZ22: -0.049113581 | BA22: 0.034048124 | BB22: -0.14517958 | BC22: -0.051379038 | BD22: 0.051391964 | BE22: 0.020936559 | BF22: 0.095210284 | BG22: 0.19641385 | BH22: 0.081165954 | BI22: 0.034671726 | BJ22: 0.056350308 | BK22: 0.03702983 | BL22: 0.053311724 | BM22: 0.02966361 | BN22: -0.0058429122 | BO22: -0.070809859 | BP22: 0.077342999 | BQ22: -0.030347224 | BR22: -0.18751365 | BS22: -0.17644364 | BT22: -0.080753232 | BU22: 0.04387049 | BV22: -0.056716532 | BW22: 0.14044014 | BX22: 0.050144258 | BY22: -0.048233632 | BZ22: -0.082958418 | CA22: -0.20801353 | CB22: -0.017029387 | CC22: -0.0135866 | CD22: -0.012462691 | CE22: 0.0061969322 | CF22: -0.044521161 | CG22: 0.19943976 | CH22: -0.13600462 | CI22: 0.07605691 | CJ22: 0.12003441 | CK22: -0.11763279 | CL22: 0.014262656 | CM22: -0.16404328 | CN22: -0.19383769 | CO22: 0.19144292 | CP22: -0.027897443 | CQ22: -0.044846318 | CR22: -0.16520794 | CS22: -0.11630342 | CT22: -0.081889834 | CU22: 0.11557095 | CV22: -0.04068302 | CW22: -0.0077342106 | CX22: -0.0079560804 | CY22: -0.0057744302 | CZ22: -0.0026066994 | DA22: 0.19353366 | DB22: 0.014994817 | DC22: 0.036887935 | DD22: -0.091927583 | DE22: -0.026908725 | DF22: -0.081986158 | DG22: -0.025022831 | DH22: 0.035297443 | DI22: 0.045775558 | DJ22: 0.055145704 | DK22: -0.13663615 | DL22: 0.0079962371 | DM22: -0.072889845 | DN22: 0.17299794 | DO22: -0.12021416 | DP22: 0.048626827 | DQ22: 0.02002375 | DR22: 0.051897249 | DS22: 0.078745216 | DT22: 0.05529428 | DU22: 0.16322592 | DV22: 0.056491247 | DW22: 0.045635085 | DX22: -0.20979312 | DY22: 0.14225805 | DZ22: 0.070757416 | EA22: 0.038940807 | EB22: 0.03795852 | EC22: 0.11130045 | ED22: 0.20918918 | EE22: 0.063649083 | EF22: -0.056302641
A23: 241 | B23: 4 | C23: -0.0088942129 | D23: 0.063789445 | E23: -0.0081404331 | F23: -0.042080175 | G23: -0.0080289697 | H23: -0.0053597609 | I23: 0.0047386625 | J23: 0.032827198 | K23: -0.097382715 | L23: 0.028435827 | M23: 0.10282485 | N23: -0.0088942129 | O23: -0.028039667 | P23: 0.067793938 | Q23: -0.08639778 | R23: 0.16719545 | S23: -0.14098784 | T23: 0.072281528 | U23: -0.13636928 | V23: 0.074071928 | W23: -0.0092551403 | X23: 0.28865687 | Y23: -0.071816243 | Z23: 0.029881733 | AA23: 0.12239785 | AB23: -0.063743631 | AC23: 0.0035232885 | AD23: -0.036530577 | AE23: 0.2331798 | AF23: 0.043819395 | AG23: -0.009401374 | AH23: 0.20229573 | AI23: -0.11521082 | AJ23: 0.037700893 | AK23: 0.04514867 | AL23: -0.13228592 | AM23: 0.062181982 | AN23: 0.11430615 | AO23: -0.065147866 | AP23: -0.054732591 | AQ23: 0.057926086 | AR23: -0.1236571 | AS23: 0.075385781 | AT23: -0.16741243 | AU23: -0.11615131 | AV23: -0.036394844 | AW23: -0.024105833 | AX23: 0.39952936 | AY23: 0.27935826 | AZ23: -0.057207149 | BA23: -0.10775415 | BB23: -0.19190754 | BC23: -0.024823237 | BD23: 0.090580084 | BE23: 0.019858018 | BF23: 0.11285353 | BG23: 0.23814807 | BH23: 0.081030379 | BI23: 0.036270501 | BJ23: 0.095876654 | BK23: 0.023480384 | BL23: 0.072002189 | BM23: 0.040791234 | BN23: -0.036308093 | BO23: -0.051331019 | BP23: 0.092476969 | BQ23: -0.062296811 | BR23: -0.19369076 | BS23: -0.20003186 | BT23: -0.11829554 | BU23: 0.034033261 | BV23: -0.072876564 | BW23: 0.11961463 | BX23: 0.03086855 | BY23: -0.024509003 | BZ23: -0.21324471 | CA23: -0.079033802 | CB23: -0.025398731 | CC23: -0.049554049 | CD23: 0.048551875 | CE23: 0.071478401 | CF23: -0.061736912 | CG23: 0.2606535 | CH23: -0.20826589 | CI23: 0.056834966 | CJ23: 0.18337825 | CK23: -0.094028156 | CL23: -0.11816125 | CM23: -0.25732808 | CN23: -0.32000939 | CO23: 0.24578873 | CP23: -0.028760601 | CQ23: -0.046950855 | CR23: -0.2160758 | CS23: -0.17429407 | CT23: -0.041679161 | CU23: 0.06912523 | CV23: -0.049639797 | CW23: -0.0069898494 | CX23: -0.037170259 | CY23: 0.10257923 | CZ23: 0.03791362 | DA23: 0.2004958 | DB23: 0.0042840668 | DC23: 0.032285948 | DD23: -0.072893036 | DE23: -0.028388242 | DF23: -0.069327674 | DG23: -0.036907295 | DH23: 0.060875549 | DI23: 0.035502557 | DJ23: 0.080823351 | DK23: -0.14846548 | DL23: -0.03954016 | DM23: -0.044283898 | DN23: 0.20325249 | DO23: -0.1504178 | DP23: 0.088246529 | DQ23: 0.074556556 | DR23: 0.079645162 | DS23: 0.11766209 | DT23: 0.075092148 | DU23: 0.14719767 | DV23: 0.093309325 | DW23: 0.027698865 | DX23: -0.21589913 | DY23: 0.022285376 | DZ23: 0.10886832 | EA23: 0.10719545 | EB23: 0.071553737 | EC23: 0.15422659 | ED23: 0.22894199 | EE23: 0.058960111 | EF23: 0.0070681189
A24: 321 | B24: 3 | C24: -0.13322237 | D24: 0.056652028 | E24: 0.012107273 | F24: -0.038256846 | G24: -0.075045985 | H24: -0.0055389195 | I24: 0.012846276 | J24: 0.025325564 | K24: -0.0014318064 | L24: -0.03334628 | M24: 0.16647798 | N24: -0.13322237 | O24: 0.0062332184 | P24: 0.067580016 | Q24: -0.21540461 | R24: 0.19088396 | S24: -0.14284789 | T24: 0.064720968 | U24: -0.23511949 | V24: 0.061879453 | W24: -0.041973953 | X24: 0.3614744 | Y24: -0.0042848302 | Z24: 0.069335337 | AA24: 0.018334691 | AB24: -0.13264174 | AC24: -0.035834724 | AD24: -0.10278229 | AE24: 0.25421917 | AF24: 0.0065189269 | AG24: 0.062154518 | AH24: 0.28556111 | AI24: -0.077449278 | AJ24: 0.11800118 | AK24: 0.073616658 | AL24: -0.027358794 | AM24: 0.091785107 | AN24: 0.12795364 | AO24: -0.13810083 | AP24: -0.040829858 | AQ24: 0.021066607 | AR24: -0.18824705 | AS24: 0.0043633746 | AT24: -0.28619576 | AU24: -0.078077497 | AV24: -0.046922579 | AW24: -0.038953145 | AX24: 0.22980768 | AY24: 0.197423 | AZ24: -0.023947139 | BA24: -0.21722337 | BB24: -0.30376601 | BC24: -0.087022192 | BD24: 0.065077708 | BE24: 0.073684392 | BF24: -0.058962981 | BG24: 0.24089469 | BH24: 0.045648386 | BI24: 0.06445268 | BJ24: 0.02280892 | BK24: 0.032605737 | BL24: 0.088438775 | BM24: -0.032985662 | BN24: -0.082604701 | BO24: -0.014859067 | BP24: 0.10138009 | BQ24: -0.068370008 | BR24: -0.17933019 | BS24: -0.28649213 | BT24: -0.076951238 | BU24: -0.011051811 | BV24: -0.091923595 | BW24: 0.14943427 | BX24: -0.010107453 | BY24: 0.10614271 | BZ24: -0.27161885 | CA24: 0.017774654 | CB24: -0.012553926 | CC24: -0.095797728 | CD24: -0.017768765 | CE24: 0.0079741021 | CF24: -0.054920515 | CG24: 0.17740357 | CH24: -0.22748447 | CI24: 0.068703076 | CJ24: 0.18685584 | CK24: -0.13696827 | CL24: -0.15004017 | CM24: -0.16428983 | CN24: -0.3035666 | CO24: 0.30692226 | CP24: -0.078437851 | CQ24: -0.026581764 | CR24: -0.23561263 | CS24: -0.23069021 | CT24: -0.0036907531 | CU24: 0.033551081 | CV24: -0.064262342 | CW24: -0.010340374 | CX24: 0.035829164 | CY24: 0.16549851 | CZ24: -0.10257847 | DA24: 0.17083434 | DB24: 0.00097339679 | DC24: 0.041760139 | DD24: -0.14961234 | DE24: -0.014323033 | DF24: -0.095756241 | DG24: -0.042089976 | DH24: 0.022899041 | DI24: 0.018696233 | DJ24: 0.066775955 | DK24: -0.13083162 | DL24: -0.078112008 | DM24: 0.014735179 | DN24: 0.24030829 | DO24: -0.18362623 | DP24: 0.051818121 | DQ24: 0.087665873 | DR24: 0.1459043 | DS24: 0.12304676 | DT24: 0.09381085 | DU24: 0.18549348 | DV24: 0.12932484 | DW24: 0.36633494 | DX24: -0.2271064 | DY24: -0.06507192 | DZ24: 0.22087716 | EA24: 0.16631396 | EB24: 0.073233156 | EC24: 0.18555698 | ED24: 0.35323643 | EE24: 0.030642909 | EF24: 0.0051963581
A25: 482 | B25: 2 | C25: -0.14698994 | D25: 0.062865427 | E25: 0.12468354 | F25: 0.0019734138 | G25: -0.0059471376 | H25: -0.033764077 | I25: 0.03881416 | J25: 0.075024393 | K25: 0.086338883 | L25: -0.029625733 | M25: 0.34149409 | N25: -0.14698994 | O25: -0.0034838585 | P25: 0.13393146 | Q25: -0.018623522 | R25: 0.19676481 | S25: -0.036850075 | T25: 0.047535122 | U25: -0.21938422 | V25: -0.01988576 | W25: -0.067468182 | X25: 0.49146157 | Y25: -0.029681484 | Z25: 0.092175229 | AA25: 0.068521766 | AB25: -0.27235092 | AC25: -0.058480254 | AD25: -0.16334801 | AE25: 0.055320838 | AF25: -0.17794023 | AG25: 0.038455508 | AH25: -0.023127356 | AI25: -0.23660797 | AJ25: 0.11301237 | AK25: 0.05513258 | AL25: 0.064524248 | AM25: 0.13324202 | AN25: 0.072826434 | AO25: -0.23691434 | AP25: -0.016469593 | AQ25: -0.016638359 | AR25: -0.30046013 | AS25: 0.033013929 | AT25: -0.45370159 | AU25: -0.076494371 | AV25: -0.084743166 | AW25: 0.00093862145 | AX25: 0.17674537 | AY25: 0.24605555 | AZ25: -0.11103016 | BA25: -0.18320204 | BB25: -0.40524586 | BC25: -0.0059107015 | BD25: 0.11721719 | BE25: 0.029999905 | BF25: -0.088177203 | BG25: 0.34214631 | BH25: 0.010733164 | BI25: -0.0634871 | BJ25: -0.066121968 | BK25: 0.061504805 | BL25: 0.034203679 | BM25: -0.043152935 | BN25: 0.031554622 | BO25: -0.12041575 | BP25: 0.23812668 | BQ25: -0.098592994 | BR25: -0.11178812 | BS25: -0.072957301 | BT25: -0.056370476 | BU25: -0.065712673 | BV25: -0.1356381 | BW25: 0.10595701 | BX25: 0.037031158 | BY25: 0.12579636 | BZ25: -0.14561878 | CA25: 0.0088784866 | CB25: 0.048822093 | CC25: -0.071481145 | CD25: -0.046451404 | CE25: 0.036894685 | CF25: -0.001867593 | CG25: -0.15471744 | CH25: -0.31184301 | CI25: 0.061038682 | CJ25: 0.253498 | CK25: -0.12733323 | CL25: -0.067318029 | CM25: -0.19234009 | CN25: -0.24087757 | CO25: 0.35901502 | CP25: 0.0095310728 | CQ25: -0.20310474 | CR25: -0.19852494 | CS25: -0.29830616 | CT25: 0.043354148 | CU25: 0.079682321 | CV25: -0.080934494 | CW25: -0.0097600512 | CX25: 0.026728746 | CY25: 0.27205189 | CZ25: -0.07291185 | DA25: 0.31964633 | DB25: 0.077332824 | DC25: 0.020146368 | DD25: -0.23648924 | DE25: -0.018932258 | DF25: -0.090994183 | DG25: -0.024388768 | DH25: 0.039242565 | DI25: -0.099357763 | DJ25: 0.049205764 | DK25: -0.12935116 | DL25: -0.15424147 | DM25: 0.04345746 | DN25: 0.2837459 | DO25: -0.19636558 | DP25: -0.11044891 | DQ25: 0.019559601 | DR25: 0.25414875 | DS25: 0.23432591 | DT25: 0.053999458 | DU25: 0.38275427 | DV25: 0.12517404 | DW25: 0.60260967 | DX25: -0.32634887 | DY25: -0.0901998 | DZ25: 0.186386 | EA25: 0.21372811 | EB25: 0.054524773 | EC25: -0.066350165 | ED25: 0.43702791 | EE25: 0.081659023 | EF25: -0.0089547329
A26: 964 | B26: 1 | C26: -0.25797045 | D26: 0.13051021 | E26: -0.067642479 | F26: 0.043740544 | G26: 0.10410548 | H26: -0.13506513 | I26: -0.10298683 | J26: 0.30685732 | K26: 0.016950159 | L26: -0.061521614 | M26: 0.34491744 | N26: -0.25797045 | O26: -0.063439746 | P26: 0.20904913 | Q26: -0.024332101 | R26: 0.29178114 | S26: -0.19860789 | T26: 0.11390603 | U26: -0.16919689 | V26: 0.2306278 | W26: -0.088603703 | X26: 0.656161 | Y26: -0.014221313 | Z26: 0.32061851 | AA26: 0.057325988 | AB26: -0.19179782 | AC26: -0.10082558 | AD26: -0.044436728 | AE26: 0.21115763 | AF26: -0.058279955 | AG26: -0.31121717 | AH26: 0.12329336 | AI26: -0.25773999 | AJ26: 0.12673853 | AK26: 0.20541973 | AL26: -0.066042241 | AM26: 0.15823926 | AN26: 0.092031952 | AO26: -0.32989053 | AP26: -0.058479939 | AQ26: -0.021177208 | AR26: -0.42212428 | AS26: 0.18391189 | AT26: -0.86987869 | AU26: -0.23476601 | AV26: -0.10816164 | AW26: 0.11565166 | AX26: 0.2725653 | AY26: 0.60336013 | AZ26: -0.061408628 | BA26: -0.43196297 | BB26: -0.087533957 | BC26: 0.13191016 | BD26: 0.18404859 | BE26: 0.069142035 | BF26: -0.24468064 | BG26: 0.56443451 | BH26: 0.20844332 | BI26: -0.11341693 | BJ26: -0.15893839 | BK26: 0.09813736 | BL26: -0.065942695 | BM26: -0.043725963 | BN26: -0.02587209 | BO26: -0.13396836 | BP26: 0.31888203 | BQ26: -0.04296518 | BR26: -0.14910552 | BS26: -0.00021029468 | BT26: -0.022464194 | BU26: -0.17073927 | BV26: 0.11943956 | BW26: -0.014411779 | BX26: 0.10529477 | BY26: 0.3049966 | BZ26: -0.11179141 | CA26: 0.0019849853 | CB26: -0.10133708 | CC26: -0.20881938 | CD26: -0.0027236287 | CE26: 0.11794096 | CF26: -0.017920393 | CG26: -0.028681981 | CH26: -0.099291308 | CI26: 0.3946056 | CJ26: 0.34307279 | CK26: -0.048734984 | CL26: -0.12467111 | CM26: -0.2178478 | CN26: -0.43093346 | CO26: 0.56993097 | CP26: 0.26595505 | CQ26: -0.25888494 | CR26: -0.096443012 | CS26: -0.14536585 | CT26: 0.073339845 | CU26: 0.1207069 | CV26: -0.14322957 | CW26: -0.037041272 | CX26: 0.010639545 | CY26: 0.1225019 | CZ26: -0.19084738 | DA26: 0.022267002 | DB26: 0.26091419 | DC26: -0.050145312 | DD26: -0.14845482 | DE26: 0.013730837 | DF26: -0.18219921 | DG26: -0.14342805 | DH26: 0.055360153 | DI26: -0.18924782 | DJ26: 0.037376049 | DK26: -0.18393473 | DL26: 0.019683363 | DM26: -0.045373737 | DN26: 0.65726889 | DO26: -0.016303778 | DP26: -0.16093888 | DQ26: 0.031826862 | DR26: 0.36175338 | DS26: 0.32345196 | DT26: 0.19724234 | DU26: 0.38338391 | DV26: -0.007417378 | DW26: 0.70028058 | DX26: -0.46913877 | DY26: -0.25706787 | DZ26: 0.20680801 | EA26: 0.08870659 | EB26: 0.18183054 | EC26: 0.051434771 | ED26: 0.1032776 | EE26: 0.055185153 | EF26: -0.03758578
A27: 大盤 | B27: TWⅡ | C27: -0.017446771 | D27: 0.020701061 | E27: 0.023982129 | F27: -0.006557579 | G27: 0.03184513 | H27: 0.034348533 | I27: -0.0082549328 | J27: 0.012843524 | K27: -0.051018525 | L27: 0.00087394274 | M27: 0.023389576 | N27: 0.012988972 | O27: 0.0058545887 | P27: 0.027413207 | Q27: -0.0037129361 | R27: 0.024076614 | S27: -0.012190025 | T27: -0.039749578 | U27: -0.07315545 | V27: -0.05826023 | W27: 0.00077279757 | X27: 0.044591521 | Y27: -0.02769968 | Z27: 0.0020950059 | AA27: -0.023400551 | AB27: 0.032129371 | AC27: 0.038903273 | AD27: -0.042865382 | AE27: 0.018647195 | AF27: 0.015229768 | AG27: 0.036016604 | AH27: 0.0093546114 | AI27: 0.010748251 | AJ27: 0.013357754 | AK27: -0.0053327473 | AL27: 0.0013831358 | AM27: 0.020795928 | AN27: 0.031517702 | AO27: 0.0062417165 | AP27: 0.0061452617 | AQ27: 0.016946358 | AR27: 0.03468283 | AS27: 0.0030985886 | AT27: 0.015081347 | AU27: -0.019251209 | AV27: 0.038711513 | AW27: -0.021856951 | AX27: 0.0077743007 | AY27: 0.042397247 | AZ27: -0.026308975 | BA27: 0.0095717493 | BB27: -0.024249741 | BC27: 0.020163374 | BD27: -0.0035049988 | BE27: 0.020151935 | BF27: 0.00058133623 | BG27: -0.005219701 | BH27: -0.11587176 | BI27: 0.0087252257 | BJ27: -0.016377261 | BK27: 0.020840372 | BL27: 0.044975872 | BM27: 0.023954306 | BN27: 0.030239101 | BO27: -0.043725888 | BP27: 0.02188947 | BQ27: 0.0086274303 | BR27: -0.019192954 | BS27: 0.01973513 | BT27: 0.047694337 | BU27: 0.011454817 | BV27: 0.043228621 | BW27: -0.04274743 | BX27: -0.017811292 | BY27: -0.1511531 | BZ27: 0.124224 | CA27: -0.0045572538 | CB27: 0.06021124 | CC27: 0.085992033 | CD27: -0.0058084796 | CE27: -0.006041347 | CF27: 0.0024523244 | CG27: 0.089636252 | CH27: 0.070992733 | CI27: 0.027170643 | CJ27: 0.052468428 | CK27: 0.029480661 | CL27: 0.066825081 | CM27: -0.028772229 | CN27: 0.039462516 | CO27: -0.029031087 | CP27: 0.013983883 | CQ27: -0.032276965 | CR27: 0.0031035766 | CS27: 0.025591856 | CT27: 0.044391886 | CU27: -0.030338959 | CV27: -0.0012579765 | CW27: 0.0023363565 | CX27: -0.064264145 | CY27: 0.012909779 | CZ27: -0.12547709 | DA27: 0.011690683 | DB27: 0.0063378437 | DC27: -0.11730536 | DD27: -0.036010872 | DE27: 0.1389113 | DF27: -0.051143506 | DG27: 0.076731447 | DH27: 0.015508782 | DI27: 0.023223774 | DJ27: -0.018372876 | DK27: 0.062199014 | DL27: 0.020098304 | DM27: 0.01349894 | DN27: -0.030252213 | DO27: -0.017022836 | DP27: -0.021788523 | DQ27: 0.085745625 | DR27: 0.028106744 | DS27: -0.0023031598 | DT27: 0.058471198 | DU27: 0.067658949 | DV27: 0.0050207706 | DW27: 0.037416184 | DX27: 0.084111004 | DY27: -0.036832399 | DZ27: 0.0030917028 | EA27: -0.0019576282 | EB27: 0.026459104 | EC27: -0.024752539 | ED27: 0.034115491 | EE27: 0.021061974 | EF27: -0.020277393
C29: 1101 | D29: 2484 | E29: 1233 | F29: 2524 | G29: 2611 | H29: 1233 | I29: 2379 | J29: 2379 | K29: 2524 | L29: 1233 | M29: 2524 | N29: 1805 | O29: 2538 | P29: 3033 | Q29: 2385 | R29: 3024 | S29: 3024 | T29: 1314 | U29: 3024 | V29: 3024 | W29: 5521 | X29: 2535 | Y29: 3033 | Z29: 5201 | AA29: 2535 | AB29: 5201 | AC29: 5471 | AD29: 5521 | AE29: 2023 | AF29: 2023 | AG29: 3017 | AH29: 3033 | AI29: 1464 | AJ29: 2451 | AK29: 2451 | AL29: 4413 | AM29: 2451 | AN29: 2451 | AO29: 6121 | AP29: 2451 | AQ29: 1805 | AR29: 4416 | AS29: 5523 | AT29: 2524 | AU29: 1436 | AV29: 2338 | AW29: 5212 | AX29: 2338 | AY29: 6186 | AZ29: 5523 | BA29: 5523 | BB29: 5443 | BC29: 3051 | BD29: 5523 | BE29: 3051 | BF29: 3051 | BG29: 3051 | BH29: 6186 | BI29: 6186 | BJ29: 2537 | BK29: 2537 | BL29: 2488 | BM29: 6192 | BN29: 8927 | BO29: 2537 | BP29: 4416 | BQ29: 2537 | BR29: 6128 | BS29: 3002 | BT29: 5007 | BU29: 4109 | BV29: 6128 | BW29: 8085 | BX29: 8927 | BY29: 1737 | BZ29: 6242 | CA29: 6242 | CB29: 8927 | CC29: 8927 | CD29: 6242 | CE29: 8927 | CF29: 6242 | CG29: 8050 | CH29: 6242 | CI29: 6242 | CJ29: 8050 | CK29: 8050 | CL29: 6242 | CM29: 4402 | CN29: 3016 | CO29: 1436 | CP29: 6242 | CQ29: 3016 | CR29: 6242 | CS29: 3005 | CT29: 2493 | CU29: 2423 | CV29: 1734 | CW29: 5306 | CX29: 4402 | CY29: 9904 | CZ29: 8072 | DA29: 5007 | DB29: 9904 | DC29: 8072 | DD29: 6021 | DE29: 3232 | DF29: 2538 | DG29: 2538 | DH29: 5306 | DI29: 2538 | DJ29: 2434 | DK29: 2538 | DL29: 6020 | DM29: 2538 | DN29: 4402 | DO29: 2538 | DP29: 5425 | DQ29: 5425 | DR29: 4402 | DS29: 6291 | DT29: 2031 | DU29: 6291 | DV29: 3232 | DW29: 2538 | DX29: 6291 | DY29: 2538 | DZ29: 2538 | EA29: 8074 | EB29: 8074 | EC29: 3232 | ED29: 4402 | EE29: 2538 | EF29: 2538
