Workbook

Sheet 真實IC
A1: Real
B2: Time | C2: 2013/12 | D2: 2014/01 | E2: 2014/02 | F2: 2014/03 | G2: 2014/04 | H2: 2014/05 | I2: 2014/06 | J2: 2014/07 | K2: 2014/08 | L2: 2014/09 | M2: 2014/10 | N2: 2014/11 | O2: 2014/12 | P2: 2015/01 | Q2: 2015/02 | R2: 2015/03 | S2: 2015/04 | T2: 2015/05 | U2: 2015/06 | V2: 2015/07 | W2: 2015/08 | X2: 2015/09 | Y2: 2015/10 | Z2: 2015/11 | AA2: 2015/12 | AB2: 2016/01 | AC2: 2016/02 | AD2: 2016/03 | AE2: 2016/04 | AF2: 2016/05 | AG2: 2016/06 | AH2: 2016/07 | AI2: 2016/08 | AJ2: 2016/09 | AK2: 2016/10 | AL2: 2016/11 | AM2: 2016/12 | AN2: 2017/01 | AO2: 2017/02 | AP2: 2017/03 | AQ2: 2017/04 | AR2: 2017/05 | AS2: 2017/06 | AT2: 2017/07 | AU2: 2017/08 | AV2: 2017/09 | AW2: 2017/10 | AX2: 2017/11 | AY2: 2017/12 | AZ2: 2018/01 | BA2: 2018/02 | BB2: 2018/03 | BC2: 2018/04 | BD2: 2018/05 | BE2: 2018/06 | BF2: 2018/07 | BG2: 2018/08 | BH2: 2018/09 | BI2: 2018/10 | BJ2: 2018/11 | BK2: 2018/12 | BL2: 2019/01 | BM2: 2019/02 | BN2: 2019/03 | BO2: 2019/04 | BP2: 2019/05 | BQ2: 2019/06 | BR2: 2019/07 | BS2: 2019/08 | BT2: 2019/09 | BU2: 2019/10 | BV2: 2019/11 | BW2: 2019/12 | BX2: 2020/01 | BY2: 2020/02 | BZ2: 2020/03 | CA2: 2020/04 | CB2: 2020/05 | CC2: 2020/06 | CD2: 2020/07 | CE2: 2020/08 | CF2: 2020/09 | CG2: 2020/10 | CH2: 2020/11 | CI2: 2020/12 | CJ2: 2021/01 | CK2: 2021/02 | CL2: 2021/03 | CM2: 2021/04 | CN2: 2021/05 | CO2: 2021/06 | CP2: 2021/07 | CQ2: 2021/08 | CR2: 2021/09 | CS2: 2021/10 | CT2: 2021/11 | CU2: 2021/12 | CV2: 2022/01 | CW2: 2022/02 | CX2: 2022/03 | CY2: 2022/04 | CZ2: 2022/05 | DA2: 2022/06 | DB2: 2022/07 | DC2: 2022/08 | DD2: 2022/09 | DE2: 2022/10 | DF2: 2022/11 | DG2: 2022/12 | DH2: 2023/01 | DI2: 2023/02 | DJ2: 2023/03 | DK2: 2023/04 | DL2: 2023/05 | DM2: 2023/06 | DN2: 2023/07 | DO2: 2023/08 | DP2: 2023/09 | DQ2: 2023/10 | DR2: 2023/11 | DS2: 2023/12 | DT2: 2024/01 | DU2: 2024/02 | DV2: 2024/03 | DW2: 2024/04 | DX2: 2024/05 | DY2: 2024/06 | DZ2: 2024/07 | EA2: 2024/08 | EB2: 2024/09 | EC2: 2024/10 | ED2: 2024/11 | EE2: 2024/12 | EF2: 2025/01
B3: bm | C3: 0.10910583 | D3: 0.014576583 | E3: -0.036154357 | F3: -0.004742601 | G3: -0.0057477531 | H3: 0.049378023 | I3: 0.18325177 | J3: 0.11648631 | K3: -0.030594946 | L3: 0.019828051 | M3: -0.020999006 | N3: 0.14977942 | O3: 0.015463406 | P3: -0.091792321 | Q3: -0.077409013 | R3: 0.054776596 | S3: -0.12533439 | T3: -0.11905342 | U3: -0.037770051 | V3: 0.081183823 | W3: 0.084008968 | X3: 0.14701136 | Y3: -0.12536054 | Z3: 0.19195355 | AA3: -0.084370782 | AB3: 0.072897614 | AC3: 0.10260456 | AD3: 0.015770167 | AE3: -0.15200716 | AF3: 0.059250252 | AG3: 0.13005884 | AH3: 0.1152564 | AI3: 0.032606622 | AJ3: 0.027999115 | AK3: 0.14657042 | AL3: 0.040841921 | AM3: 0.13137637 | AN3: 0.22143296 | AO3: -0.020941039 | AP3: -0.13715995 | AQ3: -0.024882855 | AR3: 0.015513971 | AS3: 0.034373037 | AT3: 0.063095686 | AU3: 0.043237695 | AV3: -0.074230367 | AW3: 0.027994827 | AX3: 0.11986442 | AY3: 0.076559571 | AZ3: -0.021730386 | BA3: -0.0012464633 | BB3: 0.10099582 | BC3: 0.02982693 | BD3: 0.0086757684 | BE3: 0.068557206 | BF3: 0.1569126 | BG3: 0.15920373 | BH3: 0.061121668 | BI3: 0.096912851 | BJ3: -0.054746248 | BK3: -0.087492963 | BL3: 0.094426746 | BM3: -0.022191059 | BN3: 0.015628612 | BO3: 0.08141824 | BP3: -0.018508942 | BQ3: 0.068729568 | BR3: 0.0031023605 | BS3: 0.074964418 | BT3: 0.045201588 | BU3: 0.025677329 | BV3: 0.091804031 | BW3: -0.026353999 | BX3: 0.019394832 | BY3: -0.076838899 | BZ3: 0.11330931 | CA3: -0.10735493 | CB3: 0.040844789 | CC3: -0.019801709 | CD3: 0.18837709 | CE3: 0.055574906 | CF3: 0.074872074 | CG3: 0.10000019 | CH3: 0.13602172 | CI3: -0.093741015 | CJ3: 0.0039305991 | CK3: 0.056507777 | CL3: 0.26354578 | CM3: -0.0095554349 | CN3: -0.0315119 | CO3: -0.022619032 | CP3: 0.13265561 | CQ3: 0.13307278 | CR3: -0.014956408 | CS3: -0.033419938 | CT3: 0.012281209 | CU3: 0.11681498 | CV3: -0.0031589454 | CW3: 0.038217758 | CX3: 0.13917409 | CY3: -0.023712288 | CZ3: 0.21835291 | DA3: -0.057967362 | DB3: -0.014104219 | DC3: 0.11395608 | DD3: 0.074472262 | DE3: -0.00089969275 | DF3: 0.0009770718 | DG3: -0.072980095 | DH3: -0.023845287 | DI3: -0.10153067 | DJ3: 0.027692536 | DK3: -0.049335153 | DL3: -0.0056993576 | DM3: -0.03698176 | DN3: 0.10981299 | DO3: 0.042036825 | DP3: 0.084566668 | DQ3: -0.11027981 | DR3: 0.094328709 | DS3: -0.071906913 | DT3: -0.09623643 | DU3: 0.0023455494 | DV3: 0.13401742 | DW3: 0.094732519 | DX3: -0.1037732 | DY3: 0.075762154 | DZ3: -0.03182972 | EA3: 0.16130802 | EB3: 0.010203533 | EC3: 0.073988425 | ED3: -0.15737687 | EE3: 0.079137553 | EF3: -0.021049125
B4: size | C4: -0.24758871 | D4: -0.2746933 | E4: -0.084648385 | F4: 0.022644631 | G4: -0.049680001 | H4: -0.10075963 | I4: -0.012522721 | J4: 0.07873655 | K4: -0.0341851 | L4: 0.088406798 | M4: -0.0030634546 | N4: -0.21221799 | O4: -0.036805389 | P4: 0.071033119 | Q4: -0.071261133 | R4: 0.021560447 | S4: 0.10111126 | T4: 0.04322474 | U4: 0.01488195 | V4: 0.0063260243 | W4: -0.14355298 | X4: -0.064282172 | Y4: -0.019034203 | Z4: -0.020644556 | AA4: 0.03305954 | AB4: -0.019418227 | AC4: -0.063126839 | AD4: -0.065629712 | AE4: 0.13799569 | AF4: -0.10056792 | AG4: -0.037969091 | AH4: -0.045839538 | AI4: -0.051034096 | AJ4: -0.0032204409 | AK4: 0.00048952959 | AL4: -0.10644675 | AM4: -0.013723974 | AN4: -0.12196471 | AO4: -0.048589666 | AP4: -0.0019031504 | AQ4: 0.029067485 | AR4: 0.052635777 | AS4: -0.012893259 | AT4: -0.0021311348 | AU4: -0.15538438 | AV4: 0.012681784 | AW4: -0.011942322 | AX4: -0.0042537915 | AY4: 0.029300872 | AZ4: -0.1341275 | BA4: -0.13711153 | BB4: 0.0017546605 | BC4: 0.025117126 | BD4: -0.11960191 | BE4: 0.13576165 | BF4: 0.047091162 | BG4: -0.026050044 | BH4: 0.043752774 | BI4: -0.081391828 | BJ4: -0.10060082 | BK4: 0.090490079 | BL4: -0.030898459 | BM4: 0.058814187 | BN4: 0.081345639 | BO4: -0.0077164169 | BP4: 0.10673487 | BQ4: -0.027156341 | BR4: -0.054431019 | BS4: -0.068229278 | BT4: 0.098612223 | BU4: 0.12839854 | BV4: -0.078402519 | BW4: -0.11913372 | BX4: -0.046890096 | BY4: 0.10169834 | BZ4: -0.025680084 | CA4: -0.08330179 | CB4: -0.15782765 | CC4: -0.071052572 | CD4: -0.073875492 | CE4: -0.23678647 | CF4: 0.032627706 | CG4: 0.013423085 | CH4: -0.0027966659 | CI4: 0.0479257 | CJ4: -0.0032520193 | CK4: -0.07570819 | CL4: -0.044397256 | CM4: 0.17898858 | CN4: 0.057994266 | CO4: -0.13939019 | CP4: 0.064714671 | CQ4: -0.18118789 | CR4: -0.088633532 | CS4: -0.025321775 | CT4: -0.11307907 | CU4: 0.0080959573 | CV4: -0.045200208 | CW4: -0.058941225 | CX4: -0.1077283 | CY4: -0.096503499 | CZ4: -0.21035435 | DA4: -0.10996114 | DB4: -0.19082047 | DC4: -0.020727272 | DD4: 0.087029095 | DE4: 0.082024593 | DF4: -0.16687666 | DG4: 0.22243809 | DH4: -0.14429775 | DI4: -0.11961995 | DJ4: -0.10159274 | DK4: 0.092855059 | DL4: -0.04263049 | DM4: 0.082732073 | DN4: -0.031049452 | DO4: -0.09814199 | DP4: -0.13058888 | DQ4: 0.048655718 | DR4: -0.03925191 | DS4: -0.1610302 | DT4: -0.078883966 | DU4: 0.16407716 | DV4: 0.0075052515 | DW4: -0.10164525 | DX4: -0.056040292 | DY4: -0.10665664 | DZ4: -0.069186576 | EA4: -0.12618866 | EB4: -0.064737118 | EC4: 0.051426073 | ED4: 0.034496728 | EE4: 0.1576776 | EF4: 0.24308194
B5: mom | C5: -0.054244781 | D5: 0.045377022 | E5: -0.017752273 | F5: -0.087687354 | G5: 0.10275926 | H5: 0.0025113717 | I5: -0.018303552 | J5: 0.022110525 | K5: 0.077258046 | L5: 0.0093440784 | M5: 0.053602181 | N5: -0.067877357 | O5: 0.064929886 | P5: 0.0048806818 | Q5: 0.019197818 | R5: -0.0054653492 | S5: 0.036551467 | T5: 0.12918507 | U5: 0.013692408 | V5: 0.015295252 | W5: -0.10468572 | X5: -0.29384805 | Y5: 0.059212485 | Z5: -0.18494831 | AA5: 0.098247439 | AB5: -0.00065734107 | AC5: -0.10368612 | AD5: 0.0035450938 | AE5: 0.17560149 | AF5: -0.1550331 | AG5: -0.026328625 | AH5: -0.0049988102 | AI5: 0.028067715 | AJ5: -0.022384194 | AK5: -0.047020825 | AL5: -0.10156151 | AM5: 0.023525149 | AN5: 0.05252523 | AO5: 0.058502894 | AP5: 0.033447356 | AQ5: 0.014300365 | AR5: 0.035903595 | AS5: 0.039782285 | AT5: 0.1484562 | AU5: -0.040787295 | AV5: 0.13895895 | AW5: 0.059863283 | AX5: -0.14978981 | AY5: 0.061595851 | AZ5: -0.061949751 | BA5: -0.0023892644 | BB5: -0.1488703 | BC5: 0.060350518 | BD5: -0.014685753 | BE5: -0.1465153 | BF5: -0.20876265 | BG5: -0.20144326 | BH5: -0.11804992 | BI5: -0.077026576 | BJ5: -0.036220317 | BK5: -0.018907269 | BL5: -0.17125564 | BM5: 0.1329175 | BN5: -0.035907702 | BO5: 0.021344518 | BP5: 0.049634823 | BQ5: -0.017211216 | BR5: 0.18982724 | BS5: -0.097605037 | BT5: 0.037831444 | BU5: 0.056008305 | BV5: -0.11673704 | BW5: -0.14132299 | BX5: -0.0033770259 | BY5: 0.13033606 | BZ5: 0.031697731 | CA5: 0.040555037 | CB5: -0.042037331 | CC5: 0.050013723 | CD5: -0.068456279 | CE5: -0.08083209 | CF5: -0.0019483108 | CG5: -0.118209 | CH5: -0.036719886 | CI5: -0.083332793 | CJ5: 0.23067287 | CK5: 0.13277852 | CL5: 0.14128732 | CM5: -0.11268939 | CN5: 0.22348856 | CO5: -0.10441917 | CP5: -0.014428224 | CQ5: -0.20723337 | CR5: -0.13486387 | CS5: 0.073007739 | CT5: -0.030218378 | CU5: -0.28688917 | CV5: 0.23073054 | CW5: 0.091075699 | CX5: -0.12248573 | CY5: 0.078381925 | CZ5: -0.045950104 | DA5: 0.082670165 | DB5: 0.14934927 | DC5: -0.047798705 | DD5: -0.16451346 | DE5: -0.11056835 | DF5: 0.057416867 | DG5: -0.21489022 | DH5: 0.062997155 | DI5: 0.067721109 | DJ5: 0.11880208 | DK5: 0.0072827306 | DL5: 0.071320599 | DM5: 0.021021901 | DN5: -0.030403224 | DO5: -0.096949657 | DP5: -0.23067649 | DQ5: 0.23818431 | DR5: 0.0035748752 | DS5: 0.13395562 | DT5: 0.1151061 | DU5: 0.10407979 | DV5: -0.054611063 | DW5: -0.033290194 | DX5: 0.055094917 | DY5: 0.068793773 | DZ5: 0.014480773 | EA5: -0.29313654 | EB5: -0.14097502 | EC5: -0.012209362 | ED5: 0.058167688 | EE5: -0.14440301 | EF5: 0.0067710154
A6: 選絕對值最大 | C6: {=MATCH(MAX(ABS(C3:C5)), ABS(C3:C5), 0)} -> 2 | D6: {=MATCH(MAX(ABS(D3:D5)), ABS(D3:D5), 0)} -> 2 | E6: {=MATCH(MAX(ABS(E3:E5)), ABS(E3:E5), 0)} -> 2 | F6: {=MATCH(MAX(ABS(F3:F5)), ABS(F3:F5), 0)} -> 3 | G6: {=MATCH(MAX(ABS(G3:G5)), ABS(G3:G5), 0)} -> 3 | H6: {=MATCH(MAX(ABS(H3:H5)), ABS(H3:H5), 0)} -> 2 | I6: {=MATCH(MAX(ABS(I3:I5)), ABS(I3:I5), 0)} -> 1 | J6: {=MATCH(MAX(ABS(J3:J5)), ABS(J3:J5), 0)} -> 1 | ... EE6: {=MATCH(MAX(ABS(EE3:EE5)), ABS(EE3:EE5), 0)} -> 2 | EF6: 2
C7: =IF(C6=1,"bm",IF(C6=2,"size",IF(C6=3,"mom"))) -> size | D7: =IF(D6=1,"bm",IF(D6=2,"size",IF(D6=3,"mom"))) -> size | E7: =IF(E6=1,"bm",IF(E6=2,"size",IF(E6=3,"mom"))) -> size | F7: =IF(F6=1,"bm",IF(F6=2,"size",IF(F6=3,"mom"))) -> mom | G7: =IF(G6=1,"bm",IF(G6=2,"size",IF(G6=3,"mom"))) -> mom | H7: =IF(H6=1,"bm",IF(H6=2,"size",IF(H6=3,"mom"))) -> size | I7: =IF(I6=1,"bm",IF(I6=2,"size",IF(I6=3,"mom"))) -> bm | J7: =IF(J6=1,"bm",IF(J6=2,"size",IF(J6=3,"mom"))) -> bm | ... EF7: =IF(EF6=1,"bm",IF(EF6=2,"size",IF(EF6=3,"mom"))) -> size
C8: =IF(C6=1,C3,IF(C6=2,C4,IF(C6=3,C5))) -> -0.24758871 | D8: =IF(D6=1,D3,IF(D6=2,D4,IF(D6=3,D5))) -> -0.2746933 | E8: =IF(E6=1,E3,IF(E6=2,E4,IF(E6=3,E5))) -> -0.084648385 | F8: =IF(F6=1,F3,IF(F6=2,F4,IF(F6=3,F5))) -> -0.087687354 | G8: =IF(G6=1,G3,IF(G6=2,G4,IF(G6=3,G5))) -> 0.10275926 | H8: =IF(H6=1,H3,IF(H6=2,H4,IF(H6=3,H5))) -> -0.10075963 | I8: =IF(I6=1,I3,IF(I6=2,I4,IF(I6=3,I5))) -> 0.18325177 | J8: =IF(J6=1,J3,IF(J6=2,J4,IF(J6=3,J5))) -> 0.11648631 | ... EE8: =IF(EE6=1,EE3,IF(EE6=2,EE4,IF(EE6=3,EE5))) -> 0.1576776 | EF8: 0.24308
A10: 投資組合 | C10: 公司數 | D10: 964
A11: 等分 | B11: 家數 | C11: 2014/01 | D11: 2014/02 | E11: 2014/03 | F11: 2014/04 | G11: 2014/05 | H11: 2014/06 | I11: 2014/07 | J11: 2014/08 | K11: 2014/09 | L11: 2014/10 | M11: 2014/11 | N11: 2014/12 | O11: 2015/01 | P11: 2015/02 | Q11: 2015/03 | R11: 2015/04 | S11: 2015/05 | T11: 2015/06 | U11: 2015/07 | V11: 2015/08 | W11: 2015/09 | X11: 2015/10 | Y11: 2015/11 | Z11: 2015/12 | AA11: 2016/01 | AB11: 2016/02 | AC11: 2016/03 | AD11: 2016/04 | AE11: 2016/05 | AF11: 2016/06 | AG11: 2016/07 | AH11: 2016/08 | AI11: 2016/09 | AJ11: 2016/10 | AK11: 2016/11 | AL11: 2016/12 | AM11: 2017/01 | AN11: 2017/02 | AO11: 2017/03 | AP11: 2017/04 | AQ11: 2017/05 | AR11: 2017/06 | AS11: 2017/07 | AT11: 2017/08 | AU11: 2017/09 | AV11: 2017/10 | AW11: 2017/11 | AX11: 2017/12 | AY11: 2018/01 | AZ11: 2018/02 | BA11: 2018/03 | BB11: 2018/04 | BC11: 2018/05 | BD11: 2018/06 | BE11: 2018/07 | BF11: 2018/08 | BG11: 2018/09 | BH11: 2018/10 | BI11: 2018/11 | BJ11: 2018/12 | BK11: 2019/01 | BL11: 2019/02 | BM11: 2019/03 | BN11: 2019/04 | BO11: 2019/05 | BP11: 2019/06 | BQ11: 2019/07 | BR11: 2019/08 | BS11: 2019/09 | BT11: 2019/10 | BU11: 2019/11 | BV11: 2019/12 | BW11: 2020/01 | BX11: 2020/02 | BY11: 2020/03 | BZ11: 2020/04 | CA11: 2020/05 | CB11: 2020/06 | CC11: 2020/07 | CD11: 2020/08 | CE11: 2020/09 | CF11: 2020/10 | CG11: 2020/11 | CH11: 2020/12 | CI11: 2021/01 | CJ11: 2021/02 | CK11: 2021/03 | CL11: 2021/04 | CM11: 2021/05 | CN11: 2021/06 | CO11: 2021/07 | CP11: 2021/08 | CQ11: 2021/09 | CR11: 2021/10 | CS11: 2021/11 | CT11: 2021/12 | CU11: 2022/01 | CV11: 2022/02 | CW11: 2022/03 | CX11: 2022/04 | CY11: 2022/05 | CZ11: 2022/06 | DA11: 2022/07 | DB11: 2022/08 | DC11: 2022/09 | DD11: 2022/10 | DE11: 2022/11 | DF11: 2022/12 | DG11: 2023/01 | DH11: 2023/02 | DI11: 2023/03 | DJ11: 2023/04 | DK11: 2023/05 | DL11: 2023/06 | DM11: 2023/07 | DN11: 2023/08 | DO11: 2023/09 | DP11: 2023/10 | DQ11: 2023/11 | DR11: 2023/12 | DS11: 2024/01 | DT11: 2024/02 | DU11: 2024/03 | DV11: 2024/04 | DW11: 2024/05 | DX11: 2024/06 | DY11: 2024/07 | DZ11: 2024/08 | EA11: 2024/09 | EB11: 2024/10 | EC11: 2024/11 | ED11: 2024/12 | EE11: 2025/01 | EF11: 2025/02
A12: 10 | B12: 96 | C12: 0.084653347 | D12: 0.11468863 | E12: 0.048026823 | F12: 0.055959385 | G12: 0.031947449 | H12: 0.038530512 | I12: 0.038097115 | J12: 0.043784579 | K12: 0.029187998 | L12: 0.041890941 | M12: 0.026889174 | N12: 0.069326987 | O12: 0.027914759 | P12: 0.019809765 | Q12: 0.033792784 | R12: 0.012898174 | S12: 0.075752807 | T12: 0.047867716 | U12: 0.020200814 | V12: 0.044098373 | W12: 0.064039415 | X12: 0.10964075 | Y12: 0.016788377 | Z12: 0.064919358 | AA12: 0.026918479 | AB12: 0.03460426 | AC12: 0.046772946 | AD12: 0.011230799 | AE12: 0.046437717 | AF12: 0.052012103 | AG12: 0.03061844 | AH12: 0.01309686 | AI12: 0.023246459 | AJ12: 0.0074902167 | AK12: 0.047354662 | AL12: 0.034105621 | AM12: 0.032204354 | AN12: 0.070370866 | AO12: 0.014995471 | AP12: 0.033728996 | AQ12: 0.0066823428 | AR12: 0.0075044281 | AS12: 0.019976273 | AT12: 0.072195382 | AU12: 0.063410262 | AV12: 0.053715631 | AW12: 0.017169705 | AX12: 0.044696012 | AY12: 0.024483354 | AZ12: 0.066563803 | BA12: 0.071276156 | BB12: 0.029036655 | BC12: 0.026690966 | BD12: 0.049233622 | BE12: 0.035368545 | BF12: 0.067616949 | BG12: 0.046757754 | BH12: 0.035079589 | BI12: 0.051439927 | BJ12: 0.043422499 | BK12: 0.020075652 | BL12: 0.032129098 | BM12: 0.050305685 | BN12: 0.019502538 | BO12: 0.02424631 | BP12: 0.026421957 | BQ12: 0.01520658 | BR12: 0.068693615 | BS12: 0.032642855 | BT12: 0.021288097 | BU12: 0.04808337 | BV12: 0.042282389 | BW12: 0.044477004 | BX12: 0.015984152 | BY12: 0.058929916 | BZ12: 0.045004028 | CA12: 0.030447774 | CB12: 0.072475876 | CC12: 0.065566613 | CD12: 0.11093363 | CE12: 0.15400701 | CF12: 0.026993353 | CG12: 0.04927796 | CH12: 0.06440264 | CI12: 0.035807413 | CJ12: 0.054120067 | CK12: 0.056101441 | CL12: 0.11801561 | CM12: 0.071708388 | CN12: 0.078465204 | CO12: 0.071292243 | CP12: 0.045040196 | CQ12: 0.062684347 | CR12: 0.057159987 | CS12: 0.00097857359 | CT12: 0.032114011 | CU12: 0.074779529 | CV12: 0.065033306 | CW12: 0.013036669 | CX12: 0.060989883 | CY12: 0.046072978 | CZ12: 0.079607283 | DA12: 0.036978661 | DB12: 0.088981816 | DC12: 0.033044377 | DD12: 0.069960546 | DE12: 0.024737644 | DF12: 0.055485734 | DG12: 0.046409818 | DH12: 0.061195155 | DI12: 0.059749068 | DJ12: 0.041378043 | DK12: 0.031928199 | DL12: 0.018669833 | DM12: 0.019237694 | DN12: 0.039228343 | DO12: 0.030556942 | DP12: 0.059408695 | DQ12: 0.074540647 | DR12: 0.018778943 | DS12: 0.069650552 | DT12: 0.024813842 | DU12: 0.057230283 | DV12: 0.052173184 | DW12: 0.044967834 | DX12: 0.049619207 | DY12: 0.053145311 | DZ12: 0.0061855961 | EA12: 0.11312704 | EB12: 0.030525777 | EC12: 0.02665151 | ED12: 0.056628036 | EE12: 0.026506892 | EF12: -0.039233348
A13: 20 | B13: 48 | C13: 0.10411275 | D13: 0.12374503 | E13: 0.069861556 | F13: 0.059986527 | G13: 0.012047404 | H13: 0.029989632 | I13: 0.037315684 | J13: 0.036406901 | K13: 0.060326139 | L13: 0.0060251613 | M13: 0.0032797582 | N13: 0.099806917 | O13: 0.017422699 | P13: 0.021104073 | Q13: 0.040198198 | R13: 0.016841702 | S13: 0.1229153 | T13: 0.074234082 | U13: 0.055957471 | V13: 0.05398777 | W13: 0.075476562 | X13: 0.12112777 | Y13: 0.023265061 | Z13: 0.073529553 | AA13: 0.047712648 | AB13: 0.04678235 | AC13: 0.0667717 | AD13: 0.02154369 | AE13: 0.077071417 | AF13: 0.073281161 | AG13: 0.031681783 | AH13: 0.011340352 | AI13: 0.01990991 | AJ13: -0.018507844 | AK13: 0.065987913 | AL13: 0.022550358 | AM13: 0.045764675 | AN13: 0.10533024 | AO13: -0.0017088467 | AP13: 0.05953822 | AQ13: 0.011082994 | AR13: -0.0092507325 | AS13: 0.023404964 | AT13: 0.086422915 | AU13: 0.076784334 | AV13: 0.079665976 | AW13: 0.026821238 | AX13: 0.032799832 | AY13: 0.015767643 | AZ13: 0.055449776 | BA13: 0.07982912 | BB13: 0.022547401 | BC13: 0.019110867 | BD13: 0.041676314 | BE13: 0.043773789 | BF13: 0.12165714 | BG13: 0.088397546 | BH13: 0.041023656 | BI13: 0.05278812 | BJ13: 0.051451919 | BK13: 0.025125773 | BL13: 0.03446004 | BM13: 0.053371769 | BN13: -0.0041015372 | BO13: 0.031735312 | BP13: 0.0079511464 | BQ13: 0.040819097 | BR13: 0.079831457 | BS13: 0.040180514 | BT13: 0.03366777 | BU13: 0.074658168 | BV13: 0.079930834 | BW13: 0.075714006 | BX13: 0.0014774348 | BY13: 0.039201957 | BZ13: 0.076927871 | CA13: 0.033531566 | CB13: 0.12042697 | CC13: 0.12011817 | CD13: 0.10549188 | CE13: 0.18382784 | CF13: 0.046939453 | CG13: 0.058014968 | CH13: 0.058334612 | CI13: 0.051853509 | CJ13: 0.054810181 | CK13: 0.065687126 | CL13: 0.084304391 | CM13: 0.10145222 | CN13: 0.10099417 | CO13: 0.085566239 | CP13: 0.070797472 | CQ13: 0.071178865 | CR13: 0.11164489 | CS13: 0.0095676537 | CT13: 0.043462268 | CU13: 0.10709096 | CV13: 0.077656051 | CW13: 0.03630912 | CX13: 0.060643762 | CY13: 0.064973825 | CZ13: 0.05722422 | DA13: 0.049446034 | DB13: 0.10623532 | DC13: 0.029740185 | DD13: 0.068977059 | DE13: 0.022441996 | DF13: 0.083122187 | DG13: 0.047729084 | DH13: 0.088720601 | DI13: 0.089748564 | DJ13: 0.0070211236 | DK13: 0.019386634 | DL13: 0.022050691 | DM13: -0.00053162261 | DN13: 0.014839798 | DO13: 0.037863465 | DP13: 0.058032309 | DQ13: 0.085310357 | DR13: 0.013771209 | DS13: 0.068596853 | DT13: 0.029845809 | DU13: 0.033006159 | DV13: 0.079620144 | DW13: 0.042028686 | DX13: 0.064641919 | DY13: 0.056981339 | DZ13: 0.018302124 | EA13: 0.12446896 | EB13: 0.057205293 | EC13: 0.041659753 | ED13: 0.065682094 | EE13: 0.041234384 | EF13: -0.067291157
A14: 50 | B14: 19 | C14: 0.11994149 | D14: 0.22230845 | E14: 0.098768248 | F14: 0.060341905 | G14: 0.05365663 | H14: 0.059587806 | I14: 0.04378736 | J14: 0.018612181 | K14: 0.050827466 | L14: 0.0084804476 | M14: -0.019021714 | N14: 0.20483258 | O14: 0.0014944079 | P14: 0.058345922 | Q14: 0.12456768 | R14: -0.015941187 | S14: 0.16589323 | T14: 0.035019555 | U14: 0.11019253 | V14: 0.024435027 | W14: 0.11616579 | X14: 0.1866857 | Y14: 0.0017560181 | Z14: 0.038511926 | AA14: 0.099905879 | AB14: 0.067753923 | AC14: -0.0030865623 | AD14: 0.039327892 | AE14: 0.11683692 | AF14: 0.096080095 | AG14: 0.01849082 | AH14: -0.0033462742 | AI14: 0.010964571 | AJ14: 0.015059036 | AK14: 0.066326746 | AL14: 0.018559542 | AM14: 0.068283273 | AN14: 0.092260489 | AO14: -0.038044353 | AP14: 0.069976525 | AQ14: 0.0081284167 | AR14: -0.018170823 | AS14: -0.0066693384 | AT14: 0.07940348 | AU14: 0.13785248 | AV14: 0.066258749 | AW14: 0.053928681 | AX14: 0.019370213 | AY14: 0.015068119 | AZ14: 0.025628928 | BA14: 0.096337325 | BB14: 0.11031125 | BC14: -0.028505683 | BD14: 0.043496923 | BE14: 0.07008177 | BF14: 0.15382926 | BG14: 0.12530531 | BH14: 0.073413464 | BI14: 0.052014236 | BJ14: 0.024016934 | BK14: -0.033237382 | BL14: 0.059996896 | BM14: 0.046278325 | BN14: -0.045371706 | BO14: 0.033609046 | BP14: -0.050332283 | BQ14: 0.012049423 | BR14: 0.10005242 | BS14: 0.030332724 | BT14: -0.015287928 | BU14: 0.11115945 | BV14: 0.10798163 | BW14: 0.13089751 | BX14: -0.00030713422 | BY14: -0.04260449 | BZ14: 0.11178052 | CA14: 0.024465266 | CB14: 0.1644655 | CC14: 0.12059616 | CD14: 0.09801671 | CE14: 0.1705553 | CF14: 0.095391142 | CG14: 0.057320664 | CH14: 0.064661392 | CI14: 0.10588478 | CJ14: 0.017796116 | CK14: 0.053792087 | CL14: 0.062269955 | CM14: 0.11006897 | CN14: 0.17459567 | CO14: 0.17324915 | CP14: 0.099809331 | CQ14: 0.0322279 | CR14: 0.20771971 | CS14: -0.0044126335 | CT14: 0.061872352 | CU14: 0.101545 | CV14: 0.15139684 | CW14: 0.044763884 | CX14: 0.032764329 | CY14: 0.050137743 | CZ14: 0.064063563 | DA14: 0.065393327 | DB14: 0.10460744 | DC14: 0.027534093 | DD14: 0.079205352 | DE14: 0.062526924 | DF14: 0.20156284 | DG14: 0.045583396 | DH14: 0.058741194 | DI14: 0.086646448 | DJ14: 0.0087940294 | DK14: 0.08162155 | DL14: 0.040754872 | DM14: 0.0011211497 | DN14: 0.039851708 | DO14: 0.10259219 | DP14: 0.062914808 | DQ14: 0.071172565 | DR14: 0.052622519 | DS14: 0.05605182 | DT14: 0.0077542903 | DU14: 0.068795273 | DV14: 0.10826235 | DW14: 0.0018093095 | DX14: 0.10216122 | DY14: 0.0742587 | DZ14: 0.035031 | EA14: 0.062912685 | EB14: 0.078179831 | EC14: 0.0060793821 | ED14: 0.10262971 | EE14: -0.0033992535 | EF14: -0.066632347
A15: 100 | B15: 10 | C15: 0.22764466 | D15: 0.37270922 | E15: 0.066038487 | F15: -0.034921437 | G15: 0.034403921 | H15: 0.1188437 | I15: 0.058431444 | J15: 0.049961465 | K15: 0.094514798 | L15: -0.012967085 | M15: -0.0021330164 | N15: 0.33030934 | O15: -0.012270796 | P15: 0.064116183 | Q15: 0.15553684 | R15: -0.05212969 | S15: 0.27023205 | T15: 0.045891077 | U15: 0.13696806 | V15: -0.017131853 | W15: 0.10693456 | X15: 0.21118633 | Y15: -0.011689718 | Z15: 0.046719972 | AA15: 0.16085038 | AB15: 0.066775214 | AC15: 0.0043176688 | AD15: 0.039690481 | AE15: 0.21179264 | AF15: 0.13772629 | AG15: 0.010123478 | AH15: -0.033604373 | AI15: 0.07427696 | AJ15: 0.00946486 | AK15: 0.057495575 | AL15: -0.0068817591 | AM15: 0.055122622 | AN15: 0.092861913 | AO15: -0.05138452 | AP15: 0.086457767 | AQ15: 0.019750987 | AR15: -0.02455082 | AS15: -0.048733221 | AT15: 0.070989813 | AU15: 0.16710843 | AV15: 0.037297929 | AW15: 0.091727473 | AX15: 0.081360566 | AY15: 0.028109416 | AZ15: 0.036847352 | BA15: 0.15768795 | BB15: 0.19771315 | BC15: -0.030936692 | BD15: 0.007362916 | BE15: 0.041397971 | BF15: 0.21087209 | BG15: 0.16605122 | BH15: 0.098649046 | BI15: 0.068586659 | BJ15: 0.075153898 | BK15: -0.072869419 | BL15: 0.059755421 | BM15: 0.048219004 | BN15: -0.066054035 | BO15: 0.027734476 | BP15: -0.051616854 | BQ15: 0.012802931 | BR15: 0.12376214 | BS15: 0.011865911 | BT15: 0.036633666 | BU15: 0.085545734 | BV15: 0.10464004 | BW15: 0.29887899 | BX15: 0.023949431 | BY15: -0.12602357 | BZ15: 0.10290647 | CA15: 0.018592021 | CB15: 0.1310914 | CC15: 0.17365171 | CD15: 0.12015208 | CE15: 0.07336812 | CF15: 0.098469994 | CG15: 0.085886022 | CH15: 0.062885958 | CI15: 0.027803072 | CJ15: 0.040671717 | CK15: 0.095640748 | CL15: 0.031421975 | CM15: 0.10811976 | CN15: 0.14314982 | CO15: 0.17335999 | CP15: 0.12753584 | CQ15: -0.02496336 | CR15: 0.18148893 | CS15: 0.0064830511 | CT15: 0.032216556 | CU15: 0.12404993 | CV15: 0.18261155 | CW15: 0.026072091 | CX15: 0.024039607 | CY15: 0.055732711 | CZ15: 0.077145074 | DA15: 0.088862212 | DB15: 0.097048242 | DC15: 0.024821107 | DD15: 0.014506726 | DE15: 0.057163635 | DF15: 0.30272045 | DG15: 0.047917485 | DH15: 0.12962194 | DI15: 0.042811767 | DJ15: 0.060023777 | DK15: 0.10032893 | DL15: -0.0003039932 | DM15: -0.0017732647 | DN15: 0.043996497 | DO15: 0.15954541 | DP15: 0.13430495 | DQ15: 0.037038689 | DR15: 0.039785608 | DS15: 0.037530144 | DT15: 0.05271879 | DU15: 0.11712765 | DV15: 0.13976836 | DW15: -0.060826326 | DX15: 0.11861625 | DY15: 0.14360957 | DZ15: 0.040455653 | EA15: 0.04345122 | EB15: 0.08808745 | EC15: 0.050736499 | ED15: 0.11335706 | EE15: 0.0031907205 | EF15: -0.062208305
A16: 107 | B16: 9 | C16: 0.20787478 | D16: 0.40819498 | E16: 0.065006577 | F16: -0.078715472 | G16: 0.0081465507 | H16: 0.072848056 | I16: 0.057530619 | J16: 0.046709926 | K16: 0.086420892 | L16: -0.031027151 | M16: -0.013987436 | N16: 0.36698761 | O16: -0.028587077 | P16: 0.061045232 | Q16: 0.15790307 | R16: -0.048990978 | S16: 0.2854546 | T16: 0.038406673 | U16: 0.13006247 | V16: -0.0060221453 | W16: 0.078373488 | X16: 0.24053196 | Y16: -0.020180588 | Z16: 0.043057931 | AA16: 0.16615889 | AB16: 0.074985042 | AC16: -0.012765448 | AD16: 0.034811172 | AE16: 0.20962824 | AF16: 0.14791561 | AG16: 0.013290753 | AH16: -0.0317654 | AI16: 0.090522649 | AJ16: -0.0070259661 | AK16: 0.064421401 | AL16: -0.014472512 | AM16: 0.066076731 | AN16: 0.1064562 | AO16: -0.041090153 | AP16: 0.077798368 | AQ16: 0.024036054 | AR16: -0.03249276 | AS16: -0.052642718 | AT16: 0.12256404 | AU16: 0.17023589 | AV16: 0.052080835 | AW16: 0.10898494 | AX16: 0.10062133 | AY16: 0.03381259 | AZ16: 0.046826876 | BA16: 0.1599907 | BB16: 0.22547356 | BC16: -0.038999392 | BD16: 0.0062821844 | BE16: 0.061197644 | BF16: 0.24778686 | BG16: 0.16122957 | BH16: 0.096162035 | BI16: 0.05233576 | BJ16: 0.081428119 | BK16: -0.1047732 | BL16: 0.061173599 | BM16: 0.039497985 | BN16: -0.06719797 | BO16: 0.02189036 | BP16: -0.057750061 | BQ16: 0.013312454 | BR16: 0.13058297 | BS16: 0.032006987 | BT16: 0.038066078 | BU16: 0.10153657 | BV16: 0.036585638 | BW16: 0.31797083 | BX16: 0.024078272 | BY16: -0.13255841 | BZ16: 0.11152585 | CA16: 0.017116104 | CB16: 0.13930874 | CC16: 0.044388153 | CD16: 0.15507127 | CE16: 0.09361423 | CF16: 0.10520126 | CG16: 0.061727878 | CH16: 0.041697415 | CI16: 0.038709882 | CJ16: 0.029703385 | CK16: 0.08842269 | CL16: 0.019995369 | CM16: 0.11305584 | CN16: 0.16035992 | CO16: 0.20954752 | CP16: 0.13761382 | CQ16: -0.02033378 | CR16: 0.18928653 | CS16: 0.040852188 | CT16: 0.048903526 | CU16: 0.1354717 | CV16: 0.17225152 | CW16: 0.047341659 | CX16: 0.012240285 | CY16: 0.058554306 | CZ16: 0.10263326 | DA16: 0.11818133 | DB16: 0.098017283 | DC16: 0.035357719 | DD16: 0.03174371 | DE16: 0.0345524 | DF16: 0.32557955 | DG16: 0.045676915 | DH16: 0.13714776 | DI16: 0.058505683 | DJ16: 0.070955052 | DK16: 0.096254625 | DL16: -0.021872874 | DM16: -0.038134996 | DN16: 0.042437853 | DO16: 0.16959095 | DP16: 0.16033399 | DQ16: 0.047070156 | DR16: 0.055191252 | DS16: 0.021440673 | DT16: 0.059112975 | DU16: 0.12277205 | DV16: 0.13695373 | DW16: -0.071302574 | DX16: 0.12528471 | DY16: 0.15757213 | DZ16: 0.058810748 | EA16: 0.00042051524 | EB16: 0.1006791 | EC16: 0.051117652 | ED16: 0.11541675 | EE16: 0.0043966753 | EF16: -0.039893907
A17: 120 | B17: 8 | C17: 0.20609219 | D17: 0.43958849 | E17: 0.079589849 | F17: -0.080752164 | G17: 0.10538707 | H17: 0.10499405 | I17: 0.11372503 | J17: 0.041858395 | K17: 0.10156008 | L17: -0.03377593 | M17: 0.014659142 | N17: 0.40510801 | O17: -0.011306676 | P17: 0.068410774 | Q17: 0.16180129 | R17: -0.052057609 | S17: 0.31065343 | T17: 0.023342586 | U17: 0.1417559 | V17: 0.0040111898 | W17: 0.079141989 | X17: 0.23798943 | Y17: -0.022928011 | Z17: 0.053763711 | AA17: 0.19128344 | AB17: 0.084852063 | AC17: -0.020086255 | AD17: 0.068619823 | AE17: 0.2221227 | AF17: 0.12028632 | AG17: 0.031873573 | AH17: -0.049437542 | AI17: 0.11486445 | AJ17: -0.042602631 | AK17: 0.031812486 | AL17: -0.0099837333 | AM17: 0.075369368 | AN17: 0.11328712 | AO17: -0.076694528 | AP17: 0.077242814 | AQ17: 0.0092339935 | AR17: -0.034997281 | AS17: -0.058802957 | AT17: 0.12707179 | AU17: 0.17756203 | AV17: 0.058529449 | AW17: 0.07618961 | AX17: 0.097619105 | AY17: 0.027423697 | AZ17: 0.047980434 | BA17: 0.16280641 | BB17: 0.23044204 | BC17: -0.027292824 | BD17: 0.019411872 | BE17: 0.044110253 | BF17: 0.14777683 | BG17: 0.18575158 | BH17: 0.13319111 | BI17: 0.099365392 | BJ17: 0.089191478 | BK17: -0.11481579 | BL17: 0.034152447 | BM17: 0.029059011 | BN17: -0.073656768 | BO17: 0.019886081 | BP17: -0.060638147 | BQ17: 0.01137651 | BR17: 0.11502235 | BS17: 0.020906018 | BT17: 0.033647573 | BU17: 0.1045243 | BV17: 0.038240957 | BW17: 0.20833683 | BX17: 0.0072009503 | BY17: -0.14247738 | BZ17: 0.12057816 | CA17: 0.027934832 | CB17: 0.14963316 | CC17: 0.041760252 | CD17: 0.17295974 | CE17: 0.095708074 | CF17: 0.098746197 | CG17: 0.074714989 | CH17: 0.058636447 | CI17: 0.014531185 | CJ17: 0.020950827 | CK17: 0.083955848 | CL17: -0.0094263448 | CM17: 0.095493871 | CN17: 0.17653128 | CO17: 0.19808042 | CP17: 0.14815927 | CQ17: 0.051907103 | CR17: 0.19640263 | CS17: 0.031345818 | CT17: 0.058653797 | CU17: 0.15535189 | CV17: 0.15147138 | CW17: 0.063393219 | CX17: 0.010772395 | CY17: 0.059497952 | CZ17: 0.12424884 | DA17: 0.094496399 | DB17: 0.10427163 | DC17: 0.043363469 | DD17: 0.029155421 | DE17: 0.024124863 | DF17: 0.35222555 | DG17: 0.047210988 | DH17: 0.1634318 | DI17: 0.07018239 | DJ17: 0.12892506 | DK17: 0.10278127 | DL17: -0.0039297317 | DM17: -0.042563609 | DN17: 0.035489033 | DO17: 0.17976293 | DP17: 0.14203416 | DQ17: 0.072654005 | DR17: 0.055884815 | DS17: 0.037354089 | DT17: 0.059811935 | DU17: 0.12949296 | DV17: 0.1177654 | DW17: -0.076598913 | DX17: 0.12953898 | DY17: 0.1072829 | DZ17: 0.049212629 | EA17: -0.0046325242 | EB17: 0.10728533 | EC17: 0.016425217 | ED17: 0.12832444 | EE17: -0.00019352115 | EF17: -0.047709767
A18: 137 | B18: 7 | C18: 0.18975112 | D18: 0.40188368 | E18: 0.05343935 | F18: -0.11938296 | G18: 0.10831637 | H18: 0.12853956 | I18: 0.13550018 | J18: 0.043411516 | K18: 0.13564789 | L18: -0.04667272 | M18: 0.029051464 | N18: 0.46182002 | O18: 0.031737941 | P18: 0.080174184 | Q18: 0.18897542 | R18: -0.069734027 | S18: 0.38373263 | T18: 0.052309698 | U18: 0.13249502 | V18: 0.012895135 | W18: 0.07729628 | X18: 0.21512106 | Y18: -0.019232334 | Z18: 0.089234363 | AA18: 0.17257066 | AB18: 0.088397637 | AC18: 0.0013654205 | AD18: 0.096285845 | AE18: 0.25839135 | AF18: 0.15054364 | AG18: 0.01574367 | AH18: -0.040197461 | AI18: 0.11808573 | AJ18: -0.047393756 | AK18: -0.002187481 | AL18: -0.00085555505 | AM18: 0.066643405 | AN18: 0.07929464 | AO18: 0.02458428 | AP18: 0.078278592 | AQ18: -0.016785142 | AR18: -0.061694524 | AS18: -0.083253128 | AT18: 0.16638581 | AU18: 0.19665973 | AV18: 0.060235665 | AW18: 0.097766862 | AX18: 0.12606434 | AY18: 0.034783279 | AZ18: 0.066341276 | BA18: 0.16410614 | BB18: 0.31745743 | BC18: 0.027942051 | BD18: 0.02027514 | BE18: 0.091172853 | BF18: 0.16498649 | BG18: 0.14671397 | BH18: 0.13789827 | BI18: 0.10900001 | BJ18: 0.099531519 | BK18: -0.073455627 | BL18: 0.055787881 | BM18: 0.028081356 | BN18: -0.078208699 | BO18: 0.020227496 | BP18: -0.062463432 | BQ18: 0.0019167841 | BR18: 0.12096182 | BS18: 0.032873257 | BT18: 0.013299151 | BU18: 0.11146155 | BV18: 0.039624426 | BW18: 0.2183755 | BX18: -0.015811924 | BY18: -0.087465268 | BZ18: 0.15331999 | CA18: 0.016076544 | CB18: 0.10684606 | CC18: 0.10466062 | CD18: 0.19371682 | CE18: 0.077260395 | CF18: 0.069437751 | CG18: 0.091609256 | CH18: 0.16265705 | CI18: 0.044565986 | CJ18: -0.0037723665 | CK18: 0.096058032 | CL18: -0.030989545 | CM18: 0.10276961 | CN18: 0.12094313 | CO18: 0.22828209 | CP18: 0.16283911 | CQ18: 0.038242676 | CR18: 0.19372241 | CS18: 0.057690649 | CT18: 0.076870227 | CU18: 0.14456482 | CV18: 0.12702227 | CW18: 0.066558574 | CX18: 0.061560186 | CY18: 0.071432459 | CZ18: 0.13284286 | DA18: 0.078358631 | DB18: 0.11811472 | DC18: 0.036408781 | DD18: 0.041014187 | DE18: 0.038420587 | DF18: 0.36669201 | DG18: 0.054770484 | DH18: 0.19240138 | DI18: 0.097963127 | DJ18: 0.14619608 | DK18: 0.10652726 | DL18: -0.0038302741 | DM18: -0.058457164 | DN18: -0.016722064 | DO18: 0.22032021 | DP18: 0.13348647 | DQ18: 0.065749458 | DR18: 0.076840655 | DS18: 0.011277982 | DT18: 0.022601035 | DU18: 0.15871482 | DV18: 0.10564061 | DW18: -0.06863695 | DX18: 0.15360298 | DY18: 0.13683311 | DZ18: 0.054630374 | EA18: -0.0047382972 | EB18: 0.10996435 | EC18: 0.0058228475 | ED18: 0.12007743 | EE18: 0.0011112877 | EF18: -0.048955017
A19: 160 | B19: 6 | C19: 0.19660027 | D19: 0.40752071 | E19: 0.044403932 | F19: -0.17768866 | G19: 0.096065972 | H19: 0.17761032 | I19: 0.13465433 | J19: 0.035429585 | K19: 0.23878941 | L19: -0.030362833 | M19: -0.043690236 | N19: 0.53237404 | O19: 0.031561874 | P19: 0.092534186 | Q19: 0.19013406 | R19: -0.090299091 | S19: 0.16657057 | T19: 0.051464717 | U19: 0.11376447 | V19: 0.036618688 | W19: 0.072415569 | X19: 0.14939987 | Y19: -0.029467236 | Z19: 0.091619111 | AA19: 0.1318329 | AB19: 0.099241927 | AC19: 0.014141543 | AD19: 0.095993378 | AE19: 0.30849286 | AF19: 0.16883058 | AG19: 0.027942319 | AH19: -0.042845934 | AI19: 0.091548663 | AJ19: -0.05154529 | AK19: 0.0075520425 | AL19: -0.0011362622 | AM19: 0.031311425 | AN19: 0.083568294 | AO19: 0.055890126 | AP19: 0.08757412 | AQ19: -0.054925492 | AR19: -0.074616898 | AS19: -0.10919888 | AT19: 0.18459366 | AU19: 0.23884424 | AV19: -0.0030326096 | AW19: 0.1366934 | AX19: 0.2241238 | AY19: 0.02952897 | AZ19: 0.084032472 | BA19: 0.18699678 | BB19: 0.36416093 | BC19: 0.18457179 | BD19: -7.3706968e-05 | BE19: 0.089480722 | BF19: 0.14180943 | BG19: 0.15330875 | BH19: 0.14049691 | BI19: 0.12779863 | BJ19: 0.051819308 | BK19: -0.097038423 | BL19: 0.063164534 | BM19: 0.031786265 | BN19: -0.08141326 | BO19: 0.025728961 | BP19: -0.012410341 | BQ19: 0.0099340445 | BR19: 0.13683924 | BS19: -0.0034999319 | BT19: -0.013193669 | BU19: 0.12418649 | BV19: 0.030350792 | BW19: 0.30745301 | BX19: -0.03639889 | BY19: -0.079866927 | BZ19: 0.063815394 | CA19: 0.02154569 | CB19: 0.12783821 | CC19: 0.022506233 | CD19: 0.2070858 | CE19: 0.088474859 | CF19: 0.084971509 | CG19: 0.057117625 | CH19: 0.15288987 | CI19: 0.037066946 | CJ19: -0.011811923 | CK19: 0.11879726 | CL19: -0.04324028 | CM19: 0.11023588 | CN19: 0.14319321 | CO19: 0.25123563 | CP19: 0.1590326 | CQ19: 0.032394608 | CR19: 0.17630672 | CS19: 0.05425045 | CT19: 0.026421201 | CU19: 0.14660754 | CV19: 0.094553008 | CW19: 0.060515879 | CX19: 0.093549718 | CY19: 0.073151337 | CZ19: 0.10046473 | DA19: 0.075182477 | DB19: 0.14796185 | DC19: -0.0351794 | DD19: 0.0062011253 | DE19: 0.033018415 | DF19: 0.20550175 | DG19: 0.066374265 | DH19: 0.22458978 | DI19: 0.10846144 | DJ19: 0.16525047 | DK19: 0.12144231 | DL19: -0.011982786 | DM19: -0.057300431 | DN19: -0.0041776448 | DO19: 0.24926195 | DP19: 0.17026813 | DQ19: 0.080374172 | DR19: 0.075962353 | DS19: -0.0056773135 | DT19: 0.0050332465 | DU19: 0.15058192 | DV19: 0.11953184 | DW19: -0.10129597 | DX19: 0.13836513 | DY19: 0.13924868 | DZ19: 0.078537948 | EA19: 0.032919727 | EB19: 0.10875351 | EC19: -0.0086215225 | ED19: 0.15093532 | EE19: -0.0073065267 | EF19: -0.016977955
A20: 192 | B20: 5 | C20: 0.20155105 | D20: 0.38202502 | E20: 0.05733635 | F20: -0.20553126 | G20: 0.11718314 | H20: 0.14393228 | I20: 0.15814956 | J20: 0.06672115 | K20: 0.2147245 | L20: -0.030695483 | M20: -0.077718228 | N20: 0.50001148 | O20: 0.049864886 | P20: 0.091169928 | Q20: 0.20756771 | R20: -0.10925306 | S20: 0.16233623 | T20: 0.085465456 | U20: 0.12232904 | V20: 0.012644103 | W20: 0.091084869 | X20: 0.21038641 | Y20: -0.04206749 | Z20: 0.10561696 | AA20: 0.13048337 | AB20: 0.084759841 | AC20: 0.047248263 | AD20: 0.12984342 | AE20: 0.16122121 | AF20: 0.22349782 | AG20: 0.027659219 | AH20: -0.090178201 | AI20: 0.11633676 | AJ20: -0.061990035 | AK20: -0.013595115 | AL20: -0.0056166264 | AM20: 0.033095981 | AN20: 0.075470194 | AO20: 0.049108295 | AP20: 0.13173046 | AQ20: 0.072900746 | AR20: -0.013289273 | AS20: -0.042291716 | AT20: 0.23912375 | AU20: 0.28169787 | AV20: -0.032246613 | AW20: 0.22499784 | AX20: 0.20433922 | AY20: 0.038674698 | AZ20: 0.099804303 | BA20: 0.15133773 | BB20: 0.37844679 | BC20: 0.24014067 | BD20: 0.0083601734 | BE20: 0.098278375 | BF20: 0.13797126 | BG20: 0.094062056 | BH20: 0.1500573 | BI20: 0.13174527 | BJ20: 0.055155921 | BK20: -0.11765037 | BL20: 0.069859442 | BM20: 0.047468551 | BN20: 0.018638027 | BO20: -0.038461718 | BP20: 0.0072822475 | BQ20: 0.015451707 | BR20: 0.18112708 | BS20: -0.032536198 | BT20: -0.052467623 | BU20: 0.149441 | BV20: -0.081543442 | BW20: 0.35182955 | BX20: -0.052861422 | BY20: -0.0046393591 | BZ20: 0.090271404 | CA20: 0.0019938221 | CB20: 0.12649505 | CC20: 0.012915147 | CD20: 0.1810275 | CE20: 0.085778173 | CF20: 0.080957937 | CG20: 0.075970241 | CH20: 0.071864026 | CI20: 0.030394674 | CJ20: -0.041509985 | CK20: 0.080589624 | CL20: -0.092184934 | CM20: 0.096775806 | CN20: 0.20489183 | CO20: 0.29657331 | CP20: 0.19203121 | CQ20: 0.023118045 | CR20: 0.19548611 | CS20: 0.097137099 | CT20: 0.028414407 | CU20: 0.14672801 | CV20: 0.11921413 | CW20: 0.067903708 | CX20: 0.090298551 | CY20: 0.10873284 | CZ20: 0.15516165 | DA20: 0.077081697 | DB20: 0.07696807 | DC20: -0.047084133 | DD20: 0.0035971848 | DE20: 0.010418722 | DF20: 0.24557421 | DG20: 0.052344813 | DH20: 0.27829885 | DI20: 0.13759576 | DJ20: 0.13655809 | DK20: 0.08518754 | DL20: -0.019465373 | DM20: -0.069336107 | DN20: 0.058019207 | DO20: 0.25800136 | DP20: 0.20015543 | DQ20: 0.057460182 | DR20: 0.07851266 | DS20: -0.0074906958 | DT20: -0.029685339 | DU20: 0.17637517 | DV20: 0.12934547 | DW20: -0.10354617 | DX20: 0.15386633 | DY20: 0.12159146 | DZ20: 0.090199646 | EA20: -0.0059255993 | EB20: 0.082407142 | EC20: 0.034049581 | ED20: 0.17691886 | EE20: -0.0017409798 | EF20: -0.020281417
A21: 241 | B21: 4 | C21: 0.21462958 | D21: 0.12638792 | E21: -0.01369017 | F21: -0.18403858 | G21: 0.14384215 | H21: 0.16216409 | I21: 0.14725561 | J21: 0.060435326 | K21: 0.20688003 | L21: 0.0050291533 | M21: -0.099684593 | N21: 0.58489126 | O21: 0.034351989 | P21: 0.1447726 | Q21: 0.25731007 | R21: -0.10583571 | S21: 0.12859029 | T21: 0.098461673 | U21: 0.086278418 | V21: 0.053557619 | W21: 0.12449862 | X21: 0.21363094 | Y21: -0.020833083 | Z21: 0.11787203 | AA21: 0.11063591 | AB21: 0.12814324 | AC21: 0.018827737 | AD21: 0.12882467 | AE21: 0.12810498 | AF21: 0.29514426 | AG21: 0.044302778 | AH21: -0.10758136 | AI21: 0.10212368 | AJ21: -0.070405342 | AK21: -0.030643434 | AL21: 0.019780814 | AM21: 0.064856978 | AN21: 0.11195606 | AO21: 0.085567775 | AP21: 0.062390554 | AQ21: 0.067199966 | AR21: 0.047988141 | AS21: -0.045406682 | AT21: 0.26483826 | AU21: 0.34648126 | AV21: -0.068713913 | AW21: 0.26325492 | AX21: 0.2177183 | AY21: 0.047021291 | AZ21: 0.10850236 | BA21: 0.13959268 | BB21: 0.40443143 | BC21: 0.16446053 | BD21: 0.038219147 | BE21: 0.13674536 | BF21: 0.19911722 | BG21: 0.092285572 | BH21: 0.10684211 | BI21: 0.1659696 | BJ21: 0.022394062 | BK21: -0.072723115 | BL21: 0.08734079 | BM21: 0.040795286 | BN21: 0.025790766 | BO21: -0.010668392 | BP21: -0.0041808023 | BQ21: 0.054542231 | BR21: 0.14206146 | BS21: -0.065741821 | BT21: -0.060820743 | BU21: 0.17073851 | BV21: -0.04433998 | BW21: 0.18446067 | BX21: -0.077165003 | BY21: -0.055666292 | BZ21: 0.09815671 | CA21: 0.024556069 | CB21: 0.20786985 | CC21: -0.0080189543 | CD21: 0.28805606 | CE21: 0.061514882 | CF21: 0.13126568 | CG21: 0.085085335 | CH21: 0.080100321 | CI21: 0.080499616 | CJ21: -0.055140849 | CK21: 0.06715963 | CL21: -0.21045238 | CM21: 0.11623182 | CN21: 0.080851509 | CO21: 0.33548376 | CP21: 0.22270006 | CQ21: 0.022912194 | CR21: 0.23905997 | CS21: 0.061269036 | CT21: 0.047993104 | CU21: 0.15891662 | CV21: 0.15433184 | CW21: 0.038345517 | CX21: 0.10212218 | CY21: 0.10250516 | CZ21: 0.23745137 | DA21: 0.041709064 | DB21: 0.071461214 | DC21: -0.038546271 | DD21: 0.0028187944 | DE21: 0.028977737 | DF21: 0.30115021 | DG21: 0.059409519 | DH21: 0.081436188 | DI21: 0.17983983 | DJ21: 0.15660572 | DK21: 0.090895591 | DL21: -0.012736992 | DM21: -0.024988802 | DN21: 0.061960781 | DO21: 0.3316268 | DP21: 0.22901989 | DQ21: 0.070422699 | DR21: 0.050170859 | DS21: -0.0016720947 | DT21: -0.0052151903 | DU21: 0.14861472 | DV21: 0.14027598 | DW21: -0.10353449 | DX21: 0.18596621 | DY21: 0.16673097 | DZ21: 0.098930574 | EA21: -0.035066457 | EB21: 0.026302194 | EC21: 0.0030649685 | ED21: 0.054498856 | EE21: 0.021310592 | EF21: 0.0079916029
A22: 321 | B22: 3 | C22: 0.2052803 | D22: 0.14242785 | E22: -0.017355099 | F22: -0.067831061 | G22: 0.10388436 | H22: 0.12417806 | I22: 0.12349317 | J22: 0.052598589 | K22: 0.24536591 | L22: -0.014273209 | M22: -0.074100059 | N22: 0.75614344 | O22: -0.0067158783 | P22: 0.072782884 | Q22: 0.27677689 | R22: -0.036628434 | S22: 0.16964656 | T22: 0.12881242 | U22: 0.11059002 | V22: 0.038286777 | W22: 0.15804775 | X22: 0.22178676 | Y22: -0.015732208 | Z22: 0.075548269 | AA22: 0.082524426 | AB22: 0.13443621 | AC22: 0.085776461 | AD22: 0.013572789 | AE22: 0.13082384 | AF22: 0.42991677 | AG22: 0.05284154 | AH22: -0.10586596 | AI22: 0.11100371 | AJ22: -0.031699849 | AK22: 0.10128856 | AL22: -0.0094397385 | AM22: 0.084088903 | AN22: 0.11113281 | AO22: 0.15815288 | AP22: 0.062536354 | AQ22: 0.11013171 | AR22: 0.067924488 | AS22: 0.073843703 | AT22: 0.017728371 | AU22: 0.42935378 | AV22: -0.089753982 | AW22: 0.37079928 | AX22: -0.009875186 | AY22: 0.071733385 | AZ22: 0.1551884 | BA22: 0.049774958 | BB22: 0.51826405 | BC22: 0.19562604 | BD22: 0.079259545 | BE22: 0.12806788 | BF22: 0.19910245 | BG22: -0.041231469 | BH22: 0.12770701 | BI22: 0.11108872 | BJ22: 0.040890332 | BK22: -0.048315241 | BL22: 0.13947139 | BM22: 0.0024304832 | BN22: 0.082937899 | BO22: -0.097012896 | BP22: -0.00054100012 | BQ22: 0.027830097 | BR22: 0.10656678 | BS22: -0.09704759 | BT22: 0.088726194 | BU22: 0.10435058 | BV22: -0.048603535 | BW22: 0.13217179 | BX22: -0.1130289 | BY22: -0.05559705 | BZ22: 0.047257736 | CA22: 0.027490078 | CB22: 0.25473926 | CC22: -0.125104 | CD22: 0.33387804 | CE22: 0.066840146 | CF22: 0.18879979 | CG22: 0.20708533 | CH22: 0.11591877 | CI22: 0.11777975 | CJ22: -0.12632536 | CK22: 0.11092354 | CL22: -0.2406518 | CM22: 0.21983249 | CN22: 0.15280392 | CO22: 0.2720595 | CP22: 0.25940856 | CQ22: 0.017159616 | CR22: 0.24677277 | CS22: 0.084781936 | CT22: 0.038262615 | CU22: 0.16735391 | CV22: 0.16622268 | CW22: 0.022884042 | CX22: 0.0037495933 | CY22: 0.10451083 | CZ22: 0.26292048 | DA22: 0.032453995 | DB22: 0.054041622 | DC22: -0.03949433 | DD22: 0.031710169 | DE22: -0.017756504 | DF22: 0.38966763 | DG22: 0.071889499 | DH22: 0.081454382 | DI22: 0.060122111 | DJ22: 0.15369976 | DK22: 0.091428405 | DL22: -0.0032133307 | DM22: -0.031884709 | DN22: 0.046763328 | DO22: 0.075715816 | DP22: 0.16956243 | DQ22: 0.16540417 | DR22: -0.0060925526 | DS22: -0.036346262 | DT22: 0.027128754 | DU22: 0.16154691 | DV22: 0.12570512 | DW22: -0.081415413 | DX22: 0.22244261 | DY22: 0.11995602 | DZ22: 0.1108345 | EA22: -0.034191242 | EB22: 0.12976595 | EC22: 0.021495102 | ED22: 0.077413567 | EE22: 0.047636659 | EF22: 0.034790246
A23: 482 | B23: 2 | C23: 0.28298927 | D23: 0.25409263 | E23: 0.13300519 | F23: -0.18239608 | G23: -0.026971569 | H23: -0.018188471 | I23: 0.14815203 | J23: -0.098162291 | K23: 0.14260758 | L23: -0.050770834 | M23: -0.25844992 | N23: 0.97590144 | O23: -0.019407711 | P23: 0.090401711 | Q23: -0.059568017 | R23: -0.024313795 | S23: 0.11372453 | T23: 0.15460269 | U23: 0.093757422 | V23: -0.023029457 | W23: 0.25954732 | X23: 0.18178119 | Y23: -0.014659802 | Z23: 0.033032515 | AA23: -0.056748446 | AB23: 0.06403978 | AC23: 0.1687548 | AD23: 0.071628868 | AE23: 0.13721199 | AF23: 0.32465933 | AG23: 0.091873658 | AH23: -0.084171585 | AI23: 0.2091516 | AJ23: 0.0481956 | AK23: 0.1141111 | AL23: -0.014066593 | AM23: 0.007769489 | AN23: 0.2423147 | AO23: 0.09078248 | AP23: -0.0031210994 | AQ23: 0.099380639 | AR23: 0.14613616 | AS23: 0.081663621 | AT23: 0.1095059 | AU23: 0.60833204 | AV23: -0.049150067 | AW23: 0.58225997 | AX23: -0.014812779 | AY23: 0.17023398 | AZ23: 0.078071577 | BA23: 0.053998339 | BB23: 0.68602333 | BC23: 0.25286918 | BD23: 0.12597278 | BE23: 0.12429214 | BF23: 0.21000911 | BG23: 0.038322827 | BH23: 0.063365196 | BI23: 0.19111208 | BJ23: 0.057493861 | BK23: -0.047849323 | BL23: 0.11436629 | BM23: -0.069495462 | BN23: 0.038453237 | BO23: -0.16631017 | BP23: -0.022475721 | BQ23: 0.049611841 | BR23: 0.10282259 | BS23: -0.22056709 | BT23: 0.21818668 | BU23: 0.10568527 | BV23: -0.053269051 | BW23: 0.015362515 | BX23: -0.068735089 | BY23: 0.11824923 | BZ23: 0.0076697624 | CA23: 0.0756532 | CB23: 0.31616676 | CC23: -0.084544615 | CD23: 0.19167646 | CE23: 0.059602302 | CF23: 0.15713491 | CG23: 0.21663724 | CH23: 0.18019645 | CI23: 0.30989942 | CJ23: -0.1565159 | CK23: 0.071856391 | CL23: -0.40866101 | CM23: 0.23470497 | CN23: 0.27710426 | CO23: 0.26615854 | CP23: 0.31136074 | CQ23: -0.02470227 | CR23: 0.15099817 | CS23: 0.065159884 | CT23: 0.065390215 | CU23: 0.20210388 | CV23: 0.15333097 | CW23: -0.024186288 | CX23: -0.088716994 | CY23: 0.15375033 | CZ23: 0.18199879 | DA23: 0.064644882 | DB23: 0.018747066 | DC23: 0.11919049 | DD23: 0.092798675 | DE23: -0.060085948 | DF23: 0.40879492 | DG23: 0.067620427 | DH23: 0.13922689 | DI23: 0.096040551 | DJ23: 0.12003258 | DK23: 0.091244989 | DL23: 0.026242652 | DM23: -0.046477316 | DN23: 0.006497196 | DO23: 0.12406844 | DP23: 0.17683962 | DQ23: 0.24594611 | DR23: -0.089886003 | DS23: -0.11657599 | DT23: -0.022296457 | DU23: 0.055639479 | DV23: 0.27627161 | DW23: 0.023051821 | DX23: 0.31349321 | DY23: -0.053926225 | DZ23: -0.21717399 | EA23: -0.093362079 | EB23: 0.24428466 | EC23: -0.036584316 | ED23: 0.091425905 | EE23: 0.069212076 | EF23: 0.047782279
A24: 964 | B24: 1 | C24: 0.099113364 | D24: 0.10060991 | E24: 0.2845125 | F24: -0.20154572 | G24: -0.022622389 | H24: 0.035855797 | I24: -0.0021119332 | J24: -0.099972193 | K24: 0.050444336 | L24: -0.093799693 | M24: -0.14681934 | N24: 1.7690314 | O24: 0.036648791 | P24: 0.10424841 | Q24: -0.060964962 | R24: -0.24569737 | S24: 0.35251446 | T24: -0.27048671 | U24: 0.14851867 | V24: -0.067139303 | W24: -0.16456452 | X24: -0.036157896 | Y24: -0.0094770149 | Z24: 0.10584233 | AA24: 0.21854458 | AB24: 0.19533962 | AC24: 0.40174733 | AD24: 0.1011753 | AE24: 0.19314179 | AF24: 0.49538941 | AG24: 0.13873572 | AH24: -0.05669736 | AI24: 0.31041424 | AJ24: -0.080891244 | AK24: 0.084883953 | AL24: 0.087173701 | AM24: -0.018919281 | AN24: 0.22118947 | AO24: 0.1029057 | AP24: 0.022851715 | AQ24: 0.2171272 | AR24: 0.17083341 | AS24: 0.0032867737 | AT24: 0.15076898 | AU24: 0.47705419 | AV24: 0.24768466 | AW24: -0.14871096 | AX24: 0.11149134 | AY24: 0.16812729 | AZ24: 0.11862373 | BA24: 0.050491305 | BB24: 0.87270315 | BC24: -0.0043668696 | BD24: 0.018631034 | BE24: -0.057380538 | BF24: -0.064370421 | BG24: -0.090984228 | BH24: 0.14767357 | BI24: 0.22362911 | BJ24: 0.19964003 | BK24: -0.034827647 | BL24: 0.10610692 | BM24: 0.08478294 | BN24: 0.10891326 | BO24: -0.16110969 | BP24: 0.031794104 | BQ24: -0.064169633 | BR24: 0.098920889 | BS24: -0.12162104 | BT24: 0.27671902 | BU24: 0.0087484923 | BV24: -0.046258706 | BW24: 0.15102745 | BX24: -0.10395503 | BY24: 0.11840823 | BZ24: 0.2588929 | CA24: 0.11522168 | CB24: 0.63969813 | CC24: -0.18246988 | CD24: 0.032392267 | CE24: 0.16556487 | CF24: 0.22172136 | CG24: 0.51996897 | CH24: 0.3542773 | CI24: -0.32845182 | CJ24: -0.30018689 | CK24: 0.32305927 | CL24: 0.14175533 | CM24: 0.63643326 | CN24: 0.6096772 | CO24: 0.45247744 | CP24: 0.28781577 | CQ24: -0.16018965 | CR24: 0.13778746 | CS24: 0.10797424 | CT24: -0.11954439 | CU24: 0.052729045 | CV24: 0.18286409 | CW24: -0.23499322 | CX24: 0.055207194 | CY24: 0.32114775 | CZ24: 0.11220663 | DA24: 0.033979585 | DB24: -0.016501866 | DC24: 0.1944536 | DD24: -0.19584472 | DE24: 0.13158559 | DF24: 0.52558501 | DG24: 0.11954529 | DH24: 0.26580268 | DI24: 0.037184908 | DJ24: 0.22936987 | DK24: 0.11968018 | DL24: 0.061360513 | DM24: -0.00041344525 | DN24: 0.23333457 | DO24: 0.11561196 | DP24: 0.22357182 | DQ24: 0.3590713 | DR24: -0.02051563 | DS24: -0.067362546 | DT24: -0.029435726 | DU24: -0.021781395 | DV24: 0.1582247 | DW24: 0.1011825 | DX24: 0.31159313 | DY24: -0.0032398766 | DZ24: -0.43350658 | EA24: -0.023171502 | EB24: 0.58969792 | EC24: -0.014309919 | ED24: 0.056172845 | EE24: 0.10748066 | EF24: -0.067276677
A25: 大盤 | B25: TWⅡ | C25: -0.017446771 | D25: 0.020701061 | E25: 0.023982129 | F25: -0.006557579 | G25: 0.03184513 | H25: 0.034348533 | I25: -0.0082549328 | J25: 0.012843524 | K25: -0.051018525 | L25: 0.00087394274 | M25: 0.023389576 | N25: 0.012988972 | O25: 0.0058545887 | P25: 0.027413207 | Q25: -0.0037129361 | R25: 0.024076614 | S25: -0.012190025 | T25: -0.039749578 | U25: -0.07315545 | V25: -0.05826023 | W25: 0.00077279757 | X25: 0.044591521 | Y25: -0.02769968 | Z25: 0.0020950059 | AA25: -0.023400551 | AB25: 0.032129371 | AC25: 0.038903273 | AD25: -0.042865382 | AE25: 0.018647195 | AF25: 0.015229768 | AG25: 0.036016604 | AH25: 0.0093546114 | AI25: 0.010748251 | AJ25: 0.013357754 | AK25: -0.0053327473 | AL25: 0.0013831358 | AM25: 0.020795928 | AN25: 0.031517702 | AO25: 0.0062417165 | AP25: 0.0061452617 | AQ25: 0.016946358 | AR25: 0.03468283 | AS25: 0.0030985886 | AT25: 0.015081347 | AU25: -0.019251209 | AV25: 0.038711513 | AW25: -0.021856951 | AX25: 0.0077743007 | AY25: 0.042397247 | AZ25: -0.026308975 | BA25: 0.0095717493 | BB25: -0.024249741 | BC25: 0.020163374 | BD25: -0.0035049988 | BE25: 0.020151935 | BF25: 0.00058133623 | BG25: -0.005219701 | BH25: -0.11587176 | BI25: 0.0087252257 | BJ25: -0.016377261 | BK25: 0.020840372 | BL25: 0.044975872 | BM25: 0.023954306 | BN25: 0.030239101 | BO25: -0.043725888 | BP25: 0.02188947 | BQ25: 0.0086274303 | BR25: -0.019192954 | BS25: 0.01973513 | BT25: 0.047694337 | BU25: 0.011454817 | BV25: 0.043228621 | BW25: -0.04274743 | BX25: -0.017811292 | BY25: -0.1511531 | BZ25: 0.124224 | CA25: -0.0045572538 | CB25: 0.06021124 | CC25: 0.085992033 | CD25: -0.0058084796 | CE25: -0.006041347 | CF25: 0.0024523244 | CG25: 0.089636252 | CH25: 0.070992733 | CI25: 0.027170643 | CJ25: 0.052468428 | CK25: 0.029480661 | CL25: 0.066825081 | CM25: -0.028772229 | CN25: 0.039462516 | CO25: -0.029031087 | CP25: 0.013983883 | CQ25: -0.032276965 | CR25: 0.0031035766 | CS25: 0.025591856 | CT25: 0.044391886 | CU25: -0.030338959 | CV25: -0.0012579765 | CW25: 0.0023363565 | CX25: -0.064264145 | CY25: 0.012909779 | CZ25: -0.12547709 | DA25: 0.011690683 | DB25: 0.0063378437 | DC25: -0.11730536 | DD25: -0.036010872 | DE25: 0.1389113 | DF25: -0.051143506 | DG25: 0.076731447 | DH25: 0.015508782 | DI25: 0.023223774 | DJ25: -0.018372876 | DK25: 0.062199014 | DL25: 0.020098304 | DM25: 0.01349894 | DN25: -0.030252213 | DO25: -0.017022836 | DP25: -0.021788523 | DQ25: 0.085745625 | DR25: 0.028106744 | DS25: -0.0023031598 | DT25: 0.058471198 | DU25: 0.067658949 | DV25: 0.0050207706 | DW25: 0.037416184 | DX25: 0.084111004 | DY25: -0.036832399 | DZ25: 0.0030917028 | EA25: -0.0019576282 | EB25: 0.026459104 | EC25: -0.024752539 | ED25: 0.034115491 | EE25: 0.021061974 | EF25: -0.020277393

Sheet 預測IC
A1: Predict
B2: Time | C2: 2013/12 | D2: 2014/01 | E2: 2014/02 | F2: 2014/03 | G2: 2014/04 | H2: 2014/05 | I2: 2014/06 | J2: 2014/07 | K2: 2014/08 | L2: 2014/09 | M2: 2014/10 | N2: 2014/11 | O2: 2014/12 | P2: 2015/01 | Q2: 2015/02 | R2: 2015/03 | S2: 2015/04 | T2: 2015/05 | U2: 2015/06 | V2: 2015/07 | W2: 2015/08 | X2: 2015/09 | Y2: 2015/10 | Z2: 2015/11 | AA2: 2015/12 | AB2: 2016/01 | AC2: 2016/02 | AD2: 2016/03 | AE2: 2016/04 | AF2: 2016/05 | AG2: 2016/06 | AH2: 2016/07 | AI2: 2016/08 | AJ2: 2016/09 | AK2: 2016/10 | AL2: 2016/11 | AM2: 2016/12 | AN2: 2017/01 | AO2: 2017/02 | AP2: 2017/03 | AQ2: 2017/04 | AR2: 2017/05 | AS2: 2017/06 | AT2: 2017/07 | AU2: 2017/08 | AV2: 2017/09 | AW2: 2017/10 | AX2: 2017/11 | AY2: 2017/12 | AZ2: 2018/01 | BA2: 2018/02 | BB2: 2018/03 | BC2: 2018/04 | BD2: 2018/05 | BE2: 2018/06 | BF2: 2018/07 | BG2: 2018/08 | BH2: 2018/09 | BI2: 2018/10 | BJ2: 2018/11 | BK2: 2018/12 | BL2: 2019/01 | BM2: 2019/02 | BN2: 2019/03 | BO2: 2019/04 | BP2: 2019/05 | BQ2: 2019/06 | BR2: 2019/07 | BS2: 2019/08 | BT2: 2019/09 | BU2: 2019/10 | BV2: 2019/11 | BW2: 2019/12 | BX2: 2020/01 | BY2: 2020/02 | BZ2: 2020/03 | CA2: 2020/04 | CB2: 2020/05 | CC2: 2020/06 | CD2: 2020/07 | CE2: 2020/08 | CF2: 2020/09 | CG2: 2020/10 | CH2: 2020/11 | CI2: 2020/12 | CJ2: 2021/01 | CK2: 2021/02 | CL2: 2021/03 | CM2: 2021/04 | CN2: 2021/05 | CO2: 2021/06 | CP2: 2021/07 | CQ2: 2021/08 | CR2: 2021/09 | CS2: 2021/10 | CT2: 2021/11 | CU2: 2021/12 | CV2: 2022/01 | CW2: 2022/02 | CX2: 2022/03 | CY2: 2022/04 | CZ2: 2022/05 | DA2: 2022/06 | DB2: 2022/07 | DC2: 2022/08 | DD2: 2022/09 | DE2: 2022/10 | DF2: 2022/11 | DG2: 2022/12 | DH2: 2023/01 | DI2: 2023/02 | DJ2: 2023/03 | DK2: 2023/04 | DL2: 2023/05 | DM2: 2023/06 | DN2: 2023/07 | DO2: 2023/08 | DP2: 2023/09 | DQ2: 2023/10 | DR2: 2023/11 | DS2: 2023/12 | DT2: 2024/01 | DU2: 2024/02 | DV2: 2024/03 | DW2: 2024/04 | DX2: 2024/05 | DY2: 2024/06 | DZ2: 2024/07 | EA2: 2024/08 | EB2: 2024/09 | EC2: 2024/10 | ED2: 2024/11 | EE2: 2024/12 | EF2: 2025/01
B3: bm | C3: 0.073912658 | D3: 0.075634934 | E3: 0.053515486 | F3: 0.061629988 | G3: 0.050796419 | H3: 0.035059132 | I3: 0.090367138 | J3: 0.065266319 | K3: -0.012474539 | L3: 0.07754764 | M3: 0.064441182 | N3: 0.04651219 | O3: 0.067610271 | P3: -0.025644939 | Q3: 0.033374421 | R3: 0.057588164 | S3: -0.03419546 | T3: 0.058177851 | U3: 0.038116455 | V3: -0.0055063977 | W3: 0.058136616 | X3: 0.05687042 | Y3: 0.059794772 | Z3: 0.01319172 | AA3: 0.066306375 | AB3: 0.058820508 | AC3: 0.057617776 | AD3: 0.036969934 | AE3: 0.078433976 | AF3: 0.043248169 | AG3: 0.055671927 | AH3: 0.016907433 | AI3: 0.037138056 | AJ3: 0.039113328 | AK3: 0.042720824 | AL3: 0.027467238 | AM3: 0.053318277 | AN3: 0.1098325 | AO3: 0.019733673 | AP3: 0.036758669 | AQ3: 0.05132718 | AR3: 0.053256318 | AS3: 0.054331318 | AT3: 0.043143794 | AU3: 0.038841631 | AV3: 0.055265516 | AW3: 0.050267205 | AX3: -0.060497068 | AY3: 0.056344893 | AZ3: 0.044756263 | BA3: 0.049546454 | BB3: 0.065231696 | BC3: 0.052208934 | BD3: 0.050287269 | BE3: 0.053227734 | BF3: 0.052831601 | BG3: -0.022505151 | BH3: 0.053355973 | BI3: -0.042333741 | BJ3: -0.041621774 | BK3: 0.0527323 | BL3: 0.052711453 | BM3: 0.05278958 | BN3: 0.057516374 | BO3: -0.042583652 | BP3: 0.039963931 | BQ3: 0.052070383 | BR3: 0.050181154 | BS3: 0.054154158 | BT3: 0.049134161 | BU3: 0.055349864 | BV3: 0.052839477 | BW3: 0.029234827 | BX3: 0.047284011 | BY3: -0.0042058714 | BZ3: 0.053063441 | CA3: 0.039631478 | CB3: 0.046001714 | CC3: 0.051699594 | CD3: 0.052426741 | CE3: 0.047352515 | CF3: 0.021231763 | CG3: 0.045137141 | CH3: -0.049076565 | CI3: 0.020267023 | CJ3: 0.057584956 | CK3: 0.06919612 | CL3: 0.042080969 | CM3: 0.049845971 | CN3: -0.048408799 | CO3: 0.048292059 | CP3: 0.039594132 | CQ3: 0.048842102 | CR3: 0.049500272 | CS3: 0.047897454 | CT3: 0.028369874 | CU3: 0.044375256 | CV3: 0.050530951 | CW3: 0.043176312 | CX3: 0.052143924 | CY3: 0.050900701 | CZ3: 0.042558175 | DA3: 0.044029783 | DB3: -0.04391953 | DC3: 0.051982991 | DD3: -0.0084397029 | DE3: 0.052998926 | DF3: 0.04483768 | DG3: 0.043406125 | DH3: 0.047541145 | DI3: 0.048345033 | DJ3: 0.052155863 | DK3: 0.089188196 | DL3: -0.026696257 | DM3: 0.048457604 | DN3: 0.046465918 | DO3: -0.029918596 | DP3: 0.047435947 | DQ3: 0.038500402 | DR3: 0.049186587 | DS3: 0.047889348 | DT3: 0.031652723 | DU3: 0.061842099 | DV3: 0.046563607 | DW3: 0.03281489 | DX3: 0.048260111 | DY3: -0.056952421 | DZ3: 0.033931814 | EA3: 0.048233494 | EB3: 0.0097889202 | EC3: 0.036156386 | ED3: 0.040190533 | EE3: 0.047531653 | EF3: 0.05033059
B4: size | C4: 0.010975275 | D4: -0.048196077 | E4: 0.082988262 | F4: 0.038252771 | G4: 0.050002195 | H4: 0.013410039 | I4: -0.026064049 | J4: -0.030217964 | K4: -0.033898376 | L4: -0.039842829 | M4: -0.043122668 | N4: 0.04201898 | O4: -0.034795396 | P4: -0.046467673 | Q4: -0.061648782 | R4: -0.034485668 | S4: -0.02517182 | T4: -0.037345178 | U4: 0.083096556 | V4: 0.089860611 | W4: -0.027928695 | X4: 0.082243979 | Y4: -0.07178916 | Z4: -0.030311709 | AA4: 0.036390048 | AB4: 0.038148783 | AC4: -0.024738373 | AD4: -0.09873803 | AE4: -0.044849236 | AF4: -0.044075444 | AG4: -0.029871419 | AH4: 0.016651396 | AI4: 0.027999543 | AJ4: -0.015782923 | AK4: -0.093165159 | AL4: 0.05696046 | AM4: -0.029802304 | AN4: -0.037541721 | AO4: 0.01405663 | AP4: 0.02808417 | AQ4: -0.020956615 | AR4: -0.033249192 | AS4: 0.029234178 | AT4: -0.038568161 | AU4: -0.030528501 | AV4: -0.032747496 | AW4: 0.04592634 | AX4: -0.034888666 | AY4: -0.034154564 | AZ4: 0.025950408 | BA4: -0.031192672 | BB4: -0.087475844 | BC4: 0.035330057 | BD4: -0.031129116 | BE4: -0.054915816 | BF4: -0.031478297 | BG4: -0.040066577 | BH4: 0.030623695 | BI4: -0.031123528 | BJ4: -0.030040134 | BK4: -0.041486956 | BL4: 0.039935578 | BM4: 0.018027246 | BN4: -0.10439561 | BO4: 0.0069876933 | BP4: 0.0046952195 | BQ4: 0.015195244 | BR4: -0.0073001925 | BS4: -0.043473393 | BT4: 0.0499168 | BU4: 0.034368545 | BV4: -0.042206816 | BW4: 0.040576939 | BX4: 0.11351513 | BY4: -0.060964067 | BZ4: 0.0074336347 | CA4: -0.03416634 | CB4: -0.042827509 | CC4: -0.040521652 | CD4: -0.02672508 | CE4: -0.048888609 | CF4: 0.045108072 | CG4: 0.032500137 | CH4: 0.033603519 | CI4: -0.059029229 | CJ4: -0.033231545 | CK4: 0.033614956 | CL4: -0.087717965 | CM4: -0.0078791035 | CN4: -0.031603437 | CO4: -0.024560306 | CP4: -0.024266617 | CQ4: 0.0098067364 | CR4: 0.076525658 | CS4: 0.021581039 | CT4: 0.021532454 | CU4: 0.034501176 | CV4: -0.062654153 | CW4: -0.045586068 | CX4: -0.065642618 | CY4: 0.063649572 | CZ4: -0.078583814 | DA4: -0.028124524 | DB4: -0.058803976 | DC4: -0.03196235 | DD4: -0.038284682 | DE4: 0.048030544 | DF4: -0.029363507 | DG4: 0.060822789 | DH4: -0.028199369 | DI4: -0.029792106 | DJ4: -0.030000817 | DK4: 0.01032027 | DL4: -0.042281743 | DM4: -0.048086602 | DN4: -0.019423993 | DO4: -0.040470425 | DP4: -0.034404326 | DQ4: -0.027822113 | DR4: -0.028454494 | DS4: -0.069464684 | DT4: -0.028235232 | DU4: 0.053089391 | DV4: -0.027063906 | DW4: -0.024401028 | DX4: 0.0027264939 | DY4: 0.043977614 | DZ4: -0.024560714 | EA4: -0.047766272 | EB4: -0.041742835 | EC4: -0.028310522 | ED4: -0.024022842 | EE4: 0.11009948 | EF4: -0.029047638
