Workbook

Sheet 預測IC
A1: Predict
B2: Time | C2: 2013/12 | D2: 2014/01 | E2: 2014/02 | F2: 2014/03 | G2: 2014/04 | H2: 2014/05 | I2: 2014/06 | J2: 2014/07 | K2: 2014/08 | L2: 2014/09 | M2: 2014/10 | N2: 2014/11 | O2: 2014/12 | P2: 2015/01 | Q2: 2015/02 | R2: 2015/03 | S2: 2015/04 | T2: 2015/05 | U2: 2015/06 | V2: 2015/07 | W2: 2015/08 | X2: 2015/09 | Y2: 2015/10 | Z2: 2015/11 | AA2: 2015/12 | AB2: 2016/01 | AC2: 2016/02 | AD2: 2016/03 | AE2: 2016/04 | AF2: 2016/05 | AG2: 2016/06 | AH2: 2016/07 | AI2: 2016/08 | AJ2: 2016/09 | AK2: 2016/10 | AL2: 2016/11 | AM2: 2016/12 | AN2: 2017/01 | AO2: 2017/02 | AP2: 2017/03 | AQ2: 2017/04 | AR2: 2017/05 | AS2: 2017/06 | AT2: 2017/07 | AU2: 2017/08 | AV2: 2017/09 | AW2: 2017/10 | AX2: 2017/11 | AY2: 2017/12 | AZ2: 2018/01 | BA2: 2018/02 | BB2: 2018/03 | BC2: 2018/04 | BD2: 2018/05 | BE2: 2018/06 | BF2: 2018/07 | BG2: 2018/08 | BH2: 2018/09 | BI2: 2018/10 | BJ2: 2018/11 | BK2: 2018/12 | BL2: 2019/01 | BM2: 2019/02 | BN2: 2019/03 | BO2: 2019/04 | BP2: 2019/05 | BQ2: 2019/06 | BR2: 2019/07 | BS2: 2019/08 | BT2: 2019/09 | BU2: 2019/10 | BV2: 2019/11 | BW2: 2019/12 | BX2: 2020/01 | BY2: 2020/02 | BZ2: 2020/03 | CA2: 2020/04 | CB2: 2020/05 | CC2: 2020/06 | CD2: 2020/07 | CE2: 2020/08 | CF2: 2020/09 | CG2: 2020/10 | CH2: 2020/11 | CI2: 2020/12 | CJ2: 2021/01 | CK2: 2021/02 | CL2: 2021/03 | CM2: 2021/04 | CN2: 2021/05 | CO2: 2021/06 | CP2: 2021/07 | CQ2: 2021/08 | CR2: 2021/09 | CS2: 2021/10 | CT2: 2021/11 | CU2: 2021/12 | CV2: 2022/01 | CW2: 2022/02 | CX2: 2022/03 | CY2: 2022/04 | CZ2: 2022/05 | DA2: 2022/06 | DB2: 2022/07 | DC2: 2022/08 | DD2: 2022/09 | DE2: 2022/10 | DF2: 2022/11 | DG2: 2022/12 | DH2: 2023/01 | DI2: 2023/02 | DJ2: 2023/03 | DK2: 2023/04 | DL2: 2023/05 | DM2: 2023/06 | DN2: 2023/07 | DO2: 2023/08 | DP2: 2023/09 | DQ2: 2023/10 | DR2: 2023/11 | DS2: 2023/12 | DT2: 2024/01 | DU2: 2024/02 | DV2: 2024/03 | DW2: 2024/04 | DX2: 2024/05 | DY2: 2024/06 | DZ2: 2024/07 | EA2: 2024/08 | EB2: 2024/09 | EC2: 2024/10 | ED2: 2024/11 | EE2: 2024/12 | EF2: 2025/01
B3: mom1 | C3: -0.0050384004 | D3: -0.012982815 | E3: -0.010905372 | F3: -0.0090158785 | G3: -0.0060204379 | H3: -0.018698066 | I3: -0.0049066145 | J3: 0.0012918142 | K3: 0.00059455601 | L3: -0.011971912 | M3: 0.00032288061 | N3: -0.0055110823 | O3: -0.011571469 | P3: -0.0042707395 | Q3: -0.002585418 | R3: -0.0053758063 | S3: -0.0028573336 | T3: -0.0069081392 | U3: -0.017014472 | V3: -0.0068304003 | W3: -0.0075049394 | X3: -0.0055569894 | Y3: -0.003867389 | Z3: -0.017428128 | AA3: -0.021725257 | AB3: -0.014340517 | AC3: -0.010365822 | AD3: -0.0034166214 | AE3: -0.0026355409 | AF3: -0.0071940156 | AG3: -0.0078610431 | AH3: -0.0084817388 | AI3: -0.0041172003 | AJ3: -0.0067360574 | AK3: -0.0016369971 | AL3: 0.00063693085 | AM3: -0.0044438165 | AN3: -0.0067233412 | AO3: 0.0049092075 | AP3: -0.0099909323 | AQ3: -0.014523536 | AR3: -0.0074150467 | AS3: -0.0059951026 | AT3: -0.0098077395 | AU3: -0.017088845 | AV3: -0.003013282 | AW3: 0.00087869254 | AX3: -0.0046179607 | AY3: -0.0033321956 | AZ3: -0.001500955 | BA3: -0.0034575463 | BB3: -0.010498895 | BC3: -0.0051382106 | BD3: -0.021838724 | BE3: -0.0097871538 | BF3: -0.00058077246 | BG3: -0.012396786 | BH3: -0.0074127544 | BI3: -0.0045557318 | BJ3: -0.011958173 | BK3: -0.0018365866 | BL3: -0.018712995 | BM3: -0.0019598092 | BN3: -0.0025534203 | BO3: -0.0049689199 | BP3: -0.01846295 | BQ3: -0.0084846057 | BR3: -0.0036388494 | BS3: -0.0054235401 | BT3: -0.0045689212 | BU3: -0.0077200763 | BV3: -0.007709292 | BW3: -0.0093445853 | BX3: -0.0014007349 | BY3: -0.011918208 | BZ3: -0.0083605041 | CA3: -0.0092630256 | CB3: 0.0081894825 | CC3: -0.0055994646 | CD3: -0.0081125504 | CE3: -0.0032252267 | CF3: -0.0091363272 | CG3: -0.0088645598 | CH3: -0.006788903 | CI3: 0.00027426207 | CJ3: 0.001499354 | CK3: -0.0078035199 | CL3: 0.010773722 | CM3: 0.0021381454 | CN3: 0.0070234475 | CO3: -0.016374706 | CP3: 0.0026612966 | CQ3: -0.0069274973 | CR3: -0.0045786682 | CS3: -0.0022040928 | CT3: -0.0037487094 | CU3: -0.0068773436 | CV3: 0.0009305448 | CW3: -0.01753823 | CX3: 0.00084356201 | CY3: 0.0042074168 | CZ3: -0.011305243 | DA3: -0.003258377 | DB3: 0.0014579092 | DC3: -0.0010265697 | DD3: 0.00071923354 | DE3: -0.031574928 | DF3: -0.02900289 | DG3: 0.00019130541 | DH3: -0.019153641 | DI3: -0.010576016 | DJ3: -0.0072497294 | DK3: -0.012830264 | DL3: -0.0087598248 | DM3: -0.0031057547 | DN3: -0.00077136146 | DO3: -0.00021247696 | DP3: -0.0085086976 | DQ3: -0.0061453363 | DR3: -0.0097976817 | DS3: -0.0010223566 | DT3: -0.00048198579 | DU3: -0.0038046229 | DV3: -0.002438854 | DW3: -0.0015941463 | DX3: 0.00034250873 | DY3: -0.0082488262 | DZ3: -0.0030599626 | EA3: -0.017228669 | EB3: -0.0066960271 | EC3: -0.0052121475 | ED3: -0.013153678 | EE3: -0.015124477 | EF3: -0.022053516
B4: mom12 | C4: 0.0061805661 | D4: 0.014805526 | E4: -0.0063244807 | F4: -0.0079034822 | G4: -0.0033440484 | H4: -0.01101097 | I4: 0.015573878 | J4: 0.007475631 | K4: -0.0044361147 | L4: -0.0085491171 | M4: -0.00098816579 | N4: -0.00098074365 | O4: 0.0087049367 | P4: 0.0051573093 | Q4: 0.022002689 | R4: 0.022104577 | S4: 0.018312178 | T4: 0.01862907 | U4: -0.00036948299 | V4: 0.0068269073 | W4: 0.001793762 | X4: -0.00027396904 | Y4: 0.031389569 | Z4: 0.0013355061 | AA4: -0.013008816 | AB4: 0.011004889 | AC4: 0.0092102957 | AD4: 0.0069286006 | AE4: 0.015564112 | AF4: 7.4439375e-05 | AG4: 0.0096905661 | AH4: -0.0054139333 | AI4: 0.0033298477 | AJ4: -0.003613181 | AK4: 0.013251079 | AL4: 0.0016193999 | AM4: 0.0058764556 | AN4: 0.0071891321 | AO4: 0.0091288765 | AP4: 0.00047242239 | AQ4: 0.001566021 | AR4: 0.0045222049 | AS4: 0.0052112039 | AT4: 0.00018593994 | AU4: 0.0011950427 | AV4: 0.0046712661 | AW4: 0.0096185679 | AX4: 0.0043414187 | AY4: 0.0018494369 | AZ4: -0.0050989745 | BA4: 0.00048981787 | BB4: 0.0019753757 | BC4: -0.0045793677 | BD4: -0.026436807 | BE4: -0.016424344 | BF4: -0.01389668 | BG4: -0.0078428179 | BH4: -0.0040440655 | BI4: 0.0016071736 | BJ4: -0.024063681 | BK4: -0.0028710062 | BL4: -0.016793677 | BM4: -0.0021961696 | BN4: 0.00084385606 | BO4: -0.0039948739 | BP4: -0.015462627 | BQ4: -0.0024957644 | BR4: 0.0028460561 | BS4: 0.0058091239 | BT4: 0.007046457 | BU4: 0.011460644 | BV4: 0.014529665 | BW4: 0.0082729225 | BX4: 0.022582732 | BY4: -0.0068540032 | BZ4: 0.011197619 | CA4: -0.010733091 | CB4: 0.037061121 | CC4: 0.023332729 | CD4: 0.012526107 | CE4: -0.0039841657 | CF4: 0.0063542546 | CG4: -0.012186463 | CH4: 0.0029760767 | CI4: 0.013488546 | CJ4: 0.00038189341 | CK4: -0.016958527 | CL4: 0.025384703 | CM4: 0.0040789221 | CN4: -0.016004466 | CO4: -0.019050699 | CP4: 0.0063498376 | CQ4: 0.0002540617 | CR4: 0.00046990156 | CS4: 0.0066470684 | CT4: 0.013121376 | CU4: 0.011599671 | CV4: 0.0042228287 | CW4: -0.011599476 | CX4: 0.011640357 | CY4: 0.0094536567 | CZ4: -0.0049653412 | DA4: 0.0046027036 | DB4: -0.00022975167 | DC4: 0.013161642 | DD4: 0.011348779 | DE4: -0.054686295 | DF4: -0.018909393 | DG4: 0.030039816 | DH4: -0.0058266256 | DI4: -0.0005554365 | DJ4: -0.00097956152 | DK4: -0.0057354678 | DL4: -0.0020240608 | DM4: 0.0024265753 | DN4: 0.0021730263 | DO4: -0.0046409581 | DP4: -0.0010872902 | DQ4: -0.0016084314 | DR4: 0.0042340538 | DS4: 0.014086972 | DT4: 0.008165563 | DU4: 0.0068406154 | DV4: 0.0042052644 | DW4: -0.001283242 | DX4: 0.0046892574 | DY4: -0.009609026 | DZ4: 0.01040353 | EA4: -0.015616078 | EB4: 0.0011388866 | EC4: 0.002510538 | ED4: -0.0062999148 | EE4: -0.0024910423 | EF4: -0.012933196
B5: chmom | C5: -0.0092720815 | D5: -0.012857776 | E5: 0.0050942505 | F5: 0.0085959127 | G5: 0.0053014997 | H5: 0.013212647 | I5: -0.011811166 | J5: -0.0071707354 | K5: 0.0055505781 | L5: 0.0099144932 | M5: 0.00028331023 | N5: 0.0025800548 | O5: -0.005199555 | P5: -0.0037408543 | Q5: -0.021895417 | R5: -0.013699451 | S5: -0.017717268 | T5: -0.017396199 | U5: 0.004645654 | V5: -0.0041230211 | W5: 0.0038816903 | X5: 0.0039129367 | Y5: -0.022536795 | Z5: 0.0029407776 | AA5: 0.017070736 | AB5: -0.0012415279 | AC5: -0.0014445381 | AD5: -0.0030228228 | AE5: -0.013298396 | AF5: 0.0015695131 | AG5: -0.0097780724 | AH5: 0.0010465507 | AI5: -0.0023524972 | AJ5: 0.004501993 | AK5: -0.012687695 | AL5: -0.0027227414 | AM5: -0.0016490949 | AN5: -0.0055388846 | AO5: -0.0096693138 | AP5: -0.004295599 | AQ5: 0.00017039359 | AR5: 0.00076438682 | AS5: -0.0060805486 | AT5: -0.0036865001 | AU5: 0.0001699917 | AV5: -0.0043742122 | AW5: -0.0092857527 | AX5: -0.0054065033 | AY5: -0.0020943944 | AZ5: 0.0023383323 | BA5: -0.0015167799 | BB5: -0.00023004479 | BC5: 0.0046813222 | BD5: 0.022335957 | BE5: 0.010984796 | BF5: 0.0055338612 | BG5: 0.0011516194 | BH5: 0.00299804 | BI5: -0.0044338713 | BJ5: 0.018809265 | BK5: 0.0029820425 | BL5: 0.018580868 | BM5: 0.0016188369 | BN5: 0.00058849841 | BO5: 0.0039287749 | BP5: 0.016934874 | BQ5: 0.0075863615 | BR5: -0.0044105118 | BS5: -0.0046283234 | BT5: -0.0072159473 | BU5: -0.0073684819 | BV5: -0.011292048 | BW5: -0.0066560423 | BX5: -0.01927005 | BY5: 0.0045417774 | BZ5: -0.010505151 | CA5: 0.012608863 | CB5: -0.029254288 | CC5: -0.017948689 | CD5: -0.0075695618 | CE5: 0.0079314122 | CF5: -0.00087185021 | CG5: 0.015191263 | CH5: -0.001681687 | CI5: -0.011606404 | CJ5: -4.3731839e-05 | CK5: 0.014674614 | CL5: -0.024330074 | CM5: -0.0037776647 | CN5: 0.016484476 | CO5: 0.013684989 | CP5: -0.0069592722 | CQ5: -0.0015559097 | CR5: -0.0028547856 | CS5: -0.0073687036 | CT5: -0.017778716 | CU5: -0.0093386461 | CV5: -0.0045396785 | CW5: 0.0066800236 | CX5: -0.012519719 | CY5: -0.0092358196 | CZ5: 0.00059842179 | DA5: -0.010197637 | DB5: -0.0038441287 | DC5: -0.012867943 | DD5: -0.012443783 | DE5: 0.053282467 | DF5: 0.018817933 | DG5: -0.028429015 | DH5: 0.0046323768 | DI5: -0.0024300533 | DJ5: -0.0053528206 | DK5: 0.0020432779 | DL5: -0.001239401 | DM5: -0.0016056957 | DN5: -0.0055056218 | DO5: 0.0015050842 | DP5: 0.0031050877 | DQ5: 0.002203251 | DR5: 0.00091037635 | DS5: -0.01466474 | DT5: -0.010969192 | DU5: -0.0071460903 | DV5: -0.0028658716 | DW5: -0.003803095 | DX5: -0.0084604131 | DY5: 0.0056870235 | DZ5: -0.0064920241 | EA5: 0.016170038 | EB5: 0.0014241062 | EC5: -0.0027632604 | ED5: 0.010033818 | EE5: 0.0090011883 | EF5: 0.014961207
B6: retvol | C6: 0.0010365618 | D6: 0.0066521114 | E6: 0.0022295662 | F6: -1.766161e-05 | G6: 0.00028454844 | H6: 0.0019423527 | I6: 0.0032592108 | J6: 0.00078453233 | K6: 0.0045600607 | L6: -0.0039836188 | M6: 0.00043402723 | N6: -0.00058648575 | O6: 0.0061698304 | P6: 0.0083190558 | Q6: 0.006495913 | R6: 0.0018916477 | S6: 0.0083987206 | T6: 0.0058604196 | U6: 0.0015436695 | V6: -0.0015226324 | W6: 0.00027496859 | X6: 0.0040303856 | Y6: 0.011164865 | Z6: 0.0064675963 | AA6: -0.0043190572 | AB6: 0.00079480028 | AC6: -0.00081456851 | AD6: 0.0048579145 | AE6: 0.0058616713 | AF6: 0.0010715296 | AG6: 0.0071345781 | AH6: 0.0097866272 | AI6: 0.00509956 | AJ6: 0.0081399378 | AK6: 0.0079203954 | AL6: 0.006731037 | AM6: 0.0090529832 | AN6: 0.0098439336 | AO6: 0.009354239 | AP6: 0.0085892519 | AQ6: 0.0097235851 | AR6: 0.0095244476 | AS6: 0.0084421752 | AT6: 0.0067238907 | AU6: 0.0078326832 | AV6: 0.0056654966 | AW6: 0.0047531801 | AX6: 0.0038423735 | AY6: 0.0045003795 | AZ6: 0.0017770792 | BA6: 0.0044863922 | BB6: 0.0011496488 | BC6: 0.0039048943 | BD6: 0.0068554624 | BE6: 0.0088164305 | BF6: 0.0068215814 | BG6: 0.012520618 | BH6: 0.0080111027 | BI6: 0.0038977058 | BJ6: -0.0042745456 | BK6: 0.0082787122 | BL6: 0.0065072109 | BM6: -0.00031160342 | BN6: 0.0055799499 | BO6: 0.0045815764 | BP6: 0.001757179 | BQ6: 8.198685e-05 | BR6: 0.0058708017 | BS6: 0.0048898674 | BT6: 0.0052920629 | BU6: 0.0031676735 | BV6: 0.0014151762 | BW6: 0.0085040122 | BX6: 0.0089930533 | BY6: 0.0074186137 | BZ6: 0.0072171163 | CA6: 0.0043109654 | CB6: 0.013180116 | CC6: 0.0013635522 | CD6: -0.00048130176 | CE6: 0.0025209061 | CF6: 0.00092521909 | CG6: -0.0029930359 | CH6: 0.0014875187 | CI6: 0.0078156711 | CJ6: 0.0030248279 | CK6: 0.0026380929 | CL6: 0.0088059021 | CM6: 0.0026546804 | CN6: 0.0037484542 | CO6: 0.0036902186 | CP6: 0.0078041532 | CQ6: 0.0042136154 | CR6: 0.011490456 | CS6: 0.010644578 | CT6: 0.0031507449 | CU6: 0.0093705775 | CV6: 0.0087096009 | CW6: 0.0040818424 | CX6: 0.010508158 | CY6: 0.005777574 | CZ6: 0.0039967116 | DA6: 0.0033021662 | DB6: 0.010614536 | DC6: 0.0036073663 | DD6: 0.0079975775 | DE6: 0.01171888 | DF6: 0.0024863686 | DG6: 0.0052027154 | DH6: -0.00066622599 | DI6: 0.0042183204 | DJ6: 0.0015814907 | DK6: 0.005021169 | DL6: 0.0055874446 | DM6: 0.0083006791 | DN6: 0.009176946 | DO6: 0.0051272033 | DP6: 0.0053531413 | DQ6: 0.0053520426 | DR6: 0.0013938841 | DS6: 0.0085571905 | DT6: 0.0062805059 | DU6: 0.0043852674 | DV6: 0.001145335 | DW6: 0.0024908845 | DX6: 0.0057377093 | DY6: 0.003624569 | DZ6: 0.0084137107 | EA6: 0.0030418122 | EB6: 0.0058129608 | EC6: 0.0049535677 | ED6: 0.0051790384 | EE6: 0.0048989888 | EF6: 0.0040007039
B7: maxret | C7: 0.0014917848 | D7: 0.0079996726 | E7: 0.0031564047 | F7: 0.00013534023 | G7: 0.0015726956 | H7: 0.0027273104 | I7: 0.0032216566 | J7: 0.00096610315 | K7: 0.0058362784 | L7: -0.0016236712 | M7: 0.0007499539 | N7: 0.0031234252 | O7: 0.0078117801 | P7: 0.0092209321 | Q7: 0.0073350456 | R7: 0.0021512666 | S7: 0.0083843131 | T7: 0.0061020087 | U7: 0.0014106756 | V7: 0.002121932 | W7: 0.0034750936 | X7: 0.0075520234 | Y7: 0.017980268 | Z7: 0.006617734 | AA7: -0.0012658169 | AB7: 0.0057039934 | AC7: 0.0024839612 | AD7: 0.0063527978 | AE7: 0.0075925081 | AF7: 0.0012535418 | AG7: 0.0083354666 | AH7: 0.012147769 | AI7: 0.005271774 | AJ7: 0.0078663083 | AK7: 0.0082739699 | AL7: 0.0068478737 | AM7: 0.0094179226 | AN7: 0.0096283692 | AO7: 0.0098073359 | AP7: 0.0091857468 | AQ7: 0.010895578 | AR7: 0.010779411 | AS7: 0.0080887485 | AT7: 0.0051173109 | AU7: 0.0072203256 | AV7: 0.0068563013 | AW7: 0.0043445866 | AX7: 0.0041279269 | AY7: 0.0033536434 | AZ7: -0.00014037916 | BA7: 0.0037561688 | BB7: 0.001236216 | BC7: 0.0014850211 | BD7: 0.0058227717 | BE7: 0.0097621619 | BF7: 0.0089479636 | BG7: 0.012626909 | BH7: 0.0095790369 | BI7: 0.0052433517 | BJ7: 0.0031748873 | BK7: 0.011618256 | BL7: 0.0070376649 | BM7: 0.0027773971 | BN7: 0.0085288626 | BO7: 0.006811223 | BP7: 0.0016943462 | BQ7: 0.003179325 | BR7: 0.0043176395 | BS7: 0.0052824075 | BT7: 0.0073995529 | BU7: 0.0037632426 | BV7: 0.0015867019 | BW7: 0.0090971268 | BX7: 0.008666527 | BY7: 0.0085413875 | BZ7: 0.0086097645 | CA7: 0.011139788 | CB7: 0.014182078 | CC7: 0.0041010817 | CD7: 0.0016684855 | CE7: 0.0051884226 | CF7: 0.0040941868 | CG7: -0.0017765709 | CH7: 0.0016839595 | CI7: 0.0075110402 | CJ7: 0.0030715062 | CK7: 0.0030286212 | CL7: 0.010344176 | CM7: 0.0034492366 | CN7: 0.0053918087 | CO7: 0.0050706762 | CP7: 0.01060964 | CQ7: 0.0057362488 | CR7: 0.013543009 | CS7: 0.013073755 | CT7: 0.0080472446 | CU7: 0.012295213 | CV7: 0.010097023 | CW7: 0.0070038168 | CX7: 0.011636791 | CY7: 0.0062330931 | CZ7: 0.0075709007 | DA7: 0.0047241204 | DB7: 0.012633782 | DC7: 0.0086851465 | DD7: 0.0083434573 | DE7: 0.0084945844 | DF7: 0.0056886802 | DG7: 0.010435339 | DH7: 0.0014525847 | DI7: 0.0061377884 | DJ7: 0.0043229992 | DK7: 0.0056573884 | DL7: 0.004528392 | DM7: 0.0092757333 | DN7: 0.0096440967 | DO7: 0.0063500484 | DP7: 0.006097005 | DQ7: 0.0063088391 | DR7: 0.0031697806 | DS7: 0.0086103497 | DT7: 0.0085566527 | DU7: 0.0054762658 | DV7: 0.002574895 | DW7: 0.0035685977 | DX7: 0.007235424 | DY7: 0.0054886722 | DZ7: 0.010003494 | EA7: 0.003241694 | EB7: 0.0076048842 | EC7: 0.0064774156 | ED7: 0.0060798379 | EE7: 0.0079050012 | EF7: 0.0080139301
A8: 選絕對值最大 | C8: {=MATCH(MAX(ABS(C3:C7)), ABS(C3:C7), 0)} -> 3 | D8: {=MATCH(MAX(ABS(D3:D7)), ABS(D3:D7), 0)} -> 2 | E8: {=MATCH(MAX(ABS(E3:E7)), ABS(E3:E7), 0)} -> 1 | F8: {=MATCH(MAX(ABS(F3:F7)), ABS(F3:F7), 0)} -> 1 | G8: {=MATCH(MAX(ABS(G3:G7)), ABS(G3:G7), 0)} -> 1 | H8: {=MATCH(MAX(ABS(H3:H7)), ABS(H3:H7), 0)} -> 1 | I8: {=MATCH(MAX(ABS(I3:I7)), ABS(I3:I7), 0)} -> 2 | J8: {=MATCH(MAX(ABS(J3:J7)), ABS(J3:J7), 0)} -> 2 | ... EF8: {=MATCH(MAX(ABS(EF3:EF7)), ABS(EF3:EF7), 0)} -> 1
C9: =IF(C8=1,"mom1", IF(C8=2,"mom12", IF(C8=3,"chmom", IF(C8=4,"retvol", IF(C8=5,"maxret",""))))) -> chmom | D9: =IF(D8=1,"mom1", IF(D8=2,"mom12", IF(D8=3,"chmom", IF(D8=4,"retvol", IF(D8=5,"maxret",""))))) -> mom12 | E9: =IF(E8=1,"mom1", IF(E8=2,"mom12", IF(E8=3,"chmom", IF(E8=4,"retvol", IF(E8=5,"maxret",""))))) -> mom1 | F9: =IF(F8=1,"mom1", IF(F8=2,"mom12", IF(F8=3,"chmom", IF(F8=4,"retvol", IF(F8=5,"maxret",""))))) -> mom1 | G9: =IF(G8=1,"mom1", IF(G8=2,"mom12", IF(G8=3,"chmom", IF(G8=4,"retvol", IF(G8=5,"maxret",""))))) -> mom1 | H9: =IF(H8=1,"mom1", IF(H8=2,"mom12", IF(H8=3,"chmom", IF(H8=4,"retvol", IF(H8=5,"maxret",""))))) -> mom1 | I9: =IF(I8=1,"mom1", IF(I8=2,"mom12", IF(I8=3,"chmom", IF(I8=4,"retvol", IF(I8=5,"maxret",""))))) -> mom12 | J9: =IF(J8=1,"mom1", IF(J8=2,"mom12", IF(J8=3,"chmom", IF(J8=4,"retvol", IF(J8=5,"maxret",""))))) -> mom12 | ... EF9: =IF(EF8=1,"mom1", IF(EF8=2,"mom12", IF(EF8=3,"chmom", IF(EF8=4,"retvol", IF(EF8=5,"maxret",""))))) -> mom1
C10: =IF(C8=1,C3,IF(C8=2,C4,IF(C8=3,C5,IF(C8=4,C6,IF(C8=5,C7))))) -> -0.0092720815 | D10: =IF(D8=1,D3,IF(D8=2,D4,IF(D8=3,D5,IF(D8=4,D6,IF(D8=5,D7))))) -> 0.014805526 | E10: =IF(E8=1,E3,IF(E8=2,E4,IF(E8=3,E5,IF(E8=4,E6,IF(E8=5,E7))))) -> -0.010905372 | F10: =IF(F8=1,F3,IF(F8=2,F4,IF(F8=3,F5,IF(F8=4,F6,IF(F8=5,F7))))) -> -0.0090158785 | G10: =IF(G8=1,G3,IF(G8=2,G4,IF(G8=3,G5,IF(G8=4,G6,IF(G8=5,G7))))) -> -0.0060204379 | H10: =IF(H8=1,H3,IF(H8=2,H4,IF(H8=3,H5,IF(H8=4,H6,IF(H8=5,H7))))) -> -0.018698066 | I10: =IF(I8=1,I3,IF(I8=2,I4,IF(I8=3,I5,IF(I8=4,I6,IF(I8=5,I7))))) -> 0.015573878 | J10: =IF(J8=1,J3,IF(J8=2,J4,IF(J8=3,J5,IF(J8=4,J6,IF(J8=5,J7))))) -> 0.007475631 | ... EF10: =IF(EF8=1,EF3,IF(EF8=2,EF4,IF(EF8=3,EF5,IF(EF8=4,EF6,IF(EF8=5,EF7))))) -> -0.022053516
A12: 投資組合 | C12: 公司數 | D12: 964
A13: 等分 | B13: 家數 | C13: 2014/01 | D13: 2014/02 | E13: 2014/03 | F13: 2014/04 | G13: 2014/05 | H13: 2014/06 | I13: 2014/07 | J13: 2014/08 | K13: 2014/09 | L13: 2014/10 | M13: 2014/11 | N13: 2014/12 | O13: 2015/01 | P13: 2015/02 | Q13: 2015/03 | R13: 2015/04 | S13: 2015/05 | T13: 2015/06 | U13: 2015/07 | V13: 2015/08 | W13: 2015/09 | X13: 2015/10 | Y13: 2015/11 | Z13: 2015/12 | AA13: 2016/01 | AB13: 2016/02 | AC13: 2016/03 | AD13: 2016/04 | AE13: 2016/05 | AF13: 2016/06 | AG13: 2016/07 | AH13: 2016/08 | AI13: 2016/09 | AJ13: 2016/10 | AK13: 2016/11 | AL13: 2016/12 | AM13: 2017/01 | AN13: 2017/02 | AO13: 2017/03 | AP13: 2017/04 | AQ13: 2017/05 | AR13: 2017/06 | AS13: 2017/07 | AT13: 2017/08 | AU13: 2017/09 | AV13: 2017/10 | AW13: 2017/11 | AX13: 2017/12 | AY13: 2018/01 | AZ13: 2018/02 | BA13: 2018/03 | BB13: 2018/04 | BC13: 2018/05 | BD13: 2018/06 | BE13: 2018/07 | BF13: 2018/08 | BG13: 2018/09 | BH13: 2018/10 | BI13: 2018/11 | BJ13: 2018/12 | BK13: 2019/01 | BL13: 2019/02 | BM13: 2019/03 | BN13: 2019/04 | BO13: 2019/05 | BP13: 2019/06 | BQ13: 2019/07 | BR13: 2019/08 | BS13: 2019/09 | BT13: 2019/10 | BU13: 2019/11 | BV13: 2019/12 | BW13: 2020/01 | BX13: 2020/02 | BY13: 2020/03 | BZ13: 2020/04 | CA13: 2020/05 | CB13: 2020/06 | CC13: 2020/07 | CD13: 2020/08 | CE13: 2020/09 | CF13: 2020/10 | CG13: 2020/11 | CH13: 2020/12 | CI13: 2021/01 | CJ13: 2021/02 | CK13: 2021/03 | CL13: 2021/04 | CM13: 2021/05 | CN13: 2021/06 | CO13: 2021/07 | CP13: 2021/08 | CQ13: 2021/09 | CR13: 2021/10 | CS13: 2021/11 | CT13: 2021/12 | CU13: 2022/01 | CV13: 2022/02 | CW13: 2022/03 | CX13: 2022/04 | CY13: 2022/05 | CZ13: 2022/06 | DA13: 2022/07 | DB13: 2022/08 | DC13: 2022/09 | DD13: 2022/10 | DE13: 2022/11 | DF13: 2022/12 | DG13: 2023/01 | DH13: 2023/02 | DI13: 2023/03 | DJ13: 2023/04 | DK13: 2023/05 | DL13: 2023/06 | DM13: 2023/07 | DN13: 2023/08 | DO13: 2023/09 | DP13: 2023/10 | DQ13: 2023/11 | DR13: 2023/12 | DS13: 2024/01 | DT13: 2024/02 | DU13: 2024/03 | DV13: 2024/04 | DW13: 2024/05 | DX13: 2024/06 | DY13: 2024/07 | DZ13: 2024/08 | EA13: 2024/09 | EB13: 2024/10 | EC13: 2024/11 | ED13: 2024/12 | EE13: 2025/01 | EF13: 2025/02
A14: 10 | B14: 96 | C14: 0.13959368 | D14: 0.026098817 | E14: -0.004682604 | F14: -0.016570813 | G14: -0.017761266 | H14: -0.0078258652 | I14: 0.0034609078 | J14: -0.017798511 | K14: -0.0053688851 | L14: 0.0057413588 | M14: -0.01687893 | N14: 0.010384013 | O14: -0.027424116 | P14: 0.00141333 | Q14: -0.016572394 | R14: -0.018447579 | S14: 0.0029430443 | T14: -0.009310974 | U14: -0.0061156809 | V14: 0.033269366 | W14: -0.012341719 | X14: 0.087826066 | Y14: -0.056736625 | Z14: 0.010480665 | AA14: -0.0031362814 | AB14: 0.0080840819 | AC14: 0.027969384 | AD14: 0.0029859741 | AE14: -0.0041283578 | AF14: -0.003153398 | AG14: 0.015229287 | AH14: 0.021279319 | AI14: 0.0027318791 | AJ14: -0.024638124 | AK14: -0.018118877 | AL14: 0.00071975508 | AM14: -0.020908201 | AN14: 0.0073231475 | AO14: 0.017796887 | AP14: 0.034346722 | AQ14: 0.020159407 | AR14: 0.0051068641 | AS14: 0.017430919 | AT14: -0.0095214669 | AU14: 0.0096074037 | AV14: 0.0071497717 | AW14: 0.0061192954 | AX14: -0.022664982 | AY14: -0.0055687313 | AZ14: 0.0045973301 | BA14: 0.020644357 | BB14: -0.015739585 | BC14: 0.0047345581 | BD14: 0.0076378022 | BE14: -0.023567956 | BF14: 0.015353575 | BG14: 0.03123484 | BH14: -0.0084160204 | BI14: -0.0025011977 | BJ14: -0.0039331759 | BK14: 0.0032904308 | BL14: 0.03901401 | BM14: -0.009162805 | BN14: -0.008666769 | BO14: 0.012992698 | BP14: -0.015333989 | BQ14: -0.021410231 | BR14: 0.0074126194 | BS14: -0.0073076176 | BT14: 0.037841747 | BU14: 0.017198247 | BV14: 0.0037095413 | BW14: 0.028263101 | BX14: -0.0018323531 | BY14: 0.033486521 | BZ14: -0.067028525 | CA14: -0.0042270658 | CB14: 0.0021023168 | CC14: -0.013439846 | CD14: -0.042422145 | CE14: 0.026709101 | CF14: 0.029829598 | CG14: -0.009209765 | CH14: 0.054791114 | CI14: 0.0020868137 | CJ14: -0.026798593 | CK14: -0.039709268 | CL14: 0.085244194 | CM14: -0.016897212 | CN14: 0.033291273 | CO14: -0.058377196 | CP14: -0.02164836 | CQ14: -0.0093651541 | CR14: -0.0097928265 | CS14: -0.00078060548 | CT14: 0.023051297 | CU14: -0.036255162 | CV14: 0.025009646 | CW14: -0.0018550173 | CX14: -0.028180483 | CY14: 0.0016379687 | CZ14: 0.0029579296 | DA14: 0.062230098 | DB14: 0.014355773 | DC14: -0.076009512 | DD14: 0.012365868 | DE14: 0.05816202 | DF14: -0.0050099305 | DG14: 0.041851058 | DH14: 0.007845591 | DI14: 0.025231196 | DJ14: 0.033167075 | DK14: 0.018501176 | DL14: 0.018524944 | DM14: 0.041918025 | DN14: -0.030670509 | DO14: -0.003087572 | DP14: 0.012312411 | DQ14: -0.0048160804 | DR14: 0.013994229 | DS14: 0.0070283946 | DT14: 0.027106032 | DU14: 0.00017568042 | DV14: -0.025975194 | DW14: -0.037634466 | DX14: -0.0072867652 | DY14: 0.012691587 | DZ14: 0.023887646 | EA14: -0.057983778 | EB14: 0.0076601151 | EC14: -0.01770688 | ED14: -0.0047781685 | EE14: -0.015718952 | EF14: 0.042279365
A15: 20 | B15: 48 | C15: 0.19687693 | D15: 0.072917495 | E15: -0.013256517 | F15: 0.024097566 | G15: 0.0071533853 | H15: -0.0092787547 | I15: 0.018591155 | J15: -0.010730761 | K15: -0.039153014 | L15: 0.021170672 | M15: 0.001837565 | N15: -0.01233864 | O15: -0.039621483 | P15: -0.0054472915 | Q15: 0.0060860176 | R15: -0.02641954 | S15: -0.0069610133 | T15: -0.0079036622 | U15: -0.052495007 | V15: 0.040941342 | W15: 0.01120428 | X15: 0.096634324 | Y15: -0.043586753 | Z15: 0.023007701 | AA15: -0.022660493 | AB15: 0.010205391 | AC15: 0.020173681 | AD15: 0.024754826 | AE15: -0.018527981 | AF15: 0.017851011 | AG15: 0.01051079 | AH15: 0.031655609 | AI15: -0.004911231 | AJ15: -0.038529814 | AK15: -0.038225303 | AL15: -0.0056756043 | AM15: -0.013045211 | AN15: 0.01729481 | AO15: 0.038352096 | AP15: 0.054980678 | AQ15: 0.014200007 | AR15: 0.0059358125 | AS15: 0.032345053 | AT15: -0.0088300514 | AU15: 0.036281159 | AV15: 0.017008996 | AW15: -0.044457968 | AX15: -0.02469664 | AY15: -0.0044384569 | AZ15: 0.012814034 | BA15: 0.044154468 | BB15: -0.033427568 | BC15: -0.0036834097 | BD15: 0.020199466 | BE15: -0.035566667 | BF15: -0.0091838677 | BG15: 0.034769413 | BH15: -0.0098314145 | BI15: 0.036112133 | BJ15: -0.0017650476 | BK15: -0.0018256098 | BL15: 0.031121253 | BM15: -0.013740018 | BN15: -3.5930283e-05 | BO15: 0.025323941 | BP15: -0.035219689 | BQ15: -0.027625878 | BR15: -0.014855447 | BS15: -0.026762171 | BT15: 0.050933593 | BU15: -0.018285143 | BV15: 0.025376374 | BW15: 0.041905111 | BX15: -0.0084628127 | BY15: -0.019711204 | BZ15: -0.10460996 | CA15: -0.031932391 | CB15: 0.015086941 | CC15: -0.031759322 | CD15: -0.022044056 | CE15: 0.052478166 | CF15: 0.03182044 | CG15: -0.015379607 | CH15: 0.054934197 | CI15: -0.024458243 | CJ15: -0.0061914665 | CK15: -0.043815577 | CL15: 0.065087735 | CM15: -0.025640227 | CN15: 0.017339311 | CO15: -0.095041996 | CP15: 0.013045571 | CQ15: 0.0080020647 | CR15: -0.0098590499 | CS15: -0.0098019764 | CT15: 0.02999914 | CU15: -0.039338968 | CV15: 0.044401332 | CW15: -0.011683465 | CX15: -0.014373145 | CY15: -0.011132626 | CZ15: 0.00060390683 | DA15: 0.06965848 | DB15: 0.0076960615 | DC15: -0.082259931 | DD15: 0.044784809 | DE15: 0.073137257 | DF15: 0.0098069514 | DG15: 0.042540216 | DH15: 0.024831768 | DI15: 0.016559425 | DJ15: 0.020106354 | DK15: 0.015534011 | DL15: 0.033410437 | DM15: 0.045191627 | DN15: -0.028216504 | DO15: 0.0026354625 | DP15: 0.018938737 | DQ15: 0.0002104151 | DR15: 0.048104269 | DS15: 0.020006542 | DT15: 0.017377188 | DU15: -0.01169759 | DV15: -0.031639436 | DW15: -0.043314802 | DX15: -0.017494836 | DY15: 0.031754181 | DZ15: 0.028472537 | EA15: -0.04650276 | EB15: 0.035157587 | EC15: -0.033585504 | ED15: -0.046444204 | EE15: -0.011995968 | EF15: 0.046200236
A16: 50 | B16: 19 | C16: 0.3630823 | D16: 0.062201179 | E16: -0.013724385 | F16: 0.03150917 | G16: 0.020441556 | H16: 0.013522263 | I16: -0.019791156 | J16: -0.08572329 | K16: -0.041764661 | L16: 0.015876742 | M16: -0.0085675801 | N16: -0.039315753 | O16: -0.043447211 | P16: -0.0013296587 | Q16: 0.023650108 | R16: -0.052772249 | S16: -0.025081241 | T16: -0.047365598 | U16: -0.064384322 | V16: 0.083822571 | W16: 0.028316519 | X16: 0.12779865 | Y16: -0.06809406 | Z16: 0.057637898 | AA16: -0.060309841 | AB16: -0.022355649 | AC16: 0.054444415 | AD16: 0.057438047 | AE16: -0.007258045 | AF16: 0.081801274 | AG16: 0.014926616 | AH16: 0.053626233 | AI16: 0.035066941 | AJ16: -0.051816742 | AK16: -0.0041525248 | AL16: -0.046535755 | AM16: -0.0094781193 | AN16: 0.055765618 | AO16: 0.094186589 | AP16: 0.099920696 | AQ16: -0.050805168 | AR16: 0.0012297852 | AS16: 0.02703621 | AT16: 0.048790115 | AU16: 0.067695632 | AV16: 0.013733898 | AW16: -0.011039673 | AX16: -0.050981307 | AY16: 0.0026631768 | AZ16: 0.027737745 | BA16: 0.045884348 | BB16: -0.075778122 | BC16: -0.010768669 | BD16: 0.012773755 | BE16: -0.024146216 | BF16: -0.018930015 | BG16: 0.11372091 | BH16: 0.079477942 | BI16: -0.032589581 | BJ16: 0.027633016 | BK16: -0.00069484528 | BL16: 0.056804529 | BM16: -0.027617856 | BN16: -0.0030461513 | BO16: 0.027639854 | BP16: -0.03021081 | BQ16: -0.00050559146 | BR16: -0.05819949 | BS16: -0.0055107336 | BT16: 0.017843106 | BU16: -0.067283367 | BV16: 0.049970336 | BW16: 0.070527627 | BX16: 0.0057285339 | BY16: -0.015902053 | BZ16: -0.1563386 | CA16: -0.020989044 | CB16: 0.10418672 | CC16: -0.018939469 | CD16: -0.016308735 | CE16: -0.010593728 | CF16: 0.050093062 | CG16: 0.019273753 | CH16: 0.072727223 | CI16: -0.0041301239 | CJ16: -0.057972359 | CK16: -0.028418168 | CL16: 0.010754037 | CM16: -0.0091045093 | CN16: 0.051951452 | CO16: -0.25772069 | CP16: 0.063466726 | CQ16: 0.075875372 | CR16: 0.036317552 | CS16: 0.011683432 | CT16: 0.020884058 | CU16: -0.052882079 | CV16: 0.078280245 | CW16: -0.042458824 | CX16: -0.016928207 | CY16: -0.0033918997 | CZ16: 0.011173626 | DA16: 0.089709911 | DB16: -0.032418327 | DC16: -0.073101271 | DD16: 0.031441519 | DE16: 0.041191264 | DF16: -0.0059121179 | DG16: 0.043652212 | DH16: -0.0097363273 | DI16: -0.026822377 | DJ16: 0.024056978 | DK16: -0.023871846 | DL16: 0.075602361 | DM16: 0.065888566 | DN16: 0.022779566 | DO16: 0.02515654 | DP16: 0.10270409 | DQ16: -0.0053317922 | DR16: 0.013077887 | DS16: 0.047859331 | DT16: 0.0052444824 | DU16: -0.0060000535 | DV16: -0.0089001163 | DW16: -0.045234729 | DX16: -0.065065009 | DY16: 0.051806172 | DZ16: 0.019932609 | EA16: -0.020036386 | EB16: 0.036505306 | EC16: -0.012758695 | ED16: -0.10727841 | EE16: 0.020466068 | EF16: 0.055540104
A17: 100 | B17: 10 | C17: 0.50963263 | D17: 0.086134769 | E17: 0.11635929 | F17: 0.12388834 | G17: -0.041898537 | H17: 0.01672266 | I17: 0.0019031211 | J17: -0.10827989 | K17: 0.01358015 | L17: -0.030743089 | M17: -0.0019381987 | N17: 0.03883544 | O17: -0.10936427 | P17: -0.0035283862 | Q17: 0.11092724 | R17: -0.02463546 | S17: -0.038573824 | T17: -0.1191957 | U17: -0.074637877 | V17: 0.072037822 | W17: 0.031653054 | X17: 0.15961963 | Y17: -0.036213758 | Z17: 0.075771436 | AA17: -0.049234814 | AB17: -0.081263034 | AC17: -0.0078230351 | AD17: 0.1076413 | AE17: 0.06909869 | AF17: 0.1643056 | AG17: 0.030476061 | AH17: 0.091088555 | AI17: 0.059059741 | AJ17: -0.075443777 | AK17: -0.057078796 | AL17: -0.030628477 | AM17: 0.016695893 | AN17: 0.10952938 | AO17: 0.031342987 | AP17: 0.1595168 | AQ17: 0.019790077 | AR17: -0.012316999 | AS17: 0.033533257 | AT17: 0.061883131 | AU17: 0.12192409 | AV17: 0.062329574 | AW17: -0.066359577 | AX17: -0.12360124 | AY17: -0.063062893 | AZ17: 0.0038641921 | BA17: 0.058925129 | BB17: -0.064575668 | BC17: -0.059050625 | BD17: 0.0049337599 | BE17: -0.051355329 | BF17: -0.065913548 | BG17: 0.20748183 | BH17: 0.10304016 | BI17: -0.084653603 | BJ17: 0.094970026 | BK17: -0.080679031 | BL17: 0.070933493 | BM17: -0.047822373 | BN17: -0.011634892 | BO17: 0.044885188 | BP17: -0.074309656 | BQ17: -0.01393508 | BR17: -0.084186912 | BS17: -0.025477996 | BT17: 0.036163396 | BU17: -0.11559593 | BV17: 0.11357477 | BW17: 0.006529971 | BX17: -0.033894651 | BY17: -0.011734522 | BZ17: -0.2113028 | CA17: 0.010766367 | CB17: 0.16978791 | CC17: -0.076848068 | CD17: 0.010926921 | CE17: 0.026910355 | CF17: 0.058110394 | CG17: -0.034672546 | CH17: -0.015482572 | CI17: -0.061386931 | CJ17: -0.0045160924 | CK17: -0.054737817 | CL17: -0.0042775615 | CM17: 0.014141936 | CN17: 0.13090359 | CO17: -0.25772294 | CP17: -0.009237891 | CQ17: 0.14317007 | CR17: 0.014355621 | CS17: -0.013686282 | CT17: 0.012291504 | CU17: -0.0073128662 | CV17: 0.071491322 | CW17: -0.087529691 | CX17: -0.028312886 | CY17: -0.096508703 | CZ17: 0.102522 | DA17: 0.053909116 | DB17: -0.053103264 | DC17: -0.021095691 | DD17: 0.011045424 | DE17: 0.0056922538 | DF17: 0.0047468407 | DG17: 0.019375269 | DH17: 0.00061046924 | DI17: -0.070920161 | DJ17: 0.022842503 | DK17: -0.069562202 | DL17: 0.094187497 | DM17: 0.030368331 | DN17: 0.0085354151 | DO17: 0.049867111 | DP17: 0.14910843 | DQ17: -0.023520681 | DR17: 0.013175726 | DS17: 0.015657575 | DT17: -0.06450564 | DU17: -0.010863689 | DV17: 0.030822068 | DW17: -0.072424394 | DX17: -0.028167188 | DY17: -0.0044816442 | DZ17: 0.015832415 | EA17: 0.013743109 | EB17: 0.06235544 | EC17: 0.061254631 | ED17: -0.012052379 | EE17: 0.05271458 | EF17: 0.053122746
A18: 107 | B18: 9 | C18: 0.51201375 | D18: 0.098100164 | E18: 0.10490872 | F18: 0.083179582 | G18: -0.080315667 | H18: 0.040809523 | I18: -0.014943267 | J18: -0.13392275 | K18: 0.051003248 | L18: -0.04641424 | M18: 0.031926633 | N18: 0.06038545 | O18: -0.11186302 | P18: -0.0021373521 | Q18: 0.11984252 | R18: -0.022870169 | S18: -0.041951786 | T18: -0.098217945 | U18: -0.082250982 | V18: 0.060606656 | W18: 0.020143564 | X18: 0.15778417 | Y18: -0.039654899 | Z18: 0.075980169 | AA18: -0.044378814 | AB18: -0.063508543 | AC18: 0.0037460612 | AD18: 0.15515337 | AE18: 0.078294658 | AF18: 0.17479102 | AG18: 0.046222111 | AH18: 0.07920083 | AI18: 0.012752398 | AJ18: -0.080168785 | AK18: -0.057142953 | AL18: -0.037035213 | AM18: 0.013086357 | AN18: 0.13054666 | AO18: 0.029132007 | AP18: 0.18046781 | AQ18: 0.034863251 | AR18: -0.0074643598 | AS18: 0.0040032869 | AT18: 0.049783606 | AU18: 0.11375997 | AV18: 0.050567442 | AW18: -0.034622585 | AX18: -0.15275228 | AY18: -0.07534758 | AZ18: 0.012737381 | BA18: 0.075696171 | BB18: -0.059210357 | BC18: -0.071737982 | BD18: 0.015101634 | BE18: -0.050446333 | BF18: -0.061747526 | BG18: 0.21313945 | BH18: 0.11762021 | BI18: -0.12838513 | BJ18: 0.10747997 | BK18: -0.073976121 | BL18: 0.068955644 | BM18: -0.031957791 | BN18: -0.0068211149 | BO18: 0.041217397 | BP18: -0.093985404 | BQ18: -0.061185915 | BR18: -0.10986526 | BS18: -0.020749425 | BT18: 0.055003395 | BU18: -0.12401299 | BV18: 0.11189562 | BW18: 0.060190311 | BX18: -0.049871168 | BY18: -0.061980392 | BZ18: -0.25329022 | CA18: 0.00034296846 | CB18: 0.19452321 | CC18: -0.076255125 | CD18: 0.066582598 | CE18: 0.031430835 | CF18: 0.049680014 | CG18: 0.05296769 | CH18: -0.037796611 | CI18: -0.074929092 | CJ18: 0.01827983 | CK18: -0.066249791 | CL18: -0.064150789 | CM18: 0.023304939 | CN18: 0.044786616 | CO18: -0.23372784 | CP18: -0.010360156 | CQ18: 0.15853055 | CR18: -0.0079564433 | CS18: -0.0316431 | CT18: -0.005556105 | CU18: 0.00097710644 | CV18: 0.036441513 | CW18: -0.068855905 | CX18: 0.0063875864 | CY18: -0.11038494 | CZ18: 0.11841933 | DA18: 0.03709776 | DB18: -0.048833267 | DC18: -0.013774937 | DD18: 0.0035078619 | DE18: -0.0059766028 | DF18: 0.0093120481 | DG18: 0.0028115335 | DH18: 0.0031782925 | DI18: -0.078149422 | DJ18: -0.020142525 | DK18: -0.095577695 | DL18: 0.10972129 | DM18: -0.023729882 | DN18: 0.032410309 | DO18: 0.06235584 | DP18: 0.1114644 | DQ18: -0.0311626 | DR18: 0.014578889 | DS18: 0.0016731204 | DT18: -0.06552698 | DU18: 0.0099625204 | DV18: 0.016931498 | DW18: -0.082644503 | DX18: -0.019118756 | DY18: -0.035916484 | DZ18: -0.0013584695 | EA18: 0.042287554 | EB18: 0.092113311 | EC18: 0.095294098 | ED18: -0.0021275906 | EE18: 0.063645166 | EF18: 0.06637984
A19: 120 | B19: 8 | C19: 0.52985771 | D19: 0.076061145 | E19: 0.10440408 | F19: -0.06717858 | G19: -0.082735777 | H19: 0.048538574 | I19: 0.017228104 | J19: -0.083716559 | K19: 0.043504555 | L19: -0.036605614 | M19: 0.023588566 | N19: 0.047668104 | O19: -0.12231128 | P19: -0.0068552531 | Q19: 0.13676183 | R19: -0.049627206 | S19: -0.00053140616 | T19: -0.072801924 | U19: -0.12705136 | V19: 0.047642476 | W19: 0.01511543 | X19: 0.20221851 | Y19: -0.030595375 | Z19: 0.070802849 | AA19: -0.049593906 | AB19: -0.059192407 | AC19: 0.00197018 | AD19: 0.13969011 | AE19: 0.12090141 | AF19: 0.14528084 | AG19: 0.059824625 | AH19: 0.079034205 | AI19: -0.0069087254 | AJ19: -0.088640827 | AK19: -0.048049495 | AL19: -0.040485266 | AM19: 0.009450096 | AN19: 0.13954237 | AO19: 0.02706228 | AP19: 0.21064131 | AQ19: 0.0004153587 | AR19: 0.0062558706 | AS19: 0.012558767 | AT19: 0.063393401 | AU19: 0.1407977 | AV19: 0.041395757 | AW19: -0.012224798 | AX19: -0.18435485 | AY19: -0.12809128 | AZ19: 0.0059507401 | BA19: 0.039079089 | BB19: -0.05677891 | BC19: -0.062312336 | BD19: 0.0099495228 | BE19: -0.051416418 | BF19: -0.015788925 | BG19: 0.20140513 | BH19: 0.13969197 | BI19: -0.10198312 | BJ19: 0.119702 | BK19: -0.09668799 | BL19: 0.081805321 | BM19: -0.033466951 | BN19: 0.0040575035 | BO19: 0.048053365 | BP19: -0.13589513 | BQ19: -0.066896047 | BR19: -0.11229958 | BS19: -0.020453667 | BT19: 0.063726793 | BU19: -0.12846365 | BV19: 0.13246304 | BW19: 0.031768333 | BX19: -0.038230486 | BY19: -0.079758185 | BZ19: -0.26753931 | CA19: 0.0020565279 | CB19: 0.22563407 | CC19: -0.10644024 | CD19: -0.050873354 | CE19: -0.039737205 | CF19: 0.052853073 | CG19: 0.081574797 | CH19: -0.042530619 | CI19: -0.11725745 | CJ19: 0.01711311 | CK19: -0.069748368 | CL19: -0.009312803 | CM19: 0.051487871 | CN19: 0.022772361 | CO19: -0.16747505 | CP19: -0.030928959 | CQ19: 0.20310226 | CR19: 0.023181979 | CS19: -0.0086770512 | CT19: -0.037899252 | CU19: -0.011171046 | CV19: 0.040180729 | CW19: -0.073503677 | CX19: 0.015293372 | CY19: -0.099568969 | CZ19: 0.14849636 | DA19: 0.057245568 | DB19: -0.064871694 | DC19: -0.017668364 | DD19: -0.0057846516 | DE19: -0.022127288 | DF19: 0.021587741 | DG19: 0.025060521 | DH19: 0.0082975077 | DI19: -0.083131859 | DJ19: -0.010219142 | DK19: -0.095570533 | DL19: 0.07242241 | DM19: -0.029633364 | DN19: 0.040703783 | DO19: 0.066922479 | DP19: 0.1081164 | DQ19: -0.053077386 | DR19: -0.0061282001 | DS19: -0.018473527 | DT19: -0.084857003 | DU19: 0.037965007 | DV19: 0.022166275 | DW19: -0.083543442 | DX19: 0.011892608 | DY19: 0.044396719 | DZ19: -0.0048075572 | EA19: 0.04614454 | EB19: 0.08817728 | EC19: 0.098773806 | ED19: -0.0023581203 | EE19: 0.074006134 | EF19: 0.079478953
A20: 137 | B20: 7 | C20: 0.59702667 | D20: 0.11234222 | E20: 0.11977254 | F20: -0.052670133 | G20: -0.085104963 | H20: 0.042588982 | I20: 0.025934439 | J20: -0.10291089 | K20: 0.060254317 | L20: -0.035141144 | M20: 0.06594491 | N20: 0.048725311 | O20: -0.12114281 | P20: 0.018580166 | Q20: 0.17007991 | R20: -0.050666745 | S20: -0.0078891291 | T20: -0.07758372 | U20: -0.12095281 | V20: 0.060617935 | W20: 0.034031799 | X20: 0.11902178 | Y20: -0.05917297 | Z20: 0.046364348 | AA20: -0.056977897 | AB20: -0.057732291 | AC20: 0.038247065 | AD20: 0.12174285 | AE20: 0.095786687 | AF20: 0.14793824 | AG20: 0.040076151 | AH20: 0.1060203 | AI20: 0.0088415767 | AJ20: -0.091660719 | AK20: -0.062903545 | AL20: -0.023090075 | AM20: 0.0059551741 | AN20: 0.15245896 | AO20: 0.042447332 | AP20: 0.23572912 | AQ20: -0.016630198 | AR20: -0.037023841 | AS20: -0.031522233 | AT20: 0.073773102 | AU20: 0.17022874 | AV20: 0.0364379 | AW20: -0.01028742 | AX20: -0.21646804 | AY20: -0.15878963 | AZ20: -0.073243794 | BA20: 0.039030252 | BB20: -0.029833767 | BC20: -0.067232691 | BD20: 0.010369358 | BE20: -0.058332098 | BF20: -0.048237821 | BG20: 0.20384241 | BH20: 0.12731126 | BI20: -0.030982023 | BJ20: 0.16854184 | BK20: -0.043284731 | BL20: 0.080872492 | BM20: -0.028591581 | BN20: 0.037674701 | BO20: 0.03443857 | BP20: -0.16345065 | BQ20: -0.08823425 | BR20: -0.12937015 | BS20: -0.008026796 | BT20: 0.12060036 | BU20: -0.059011248 | BV20: 0.081313722 | BW20: 0.023036326 | BX20: -0.064435825 | BY20: -0.079395837 | BZ20: -0.22233143 | CA20: -0.00033634169 | CB20: 0.20437027 | CC20: -0.15077476 | CD20: -0.069076709 | CE20: -0.053557467 | CF20: 0.059428907 | CG20: 0.096535295 | CH20: -0.070558229 | CI20: -0.12316024 | CJ20: -0.02552087 | CK20: -0.059404698 | CL20: -0.015808281 | CM20: 0.02744199 | CN20: 0.010380079 | CO20: -0.1529223 | CP20: -0.036841767 | CQ20: 0.24824018 | CR20: 0.0016801623 | CS20: 0.012760755 | CT20: -0.039989379 | CU20: -0.016964815 | CV20: 0.01716022 | CW20: -0.076679093 | CX20: 0.027565591 | CY20: -0.097612476 | CZ20: 0.1460158 | DA20: 0.061880195 | DB20: -0.058935192 | DC20: -0.010253509 | DD20: 0.024323833 | DE20: -0.031841769 | DF20: 0.032191641 | DG20: 0.025642306 | DH20: 0.0022638178 | DI20: -0.072426308 | DJ20: -0.025905625 | DK20: -0.054742387 | DL20: 0.084636771 | DM20: -0.021697179 | DN20: 0.051943746 | DO20: 0.056454224 | DP20: 0.11984535 | DQ20: -0.10782357 | DR20: -0.020824985 | DS20: -0.011093287 | DT20: -0.11481388 | DU20: 0.064428265 | DV20: 0.037284648 | DW20: -0.051251544 | DX20: 0.014207202 | DY20: 0.081730372 | DZ20: 0.035042142 | EA20: 0.08196545 | EB20: 0.099856613 | EC20: 0.12283663 | ED20: -0.030402289 | EE20: 0.074032574 | EF20: 0.09006019
A21: 160 | B21: 6 | C21: 0.58903403 | D21: 0.12101827 | E21: 0.14904739 | F21: -0.051161742 | G21: -0.07614315 | H21: 0.052045692 | I21: -0.014323776 | J21: -0.087658148 | K21: 0.10999562 | L21: -0.010350047 | M21: 0.095319388 | N21: 0.051909197 | O21: -0.14279046 | P21: 0.01191346 | Q21: 0.17299663 | R21: -0.060054947 | S21: 0.0029282475 | T21: -0.084714245 | U21: -0.14008403 | V21: 0.052065875 | W21: 0.032223956 | X21: 0.07246097 | Y21: -0.046392707 | Z21: 0.046385964 | AA21: -0.047376075 | AB21: -0.056662466 | AC21: 0.041917627 | AD21: 0.14347554 | AE21: 0.13393969 | AF21: 0.13976035 | AG21: 0.058270038 | AH21: 0.11058398 | AI21: 0.025698749 | AJ21: -0.12534083 | AK21: 0.021712838 | AL21: 0.022439216 | AM21: 0.028344364 | AN21: 0.17393219 | AO21: 0.075256079 | AP21: 0.11552752 | AQ21: -0.040305129 | AR21: -0.024064235 | AS21: -0.082810152 | AT21: 0.085553942 | AU21: 0.19824898 | AV21: 0.050253807 | AW21: -0.059856918 | AX21: -0.23920275 | AY21: -0.19532085 | AZ21: -0.07382017 | BA21: 0.020494207 | BB21: -0.077932698 | BC21: -0.075595124 | BD21: 0.0062471472 | BE21: -0.053023862 | BF21: -0.032345345 | BG21: 0.26160881 | BH21: 0.081861771 | BI21: 0.0057666495 | BJ21: 0.18255109 | BK21: -0.051200608 | BL21: 0.082581647 | BM21: 0.014447746 | BN21: 0.021655654 | BO21: 0.046419084 | BP21: -0.15934268 | BQ21: -0.080440695 | BR21: -0.16823039 | BS21: -0.030264806 | BT21: 0.13603345 | BU21: -0.051609422 | BV21: 0.072476835 | BW21: 0.0078441974 | BX21: -0.055721084 | BY21: -0.098363061 | BZ21: -0.19991689 | CA21: 0.037753679 | CB21: 0.20379029 | CC21: -0.18818714 | CD21: -0.074047646 | CE21: -0.057290904 | CF21: 0.10613869 | CG21: 0.045719748 | CH21: -0.13243064 | CI21: -0.17283375 | CJ21: -0.03151917 | CK21: -0.078468322 | CL21: -0.045994719 | CM21: 0.030084793 | CN21: -0.026759955 | CO21: -0.15204785 | CP21: -0.036223363 | CQ21: 0.32077598 | CR21: -0.014852952 | CS21: -0.0038005711 | CT21: -0.050488759 | CU21: 0.027728529 | CV21: 0.016311753 | CW21: -0.055317418 | CX21: 0.066263572 | CY21: -0.1034562 | CZ21: 0.11519659 | DA21: 0.06747171 | DB21: -0.042268358 | DC21: -0.01734549 | DD21: 0.038316496 | DE21: -0.033452283 | DF21: 0.021548499 | DG21: 0.040422527 | DH21: 0.0066989803 | DI21: -0.069408931 | DJ21: -0.038777372 | DK21: -0.031601872 | DL21: 0.037777794 | DM21: -0.065635413 | DN21: 0.037554489 | DO21: 0.056910691 | DP21: 0.12103622 | DQ21: -0.098994753 | DR21: -0.011054394 | DS21: -0.034647927 | DT21: -0.11762443 | DU21: -0.04903794 | DV21: 0.0080006969 | DW21: 0.10490809 | DX21: 0.07639991 | DY21: 0.012094565 | DZ21: 0.011537309 | EA21: 0.060595958 | EB21: 0.12693199 | EC21: 0.11463543 | ED21: -0.044745873 | EE21: 0.085076635 | EF21: 0.092928816
A22: 192 | B22: 5 | C22: 0.48688323 | D22: 0.14754148 | E22: 0.15805919 | F22: -0.06901927 | G22: -0.077451021 | H22: -0.0071708541 | I22: -0.03367232 | J22: -0.07142734 | K22: 0.13014253 | L22: -0.060974844 | M22: 0.010482042 | N22: 0.10127858 | O22: -0.13009359 | P22: 0.029811983 | Q22: 0.17356576 | R22: -0.061256067 | S22: -0.0050269768 | T22: -0.072740849 | U22: -0.16648222 | V22: 0.054648868 | W22: 0.051064791 | X22: 0.10701387 | Y22: -0.082230025 | Z22: 0.042910792 | AA22: -0.055683174 | AB22: -0.057372286 | AC22: 0.066093906 | AD22: 0.1871406 | AE22: 0.15411462 | AF22: 0.10085416 | AG22: 0.056049469 | AH22: 0.1799513 | AI22: 0.046677777 | AJ22: -0.14950342 | AK22: 0.028893065 | AL22: 0.021185374 | AM22: 0.047696201 | AN22: 0.19178404 | AO22: 0.11257277 | AP22: 0.13425491 | AQ22: -0.090084251 | AR22: -0.053467099 | AS22: -0.09714662 | AT22: 0.093996824 | AU22: 0.23802169 | AV22: 0.083251118 | AW22: -0.077055991 | AX22: -0.086651293 | AY22: -0.22539263 | AZ22: -0.041420954 | BA22: 0.04729685 | BB22: -0.051572867 | BC22: -0.16524946 | BD22: 0.0018439458 | BE22: -0.066886543 | BF22: -0.012335267 | BG22: 0.28123534 | BH22: 0.034445877 | BI22: -0.024662655 | BJ22: 0.15111531 | BK22: -0.083923624 | BL22: 0.074116349 | BM22: 0.026508863 | BN22: 0.0357811 | BO22: 0.15662005 | BP22: -0.17357038 | BQ22: -0.090739883 | BR22: -0.22251482 | BS22: -0.038373754 | BT22: 0.15364436 | BU22: -0.01263817 | BV22: 0.08646628 | BW22: -0.020441636 | BX22: -0.032103214 | BY22: 0.012763254 | BZ22: -0.11812871 | CA22: 0.11364965 | CB22: 0.24362943 | CC22: -0.21009105 | CD22: -0.041779842 | CE22: -0.073621299 | CF22: 0.11567724 | CG22: 0.074854351 | CH22: -0.18972821 | CI22: -0.18107813 | CJ22: -0.022311851 | CK22: -0.06508595 | CL22: -0.093860005 | CM22: 0.034557342 | CN22: -0.0018771081 | CO22: -0.15150334 | CP22: -0.052175817 | CQ22: 0.41254719 | CR22: -0.02634783 | CS22: -0.13075548 | CT22: -0.054838637 | CU22: 0.015967234 | CV22: 0.035487819 | CW22: -0.051113617 | CX22: 0.1106162 | CY22: -0.089499376 | CZ22: 0.14483605 | DA22: 0.040398834 | DB22: -0.063717545 | DC22: -0.011081018 | DD22: 0.051746287 | DE22: -0.070844489 | DF22: 0.015480851 | DG22: 0.051069304 | DH22: 0.0061205474 | DI22: -0.10085032 | DJ22: -0.017964279 | DK22: 0.03951058 | DL22: 0.02634758 | DM22: -0.052430565 | DN22: 0.08176097 | DO22: 0.027338151 | DP22: 0.11046314 | DQ22: -0.094540332 | DR22: 0.0064571324 | DS22: -0.062147273 | DT22: -0.12213638 | DU22: -0.0043957438 | DV22: 0.012148641 | DW22: 0.058291235 | DX22: 0.01428522 | DY22: 0.049379798 | DZ22: 0.0095009896 | EA22: 0.082111353 | EB22: 0.18054858 | EC22: 0.09854277 | ED22: -0.070199935 | EE22: 0.088819049 | EF22: 0.071103802
A23: 241 | B23: 4 | C23: 0.49455411 | D23: 0.25549016 | E23: 0.15834077 | F23: -0.048048285 | G23: -0.055465653 | H23: -0.037401185 | I23: -0.090799177 | J23: -0.041272485 | K23: 0.13344374 | L23: -0.057040399 | M23: 0.084348637 | N23: 0.12191505 | O23: -0.16028548 | P23: 0.030477232 | Q23: 0.20165287 | R23: 0.017838855 | S23: -0.090925954 | T23: -0.057105512 | U23: -0.21884034 | V23: 0.048176244 | W23: -0.025378307 | X23: 0.13376734 | Y23: -0.084925715 | Z23: 0.030428853 | AA23: -0.098444599 | AB23: -0.10472394 | AC23: 0.0065264698 | AD23: 0.22178515 | AE23: 0.22483231 | AF23: 0.11764732 | AG23: 0.079354631 | AH23: 0.20961706 | AI23: 0.015049953 | AJ23: -0.15440734 | AK23: 0.017776042 | AL23: 0.035338826 | AM23: 0.067624763 | AN23: 0.30187139 | AO23: 0.14427626 | AP23: 0.11872683 | AQ23: -0.12985516 | AR23: -0.051272934 | AS23: -0.025222117 | AT23: 0.088378856 | AU23: 0.11950448 | AV23: 0.11850128 | AW23: -0.095095303 | AX23: -0.054032247 | AY23: -0.31667605 | AZ23: -0.11155375 | BA23: 0.06227626 | BB23: -0.060739285 | BC23: -0.18197003 | BD23: 0.016487273 | BE23: -0.085046601 | BF23: -0.01250869 | BG23: 0.035545251 | BH23: -0.014262288 | BI23: 0.027055069 | BJ23: 0.20538193 | BK23: -0.08909616 | BL23: 0.10828529 | BM23: 0.098666559 | BN23: 0.025738194 | BO23: 0.19310975 | BP23: -0.21630846 | BQ23: -0.013438018 | BR23: -0.19820838 | BS23: -0.093364095 | BT23: 0.15332668 | BU23: -0.04604194 | BV23: 0.082497857 | BW23: 0.030004934 | BX23: -0.056023329 | BY23: -0.045250525 | BZ23: -0.097177664 | CA23: 0.1649117 | CB23: 0.23163172 | CC23: -0.26165595 | CD23: 0.045386284 | CE23: -0.044601754 | CF23: 0.14649218 | CG23: 0.10613073 | CH23: -0.35777319 | CI23: -0.21143661 | CJ23: -0.00051861204 | CK23: -0.11459941 | CL23: -0.026372923 | CM23: 0.094255199 | CN23: -0.01666558 | CO23: -0.21855023 | CP23: -0.0046121271 | CQ23: 0.23044092 | CR23: -0.052596479 | CS23: -0.13055596 | CT23: -0.053826874 | CU23: -0.023500925 | CV23: 0.063140272 | CW23: -0.034635845 | CX23: 0.13351105 | CY23: -0.038264236 | CZ23: 0.22667708 | DA23: -0.014277421 | DB23: -0.07509634 | DC23: -0.12726115 | DD23: 0.042416125 | DE23: -0.08405872 | DF23: 2.2440721e-05 | DG23: -0.0071756513 | DH23: -0.02581954 | DI23: -0.12135655 | DJ23: -0.047984589 | DK23: -0.036226719 | DL23: -0.0099343053 | DM23: -0.07820593 | DN23: 0.061683486 | DO23: 0.014290032 | DP23: 0.15548646 | DQ23: -0.037687783 | DR23: 0.01151695 | DS23: -0.013803607 | DT23: -0.15441165 | DU23: 0.028426183 | DV23: -0.04364331 | DW23: 0.043162558 | DX23: 0.030487677 | DY23: -0.090037411 | DZ23: 0.0053346339 | EA23: 0.053941846 | EB23: 0.27542734 | EC23: 0.1524411 | ED23: -0.05970855 | EE23: 0.1268912 | EF23: 0.078128209
A24: 321 | B24: 3 | C24: 0.63578988 | D24: 0.14371046 | E24: 0.2567837 | F24: -0.030912073 | G24: 0.066425395 | H24: -0.022668733 | I24: -0.18400393 | J24: 0.0021578764 | K24: 0.051847408 | L24: -0.047982676 | M24: 0.066596074 | N24: 0.16484966 | O24: -0.20923212 | P24: 0.019606911 | Q24: 0.23377539 | R24: -0.10944564 | S24: -0.18376368 | T24: -0.04100274 | U24: -0.21689707 | V24: 0.076605299 | W24: -0.047616796 | X24: 0.13134145 | Y24: -0.10828845 | Z24: 0.018824964 | AA24: -0.05882885 | AB24: -0.070771132 | AC24: 0.098352654 | AD24: 0.15048828 | AE24: 0.29118075 | AF24: 0.18423826 | AG24: 0.16253189 | AH24: 0.28196454 | AI24: 0.052095579 | AJ24: 0.028392331 | AK24: 0.054611139 | AL24: 0.01335053 | AM24: 0.073700392 | AN24: 0.38458143 | AO24: 0.16756058 | AP24: 0.077961907 | AQ24: 0.0047467039 | AR24: -0.11584375 | AS24: -0.034990463 | AT24: 0.096233719 | AU24: 0.10418083 | AV24: 0.16684895 | AW24: -0.11911501 | AX24: -0.039664867 | AY24: -0.25357516 | AZ24: -0.088068891 | BA24: 0.028023673 | BB24: -0.13226649 | BC24: -0.059704553 | BD24: 0.057338231 | BE24: -0.083243522 | BF24: -0.04539006 | BG24: -0.016352671 | BH24: -0.033326012 | BI24: 0.078567866 | BJ24: 0.2768646 | BK24: -0.092238539 | BL24: 0.075908851 | BM24: 0.11601369 | BN24: 0.17452606 | BO24: 0.15927909 | BP24: -0.23874024 | BQ24: -0.18380547 | BR24: -0.14964732 | BS24: -0.017276844 | BT24: 0.16689298 | BU24: -0.10089866 | BV24: 0.10678972 | BW24: 0.034558381 | BX24: -0.013427594 | BY24: 0.024780026 | BZ24: -0.12405057 | CA24: 0.19509669 | CB24: 0.25718022 | CC24: -0.20779281 | CD24: 0.12770443 | CE24: -0.029309541 | CF24: 0.20617324 | CG24: 0.19038219 | CH24: -0.16021486 | CI24: -0.26603981 | CJ24: 0.012724137 | CK24: -0.13025632 | CL24: -0.14237495 | CM24: 0.082145297 | CN24: -0.11069707 | CO24: -0.21448033 | CP24: -0.030343543 | CQ24: 0.22095958 | CR24: -0.055866839 | CS24: -0.20536498 | CT24: -0.12512942 | CU24: 0.034810787 | CV24: 0.055587283 | CW24: -0.1364392 | CX24: 0.19894507 | CY24: -0.052274475 | CZ24: 0.25591544 | DA24: -0.00018551745 | DB24: -0.066834041 | DC24: -0.10172515 | DD24: 0.1199191 | DE24: -0.067892567 | DF24: 0.01343753 | DG24: -0.040187434 | DH24: -0.057238887 | DI24: -0.13025366 | DJ24: -0.023864622 | DK24: 0.05052803 | DL24: 0.013402856 | DM24: -0.047749552 | DN24: 0.083437946 | DO24: 0.032817615 | DP24: 0.048987677 | DQ24: -0.094489696 | DR24: 0.024757378 | DS24: -0.12419424 | DT24: -0.18313965 | DU24: -0.0073840122 | DV24: -0.12607025 | DW24: -0.025817603 | DX24: 0.041449748 | DY24: -0.14035838 | DZ24: -0.063554289 | EA24: 0.21572269 | EB24: 0.24680454 | EC24: 0.17725234 | ED24: -0.068676607 | EE24: 0.12488533 | EF24: 0.11931067
A25: 482 | B25: 2 | C25: 0.63761018 | D25: 0.23795575 | E25: 0.12312891 | F25: -0.075190133 | G25: 0.26530324 | H25: -0.11577404 | I25: -0.11131688 | J25: 0.03664981 | K25: 0.034438287 | L25: -0.0075470115 | M25: -0.056137762 | N25: 0.19066143 | O25: -0.24659809 | P25: 0.021837912 | Q25: 0.31415974 | R25: -0.18753075 | S25: -0.21928765 | T25: -0.036889939 | U25: -0.20997192 | V25: -0.038262635 | W25: 0.01094415 | X25: 0.1035642 | Y25: -0.14925654 | Z25: -0.021502548 | AA25: -0.12810205 | AB25: -0.099403582 | AC25: 0.17839997 | AD25: 0.15341673 | AE25: 0.38007623 | AF25: 0.1343322 | AG25: 0.20974022 | AH25: 0.39274118 | AI25: 0.072208869 | AJ25: 0.036800055 | AK25: 0.064113781 | AL25: 0.076627557 | AM25: 0.0029941228 | AN25: 0.37729158 | AO25: 0.16261603 | AP25: 0.23285455 | AQ25: 0.034840127 | AR25: -0.20324627 | AS25: -0.060066015 | AT25: 0.12536021 | AU25: 0.079172046 | AV25: 0.24185872 | AW25: -0.19133981 | AX25: -0.0022886687 | AY25: -0.31417848 | AZ25: -0.1182689 | BA25: 0.019837025 | BB25: -0.28483809 | BC25: -0.088808886 | BD25: 0.044158357 | BE25: 0.021094349 | BF25: -0.049158473 | BG25: -0.039297025 | BH25: -0.06670356 | BI25: -0.24512419 | BJ25: 0.31627967 | BK25: -0.020279977 | BL25: 0.032574743 | BM25: 0.16742568 | BN25: 0.19132555 | BO25: 0.124396 | BP25: -0.36320679 | BQ25: -0.20320176 | BR25: -0.24421961 | BS25: -0.055589738 | BT25: 0.24989347 | BU25: 0.073173726 | BV25: 0.24729165 | BW25: 0.10416765 | BX25: -0.023111115 | BY25: 0.14061789 | BZ25: -0.16944196 | CA25: 0.17663954 | CB25: 0.17587603 | CC25: -0.16161906 | CD25: 0.25287722 | CE25: -0.11687847 | CF25: -0.01516571 | CG25: 0.085242685 | CH25: 0.013862678 | CI25: -0.41183998 | CJ25: 0.08606187 | CK25: -0.1714284 | CL25: -0.06143508 | CM25: 0.053674129 | CN25: -0.076448359 | CO25: -0.27279203 | CP25: -0.15239381 | CQ25: 0.30257491 | CR25: -0.18127479 | CS25: -0.10760301 | CT25: -0.085021073 | CU25: 0.092479557 | CV25: 0.056899202 | CW25: -0.13986949 | CX25: 0.20560924 | CY25: -0.069752467 | CZ25: 0.34609707 | DA25: 0.053805969 | DB25: -0.10200756 | DC25: -0.17235787 | DD25: 0.097288584 | DE25: -0.23881192 | DF25: 0.038070252 | DG25: -0.092525535 | DH25: -0.054769437 | DI25: -0.1952049 | DJ25: -0.012019494 | DK25: 0.087152024 | DL25: 0.03055163 | DM25: 0.16855435 | DN25: -0.1217378 | DO25: 0.00024981968 | DP25: -0.053165159 | DQ25: -0.069051619 | DR25: 0.062495104 | DS25: -0.23541058 | DT25: -0.23008776 | DU25: -0.06438418 | DV25: -0.14230302 | DW25: -0.039291309 | DX25: 0.10996877 | DY25: -0.08207174 | DZ25: -0.039346196 | EA25: 0.25845567 | EB25: 0.34685488 | EC25: 0.18511412 | ED25: -0.097611134 | EE25: 0.099797778 | EF25: 0.059802184
A26: 964 | B26: 1 | C26: 0.90919898 | D26: 0.38824497 | E26: 0.1294749 | F26: -0.13645906 | G26: 0.47209974 | H26: 0.20906099 | I26: -0.32592603 | J26: -0.19062398 | K26: 0.044331792 | L26: 0.25204889 | M26: 0.14165758 | N26: 0.173452 | O26: -0.4107269 | P26: 0.069342395 | Q26: 0.60927025 | R26: -0.29178114 | S26: -0.29392432 | T26: 0.038801158 | U26: -0.42322996 | V26: 0.16372718 | W26: 0.087206146 | X26: 0.13162844 | Y26: -0.12432245 | Z26: 0.057154149 | AA26: 0.029539653 | AB26: -0.092340447 | AC26: 0.4033 | AD26: 0.49910074 | AE26: 0.18904454 | AF26: 0.00035461655 | AG26: 0.31121717 | AH26: 0.90293805 | AI26: 0.096799751 | AJ26: 0.08009608 | AK26: 0.26078301 | AL26: 0.04605441 | AM26: 0.023701914 | AN26: 0.13267246 | AO26: 0.10218953 | AP26: 0.085535447 | AQ26: -0.099630652 | AR26: -0.42212428 | AS26: -0.33629717 | AT26: 0.33042944 | AU26: 0.10307129 | AV26: 0.38312662 | AW26: -0.12669497 | AX26: 0.0735115 | AY26: -0.71081456 | AZ26: -0.19139485 | BA26: -0.08394074 | BB26: -0.66158882 | BC26: -0.19640103 | BD26: 0.03733116 | BE26: -0.090417066 | BF26: 0.011230242 | BG26: -0.13985386 | BH26: -0.032588391 | BI26: -0.057866128 | BJ26: 0.38745342 | BK26: 0.010019727 | BL26: 0.04514622 | BM26: 0.084093788 | BN26: 0.18512837 | BO26: -0.026668247 | BP26: -0.836394 | BQ26: -0.13694109 | BR26: -0.38171494 | BS26: -0.12162104 | BT26: -0.055799256 | BU26: -0.050687688 | BV26: -0.07442795 | BW26: 0.057307859 | BX26: 0.066604644 | BY26: 0.15739858 | BZ26: -0.41150141 | CA26: 0.053526593 | CB26: 0.33692898 | CC26: -0.22069348 | CD26: 0.55059299 | CE26: 0.17967255 | CF26: -0.020033171 | CG26: 0.095486531 | CH26: -0.47591535 | CI26: 0.072090777 | CJ26: 0.30472255 | CK26: -0.055315861 | CL26: -0.037249281 | CM26: 0.20229818 | CN26: 0.064923289 | CO26: -0.25478149 | CP26: 0.062154233 | CQ26: 0.64177463 | CR26: -0.35399521 | CS26: -0.058364981 | CT26: -0.1266038 | CU26: 0.06422361 | CV26: 0.10734401 | CW26: -0.22735366 | CX26: 0.17994577 | CY26: 0.0045783886 | CZ26: 0.4146748 | DA26: -0.28742785 | DB26: -0.15353434 | DC26: -0.13150657 | DD26: 0.16487824 | DE26: -0.2415252 | DF26: -0.012383701 | DG26: -0.11666334 | DH26: 0.10181294 | DI26: -0.11728018 | DJ26: 0.060056651 | DK26: 0.028211668 | DL26: -0.18051197 | DM26: -0.097547558 | DN26: 0.050940226 | DO26: -0.10084896 | DP26: 0.098496164 | DQ26: -0.058675277 | DR26: 0.021897608 | DS26: -0.26938035 | DT26: -0.42208361 | DU26: -0.075127002 | DV26: -0.20834033 | DW26: -0.014577288 | DX26: 0.42756103 | DY26: -0.102493 | DZ26: 0.041473998 | EA26: 0.59865801 | EB26: 0.21117526 | EC26: 0.51950018 | ED26: -0.10254895 | EE26: 0.10813289 | EF26: 0.096235608
A27: 大盤 | B27: TWⅡ | C27: -0.017446771 | D27: 0.020701061 | E27: 0.023982129 | F27: -0.006557579 | G27: 0.03184513 | H27: 0.034348533 | I27: -0.0082549328 | J27: 0.012843524 | K27: -0.051018525 | L27: 0.00087394274 | M27: 0.023389576 | N27: 0.012988972 | O27: 0.0058545887 | P27: 0.027413207 | Q27: -0.0037129361 | R27: 0.024076614 | S27: -0.012190025 | T27: -0.039749578 | U27: -0.07315545 | V27: -0.05826023 | W27: 0.00077279757 | X27: 0.044591521 | Y27: -0.02769968 | Z27: 0.0020950059 | AA27: -0.023400551 | AB27: 0.032129371 | AC27: 0.038903273 | AD27: -0.042865382 | AE27: 0.018647195 | AF27: 0.015229768 | AG27: 0.036016604 | AH27: 0.0093546114 | AI27: 0.010748251 | AJ27: 0.013357754 | AK27: -0.0053327473 | AL27: 0.0013831358 | AM27: 0.020795928 | AN27: 0.031517702 | AO27: 0.0062417165 | AP27: 0.0061452617 | AQ27: 0.016946358 | AR27: 0.03468283 | AS27: 0.0030985886 | AT27: 0.015081347 | AU27: -0.019251209 | AV27: 0.038711513 | AW27: -0.021856951 | AX27: 0.0077743007 | AY27: 0.042397247 | AZ27: -0.026308975 | BA27: 0.0095717493 | BB27: -0.024249741 | BC27: 0.020163374 | BD27: -0.0035049988 | BE27: 0.020151935 | BF27: 0.00058133623 | BG27: -0.005219701 | BH27: -0.11587176 | BI27: 0.0087252257 | BJ27: -0.016377261 | BK27: 0.020840372 | BL27: 0.044975872 | BM27: 0.023954306 | BN27: 0.030239101 | BO27: -0.043725888 | BP27: 0.02188947 | BQ27: 0.0086274303 | BR27: -0.019192954 | BS27: 0.01973513 | BT27: 0.047694337 | BU27: 0.011454817 | BV27: 0.043228621 | BW27: -0.04274743 | BX27: -0.017811292 | BY27: -0.1511531 | BZ27: 0.124224 | CA27: -0.0045572538 | CB27: 0.06021124 | CC27: 0.085992033 | CD27: -0.0058084796 | CE27: -0.006041347 | CF27: 0.0024523244 | CG27: 0.089636252 | CH27: 0.070992733 | CI27: 0.027170643 | CJ27: 0.052468428 | CK27: 0.029480661 | CL27: 0.066825081 | CM27: -0.028772229 | CN27: 0.039462516 | CO27: -0.029031087 | CP27: 0.013983883 | CQ27: -0.032276965 | CR27: 0.0031035766 | CS27: 0.025591856 | CT27: 0.044391886 | CU27: -0.030338959 | CV27: -0.0012579765 | CW27: 0.0023363565 | CX27: -0.064264145 | CY27: 0.012909779 | CZ27: -0.12547709 | DA27: 0.011690683 | DB27: 0.0063378437 | DC27: -0.11730536 | DD27: -0.036010872 | DE27: 0.1389113 | DF27: -0.051143506 | DG27: 0.076731447 | DH27: 0.015508782 | DI27: 0.023223774 | DJ27: -0.018372876 | DK27: 0.062199014 | DL27: 0.020098304 | DM27: 0.01349894 | DN27: -0.030252213 | DO27: -0.017022836 | DP27: -0.021788523 | DQ27: 0.085745625 | DR27: 0.028106744 | DS27: -0.0023031598 | DT27: 0.058471198 | DU27: 0.067658949 | DV27: 0.0050207706 | DW27: 0.037416184 | DX27: 0.084111004 | DY27: -0.036832399 | DZ27: 0.0030917028 | EA27: -0.0019576282 | EB27: 0.026459104 | EC27: -0.024752539 | ED27: 0.034115491 | EE27: 0.021061974 | EF27: -0.020277393

Sheet RF勝率
A10: 投資組合 | C10: 公司數 | D10: 964
A11: 等分 | B11: 家數 | C11: 2014/01 | D11: 2014/02 | E11: 2014/03 | F11: 2014/04 | G11: 2014/05 | H11: 2014/06 | I11: 2014/07 | J11: 2014/08 | K11: 2014/09 | L11: 2014/10 | M11: 2014/11 | N11: 2014/12 | O11: 2015/01 | P11: 2015/02 | Q11: 2015/03 | R11: 2015/04 | S11: 2015/05 | T11: 2015/06 | U11: 2015/07 | V11: 2015/08 | W11: 2015/09 | X11: 2015/10 | Y11: 2015/11 | Z11: 2015/12 | AA11: 2016/01 | AB11: 2016/02 | AC11: 2016/03 | AD11: 2016/04 | AE11: 2016/05 | AF11: 2016/06 | AG11: 2016/07 | AH11: 2016/08 | AI11: 2016/09 | AJ11: 2016/10 | AK11: 2016/11 | AL11: 2016/12 | AM11: 2017/01 | AN11: 2017/02 | AO11: 2017/03 | AP11: 2017/04 | AQ11: 2017/05 | AR11: 2017/06 | AS11: 2017/07 | AT11: 2017/08 | AU11: 2017/09 | AV11: 2017/10 | AW11: 2017/11 | AX11: 2017/12 | AY11: 2018/01 | AZ11: 2018/02 | BA11: 2018/03 | BB11: 2018/04 | BC11: 2018/05 | BD11: 2018/06 | BE11: 2018/07 | BF11: 2018/08 | BG11: 2018/09 | BH11: 2018/10 | BI11: 2018/11 | BJ11: 2018/12 | BK11: 2019/01 | BL11: 2019/02 | BM11: 2019/03 | BN11: 2019/04 | BO11: 2019/05 | BP11: 2019/06 | BQ11: 2019/07 | BR11: 2019/08 | BS11: 2019/09 | BT11: 2019/10 | BU11: 2019/11 | BV11: 2019/12 | BW11: 2020/01 | BX11: 2020/02 | BY11: 2020/03 | BZ11: 2020/04 | CA11: 2020/05 | CB11: 2020/06 | CC11: 2020/07 | CD11: 2020/08 | CE11: 2020/09 | CF11: 2020/10 | CG11: 2020/11 | CH11: 2020/12 | CI11: 2021/01 | CJ11: 2021/02 | CK11: 2021/03 | CL11: 2021/04 | CM11: 2021/05 | CN11: 2021/06 | CO11: 2021/07 | CP11: 2021/08 | CQ11: 2021/09 | CR11: 2021/10 | CS11: 2021/11 | CT11: 2021/12 | CU11: 2022/01 | CV11: 2022/02 | CW11: 2022/03 | CX11: 2022/04 | CY11: 2022/05 | CZ11: 2022/06 | DA11: 2022/07 | DB11: 2022/08 | DC11: 2022/09 | DD11: 2022/10 | DE11: 2022/11 | DF11: 2022/12 | DG11: 2023/01 | DH11: 2023/02 | DI11: 2023/03 | DJ11: 2023/04 | DK11: 2023/05 | DL11: 2023/06 | DM11: 2023/07 | DN11: 2023/08 | DO11: 2023/09 | DP11: 2023/10 | DQ11: 2023/11 | DR11: 2023/12 | DS11: 2024/01 | DT11: 2024/02 | DU11: 2024/03 | DV11: 2024/04 | DW11: 2024/05 | DX11: 2024/06 | DY11: 2024/07 | DZ11: 2024/08 | EA11: 2024/09 | EB11: 2024/10 | EC11: 2024/11 | ED11: 2024/12 | EE11: 2025/01 | EF11: 2025/02 | EG11: SUM | EH11: 勝率
