Workbook

Sheet 預測IC
A1: Predict
B2: Time | C2: 2013/12 | D2: 2014/01 | E2: 2014/02 | F2: 2014/03 | G2: 2014/04 | H2: 2014/05 | I2: 2014/06 | J2: 2014/07 | K2: 2014/08 | L2: 2014/09 | M2: 2014/10 | N2: 2014/11 | O2: 2014/12 | P2: 2015/01 | Q2: 2015/02 | R2: 2015/03 | S2: 2015/04 | T2: 2015/05 | U2: 2015/06 | V2: 2015/07 | W2: 2015/08 | X2: 2015/09 | Y2: 2015/10 | Z2: 2015/11 | AA2: 2015/12 | AB2: 2016/01 | AC2: 2016/02 | AD2: 2016/03 | AE2: 2016/04 | AF2: 2016/05 | AG2: 2016/06 | AH2: 2016/07 | AI2: 2016/08 | AJ2: 2016/09 | AK2: 2016/10 | AL2: 2016/11 | AM2: 2016/12 | AN2: 2017/01 | AO2: 2017/02 | AP2: 2017/03 | AQ2: 2017/04 | AR2: 2017/05 | AS2: 2017/06 | AT2: 2017/07 | AU2: 2017/08 | AV2: 2017/09 | AW2: 2017/10 | AX2: 2017/11 | AY2: 2017/12 | AZ2: 2018/01 | BA2: 2018/02 | BB2: 2018/03 | BC2: 2018/04 | BD2: 2018/05 | BE2: 2018/06 | BF2: 2018/07 | BG2: 2018/08 | BH2: 2018/09 | BI2: 2018/10 | BJ2: 2018/11 | BK2: 2018/12 | BL2: 2019/01 | BM2: 2019/02 | BN2: 2019/03 | BO2: 2019/04 | BP2: 2019/05 | BQ2: 2019/06 | BR2: 2019/07 | BS2: 2019/08 | BT2: 2019/09 | BU2: 2019/10 | BV2: 2019/11 | BW2: 2019/12 | BX2: 2020/01 | BY2: 2020/02 | BZ2: 2020/03 | CA2: 2020/04 | CB2: 2020/05 | CC2: 2020/06 | CD2: 2020/07 | CE2: 2020/08 | CF2: 2020/09 | CG2: 2020/10 | CH2: 2020/11 | CI2: 2020/12 | CJ2: 2021/01 | CK2: 2021/02 | CL2: 2021/03 | CM2: 2021/04 | CN2: 2021/05 | CO2: 2021/06 | CP2: 2021/07 | CQ2: 2021/08 | CR2: 2021/09 | CS2: 2021/10 | CT2: 2021/11 | CU2: 2021/12 | CV2: 2022/01 | CW2: 2022/02 | CX2: 2022/03 | CY2: 2022/04 | CZ2: 2022/05 | DA2: 2022/06 | DB2: 2022/07 | DC2: 2022/08 | DD2: 2022/09 | DE2: 2022/10 | DF2: 2022/11 | DG2: 2022/12 | DH2: 2023/01 | DI2: 2023/02 | DJ2: 2023/03 | DK2: 2023/04 | DL2: 2023/05 | DM2: 2023/06 | DN2: 2023/07 | DO2: 2023/08 | DP2: 2023/09 | DQ2: 2023/10 | DR2: 2023/11 | DS2: 2023/12 | DT2: 2024/01 | DU2: 2024/02 | DV2: 2024/03 | DW2: 2024/04 | DX2: 2024/05 | DY2: 2024/06 | DZ2: 2024/07 | EA2: 2024/08 | EB2: 2024/09 | EC2: 2024/10 | ED2: 2024/11 | EE2: 2024/12 | EF2: 2025/01
B3: mom1 | C3: -0.070510313 | D3: -0.020690763 | E3: -0.049750485 | F3: -0.092162974 | G3: -0.090981476 | H3: 0.017403694 | I3: -0.0014660321 | J3: -0.042782601 | K3: -0.048218094 | L3: -0.054908209 | M3: -0.0042270971 | N3: -0.015415508 | O3: -0.026379582 | P3: 0.0021669322 | Q3: -0.063427776 | R3: -0.026445759 | S3: -0.030793073 | T3: -0.0013314302 | U3: -0.011667066 | V3: -0.0074396813 | W3: -0.0056037698 | X3: -0.054782856 | Y3: 0.0014601285 | Z3: -0.051124588 | AA3: -0.049931929 | AB3: 0.035460174 | AC3: -0.036260024 | AD3: -0.02177857 | AE3: -0.012961893 | AF3: -0.019972652 | AG3: -0.042137694 | AH3: 0.0011005618 | AI3: 0.0017914374 | AJ3: 0.012323425 | AK3: -0.041931521 | AL3: -0.036095079 | AM3: -0.0013822748 | AN3: -0.028956376 | AO3: -0.042428315 | AP3: -0.049674943 | AQ3: -0.032604296 | AR3: -0.013108823 | AS3: -0.035700481 | AT3: -0.005788805 | AU3: -0.014518599 | AV3: -0.031922929 | AW3: -0.011949936 | AX3: -0.010149507 | AY3: -0.033810735 | AZ3: -0.048453212 | BA3: -0.027815299 | BB3: -0.030379677 | BC3: 0.024711607 | BD3: -0.023138821 | BE3: -0.0015485354 | BF3: 0.048466574 | BG3: -0.0068415171 | BH3: -0.029017322 | BI3: 0.063621186 | BJ3: 0.051039994 | BK3: 0.020570621 | BL3: -0.044453237 | BM3: 0.016062213 | BN3: -0.011407252 | BO3: -0.021107044 | BP3: -0.024570042 | BQ3: 0.00058053539 | BR3: 0.014106971 | BS3: -0.022216966 | BT3: -0.021804685 | BU3: -0.00032476775 | BV3: -0.016946584 | BW3: -0.0091368407 | BX3: -0.024530711 | BY3: -0.013744997 | BZ3: 0.016965671 | CA3: -0.0049971738 | CB3: 0.025937315 | CC3: -0.050457574 | CD3: -0.017129438 | CE3: -0.015958412 | CF3: -0.036173265 | CG3: -0.033427384 | CH3: -0.018980077 | CI3: -0.015892658 | CJ3: -0.019351164 | CK3: -0.036270283 | CL3: 0.02185446 | CM3: -0.030669076 | CN3: -0.03356621 | CO3: -0.057102174 | CP3: -0.014168661 | CQ3: -0.024477812 | CR3: -0.0051261066 | CS3: 0.018650705 | CT3: -0.036899783 | CU3: -0.030328931 | CV3: -0.01596538 | CW3: -0.028334806 | CX3: -0.02261522 | CY3: -0.0081325807 | CZ3: -0.0065493393 | DA3: -0.018719476 | DB3: -0.023759631 | DC3: -0.015671693 | DD3: -0.01952298 | DE3: -0.040282518 | DF3: -0.0088851424 | DG3: 0.00091460929 | DH3: -0.012378844 | DI3: 0.0090523073 | DJ3: -0.019859632 | DK3: -0.022675382 | DL3: -0.042003386 | DM3: -0.027967073 | DN3: 0.0070053488 | DO3: -0.026276816 | DP3: -0.036057945 | DQ3: -0.033415288 | DR3: -0.016046343 | DS3: -0.014641634 | DT3: -0.035933752 | DU3: 0.0030717822 | DV3: -0.015330855 | DW3: -0.01494637 | DX3: -0.011101509 | DY3: -0.0047925967 | DZ3: -0.018466953 | EA3: -0.012543919 | EB3: -0.032696195 | EC3: -0.056490704 | ED3: -0.026412357 | EE3: -0.018078614 | EF3: -0.0036580674
B4: mom12 | C4: 0.028248634 | D4: 0.014183227 | E4: 0.031993348 | F4: 0.0042365594 | G4: 0.012714939 | H4: 0.010832135 | I4: 0.063727826 | J4: 0.014011074 | K4: 0.066770576 | L4: 0.021485414 | M4: 0.028019289 | N4: 0.008423822 | O4: 0.026018109 | P4: 0.0088989316 | Q4: 0.01201281 | R4: 0.0065032719 | S4: -0.00066254294 | T4: 0.011814414 | U4: 0.013395538 | V4: 0.011924206 | W4: 0.027815573 | X4: 2.5693094e-05 | Y4: 0.039316867 | Z4: 0.056920212 | AA4: 0.098233536 | AB4: 0.064750098 | AC4: 0.067361787 | AD4: 0.051507805 | AE4: 0.049662109 | AF4: 0.020239389 | AG4: 0.00093923445 | AH4: -0.011057081 | AI4: 0.016824111 | AJ4: -0.00074724434 | AK4: 0.01140181 | AL4: 0.00044149283 | AM4: -0.017898617 | AN4: -0.010071121 | AO4: 0.0066899019 | AP4: -0.011917489 | AQ4: -0.027241044 | AR4: -0.004914077 | AS4: -0.030879321 | AT4: -0.014748431 | AU4: -0.022974038 | AV4: -0.0022748797 | AW4: -0.016570061 | AX4: -0.01187692 | AY4: -0.02451757 | AZ4: 0.0014865461 | BA4: 0.010297449 | BB4: 0.0025721302 | BC4: 0.003916319 | BD4: -0.0025292612 | BE4: -0.0082999747 | BF4: -0.0046186103 | BG4: -0.0061649741 | BH4: -0.0037486088 | BI4: 0.00596953 | BJ4: -0.008252495 | BK4: -0.0031494102 | BL4: -0.022762906 | BM4: -0.015299521 | BN4: -0.010563814 | BO4: 0.0046637068 | BP4: 0.0046207542 | BQ4: 0.03309983 | BR4: 0.079383321 | BS4: 0.032730803 | BT4: 0.015519017 | BU4: 0.017918561 | BV4: 0.012576747 | BW4: 0.017560082 | BX4: 0.019561546 | BY4: 0.00948299 | BZ4: 0.023618856 | CA4: 0.024344778 | CB4: -0.0084261037 | CC4: 7.1666633e-05 | CD4: 0.0015852515 | CE4: -0.0041839518 | CF4: -0.019255713 | CG4: -0.02450777 | CH4: -0.025543062 | CI4: -0.016113311 | CJ4: -0.023990631 | CK4: -0.030572861 | CL4: -0.033399541 | CM4: -0.013533869 | CN4: -0.016596911 | CO4: -0.012488239 | CP4: -0.015990794 | CQ4: -0.0072096372 | CR4: -0.028411187 | CS4: -0.030072507 | CT4: -0.027659753 | CU4: -0.017069595 | CV4: -0.017912267 | CW4: -0.012390219 | CX4: -0.017721431 | CY4: -0.0019734646 | CZ4: 0.0087843286 | DA4: -0.032751679 | DB4: -0.0091977678 | DC4: -0.0043027769 | DD4: -0.017814325 | DE4: 0.0041021798 | DF4: -0.00723154 | DG4: 0.004289207 | DH4: 0.0095487144 | DI4: 0.0070580319 | DJ4: 0.0068894681 | DK4: 0.0070452648 | DL4: 0.0078367051 | DM4: 0.011320108 | DN4: 0.0033352235 | DO4: 0.013803395 | DP4: 0.010737471 | DQ4: 0.00061118975 | DR4: 0.014212187 | DS4: 0.0017021111 | DT4: 0.0035690044 | DU4: 0.0020074488 | DV4: 0.029247954 | DW4: 0.018428531 | DX4: 0.018775085 | DY4: 0.012516481 | DZ4: 0.018593142 | EA4: 0.018734032 | EB4: 0.011606191 | EC4: 0.031247735 | ED4: 0.018441975 | EE4: 0.0075100353 | EF4: 0.018255115
B5: chmom | C5: -0.030935572 | D5: -0.078517266 | E5: -0.071969844 | F5: -0.0216826 | G5: 0.003931568 | H5: -0.019784926 | I5: -0.010177304 | J5: -0.0082358997 | K5: 0.023635531 | L5: -0.014618007 | M5: 0.02276809 | N5: -0.043634202 | O5: -0.057530195 | P5: -0.061749738 | Q5: -0.064170286 | R5: -0.056614187 | S5: -0.039280273 | T5: -0.045374379 | U5: 0.021098524 | V5: -0.050834861 | W5: -0.043037977 | X5: -0.026595533 | Y5: -0.015138762 | Z5: -0.024952777 | AA5: -0.064031586 | AB5: -0.029604986 | AC5: -0.0019446176 | AD5: 0.0057631759 | AE5: -0.011790563 | AF5: -0.0022569329 | AG5: -0.027719086 | AH5: -0.0021214748 | AI5: -0.029802717 | AJ5: -0.00033187165 | AK5: 0.013484867 | AL5: -0.0078548426 | AM5: -0.021816308 | AN5: 0.010699071 | AO5: 0.0011102274 | AP5: 0.00079638074 | AQ5: -0.0055128955 | AR5: -0.015489822 | AS5: -0.013374983 | AT5: -0.0028082796 | AU5: 0.013588437 | AV5: 0.011518656 | AW5: -0.0051678196 | AX5: -0.017534591 | AY5: -0.012889344 | AZ5: 0.0046084509 | BA5: -0.0037847871 | BB5: -0.0049904352 | BC5: -0.017079908 | BD5: -0.02391563 | BE5: 0.0021333401 | BF5: 0.031931266 | BG5: 0.022714403 | BH5: 0.054914258 | BI5: 0.023081651 | BJ5: 0.041425202 | BK5: -0.045687266 | BL5: -0.024188107 | BM5: -0.045954537 | BN5: -0.052363675 | BO5: -0.06094883 | BP5: -0.046518847 | BQ5: -0.031062063 | BR5: 0.0032680221 | BS5: 0.068480939 | BT5: 0.002156435 | BU5: -0.038370479 | BV5: -0.037749019 | BW5: -0.037364159 | BX5: -0.027728325 | BY5: -0.03027585 | BZ5: -0.043461852 | CA5: -0.031515237 | CB5: -0.031081436 | CC5: -0.035361417 | CD5: -0.033158984 | CE5: -0.023513908 | CF5: -0.012064296 | CG5: -0.0032220706 | CH5: -0.019549627 | CI5: -0.0096641975 | CJ5: -0.0020440889 | CK5: -0.026424447 | CL5: -0.043267768 | CM5: -0.019405793 | CN5: -0.02635004 | CO5: 0.003180597 | CP5: -0.0062574027 | CQ5: -0.013818862 | CR5: -0.021159159 | CS5: -0.018966084 | CT5: -0.029068194 | CU5: -0.051458955 | CV5: -0.024589416 | CW5: -0.047959473 | CX5: -0.024629397 | CY5: -0.027626641 | CZ5: -0.055032276 | DA5: -0.028730303 | DB5: -0.066727802 | DC5: -0.10732984 | DD5: -0.052791093 | DE5: -0.060571522 | DF5: -0.039159801 | DG5: -0.051414531 | DH5: -0.065701395 | DI5: -0.033493325 | DJ5: -0.024839012 | DK5: -0.02238475 | DL5: -0.03650948 | DM5: -0.0039328607 | DN5: -0.0096125035 | DO5: 0.014951462 | DP5: -0.0031372069 | DQ5: -0.0028361599 | DR5: 0.0051981704 | DS5: 0.011405285 | DT5: -0.00064447051 | DU5: -0.012735923 | DV5: -0.021273775 | DW5: -0.011831686 | DX5: -0.0043031299 | DY5: 0.0059299008 | DZ5: -0.0031490331 | EA5: -0.0087568779 | EB5: 0.0047055804 | EC5: -0.014093491 | ED5: -0.0073874481 | EE5: -0.024573959 | EF5: -0.030077245
B6: retvol | C6: 0.022974487 | D6: 0.01708141 | E6: 0.031377148 | F6: 0.016779406 | G6: -0.0013170848 | H6: 0.01384645 | I6: 0.021910241 | J6: 0.012609055 | K6: -0.0050779725 | L6: 0.0058798324 | M6: 0.013324283 | N6: 0.017233521 | O6: -5.6088713e-05 | P6: -0.0062972903 | Q6: 0.024710532 | R6: 0.013924113 | S6: 0.023693526 | T6: 0.019597102 | U6: 0.01067257 | V6: 0.02010666 | W6: 0.00167046 | X6: 0.0025238169 | Y6: 0.0092325034 | Z6: 0.012824959 | AA6: 0.0090660788 | AB6: -0.0012093025 | AC6: -0.006835869 | AD6: 0.0019463961 | AE6: 0.014238626 | AF6: 0.0088263219 | AG6: 0.02088213 | AH6: 0.051983811 | AI6: 0.01881082 | AJ6: 0.016175123 | AK6: 0.017538745 | AL6: 0.019539744 | AM6: 0.012414113 | AN6: -0.0030713342 | AO6: 0.0018124989 | AP6: 0.027226977 | AQ6: 0.015237001 | AR6: 0.020699002 | AS6: 0.018039731 | AT6: 0.01990521 | AU6: 0.013922203 | AV6: 0.014918374 | AW6: 0.0026367004 | AX6: 0.041243367 | AY6: 0.016222967 | AZ6: 0.020173013 | BA6: 0.016433232 | BB6: 0.022108844 | BC6: 0.020426225 | BD6: 0.014836632 | BE6: 0.01464956 | BF6: 0.0098656453 | BG6: 0.0065305722 | BH6: 0.00423531 | BI6: 0.0056681097 | BJ6: 0.0025409893 | BK6: 0.002166657 | BL6: 0.0033819519 | BM6: 0.0040704762 | BN6: 0.0089805722 | BO6: 0.0097311186 | BP6: 0.0048173126 | BQ6: 0.0098657906 | BR6: 0.01376301 | BS6: 0.014573461 | BT6: 0.020938689 | BU6: 0.014000543 | BV6: 0.019158285 | BW6: 0.017214477 | BX6: 0.011270096 | BY6: 0.025030509 | BZ6: 0.031615071 | CA6: 0.025428476 | CB6: 0.11305705 | CC6: 0.027973102 | CD6: 0.0076278588 | CE6: 0.013782011 | CF6: 0.0025310908 | CG6: 0.0017127168 | CH6: -0.0050100181 | CI6: 0.0032922137 | CJ6: 0.088564754 | CK6: 0.012102538 | CL6: 0.013237392 | CM6: 0.010921693 | CN6: 0.0040465407 | CO6: 0.001302311 | CP6: 0.010241216 | CQ6: 0.0059799491 | CR6: -0.0075976653 | CS6: 0.0023250426 | CT6: 0.022010699 | CU6: 0.0023386679 | CV6: 0.00076710118 | CW6: 0.0088794772 | CX6: 0.013562209 | CY6: 0.012153903 | CZ6: 0.01677263 | DA6: 0.014646888 | DB6: 0.017232055 | DC6: 0.013960229 | DD6: 0.0097235097 | DE6: 0.011490203 | DF6: 0.0053679054 | DG6: 0.0068998714 | DH6: 0.00763071 | DI6: 0.011459526 | DJ6: 0.0093496377 | DK6: 0.010472308 | DL6: 0.0099879391 | DM6: 0.014417588 | DN6: 0.015461322 | DO6: 0.072593644 | DP6: 0.066633999 | DQ6: 0.076050833 | DR6: 0.079444081 | DS6: 0.096407637 | DT6: 0.098738469 | DU6: 0.084987722 | DV6: 0.083614707 | DW6: 0.079545408 | DX6: 0.096235953 | DY6: 0.10154732 | DZ6: 0.13149092 | EA6: 0.11485938 | EB6: 0.11237456 | EC6: 0.12511362 | ED6: 0.0316572 | EE6: 0.029610975 | EF6: 0.031239053
B7: maxret | C7: 0.0021774524 | D7: 0.013015066 | E7: 0.0098455846 | F7: 0.0080243433 | G7: -0.0052677239 | H7: 0.001404033 | I7: 0.0033509603 | J7: -0.0040541883 | K7: 0.0016413978 | L7: -0.003604586 | M7: 0.0025401565 | N7: -0.0089025497 | O7: 0.010533438 | P7: 0.0097276494 | Q7: 0.011463934 | R7: 0.020894568 | S7: 0.021158934 | T7: 0.025689144 | U7: 0.024543272 | V7: 0.011583937 | W7: 0.017569646 | X7: 0.087800547 | Y7: 0.050161928 | Z7: 0.031262714 | AA7: 0.0042858967 | AB7: 0.046123538 | AC7: 0.080575474 | AD7: 0.036530923 | AE7: 0.02460568 | AF7: 0.012908366 | AG7: 0.021753384 | AH7: 0.0030683321 | AI7: 0.0085161366 | AJ7: -0.0049905563 | AK7: -0.0040547512 | AL7: 0.0096464334 | AM7: 0.02050478 | AN7: 0.02069281 | AO7: 0.0046984786 | AP7: -0.0045743487 | AQ7: -0.0068781576 | AR7: -0.0098103778 | AS7: -0.0095568029 | AT7: 0.0059230537 | AU7: 0.0014722419 | AV7: 0.028763983 | AW7: 0.026538765 | AX7: 0.0083058588 | AY7: 0.0053748903 | AZ7: 0.01186728 | BA7: 0.011852427 | BB7: 0.032360878 | BC7: 0.014286506 | BD7: 0.007969927 | BE7: -0.00060811342 | BF7: -0.011188488 | BG7: -0.019261265 | BH7: -0.021502297 | BI7: 0.05841824 | BJ7: 0.040143382 | BK7: 0.028391568 | BL7: 0.025553938 | BM7: 0.0096509531 | BN7: 0.0046400707 | BO7: 0.0036845333 | BP7: 0.013291311 | BQ7: 0.0078903371 | BR7: 0.0070404992 | BS7: 0.0071611647 | BT7: 0.014413588 | BU7: 0.011038203 | BV7: 0.023246251 | BW7: 0.023113625 | BX7: 0.07020662 | BY7: 0.061465926 | BZ7: 0.058226619 | CA7: 0.0049403347 | CB7: 0.010325176 | CC7: 0.00055629481 | CD7: 0.025742874 | CE7: 0.026346749 | CF7: 0.020780452 | CG7: 0.019359628 | CH7: 0.02775068 | CI7: 0.024828408 | CJ7: 0.022081017 | CK7: 0.0086565986 | CL7: 0.0070795948 | CM7: 0.0084662102 | CN7: 0.0027852557 | CO7: 0.0060324417 | CP7: 0.0048775836 | CQ7: -0.00088366348 | CR7: -0.0029415216 | CS7: -0.0065762377 | CT7: -0.0050856704 | CU7: 0.037310883 | CV7: 0.030856956 | CW7: 0.019465599 | CX7: 0.021523755 | CY7: 0.030290527 | CZ7: 0.030590203 | DA7: 0.028499866 | DB7: 0.021195518 | DC7: 0.026068831 | DD7: 0.059307549 | DE7: 0.019247701 | DF7: 0.018887985 | DG7: 0.014815512 | DH7: 0.016671358 | DI7: 0.017327722 | DJ7: 0.01561035 | DK7: 0.015836952 | DL7: 0.017583078 | DM7: 0.01280765 | DN7: 0.020481693 | DO7: 0.011080808 | DP7: 0.015453166 | DQ7: 0.01020689 | DR7: 0.012916479 | DS7: 0.019664204 | DT7: 0.022220226 | DU7: 0.023969663 | DV7: 0.014732354 | DW7: 0.013176583 | DX7: 0.017936071 | DY7: 0.016969321 | DZ7: 0.016285731 | EA7: 0.011118081 | EB7: 0.014203252 | EC7: 0.008901258 | ED7: 0.007033038 | EE7: 0.011094453 | EF7: 0.011496754
A8: 選絕對值最大 | C8: {=MATCH(MAX(ABS(C3:C7)), ABS(C3:C7), 0)} -> 1 | D8: {=MATCH(MAX(ABS(D3:D7)), ABS(D3:D7), 0)} -> 3 | E8: {=MATCH(MAX(ABS(E3:E7)), ABS(E3:E7), 0)} -> 3 | F8: {=MATCH(MAX(ABS(F3:F7)), ABS(F3:F7), 0)} -> 1 | G8: {=MATCH(MAX(ABS(G3:G7)), ABS(G3:G7), 0)} -> 1 | H8: {=MATCH(MAX(ABS(H3:H7)), ABS(H3:H7), 0)} -> 3 | I8: {=MATCH(MAX(ABS(I3:I7)), ABS(I3:I7), 0)} -> 2 | J8: {=MATCH(MAX(ABS(J3:J7)), ABS(J3:J7), 0)} -> 1 | ... EF8: {=MATCH(MAX(ABS(EF3:EF7)), ABS(EF3:EF7), 0)} -> 4
C9: =IF(C8=1,"mom1", IF(C8=2,"mom12", IF(C8=3,"chmom", IF(C8=4,"retvol", IF(C8=5,"maxret",""))))) -> mom1 | D9: =IF(D8=1,"mom1", IF(D8=2,"mom12", IF(D8=3,"chmom", IF(D8=4,"retvol", IF(D8=5,"maxret",""))))) -> chmom | E9: =IF(E8=1,"mom1", IF(E8=2,"mom12", IF(E8=3,"chmom", IF(E8=4,"retvol", IF(E8=5,"maxret",""))))) -> chmom | F9: =IF(F8=1,"mom1", IF(F8=2,"mom12", IF(F8=3,"chmom", IF(F8=4,"retvol", IF(F8=5,"maxret",""))))) -> mom1 | G9: =IF(G8=1,"mom1", IF(G8=2,"mom12", IF(G8=3,"chmom", IF(G8=4,"retvol", IF(G8=5,"maxret",""))))) -> mom1 | H9: =IF(H8=1,"mom1", IF(H8=2,"mom12", IF(H8=3,"chmom", IF(H8=4,"retvol", IF(H8=5,"maxret",""))))) -> chmom | I9: =IF(I8=1,"mom1", IF(I8=2,"mom12", IF(I8=3,"chmom", IF(I8=4,"retvol", IF(I8=5,"maxret",""))))) -> mom12 | J9: =IF(J8=1,"mom1", IF(J8=2,"mom12", IF(J8=3,"chmom", IF(J8=4,"retvol", IF(J8=5,"maxret",""))))) -> mom1 | ... EF9: =IF(EF8=1,"mom1", IF(EF8=2,"mom12", IF(EF8=3,"chmom", IF(EF8=4,"retvol", IF(EF8=5,"maxret",""))))) -> retvol
C10: =IF(C8=1,C3,IF(C8=2,C4,IF(C8=3,C5,IF(C8=4,C6,IF(C8=5,C7))))) -> -0.070510313 | D10: =IF(D8=1,D3,IF(D8=2,D4,IF(D8=3,D5,IF(D8=4,D6,IF(D8=5,D7))))) -> -0.078517266 | E10: =IF(E8=1,E3,IF(E8=2,E4,IF(E8=3,E5,IF(E8=4,E6,IF(E8=5,E7))))) -> -0.071969844 | F10: =IF(F8=1,F3,IF(F8=2,F4,IF(F8=3,F5,IF(F8=4,F6,IF(F8=5,F7))))) -> -0.092162974 | G10: =IF(G8=1,G3,IF(G8=2,G4,IF(G8=3,G5,IF(G8=4,G6,IF(G8=5,G7))))) -> -0.090981476 | H10: =IF(H8=1,H3,IF(H8=2,H4,IF(H8=3,H5,IF(H8=4,H6,IF(H8=5,H7))))) -> -0.019784926 | I10: =IF(I8=1,I3,IF(I8=2,I4,IF(I8=3,I5,IF(I8=4,I6,IF(I8=5,I7))))) -> 0.063727826 | J10: =IF(J8=1,J3,IF(J8=2,J4,IF(J8=3,J5,IF(J8=4,J6,IF(J8=5,J7))))) -> -0.042782601 | ... EF10: =IF(EF8=1,EF3,IF(EF8=2,EF4,IF(EF8=3,EF5,IF(EF8=4,EF6,IF(EF8=5,EF7))))) -> 0.031239053
A12: 投資組合 | C12: 公司數 | D12: 964
A13: 等分 | B13: 家數 | C13: 2014/01 | D13: 2014/02 | E13: 2014/03 | F13: 2014/04 | G13: 2014/05 | H13: 2014/06 | I13: 2014/07 | J13: 2014/08 | K13: 2014/09 | L13: 2014/10 | M13: 2014/11 | N13: 2014/12 | O13: 2015/01 | P13: 2015/02 | Q13: 2015/03 | R13: 2015/04 | S13: 2015/05 | T13: 2015/06 | U13: 2015/07 | V13: 2015/08 | W13: 2015/09 | X13: 2015/10 | Y13: 2015/11 | Z13: 2015/12 | AA13: 2016/01 | AB13: 2016/02 | AC13: 2016/03 | AD13: 2016/04 | AE13: 2016/05 | AF13: 2016/06 | AG13: 2016/07 | AH13: 2016/08 | AI13: 2016/09 | AJ13: 2016/10 | AK13: 2016/11 | AL13: 2016/12 | AM13: 2017/01 | AN13: 2017/02 | AO13: 2017/03 | AP13: 2017/04 | AQ13: 2017/05 | AR13: 2017/06 | AS13: 2017/07 | AT13: 2017/08 | AU13: 2017/09 | AV13: 2017/10 | AW13: 2017/11 | AX13: 2017/12 | AY13: 2018/01 | AZ13: 2018/02 | BA13: 2018/03 | BB13: 2018/04 | BC13: 2018/05 | BD13: 2018/06 | BE13: 2018/07 | BF13: 2018/08 | BG13: 2018/09 | BH13: 2018/10 | BI13: 2018/11 | BJ13: 2018/12 | BK13: 2019/01 | BL13: 2019/02 | BM13: 2019/03 | BN13: 2019/04 | BO13: 2019/05 | BP13: 2019/06 | BQ13: 2019/07 | BR13: 2019/08 | BS13: 2019/09 | BT13: 2019/10 | BU13: 2019/11 | BV13: 2019/12 | BW13: 2020/01 | BX13: 2020/02 | BY13: 2020/03 | BZ13: 2020/04 | CA13: 2020/05 | CB13: 2020/06 | CC13: 2020/07 | CD13: 2020/08 | CE13: 2020/09 | CF13: 2020/10 | CG13: 2020/11 | CH13: 2020/12 | CI13: 2021/01 | CJ13: 2021/02 | CK13: 2021/03 | CL13: 2021/04 | CM13: 2021/05 | CN13: 2021/06 | CO13: 2021/07 | CP13: 2021/08 | CQ13: 2021/09 | CR13: 2021/10 | CS13: 2021/11 | CT13: 2021/12 | CU13: 2022/01 | CV13: 2022/02 | CW13: 2022/03 | CX13: 2022/04 | CY13: 2022/05 | CZ13: 2022/06 | DA13: 2022/07 | DB13: 2022/08 | DC13: 2022/09 | DD13: 2022/10 | DE13: 2022/11 | DF13: 2022/12 | DG13: 2023/01 | DH13: 2023/02 | DI13: 2023/03 | DJ13: 2023/04 | DK13: 2023/05 | DL13: 2023/06 | DM13: 2023/07 | DN13: 2023/08 | DO13: 2023/09 | DP13: 2023/10 | DQ13: 2023/11 | DR13: 2023/12 | DS13: 2024/01 | DT13: 2024/02 | DU13: 2024/03 | DV13: 2024/04 | DW13: 2024/05 | DX13: 2024/06 | DY13: 2024/07 | DZ13: 2024/08 | EA13: 2024/09 | EB13: 2024/10 | EC13: 2024/11 | ED13: 2024/12 | EE13: 2025/01 | EF13: 2025/02
A14: 10 | B14: 96 | C14: 0.29562127 | D14: 0.29579885 | E14: 0.31223014 | F14: 0.31619112 | G14: 0.28955698 | H14: 0.30198331 | I14: 0.28076304 | J14: 0.30811007 | K14: 0.25551553 | L14: 0.28512252 | M14: 0.29293717 | N14: 0.26978649 | O14: 0.033855419 | P14: 0.009187813 | Q14: 0.0036922926 | R14: 0.018857347 | S14: -0.010400127 | T14: 0.039154164 | U14: 0.034050841 | V14: 0.012774886 | W14: -0.015833487 | X14: 0.018526807 | Y14: -0.0081941143 | Z14: 0.016844199 | AA14: -0.034925567 | AB14: 0.011733349 | AC14: 0.0024528133 | AD14: 0.014606485 | AE14: -0.047310557 | AF14: 0.037226253 | AG14: -0.010645152 | AH14: -0.00083143259 | AI14: -0.008833542 | AJ14: 0.014792736 | AK14: 0.0035002465 | AL14: -0.028172463 | AM14: 0.01018642 | AN14: -0.028398857 | AO14: -0.035094545 | AP14: -0.00011593659 | AQ14: 0.0068169447 | AR14: -0.0076047465 | AS14: -0.010693768 | AT14: -0.025356079 | AU14: 0.0087458125 | AV14: -0.0018328601 | AW14: -7.4897106e-05 | AX14: 0.0037427824 | AY14: 0.0069931348 | AZ14: -0.0043569513 | BA14: -0.0073738228 | BB14: -0.0033325844 | BC14: 0.0049337918 | BD14: -0.0070471841 | BE14: -0.019972054 | BF14: 0.0062837621 | BG14: 0.0035711131 | BH14: 0.083666686 | BI14: -0.079114243 | BJ14: -0.0082203428 | BK14: 0.01598367 | BL14: 0.0084824333 | BM14: 0.0094280581 | BN14: 0.023430297 | BO14: -0.0072456026 | BP14: 0.027158397 | BQ14: 0.028064502 | BR14: -0.056652371 | BS14: 0.014129938 | BT14: -0.041094473 | BU14: 0.013669865 | BV14: -0.0058086607 | BW14: -0.012734028 | BX14: 0.034835509 | BY14: 0.0057107008 | BZ14: -0.017428342 | CA14: 0.01137036 | CB14: 0.0051536318 | CC14: -0.019729777 | CD14: -0.021597667 | CE14: -0.0034906997 | CF14: -0.037333152 | CG14: 0.034151714 | CH14: 0.0078461011 | CI14: 0.0110822 | CJ14: -0.0051528175 | CK14: -0.015642306 | CL14: -0.081055991 | CM14: -0.0082143853 | CN14: 0.058968745 | CO14: -9.5717325e-05 | CP14: 0.0418224 | CQ14: -0.040079893 | CR14: -0.022438533 | CS14: 0.015178593 | CT14: 0.010719656 | CU14: -0.01002698 | CV14: -0.010830328 | CW14: 0.021778987 | CX14: 0.013771878 | CY14: 0.0019081475 | CZ14: 0.049818835 | DA14: -0.0029251034 | DB14: 0.010544306 | DC14: 0.035590313 | DD14: 1.4532099e-05 | DE14: -0.043065205 | DF14: -0.0055114635 | DG14: -0.032901993 | DH14: -0.0047876524 | DI14: -0.01776744 | DJ14: 0.019733787 | DK14: -0.019272709 | DL14: -0.026820375 | DM14: -0.017381543 | DN14: -0.017102502 | DO14: -0.020508085 | DP14: -0.00065093147 | DQ14: -0.0057251368 | DR14: 0.014115493 | DS14: -0.0030979458 | DT14: -0.0050880895 | DU14: 0.0061003211 | DV14: -0.0076564706 | DW14: -0.00083006673 | DX14: 0.0058533417 | DY14: -0.018883661 | DZ14: -0.030241386 | EA14: 0.010256941 | EB14: 0.01249673 | EC14: 0.001486557 | ED14: 0.018010473 | EE14: -0.0012909397 | EF14: 0.014839088
A15: 20 | B15: 48 | C15: 0.39331188 | D15: 0.3963549 | E15: 0.40431638 | F15: 0.45011884 | G15: 0.39396995 | H15: 0.39233842 | I15: 0.3767573 | J15: 0.42101089 | K15: 0.35518562 | L15: 0.3800904 | M15: 0.41971579 | N15: 0.37367531 | O15: 0.035515573 | P15: 0.010628823 | Q15: 0.016712992 | R15: 0.028785564 | S15: -0.030482854 | T15: 0.05345274 | U15: 0.022228388 | V15: 0.022568189 | W15: -0.014286003 | X15: 0.015769134 | Y15: -0.0018116477 | Z15: 0.035660659 | AA15: -0.052138646 | AB15: -0.0032576149 | AC15: -0.0044018582 | AD15: 0.023871033 | AE15: -0.045846849 | AF15: 0.065917249 | AG15: -0.0087411736 | AH15: 0.019819459 | AI15: -0.024804935 | AJ15: 0.014472795 | AK15: -0.014342491 | AL15: -0.023471247 | AM15: 0.034264019 | AN15: -0.018339292 | AO15: -0.011837745 | AP15: -0.0043498668 | AQ15: 0.019236499 | AR15: 0.0036919017 | AS15: -0.03213816 | AT15: -0.018727579 | AU15: 0.022220706 | AV15: 0.0066898372 | AW15: -0.020913992 | AX15: 0.0011904461 | AY15: 0.034040481 | AZ15: -0.022274403 | BA15: -0.0086804536 | BB15: -0.037682455 | BC15: -0.0016860244 | BD15: 0.0063971764 | BE15: -0.014666555 | BF15: -0.0075911485 | BG15: 0.008388645 | BH15: 0.086679819 | BI15: -0.093452031 | BJ15: -0.034383243 | BK15: 0.020952221 | BL15: 0.01749842 | BM15: 0.020059702 | BN15: 0.018618995 | BO15: -0.005660455 | BP15: 0.041028759 | BQ15: 0.011708171 | BR15: -0.074094909 | BS15: 0.0025179209 | BT15: -0.01771527 | BU15: 0.015907117 | BV15: 0.044142405 | BW15: -0.024125627 | BX15: 0.023708027 | BY15: 0.029153996 | BZ15: -0.020891445 | CA15: 0.028493747 | CB15: 0.025005095 | CC15: -0.029212612 | CD15: -0.028901628 | CE15: 0.018406167 | CF15: 0.0047397015 | CG15: 0.041020337 | CH15: 0.017138792 | CI15: 0.007406634 | CJ15: 0.01321239 | CK15: 0.013444767 | CL15: -0.10334166 | CM15: -0.032208208 | CN15: 0.10292046 | CO15: -0.011370086 | CP15: 0.049128216 | CQ15: -0.06354266 | CR15: -0.05326357 | CS15: -0.021820504 | CT15: 0.011875474 | CU15: -0.011974086 | CV15: -0.03097481 | CW15: 0.02077505 | CX15: 0.0034736558 | CY15: -0.018205109 | CZ15: 0.049122761 | DA15: 0.014664731 | DB15: 0.029569403 | DC15: 0.0035454961 | DD15: 0.0073567451 | DE15: -0.026688068 | DF15: -0.029168816 | DG15: -0.066597429 | DH15: -0.016940775 | DI15: 0.039659984 | DJ15: 0.038611334 | DK15: -0.030272381 | DL15: -0.043054104 | DM15: -0.029771114 | DN15: -0.0015267608 | DO15: -0.025795463 | DP15: -0.0076374981 | DQ15: 0.00045938004 | DR15: -0.002467663 | DS15: 0.019207434 | DT15: 0.0056904499 | DU15: -0.0078709431 | DV15: -0.0062293475 | DW15: 0.0042471667 | DX15: -0.0036317916 | DY15: -0.033335434 | DZ15: -0.029467191 | EA15: 0.018653144 | EB15: 0.0053733036 | EC15: -0.012039813 | ED15: 0.019665626 | EE15: 0.0046482073 | EF15: -0.00042282991
A16: 50 | B16: 19 | C16: 0.5686931 | D16: 0.58304727 | E16: 0.50875996 | F16: 0.7012067 | G16: 0.56764502 | H16: 0.51353529 | I16: 0.52459778 | J16: 0.57452631 | K16: 0.53353306 | L16: 0.52383984 | M16: 0.6622189 | N16: 0.52968663 | O16: 0.068478184 | P16: 0.019746294 | Q16: 0.024762036 | R16: -0.029131345 | S16: -0.08516785 | T16: 0.013326202 | U16: 0.027444889 | V16: -0.021051858 | W16: -0.014010518 | X16: -0.006826167 | Y16: -0.01755346 | Z16: 0.077504967 | AA16: -0.09320599 | AB16: -0.031541049 | AC16: 0.013922593 | AD16: 0.01921809 | AE16: -0.045766445 | AF16: 0.10735393 | AG16: -0.0041558719 | AH16: -0.00094518944 | AI16: -0.06587392 | AJ16: 0.014769621 | AK16: -0.048440554 | AL16: -0.022912714 | AM16: 0.047350532 | AN16: -0.0026452158 | AO16: -0.035452962 | AP16: -0.031143256 | AQ16: 0.067558758 | AR16: 0.038925731 | AS16: -0.049735401 | AT16: -0.0034809151 | AU16: 0.059085209 | AV16: 0.010185368 | AW16: -0.032178126 | AX16: 0.048824772 | AY16: 0.018790188 | AZ16: -0.025958601 | BA16: 0.013575526 | BB16: -0.037817078 | BC16: -0.057375223 | BD16: -0.022258856 | BE16: -0.005623067 | BF16: -0.0055154292 | BG16: -0.011254463 | BH16: 0.093489899 | BI16: -0.034212864 | BJ16: 0.01136275 | BK16: 0.034738169 | BL16: 0.039064744 | BM16: 0.050251896 | BN16: 0.022130917 | BO16: -0.027425149 | BP16: 0.098417959 | BQ16: 0.013578424 | BR16: -0.11254954 | BS16: 0.0010903994 | BT16: 0.061330951 | BU16: 0.003367388 | BV16: 0.072334374 | BW16: -0.05047749 | BX16: -0.0025419882 | BY16: -0.0076570666 | BZ16: 0.0068159629 | CA16: 0.021662672 | CB16: 0.039452833 | CC16: 0.0090658816 | CD16: 0.031381778 | CE16: 0.040838226 | CF16: 0.029202458 | CG16: 0.00073593443 | CH16: -0.0027508871 | CI16: 0.039620771 | CJ16: 0.025473179 | CK16: -0.0043052651 | CL16: -0.094229656 | CM16: -0.045719847 | CN16: 0.084019795 | CO16: -0.0090796999 | CP16: 0.070055971 | CQ16: -0.081929759 | CR16: -0.13305769 | CS16: -0.048241793 | CT16: 0.029899337 | CU16: -0.10598424 | CV16: -0.019031688 | CW16: 0.039286002 | CX16: 0.044870517 | CY16: -0.026444541 | CZ16: 0.033443031 | DA16: 0.044457056 | DB16: 0.1334724 | DC16: -0.10620858 | DD16: -0.0024562593 | DE16: 0.01586771 | DF16: -0.045963065 | DG16: -0.066648697 | DH16: 0.0010066448 | DI16: 0.017637508 | DJ16: 0.11147861 | DK16: -0.058643337 | DL16: -0.054308872 | DM16: -0.10576986 | DN16: 0.016945185 | DO16: -0.052795643 | DP16: -0.0066744724 | DQ16: -0.022091004 | DR16: 0.010223609 | DS16: 0.039002691 | DT16: 0.026047706 | DU16: 0.0085794605 | DV16: -0.031960903 | DW16: 0.02016054 | DX16: -0.055939831 | DY16: -0.044764042 | DZ16: -0.0237305 | EA16: 0.029844709 | EB16: -0.02212064 | EC16: -0.0088992372 | ED16: 0.0069462438 | EE16: -0.016784725 | EF16: 0.019105207
A17: 100 | B17: 10 | C17: 0.70578593 | D17: 0.71806043 | E17: 0.58979494 | F17: 0.91756882 | G17: 0.68479394 | H17: 0.59162455 | I17: 0.5633484 | J17: 0.70177216 | K17: 0.69443187 | L17: 0.64151964 | M17: 0.90573452 | N17: 0.69053013 | O17: 0.10954475 | P17: 0.014468125 | Q17: -0.069735273 | R17: -0.040956074 | S17: -0.073286062 | T17: -0.040580768 | U17: 0.047155577 | V17: -0.00088747123 | W17: -0.033198217 | X17: 0.021082176 | Y17: -0.012681867 | Z17: 0.072942012 | AA17: -0.16338792 | AB17: -0.025216572 | AC17: 0.02409873 | AD17: 0.037805405 | AE17: -0.031114693 | AF17: 0.17329739 | AG17: -0.018162447 | AH17: -0.019528413 | AI17: -0.047927622 | AJ17: -0.030000638 | AK17: -0.085653644 | AL17: -0.061223065 | AM17: 0.15861072 | AN17: 0.027677887 | AO17: -0.020839103 | AP17: -0.077175384 | AQ17: 0.11668327 | AR17: 0.029753374 | AS17: -0.047506168 | AT17: -0.01192887 | AU17: -0.012308077 | AV17: 0.030966 | AW17: -0.081214489 | AX17: 0.010074262 | AY17: 0.046059946 | AZ17: 0.0062275797 | BA17: 0.058968954 | BB17: -0.059131087 | BC17: -0.017544555 | BD17: -0.076794726 | BE17: -0.02665327 | BF17: 0.037606826 | BG17: 0.046645199 | BH17: 0.16308107 | BI17: -0.041037578 | BJ17: 0.055139281 | BK17: 0.040829705 | BL17: 0.084283106 | BM17: 0.025265211 | BN17: 0.013380564 | BO17: -0.014857903 | BP17: 0.07925408 | BQ17: 0.004072175 | BR17: -0.1096683 | BS17: -0.0062500353 | BT17: 0.054440943 | BU17: -0.0044750741 | BV17: 0.092808262 | BW17: -0.14634498 | BX17: 0.0093279871 | BY17: -0.038094766 | BZ17: 0.030885133 | CA17: -0.018009665 | CB17: 0.079453545 | CC17: 0.055771096 | CD17: 0.0079493117 | CE17: 0.053024704 | CF17: 0.0028356415 | CG17: 0.0063658827 | CH17: 0.010157749 | CI17: 0.05202488 | CJ17: 0.021180411 | CK17: -0.069569201 | CL17: -0.035204077 | CM17: 0.062701347 | CN17: 0.1072043 | CO17: 0.037305258 | CP17: 0.15347266 | CQ17: -0.12677704 | CR17: -0.2961227 | CS17: -0.027546867 | CT17: -0.0014671071 | CU17: -0.073679353 | CV17: -0.036577081 | CW17: 0.063888931 | CX17: 0.029677246 | CY17: -0.022930107 | CZ17: 0.028911753 | DA17: 0.022730569 | DB17: 0.11638942 | DC17: -0.11436194 | DD17: -0.010616971 | DE17: 0.019455621 | DF17: -0.030707637 | DG17: -0.048812216 | DH17: -0.026203433 | DI17: 0.1046142 | DJ17: 0.11235574 | DK17: -0.098536991 | DL17: -0.055369241 | DM17: -0.090133817 | DN17: -0.0038424307 | DO17: -0.049829068 | DP17: -0.023175574 | DQ17: -0.066664832 | DR17: -0.0070754532 | DS17: 0.067361012 | DT17: 0.020190551 | DU17: 0.0078847446 | DV17: -0.0076580008 | DW17: 0.077111655 | DX17: -0.053153786 | DY17: -0.0035108425 | DZ17: 0.0087029879 | EA17: 0.019191483 | EB17: 0.030213474 | EC17: -0.044418709 | ED17: 0.011334349 | EE17: -0.030801745 | EF17: 0.020254495
A18: 107 | B18: 9 | C18: 0.73827782 | D18: 0.74848648 | E18: 0.60288717 | F18: 0.97134857 | G18: 0.701867 | H18: 0.60640992 | I18: 0.58066627 | J18: 0.72245849 | K18: 0.71974645 | L18: 0.66351567 | M18: 0.94250078 | N18: 0.71815271 | O18: 0.096541358 | P18: 0.0067810463 | Q18: -0.088476965 | R18: -0.024058414 | S18: -0.12347104 | T18: 0.0079330935 | U18: 0.03256884 | V18: 0.013277878 | W18: -0.035768982 | X18: 0.044956629 | Y18: -0.0061081102 | Z18: 0.058014636 | AA18: -0.17131289 | AB18: -0.0089193648 | AC18: 0.019996469 | AD18: 0.047722018 | AE18: -0.032171098 | AF18: 0.18870238 | AG18: -0.012906273 | AH18: -0.011606988 | AI18: -0.047503493 | AJ18: -0.032237718 | AK18: -0.065937888 | AL18: -0.063904816 | AM18: 0.17121245 | AN18: 0.014745242 | AO18: -0.022695897 | AP18: -0.071761369 | AQ18: 0.12895768 | AR18: 0.039961838 | AS18: -0.064984088 | AT18: -0.0088140588 | AU18: -0.017882078 | AV18: 0.025993573 | AW18: -0.072537595 | AX18: 0.003101712 | AY18: 0.075021252 | AZ18: -0.015398932 | BA18: 0.010837477 | BB18: -0.079484836 | BC18: 0.0022581636 | BD18: -0.079974316 | BE18: -0.020306773 | BF18: 0.044868441 | BG18: 0.06608622 | BH18: 0.13804961 | BI18: -0.046760787 | BJ18: 0.072598638 | BK18: 0.046965088 | BL18: 0.074173114 | BM18: 0.015268058 | BN18: 0.0087436612 | BO18: -0.029603539 | BP18: 0.086689114 | BQ18: 0.0077743508 | BR18: -0.091481773 | BS18: -0.0061396828 | BT18: 0.059012779 | BU18: 0.010422955 | BV18: 0.11634363 | BW18: -0.14464117 | BX18: 0.01220687 | BY18: -0.057959567 | BZ18: 0.0208792 | CA18: -0.023746815 | CB18: 0.077410215 | CC18: 0.069763549 | CD18: -0.021611863 | CE18: -0.0087924931 | CF18: 0.0043310548 | CG18: 0.0058015312 | CH18: -0.0073778632 | CI18: 0.031852736 | CJ18: 0.027137879 | CK18: -0.042457434 | CL18: -0.074558367 | CM18: 0.097720329 | CN18: 0.085183844 | CO18: 0.04565414 | CP18: 0.16927995 | CQ18: -0.11635584 | CR18: -0.13513727 | CS18: -0.031808983 | CT18: -0.0050162431 | CU18: -0.077250392 | CV18: -0.042556163 | CW18: 0.072360085 | CX18: 0.039432633 | CY18: -0.043988666 | CZ18: 0.012520753 | DA18: 0.0081307726 | DB18: 0.1304838 | DC18: -0.099360528 | DD18: -0.0014563112 | DE18: 0.0073854979 | DF18: -0.021283346 | DG18: -0.049363147 | DH18: -0.025255068 | DI18: 0.094352085 | DJ18: 0.12949551 | DK18: -0.1180139 | DL18: -0.084843517 | DM18: -0.11810027 | DN18: -0.0056521014 | DO18: -0.04945722 | DP18: -0.01399498 | DQ18: -0.07021975 | DR18: -0.027337974 | DS18: 0.047322197 | DT18: -0.0036484706 | DU18: -0.0079667563 | DV18: 0.010855974 | DW18: 0.082175676 | DX18: -0.054797165 | DY18: 0.00080457128 | DZ18: 0.0077419073 | EA18: 0.014997464 | EB18: -0.017902482 | EC18: -0.019342095 | ED18: 0.020857561 | EE18: -0.029271984 | EF18: 0.051983527
A19: 120 | B19: 8 | C19: 0.77539547 | D19: 0.77891925 | E19: 0.61873716 | F19: 0.99392066 | G19: 0.72949195 | H19: 0.63393238 | I19: 0.59856354 | J19: 0.75563695 | K19: 0.75565561 | L19: 0.68751196 | M19: 1.0030482 | N19: 0.73723945 | O19: 0.10593459 | P19: 0.0037564315 | Q19: -0.088957239 | R19: -0.032551067 | S19: -0.1713494 | T19: 0.016146217 | U19: 0.053096627 | V19: 0.013219211 | W19: -0.04756092 | X19: 0.049941201 | Y19: -0.0083184169 | Z19: 0.04753617 | AA19: -0.18092472 | AB19: -0.014900977 | AC19: 0.023447598 | AD19: 0.0426396 | AE19: -0.0098710655 | AF19: 0.16905095 | AG19: -0.040367725 | AH19: 0.0091634577 | AI19: -0.037380122 | AJ19: -0.02202459 | AK19: -0.078022998 | AL19: -0.046198397 | AM19: 0.17537508 | AN19: 0.00036767491 | AO19: -0.018434319 | AP19: -0.055217287 | AQ19: 0.13074597 | AR19: 0.035467097 | AS19: -0.031277059 | AT19: -0.0094443398 | AU19: -0.0070224684 | AV19: 0.013706422 | AW19: -0.059530197 | AX19: 0.0018194998 | AY19: 0.10024024 | AZ19: -0.018352182 | BA19: 0.0055056888 | BB19: -0.097082648 | BC19: 0.013459782 | BD19: -0.034166223 | BE19: -0.0331275 | BF19: 0.050654932 | BG19: 0.052510648 | BH19: 0.14159955 | BI19: -0.043402026 | BJ19: 0.081266046 | BK19: 0.057218961 | BL19: 0.077488342 | BM19: 0.014828702 | BN19: 0.039163432 | BO19: -0.037875739 | BP19: 0.10932636 | BQ19: 0.037061816 | BR19: -0.10495501 | BS19: -0.023301685 | BT19: 0.049060124 | BU19: 0.027544578 | BV19: 0.11651514 | BW19: -0.15895738 | BX19: 0.012615336 | BY19: -0.043176706 | BZ19: 0.0036557394 | CA19: -0.044612534 | CB19: 0.018739462 | CC19: 0.059035549 | CD19: -0.046066663 | CE19: -0.0092478857 | CF19: 0.036529416 | CG19: 0.0053694518 | CH19: 0.010461049 | CI19: 0.038984936 | CJ19: 0.010367763 | CK19: -0.038136563 | CL19: -0.082730794 | CM19: 0.10566769 | CN19: 0.10998248 | CO19: 0.073230866 | CP19: 0.16047955 | CQ19: -0.13498191 | CR19: -0.10140672 | CS19: -0.022363405 | CT19: -0.059171097 | CU19: -0.087396345 | CV19: -0.026596483 | CW19: 0.074606038 | CX19: 0.063264389 | CY19: -0.044859379 | CZ19: 0.014107505 | DA19: -0.014893849 | DB19: 0.15141241 | DC19: -0.11860967 | DD19: -0.0048420354 | DE19: 0.033841574 | DF19: -0.020409893 | DG19: -0.061429783 | DH19: -0.018883961 | DI19: 0.1021129 | DJ19: 0.13083847 | DK19: -0.098276066 | DL19: -0.10593818 | DM19: -0.13338112 | DN19: 0.0091614927 | DO19: -0.059615163 | DP19: -0.0052327895 | DQ19: -0.084455165 | DR19: -0.0050224851 | DS19: 0.031569521 | DT19: 0.0077237401 | DU19: 0.0054295704 | DV19: 0.0042263963 | DW19: 0.091952263 | DX19: -0.013938237 | DY19: 0.016347593 | DZ19: 0.00066202956 | EA19: 0.018648376 | EB19: -0.014687622 | EC19: 0.0058054595 | ED19: 0.04018614 | EE19: -0.007645259 | EF19: 0.067478446
A20: 137 | B20: 7 | C20: 0.80947125 | D20: 0.8065159 | E20: 0.63963193 | F20: 1.0414337 | G20: 0.73968599 | H20: 0.65207545 | I20: 0.62490493 | J20: 0.77185517 | K20: 0.80515135 | L20: 0.73060419 | M20: 1.0612139 | N20: 0.7611882 | O20: 0.1127026 | P20: -0.0049267242 | Q20: -0.099682786 | R20: -0.065338911 | S20: -0.1896906 | T20: 0.035205464 | U20: 0.02106465 | V20: -0.0077900161 | W20: -0.00053341979 | X20: 0.046942317 | Y20: 0.01133735 | Z20: 0.067055957 | AA20: -0.14720008 | AB20: -0.02027658 | AC20: 0.015671661 | AD20: 0.043879702 | AE20: -0.015940903 | AF20: 0.19976679 | AG20: -0.064698395 | AH20: 0.020615554 | AI20: -0.05490214 | AJ20: -0.0097395299 | AK20: -0.088275992 | AL20: -0.022146701 | AM20: 0.21669139 | AN20: 0.013075886 | AO20: -0.022320486 | AP20: -0.053549332 | AQ20: 0.18243071 | AR20: 0.016382652 | AS20: -0.077212012 | AT20: -0.00304897 | AU20: -0.0073761624 | AV20: -0.00036281826 | AW20: -0.05744145 | AX20: -0.0051604282 | AY20: 0.09142383 | AZ20: -0.041269185 | BA20: 0.011334949 | BB20: -0.13234267 | BC20: -0.007948008 | BD20: 0.0011628948 | BE20: -0.023242404 | BF20: 0.072855184 | BG20: 0.069370031 | BH20: 0.16010374 | BI20: -0.061305254 | BJ20: 0.088339952 | BK20: 0.046174065 | BL20: 0.083537379 | BM20: 0.04054359 | BN20: 0.03116447 | BO20: -0.040855668 | BP20: 0.13361783 | BQ20: 0.045470403 | BR20: -0.10326149 | BS20: -0.041540018 | BT20: 0.085286708 | BU20: 0.041687941 | BV20: 0.13781727 | BW20: -0.14652591 | BX20: 0.03052463 | BY20: -0.059704276 | BZ20: 0.00067561337 | CA20: -0.059561569 | CB20: 0.00039704267 | CC20: 0.04555689 | CD20: -0.056154178 | CE20: -0.015070662 | CF20: 0.055791711 | CG20: -0.019650045 | CH20: 0.013745448 | CI20: 0.045865635 | CJ20: 0.006426607 | CK20: -0.058303085 | CL20: -0.11829381 | CM20: 0.091881074 | CN20: 0.10824838 | CO20: 0.082399695 | CP20: 0.18631143 | CQ20: -0.13656789 | CR20: -0.12156873 | CS20: -0.0042068597 | CT20: -0.073692119 | CU20: -0.092843794 | CV20: -0.03342502 | CW20: 0.038854033 | CX20: 0.050298119 | CY20: -0.060497961 | CZ20: 0.049441166 | DA20: -0.014641192 | DB20: 0.14544065 | DC20: -0.12354416 | DD20: -0.0033944578 | DE20: 0.06205403 | DF20: -0.021973056 | DG20: -0.063698565 | DH20: -0.0066318002 | DI20: 0.093933971 | DJ20: 0.13447216 | DK20: -0.071929498 | DL20: -0.092496214 | DM20: -0.12095349 | DN20: -0.00742413 | DO20: -0.043407539 | DP20: -0.033456321 | DQ20: -0.080702746 | DR20: -0.013302893 | DS20: 0.044926075 | DT20: 0.0074398147 | DU20: 0.019058526 | DV20: -0.0094277442 | DW20: 0.1129153 | DX20: -0.00053349995 | DY20: -0.0097610512 | DZ20: 0.011349583 | EA20: 0.028383412 | EB20: -0.024334567 | EC20: 0.007403275 | ED20: 0.042521222 | EE20: 0.017521793 | EF20: 0.073131627
A21: 160 | B21: 6 | C21: 0.85469134 | D21: 0.85981288 | E21: 0.6873719 | F21: 1.1154683 | G21: 0.77643468 | H21: 0.67959728 | I21: 0.64356871 | J21: 0.81274475 | K21: 0.85778848 | L21: 0.79248943 | M21: 1.09624 | N21: 0.81746856 | O21: 0.10751491 | P21: 0.002416152 | Q21: -0.11996297 | R21: -0.059781639 | S21: -0.22684984 | T21: 0.020541228 | U21: 0.035269752 | V21: 0.0067159003 | W21: 0.0067172766 | X21: 0.06911173 | Y21: 0.012489569 | Z21: 0.05430593 | AA21: -0.14128544 | AB21: -0.039711825 | AC21: 0.010093584 | AD21: 0.035454153 | AE21: -0.03611675 | AF21: 0.2361471 | AG21: -0.080159601 | AH21: -0.026356627 | AI21: -0.067899571 | AJ21: -0.039168091 | AK21: -0.06206835 | AL21: -0.027223271 | AM21: 0.23868806 | AN21: -0.0054080998 | AO21: -0.11776746 | AP21: -0.066059762 | AQ21: 0.17130346 | AR21: 0.0022443487 | AS21: -0.074415862 | AT21: 0.0039788265 | AU21: 0.031220398 | AV21: -0.005402059 | AW21: -0.048842219 | AX21: -0.032290107 | AY21: 0.067282605 | AZ21: 0.0033305684 | BA21: 0.0002346842 | BB21: -0.1599895 | BC21: -0.0093052995 | BD21: 0.0011950178 | BE21: -0.016292177 | BF21: 0.078578164 | BG21: 0.11567804 | BH21: 0.15920196 | BI21: -0.044007661 | BJ21: 0.089101388 | BK21: 0.066495044 | BL21: 0.099251071 | BM21: 0.032630456 | BN21: 0.090428702 | BO21: -0.075999662 | BP21: 0.15026246 | BQ21: 0.048842509 | BR21: -0.13231543 | BS21: -0.058352729 | BT21: 0.12712836 | BU21: 0.041646779 | BV21: 0.082898608 | BW21: -0.16629998 | BX21: 0.023915355 | BY21: -0.028272016 | BZ21: -0.026436234 | CA21: -0.062796324 | CB21: 0.023837369 | CC21: 0.10059654 | CD21: -0.070589742 | CE21: -0.0088644778 | CF21: 0.048118144 | CG21: -0.02338854 | CH21: 0.011450904 | CI21: 0.039617158 | CJ21: 0.0036200769 | CK21: -0.048523425 | CL21: -0.15378371 | CM21: 0.094026482 | CN21: 0.14956703 | CO21: 0.11250238 | CP21: 0.19805058 | CQ21: -0.22126467 | CR21: -0.15460024 | CS21: 0.043625928 | CT21: -0.10187328 | CU21: -0.073702181 | CV21: -0.058264071 | CW21: 0.027151189 | CX21: 0.049242249 | CY21: -0.081119542 | CZ21: 0.081906295 | DA21: -0.018696524 | DB21: 0.17202789 | DC21: -0.13663152 | DD21: 0.0095778362 | DE21: 0.073760657 | DF21: -0.080758624 | DG21: -0.030551426 | DH21: -0.012274414 | DI21: 0.078957519 | DJ21: 0.14827264 | DK21: -0.010990861 | DL21: -0.05801686 | DM21: -0.17279747 | DN21: -0.038329244 | DO21: -0.053508604 | DP21: -0.053008721 | DQ21: -0.078585762 | DR21: 0.023387955 | DS21: 0.057552841 | DT21: 0.054627215 | DU21: 0.015657831 | DV21: -0.024746391 | DW21: 0.12946161 | DX21: 0.0010756611 | DY21: 0.021405241 | DZ21: 0.028577987 | EA21: 0.043166641 | EB21: 0.01307606 | EC21: 0.012779656 | ED21: 0.074490617 | EE21: 0.025631187 | EF21: 0.1012339
A22: 192 | B22: 5 | C22: 0.89798478 | D22: 0.94543462 | E22: 0.73386991 | F22: 1.1973418 | G22: 0.76583068 | H22: 0.69624214 | I22: 0.67505623 | J22: 0.83838692 | K22: 0.91933407 | L22: 0.80295742 | M22: 1.1686637 | N22: 0.89526736 | O22: 0.11753073 | P22: 0.022332825 | Q22: -0.11453169 | R22: -0.057530545 | S22: -0.28163244 | T22: 0.034378816 | U22: 0.020840616 | V22: 0.057534212 | W22: 0.036572369 | X22: 0.085487622 | Y22: 0.0047431466 | Z22: 0.074027168 | AA22: -0.12390598 | AB22: -0.029838534 | AC22: 0.017221724 | AD22: 0.084152137 | AE22: -0.066617836 | AF22: 0.21306705 | AG22: -0.035531537 | AH22: -0.028150244 | AI22: -0.042319199 | AJ22: -0.050034172 | AK22: -0.054383743 | AL22: -0.094575934 | AM22: 0.20070309 | AN22: -0.027928523 | AO22: -0.15459112 | AP22: -0.10034171 | AQ22: 0.24310312 | AR22: 0.0079033538 | AS22: -0.028971081 | AT22: 0.0099337329 | AU22: 0.014409675 | AV22: -0.0051610685 | AW22: -0.073411248 | AX22: -0.032674181 | AY22: 0.011524899 | AZ22: -0.014955679 | BA22: -0.0081267139 | BB22: -0.14818363 | BC22: -0.016384162 | BD22: 0.048133687 | BE22: -0.014111308 | BF22: 0.076703928 | BG22: 0.11779801 | BH22: 0.10228555 | BI22: -0.059359816 | BJ22: 0.10059798 | BK22: 0.071324544 | BL22: 0.10760522 | BM22: 0.046199085 | BN22: 0.046172829 | BO22: -0.043368169 | BP22: 0.18031495 | BQ22: -0.015210644 | BR22: -0.16110021 | BS22: -0.07338909 | BT22: 0.12423951 | BU22: -0.025096024 | BV22: 0.10644459 | BW22: -0.14965861 | BX22: 0.018271861 | BY22: -0.036573235 | BZ22: 0.021943517 | CA22: -0.055700307 | CB22: -0.0099684615 | CC22: 0.12071584 | CD22: -0.065341472 | CE22: -0.00075636797 | CF22: 0.020681814 | CG22: -0.01892756 | CH22: 0.023059612 | CI22: 0.06673311 | CJ22: -0.011290228 | CK22: -0.05920152 | CL22: -0.1677854 | CM22: 0.060426711 | CN22: 0.1652647 | CO22: 0.16001139 | CP22: 0.20616853 | CQ22: -0.29882955 | CR22: -0.19007887 | CS22: 0.062157143 | CT22: -0.18244318 | CU22: -0.059669284 | CV22: -0.085542168 | CW22: -0.0067954546 | CX22: 0.0097950625 | CY22: -0.10904881 | CZ22: 0.10948324 | DA22: -0.054278231 | DB22: 0.037973494 | DC22: -0.10079786 | DD22: 0.010030554 | DE22: 0.05950349 | DF22: -0.049979404 | DG22: 0.01199474 | DH22: -0.037358449 | DI22: 0.064370661 | DJ22: 0.17245571 | DK22: 0.028400558 | DL22: -0.045152305 | DM22: -0.19107006 | DN22: -0.077746477 | DO22: -0.054920464 | DP22: -0.069092978 | DQ22: -0.0062392528 | DR22: 0.029050769 | DS22: 0.062384152 | DT22: 0.055342801 | DU22: 0.034850029 | DV22: -0.038393355 | DW22: 0.048845142 | DX22: 0.0058677129 | DY22: 0.0187253 | DZ22: 0.047652752 | EA22: 0.045115539 | EB22: -0.0016766847 | EC22: 0.01389284 | ED22: 0.075847776 | EE22: 0.02486761 | EF22: 0.080230117
A23: 241 | B23: 4 | C23: 0.89783897 | D23: 1.0020829 | E23: 0.78060473 | F23: 1.2842884 | G23: 0.80263488 | H23: 0.72491378 | I23: 0.70115461 | J23: 0.88608966 | K23: 1.0262466 | L23: 0.86975802 | M23: 1.2562074 | N23: 0.98784076 | O23: 0.10606485 | P23: 0.030767552 | Q23: -0.19146939 | R23: -0.085418074 | S23: 0.0032310906 | T23: 0.08932482 | U23: 0.036149622 | V23: 0.013187181 | W23: 0.029262157 | X23: 0.079534654 | Y23: -0.0021091063 | Z23: 0.047424042 | AA23: -0.088434892 | AB23: -0.021286599 | AC23: 0.021961258 | AD23: 0.12761676 | AE23: -0.081830038 | AF23: 0.24783001 | AG23: -0.028486473 | AH23: -0.011587424 | AI23: -0.038013934 | AJ23: -0.018953338 | AK23: -0.037866538 | AL23: -0.10161843 | AM23: 0.23315201 | AN23: -0.0040887482 | AO23: -0.087094927 | AP23: -0.11222647 | AQ23: 0.20268033 | AR23: -0.0012455074 | AS23: -0.017496951 | AT23: 0.017084458 | AU23: 0.00694785 | AV23: -0.012762265 | AW23: -0.10772529 | AX23: -0.053576356 | AY23: 0.033665897 | AZ23: 0.01250583 | BA23: -0.027224161 | BB23: -0.098709292 | BC23: 0.025402165 | BD23: -0.021044623 | BE23: -0.061636102 | BF23: 0.087442664 | BG23: 0.1162124 | BH23: 0.049555147 | BI23: -0.059572684 | BJ23: 0.13580723 | BK23: 0.1132077 | BL23: 0.12937905 | BM23: 0.034113212 | BN23: 0.039265043 | BO23: 0.010631558 | BP23: 0.2308866 | BQ23: 0.018280308 | BR23: -0.17751187 | BS23: -0.042872973 | BT23: 0.16568483 | BU23: -0.013224713 | BV23: 0.061813873 | BW23: -0.214527 | BX23: 0.015484343 | BY23: -0.036768693 | BZ23: -0.11756671 | CA23: -0.054048985 | CB23: 0.0012747026 | CC23: 0.075534655 | CD23: -0.081232169 | CE23: 0.003806471 | CF23: 0.024796563 | CG23: 0.052759811 | CH23: 0.050615918 | CI23: 0.049728701 | CJ23: -0.028200575 | CK23: -0.065740089 | CL23: -0.2132961 | CM23: 0.035246237 | CN23: 0.097932665 | CO23: 0.17895133 | CP23: 0.1896817 | CQ23: -0.29565562 | CR23: -0.16736738 | CS23: 0.061774129 | CT23: -0.082919265 | CU23: -0.07599671 | CV23: -0.10124192 | CW23: -0.032629762 | CX23: 0.019190105 | CY23: -0.065949245 | CZ23: 0.15117999 | DA23: -0.077619403 | DB23: 0.050138627 | DC23: -0.10409825 | DD23: 0.011786541 | DE23: 0.019740148 | DF23: -0.040654908 | DG23: -0.014693612 | DH23: -0.049906333 | DI23: 0.058000689 | DJ23: 0.16072931 | DK23: 0.04966873 | DL23: -0.13239744 | DM23: -0.18287767 | DN23: -0.058299937 | DO23: -0.0649367 | DP23: -0.087197178 | DQ23: -6.7701314e-05 | DR23: 0.013294334 | DS23: 0.019041483 | DT23: 0.027505688 | DU23: 0.043993441 | DV23: -0.058315208 | DW23: 0.065352586 | DX23: 0.017664567 | DY23: -0.044315571 | DZ23: 0.061710545 | EA23: 0.055283081 | EB23: 0.0035098692 | EC23: 0.0031858253 | ED23: 0.090028621 | EE23: 0.03613519 | EF23: 0.076086493
A24: 321 | B24: 3 | C24: 0.98736986 | D24: 1.0942713 | E24: 0.8274379 | F24: 1.3518268 | G24: 0.82579708 | H24: 0.69623534 | I24: 0.70311818 | J24: 0.94552338 | K24: 1.187407 | L24: 1.0024727 | M24: 1.4450191 | N24: 1.1048151 | O24: 0.09595127 | P24: 0.01985561 | Q24: -0.34936843 | R24: -0.044469134 | S24: -0.028760067 | T24: 0.1028964 | U24: -0.021715198 | V24: 0.0099829253 | W24: 0.083020961 | X24: 0.10008505 | Y24: -0.021809849 | Z24: 0.030929238 | AA24: -0.073338112 | AB24: -0.011586439 | AC24: 0.035941748 | AD24: 0.049999952 | AE24: -0.081122845 | AF24: 0.27542439 | AG24: 0.027972051 | AH24: 0.035085513 | AI24: -0.15058733 | AJ24: 0.00027868636 | AK24: -0.062743331 | AL24: -0.052143047 | AM24: 0.14555518 | AN24: 0.080952555 | AO24: -0.093240229 | AP24: -0.1664252 | AQ24: 0.40213418 | AR24: 0.04183366 | AS24: -0.051664867 | AT24: 0.032672261 | AU24: -0.048831637 | AV24: -0.0043739625 | AW24: -0.0625178 | AX24: -0.060009664 | AY24: -0.10172032 | AZ24: -0.053830869 | BA24: -0.068409471 | BB24: -0.17617855 | BC24: 0.028321575 | BD24: -0.071088478 | BE24: -0.032158539 | BF24: 0.089507661 | BG24: 0.12525192 | BH24: 0.104416 | BI24: -0.12398409 | BJ24: 0.15814023 | BK24: 0.10890123 | BL24: 0.16992546 | BM24: 0.035128318 | BN24: 0.081554336 | BO24: -0.042193027 | BP24: 0.26185376 | BQ24: 0.01724416 | BR24: -0.16405141 | BS24: -0.016397445 | BT24: 0.048788197 | BU24: -0.016244323 | BV24: 0.10840256 | BW24: -0.17169636 | BX24: -0.019924632 | BY24: 0.064456251 | BZ24: -0.04494227 | CA24: -0.059220121 | CB24: 0.01442319 | CC24: 0.041339583 | CD24: -0.073084911 | CE24: 0.059238449 | CF24: 0.0058746433 | CG24: 0.081567471 | CH24: 0.013783396 | CI24: -0.055946992 | CJ24: -0.025924478 | CK24: -0.11272485 | CL24: -0.2331544 | CM24: 0.11597264 | CN24: 0.11245635 | CO24: 0.21503388 | CP24: 0.23464913 | CQ24: -0.38945649 | CR24: -0.13974246 | CS24: 0.11124118 | CT24: -0.098268996 | CU24: -0.12483203 | CV24: -0.11862389 | CW24: -0.079751655 | CX24: 0.057301938 | CY24: -0.0918293 | CZ24: 0.13417621 | DA24: -0.059841203 | DB24: -0.08565459 | DC24: -0.15157728 | DD24: 0.083019621 | DE24: -0.059402562 | DF24: -0.018396145 | DG24: 0.017490433 | DH24: -0.022988135 | DI24: 0.1114272 | DJ24: 0.11106784 | DK24: 0.16853807 | DL24: -0.17117372 | DM24: -0.19461801 | DN24: -0.078061163 | DO24: -0.06340434 | DP24: -0.060051225 | DQ24: -0.01887133 | DR24: 0.04515224 | DS24: 0.03514798 | DT24: 0.038026243 | DU24: 0.02036838 | DV24: -0.060704285 | DW24: 0.057589342 | DX24: -0.005730256 | DY24: -0.055099335 | DZ24: 0.05825909 | EA24: 0.043144705 | EB24: -0.0098401024 | EC24: -0.00010375916 | ED24: 0.075527698 | EE24: 0.004424791 | EF24: 0.086516089
A25: 482 | B25: 2 | C25: 1.1374397 | D25: 1.2261253 | E25: 0.9101068 | F25: 1.5345969 | G25: 0.85587885 | H25: 0.74148684 | I25: 0.7201831 | J25: 1.0040576 | K25: 1.5174868 | L25: 1.0896013 | M25: 1.7317846 | N25: 1.3608174 | O25: 0.059773044 | P25: 0.0079909749 | Q25: -0.38713792 | R25: -0.098737353 | S25: 0.020493301 | T25: 0.2354145 | U25: 0.011072453 | V25: 0.12534885 | W25: 0.092338815 | X25: 0.17035049 | Y25: -0.024590591 | Z25: 0.052858619 | AA25: -0.2760279 | AB25: 0.089452054 | AC25: 0.061391272 | AD25: 0.0062518696 | AE25: -0.083163666 | AF25: 0.37409482 | AG25: -0.029474732 | AH25: 0.055941234 | AI25: -0.21551305 | AJ25: 0.010058311 | AK25: -0.0588367 | AL25: -0.15757765 | AM25: -0.002580655 | AN25: 0.1441091 | AO25: 0.0017353726 | AP25: -0.087042998 | AQ25: 0.49475647 | AR25: 0.011915452 | AS25: -0.15932192 | AT25: 0.050288746 | AU25: -0.027297663 | AV25: 0.068670672 | AW25: -0.13494266 | AX25: -0.10253922 | AY25: -0.10028846 | AZ25: -0.076368791 | BA25: -0.078045734 | BB25: -0.24970327 | BC25: 0.035272674 | BD25: -0.059785319 | BE25: -0.027421759 | BF25: 0.073070062 | BG25: 0.067099557 | BH25: 0.1118505 | BI25: -0.13778559 | BJ25: 0.15789566 | BK25: 0.15593098 | BL25: 0.18641842 | BM25: 0.16868329 | BN25: 0.19314386 | BO25: -0.12313673 | BP25: 0.11428277 | BQ25: 0.098310589 | BR25: -0.16373106 | BS25: 0.079227316 | BT25: -0.063825999 | BU25: 0.14218127 | BV25: 0.28186182 | BW25: -0.26479648 | BX25: -0.014498279 | BY25: 0.087748084 | BZ25: -0.054114356 | CA25: -0.1235747 | CB25: -0.061107293 | CC25: 0.17671209 | CD25: -0.099177411 | CE25: 0.036594952 | CF25: -0.054035202 | CG25: -0.023533703 | CH25: 0.065836413 | CI25: -0.0067624178 | CJ25: -0.045575141 | CK25: -0.098702133 | CL25: -0.283613 | CM25: 0.098351883 | CN25: -0.015853708 | CO25: 0.29264999 | CP25: 0.27456697 | CQ25: -0.049218855 | CR25: -0.10272701 | CS25: 0.10033933 | CT25: -0.13084377 | CU25: -0.1683791 | CV25: -0.19013957 | CW25: -0.041641378 | CX25: 0.013850792 | CY25: -0.12081705 | CZ25: 0.19361577 | DA25: -0.093976553 | DB25: -0.1350627 | DC25: -0.12577824 | DD25: 0.18257245 | DE25: -0.0271053 | DF25: 0.022446127 | DG25: -0.047603313 | DH25: -0.090540939 | DI25: 0.11467221 | DJ25: 0.10666119 | DK25: 0.11045221 | DL25: -0.020531079 | DM25: -0.28184469 | DN25: -0.039196722 | DO25: -0.079801776 | DP25: -0.086307172 | DQ25: 0.047732242 | DR25: 0.082734453 | DS25: 0.10587729 | DT25: 0.0078580225 | DU25: 0.0797373 | DV25: -0.089230584 | DW25: 0.0016941779 | DX25: -0.025413191 | DY25: -0.081570436 | DZ25: -0.068895317 | EA25: 0.050474176 | EB25: -0.011968492 | EC25: 0.084055452 | ED25: 0.11459046 | EE25: 0.032965079 | EF25: 0.02428345
A26: 964 | B26: 1 | C26: 1.2743168 | D26: 1.5484498 | E26: 1.0878457 | F26: 1.7939017 | G26: 0.81847335 | H26: 0.80669328 | I26: 0.7981047 | J26: 0.9902416 | K26: 2.4095839 | L26: 1.2461443 | M26: 1.9358495 | N26: 1.8998396 | O26: 0.22046376 | P26: -0.012352938 | Q26: -0.0032425111 | R26: -0.2388361 | S26: 0.067547477 | T26: 0.026090402 | U26: 0.017576294 | V26: 0.27540859 | W26: 0.21110575 | X26: 0.1607978 | Y26: -0.052630286 | Z26: -0.082453345 | AA26: -0.18509425 | AB26: 0.12193388 | AC26: 0.046703654 | AD26: -0.46171231 | AE26: -0.19314179 | AF26: 0.49538941 | AG26: 0.14943001 | AH26: 0.11619705 | AI26: -0.38401214 | AJ26: -0.081596995 | AK26: 0.0041856518 | AL26: -0.16007283 | AM26: 0.04512287 | AN26: 0.158177 | AO26: 0.074292187 | AP26: 0.050877885 | AQ26: 0.52024738 | AR26: 0.13531 | AS26: -0.14330079 | AT26: -0.027319332 | AU26: -0.074705995 | AV26: 0.16261077 | AW26: -0.25174311 | AX26: 0.10186693 | AY26: 0.10890619 | AZ26: -0.029000145 | BA26: -0.032014375 | BB26: -0.36846089 | BC26: 0.057786489 | BD26: -0.16356221 | BE26: -0.011316128 | BF26: 0.1552131 | BG26: -0.12085976 | BH26: 0.35757282 | BI26: -0.18118602 | BJ26: 0.16928438 | BK26: 0.15422186 | BL26: 0.19690897 | BM26: 0.37128517 | BN26: 0.34362723 | BO26: -0.22401801 | BP26: 0.21777922 | BQ26: 0.11828987 | BR26: -0.20755395 | BS26: 0.077458059 | BT26: -0.011938024 | BU26: 0.45498428 | BV26: -0.027864034 | BW26: -0.20142979 | BX26: -0.059047937 | BY26: 0.1614651 | BZ26: -0.160591 | CA26: -0.22127264 | CB26: -0.03957119 | CC26: 0.23239978 | CD26: 0.098126602 | CE26: 0.071905694 | CF26: -0.10893221 | CG26: 0.36465886 | CH26: 0.25265698 | CI26: 0.12033188 | CJ26: -0.036949282 | CK26: 0.13933638 | CL26: -0.49854577 | CM26: -0.092976016 | CN26: -0.0584582 | CO26: 0.25125125 | CP26: 0.22531983 | CQ26: -0.15526089 | CR26: 0.017859828 | CS26: 0.10079402 | CT26: -0.25244549 | CU26: -0.22157881 | CV26: -0.11165149 | CW26: -0.085981192 | CX26: 0.036845313 | CY26: -0.064456227 | CZ26: 0.35718348 | DA26: -0.07319918 | DB26: -0.2497581 | DC26: -0.34048223 | DD26: 0.14217003 | DE26: -0.13396346 | DF26: 0.039018254 | DG26: -0.081195889 | DH26: -0.040775633 | DI26: 0.37614904 | DJ26: 0.14423646 | DK26: -0.080864891 | DL26: 0.13067999 | DM26: -0.096084673 | DN26: -0.10052771 | DO26: -0.012249451 | DP26: -0.034800684 | DQ26: 0.084460701 | DR26: 0.17966289 | DS26: 0.13076502 | DT26: -0.0029185654 | DU26: 0.066506497 | DV26: -0.069942612 | DW26: -0.30521969 | DX26: -0.037063051 | DY26: -0.11911462 | DZ26: -0.18891968 | EA26: 0.071593653 | EB26: 4.0830075e-05 | EC26: 0.19436129 | ED26: 0.24781425 | EE26: 0.017018539 | EF26: 0.017684006
A27: 大盤 | B27: TWⅡ | C27: -0.017446771 | D27: 0.020701061 | E27: 0.023982129 | F27: -0.006557579 | G27: 0.03184513 | H27: 0.034348533 | I27: -0.0082549328 | J27: 0.012843524 | K27: -0.051018525 | L27: 0.00087394274 | M27: 0.023389576 | N27: 0.012988972 | O27: 0.0058545887 | P27: 0.027413207 | Q27: -0.0037129361 | R27: 0.024076614 | S27: -0.012190025 | T27: -0.039749578 | U27: -0.07315545 | V27: -0.05826023 | W27: 0.00077279757 | X27: 0.044591521 | Y27: -0.02769968 | Z27: 0.0020950059 | AA27: -0.023400551 | AB27: 0.032129371 | AC27: 0.038903273 | AD27: -0.042865382 | AE27: 0.018647195 | AF27: 0.015229768 | AG27: 0.036016604 | AH27: 0.0093546114 | AI27: 0.010748251 | AJ27: 0.013357754 | AK27: -0.0053327473 | AL27: 0.0013831358 | AM27: 0.020795928 | AN27: 0.031517702 | AO27: 0.0062417165 | AP27: 0.0061452617 | AQ27: 0.016946358 | AR27: 0.03468283 | AS27: 0.0030985886 | AT27: 0.015081347 | AU27: -0.019251209 | AV27: 0.038711513 | AW27: -0.021856951 | AX27: 0.0077743007 | AY27: 0.042397247 | AZ27: -0.026308975 | BA27: 0.0095717493 | BB27: -0.024249741 | BC27: 0.020163374 | BD27: -0.0035049988 | BE27: 0.020151935 | BF27: 0.00058133623 | BG27: -0.005219701 | BH27: -0.11587176 | BI27: 0.0087252257 | BJ27: -0.016377261 | BK27: 0.020840372 | BL27: 0.044975872 | BM27: 0.023954306 | BN27: 0.030239101 | BO27: -0.043725888 | BP27: 0.02188947 | BQ27: 0.0086274303 | BR27: -0.019192954 | BS27: 0.01973513 | BT27: 0.047694337 | BU27: 0.011454817 | BV27: 0.043228621 | BW27: -0.04274743 | BX27: -0.017811292 | BY27: -0.1511531 | BZ27: 0.124224 | CA27: -0.0045572538 | CB27: 0.06021124 | CC27: 0.085992033 | CD27: -0.0058084796 | CE27: -0.006041347 | CF27: 0.0024523244 | CG27: 0.089636252 | CH27: 0.070992733 | CI27: 0.027170643 | CJ27: 0.052468428 | CK27: 0.029480661 | CL27: 0.066825081 | CM27: -0.028772229 | CN27: 0.039462516 | CO27: -0.029031087 | CP27: 0.013983883 | CQ27: -0.032276965 | CR27: 0.0031035766 | CS27: 0.025591856 | CT27: 0.044391886 | CU27: -0.030338959 | CV27: -0.0012579765 | CW27: 0.0023363565 | CX27: -0.064264145 | CY27: 0.012909779 | CZ27: -0.12547709 | DA27: 0.011690683 | DB27: 0.0063378437 | DC27: -0.11730536 | DD27: -0.036010872 | DE27: 0.1389113 | DF27: -0.051143506 | DG27: 0.076731447 | DH27: 0.015508782 | DI27: 0.023223774 | DJ27: -0.018372876 | DK27: 0.062199014 | DL27: 0.020098304 | DM27: 0.01349894 | DN27: -0.030252213 | DO27: -0.017022836 | DP27: -0.021788523 | DQ27: 0.085745625 | DR27: 0.028106744 | DS27: -0.0023031598 | DT27: 0.058471198 | DU27: 0.067658949 | DV27: 0.0050207706 | DW27: 0.037416184 | DX27: 0.084111004 | DY27: -0.036832399 | DZ27: 0.0030917028 | EA27: -0.0019576282 | EB27: 0.026459104 | EC27: -0.024752539 | ED27: 0.034115491 | EE27: 0.021061974 | EF27: -0.020277393
C29: 1101 | D29: 2484 | E29: 1233 | F29: 2524 | G29: 2611 | H29: 1233 | I29: 2379 | J29: 2379 | K29: 2524 | L29: 1233 | M29: 2524 | N29: 1805 | O29: 2538 | P29: 3033 | Q29: 2385 | R29: 3024 | S29: 3024 | T29: 1314 | U29: 3024 | V29: 3024 | W29: 5521 | X29: 2535 | Y29: 3033 | Z29: 5201 | AA29: 2535 | AB29: 5201 | AC29: 5471 | AD29: 5521 | AE29: 2023 | AF29: 2023 | AG29: 3017 | AH29: 3033 | AI29: 1464 | AJ29: 2451 | AK29: 2451 | AL29: 4413 | AM29: 2451 | AN29: 2451 | AO29: 6121 | AP29: 2451 | AQ29: 1805 | AR29: 4416 | AS29: 5523 | AT29: 2524 | AU29: 1436 | AV29: 2338 | AW29: 5212 | AX29: 2338 | AY29: 6186 | AZ29: 5523 | BA29: 5523 | BB29: 5443 | BC29: 3051 | BD29: 5523 | BE29: 3051 | BF29: 3051 | BG29: 3051 | BH29: 6186 | BI29: 6186 | BJ29: 2537 | BK29: 2537 | BL29: 2488 | BM29: 6192 | BN29: 8927 | BO29: 2537 | BP29: 4416 | BQ29: 2537 | BR29: 6128 | BS29: 3002 | BT29: 5007 | BU29: 4109 | BV29: 6128 | BW29: 8085 | BX29: 8927 | BY29: 1737 | BZ29: 6242 | CA29: 6242 | CB29: 8927 | CC29: 8927 | CD29: 6242 | CE29: 8927 | CF29: 6242 | CG29: 8050 | CH29: 6242 | CI29: 6242 | CJ29: 8050 | CK29: 8050 | CL29: 6242 | CM29: 4402 | CN29: 3016 | CO29: 1436 | CP29: 6242 | CQ29: 3016 | CR29: 6242 | CS29: 3005 | CT29: 2493 | CU29: 2423 | CV29: 1734 | CW29: 5306 | CX29: 4402 | CY29: 9904 | CZ29: 8072 | DA29: 5007 | DB29: 9904 | DC29: 8072 | DD29: 6021 | DE29: 3232 | DF29: 2538 | DG29: 2538 | DH29: 5306 | DI29: 2538 | DJ29: 2434 | DK29: 2538 | DL29: 6020 | DM29: 2538 | DN29: 4402 | DO29: 2538 | DP29: 5425 | DQ29: 5425 | DR29: 4402 | DS29: 6291 | DT29: 2031 | DU29: 6291 | DV29: 3232 | DW29: 2538 | DX29: 6291 | DY29: 2538 | DZ29: 2538 | EA29: 8074 | EB29: 8074 | EC29: 3232 | ED29: 4402 | EE29: 2538 | EF29: 2538
